Workbook

Sheet RIEPILOGO CAMPUS
A1: CAMPUS 2025
B2: ISCRITTI | C2: QUOTA | D2: TOTALE | E2: PERIODO | F2: NOTE
A4: ESTIVO PRIMA SETTIMANA | B4: =CAMPUS_ESTIVO!D80 -> 39 | C4: =CAMPUS_ESTIVO!J80 -> 425 | D4: =CAMPUS_ESTIVO!L80 -> 2745 | E4: dal 9 al 13 giugno 2025
A6: ESTIVO SECONDA SETTIMANA | B6: =CAMPUS_ESTIVO!D138 -> 50 | C6: =CAMPUS_ESTIVO!J138 -> 475 | D6: =CAMPUS_ESTIVO!L138 -> 3475 | E6: dal 16 al 20 giugno 2025
A8: ESTIVO TERZA SETTIMANA | B8: =CAMPUS_ESTIVO!D185 -> 34 | C8: =CAMPUS_ESTIVO!J185 -> 300 | D8: =CAMPUS_ESTIVO!L185 -> 2429 | E8: dal 23 al 27 giugno 2025
A10: DANZA PRIMA SETTIMANA | B10: =CAMPUS_DANZA!D46 -> 8 | C10: =CAMPUS_DANZA!J46 -> 75 | D10: =CAMPUS_DANZA!L46 -> 695 | E10: dal 09 al 13 giugno 2025
A12: DANZA SECONDA SETTIMANA | B12: =CAMPUS_DANZA!D97 -> 5 | C12: =CAMPUS_DANZA!J97 -> 25 | D12: =CAMPUS_DANZA!L97 -> 445 | E12: dal 16 al 20 giugno 2025
A14: TOTALE | B14: =SUM(B3:B12) -> 136 | C14: =SUM(C3:C12) -> 1300 | D14: =SUM(D3:D12) -> 9789

Sheet CAMPUS_ESTIVO
A1: CAMPUS ESTIVO - (FINO AL 30/04: 1 settimana = €70; 2 settimane = €130; 3 settimane = €195 ⚫ DAL 01/05: 1 settimana = €100; 2 settimane = €160; 3 settimane = €210)
A2: CHI SCRIVE | B2: VENDITA E PAGAMENTO | C2: DATA PAGAMENTO | D2: COGNOME | E2: NOME | F2: TELEFONO | G2: ETA' | H2: CLASSE | I2: SCUOLA | J2: QUOTA TESS. | K2: SCADENZA TESSERA | L2: QUOTA CAMPUS | M2: CODICE SCONTO | N2: CERTIFICATO | O2: MODULO | P2: PARCO | Q2: EMAIL | R2: DELEGA x RITIRO | S2: CONTATTO/I RITIRANTE/I | T2: NOTE
A3: PRIMA SETTIMANA dal 9 al 13 giugno 2025
A4: Alexandra | B4: ONLINE | C4: 45720 | D4: GRASSO | E4: ANDREA | F4: 3392262465 | G4: 11 | H4: IC MEDIE | I4: SACRO CUORE | J4: 25 | K4: 46141 | L4: 65 | N4: TRUE | O4: TRUE | P4: TRUE | Q4: benedictberger@yahoo.it | R4: GRASSO RENATO oppure esce da sola | S4: 3334283886 | T4: CON BEFFASTI CAMPO// chiedono di essere messe con le bimbe delle medie la seconda settimana arriverà alle 13:00 (tutta la seconda settimana)
A5: Giuditta | B5: ONLINE | C5: 45736 | D5: CASTALDO | E5: CHRISTIAN | F5: 3470407484 | G5: 9 | J5: 25 | K5: 46101 | L5: 65 | N5: TRUE | O5: TRUE | P5: FALSE | Q5: helaf1979@hotmail.it
A6: Estefany | B6: ONLINE | C6: 45743 | D6: ESPOSITO | E6: GIULIA MARIA CHARLOTTE | F6: 3475476654 | G6: 11 | J6: 0 | K6: 45926 | L6: 70 | N6: TRUE | O6: TRUE | P6: FALSE | Q6: rxandreaesposito@yahoo.it
A7: Joel | B7: SEDE Joel | C7: 45747 | D7: ELIA | E7: LUNA | F7: 3420327443 | G7: 8 | H7: 2B | I7: GIULIO ROMANO | K7: 45843 | L7: 70 | N7: TRUE | O7: TRUE | P7: TRUE | Q7: stefania.macis85@gmail.com | R7: NESSUNO | S7: /
A8: Joel | B8: ONLINE | C8: 45747 | D8: FEZZI | E8: ANNA | F8: 3385096459 | G8: 7 | H8: 2A | I8: ALESSANDRO DA FANO | K8: 45812 | L8: 70 | N8: TRUE | O8: TRUE | P8: TRUE | Q8: rachele.jesurum@gmail.com | R8: CARLA BIAGI | S8: 3357026268
A9: Joel | B9: ONLINE | C9: 45747 | D9: DI NEPI | E9: ANNA | F9: 3286850883 | G9: 7 | H9: 2A | I9: DA FANO ALESSANDRO | J9: 0 | K9: 45940 | L9: 70 | N9: TRUE | O9: TRUE | P9: TRUE | Q9: rebecca.treves@gmail.com | R9: JESURUM RACHELE CARLA BIAGI | S9: 3385096459 3385096459
A10: Joel | B10: SEDE Joel | C10: 45748 | D10: ZACCARIELLO | E10: MATTIA | F10: 3383396071 | G10: 7 | H10: 1A | I10: PRIMARIA G. ROMANO | J10: 25 | K10: 46112 | L10: 65 | N10: TRUE | O10: TRUE | P10: TRUE | Q10: raffaella.santoro82@gmail.com | R10: NESSUNO | S10: /
A11: Estefany | B11: SEDE Estefany | C11: 45749 | D11: SAVANCO | E11: GAIA VALERIA | F11: 3393506966 | G11: 11 | H11: 5D | I11: LAVAROZZI | J11: 25 | K11: 46113 | L11: 70 | N11: TRUE | O11: TRUE | P11: TRUE | Q11: gabriellagrimaldi@studiosavanco.it | R11: VINCENZO GRIMALDI | S11: 3473125149
A12: Estefany | B12: ONLINE | C12: 45751 | D12: FOSSATI BELLANI | E12: FRANCESCO | F12: 3358125176 | G12: 9 | H12: 4C | I12: PORTA AGNESI | J12: 0 | K12: 45959 | L12: 65 | N12: TRUE | O12: TRUE | P12: TRUE | Q12: federico32@gmail.com
A13: Alexandra | B13: ONLINE | C13: 45756 | D13: SANTORO | E13: SILVIA | F13: 3485299498 | G13: 10 | H13: 4 C | I13: BAROZZI | J13: 0 | K13: 45927 | L13: 65 | M13: GIUDITTA05CAMPUS | N13: TRUE | O13: TRUE | P13: TRUE | Q13: erika.vetrugno@gmail.com | T13: con de donno Beatrice e Bianca PAKUSEVSKIJ
A14: Giuditta | B14: ONLINE | C14: 45755 | D14: CAPALBO | E14: EMMA | F14: 3343517193 | G14: 10 | H14: 4D | I14: JACOPO BAROZZI | J14: 0 | K14: 45938 | L14: 65 | M14: NURA05CAMPUS | N14: TRUE | O14: TRUE | P14: TRUE | Q14: alice.ruggiero88@gmail.com | R14: RUGGIERO MARCELLO | S14: 3349275758 | T14: NO FOTO (modulo non acconsente)
A15: Giuditta | B15: ONLINE | C15: 45755 | D15: RACCA | E15: IRENE | F15: 3319851991 | G15: 7 | H15: 1 B | I15: PORTA AGNESI | J15: 0 | K15: 46039 | L15: 65 | M15: GIUDITTA05CAMPUS | N15: TRUE | O15: TRUE | P15: TRUE | Q15: federica.anna.santi@gmail.com | R15: DI CREDDO JULIA | S15: 3515419041
A16: Nura | B16: SEDE Nura | C16: 45756 | D16: DE DONNO | E16: BEATRICE | F16: 3496200511 | G16: 9 | H16: 4C | I16: BAROZZI | J16: 0 | K16: 45926 | L16: 65 | M16: NURA05CAMPUS | N16: TRUE | O16: TRUE | P16: TRUE | Q16: elisacamilla.fasulo@gmail.com | R16: CATERINA CONTI | S16: 3389964321 | T16: con Silvia Santoro e Bianca PAKUSEVSKIJ
A17: Giuditta | B17: SEDE Giuditta | C17: 45782 | D17: FERRARI | E17: ADELE | F17: 3286513622 | G17: 9 | H17: 4 C | I17: DIAZ | J17: 25 | K17: 46171 | L17: 75 | M17: GIUDITTA05CAMPUS | N17: TRUE | O17: TRUE | P17: TRUE | Q17: amzinfollino@gmail.com | R17: RAMOS MILAGRO | S17: 3207053206
A18: Giuditta | B18: SEDE Giuditta | C18: 45782 | D18: FERRARI | E18: MATILDE | F18: 3286513622 | G18: 9 | H18: 4 D | I18: DIAZ | J18: 0 | K18: 45936 | L18: 75 | M18: GIUDITTA05CAMPUS | N18: TRUE | O18: TRUE | P18: TRUE | Q18: amzinfollino@gmail.com | R18: RAMOS MILAGRO | S18: 3207053206
A19: Alexandra | B19: ONLINE | C19: 45763 | D19: DE LUCA | E19: VITTORIA | F19: 3931644344 | G19: 8 | J19: 0 | K19: 45921 | L19: 65 | M19: ALEXANDRA05CAMPUS | N19: TRUE | O19: TRUE | P19: FALSE | Q19: sofiapagnoni@hotmail.it
A20: Nura | B20: SEDE Nura | C20: 45762 | D20: TURCONI | E20: DANIELE | F20: 3288011864 | G20: 11 | H20: 1 MEDIA | I20: STEINER | J20: 0 | K20: 45920 | L20: 65 | M20: NURA05CAMPUS | N20: TRUE | O20: TRUE | P20: TRUE | Q20: smileblu@hotmail.com | R20: NESSUNO | T20: USCITA AUTONOMA
A21: Estefany | B21: ONLINE | C21: 45762 | D21: LAVATELLI | E21: ALBA | F21: 3473685878 | G21: 7 | J21: 25 | K21: 46123 | L21: 75 | N21: TRUE | O21: TRUE | P21: FALSE | Q21: lorenzo.lavatelli@gmail.com | T21: MANCA TUTTO
A22: Alexandra | B22: ONLINE | C22: 45762 | D22: MANCINO | E22: BIANCA | F22: 3384272229 | G22: 6 | H22: 1 | I22: montessori bilinghue | J22: 25 | K22: 46126 | L22: 75 | M22: JOEL05CAMPUS | N22: TRUE | O22: TRUE | P22: TRUE | Q22: silviaandena@hotmail.com | R22: PATRIZIA CIDDA (TATA) ATTILIO ANDENA (NONNO) FRANCESCA BONACCORDI (NONNA) | S22: 3343605077 3335688740 3347896169 | T22: DELEGHE OK
A23: Alexandra | B23: SEDE Alexandra | C23: 45765 | D23: VELTRI | E23: FRANCESCO | F23: 3342661250 | G23: 11 | H23: 1 MEDIA | I23: MAJNO | J23: 25 | K23: 46161 | L23: 65 | M23: ALEXANDRA05CAMPUS | N23: TRUE | O23: TRUE | P23: TRUE | Q23: carladalessio24@gmail.com | R23: NESSUNO | T23: USCITA AUTONOMA
N24: FALSE | O24: FALSE | P24: FALSE
A25: Alexandra | B25: ONLINE | C25: 45769 | D25: PAKUSEVSKIJ | E25: BIANCA | F25: 3338026678 | G25: 9 | H25: 4C | I25: BAROZZI | J25: 25 | K25: 46075 | L25: 65 | M25: GIUDITTA05CAMPUS | N25: TRUE | O25: TRUE | P25: TRUE | Q25: elisabettagiovi@gmail.com | R25: BUGA SARAC | S25: 385993247445 | T25: CON DE DONNO BEATRICE E SANTORO SILVIA
A26: Joel | B26: ONLINE | C26: 45768 | D26: MACCHIARULO | E26: VIOLA SARAH | F26: 3446218084 | G26: 6 | H26: 1C | I26: MONTESSORI | J26: 0 | K26: 45768 | L26: 65 | M26: JOEL05CAMPUS | N26: TRUE | O26: TRUE | P26: TRUE | Q26: MAFEMAC@GMAIL.COM
A27: Nura | B27: SEDE Nura | C27: 45770 | D27: KUDHI | E27: CHIARA | F27: 3289715050 | G27: 7 | H27: 1B | I27: g.romano | J27: 0 | K27: 45990 | L27: 65 | M27: NURA05CAMPUS | N27: TRUE | O27: TRUE | P27: TRUE | Q27: ADELINAKUDHI@GMAIL.COM | R27: kudhi sofia | S27: 3271648181
A28: Alexandra | B28: ONLINE | C28: 45779 | D28: DELPERO | E28: OLIVIA | F28: 3471193300 | J28: 0 | K28: 45953 | L28: 65 | M28: ALEXANDRA05CAMPUS | N28: TRUE | O28: TRUE | P28: FALSE | Q28: ilecolla@hotmail.com
A29: Alexandra | B29: ONLINE | C29: 45779 | D29: DELPERO | E29: ANITA | F29: 3471193300 | J29: 0 | K29: 45953 | L29: 65 | M29: ALEXANDRA05CAMPUS | N29: TRUE | O29: TRUE | P29: FALSE | Q29: ilecolla@hotmail.com
A30: Joel | B30: ONLINE | C30: 45776 | D30: CARLONI | E30: EMMA | F30: 3391676729 | G30: 10 | J30: 0 | K30: 45928 | L30: 70 | N30: TRUE | O30: TRUE | P30: FALSE | Q30: avv.farina@gmail.com | R30: VILMA IVETTE FLORES CRUZ
A31: Joel | B31: ONLINE | C31: 45776 | D31: ERCOLI | E31: ANNA | F31: 3737434143 | G31: 10 | J31: 0 | K31: 45928 | L31: 70 | N31: TRUE | O31: TRUE | P31: FALSE | Q31: Giuticone@heidrick.com
A32: Estefany | B32: ONLINE | C32: 45777 | D32: BEFFASTI CAMPO | E32: LEA | F32: 3394587986 | G32: 11 | H32: 1F | I32: MAJNO | J32: 25 | K32: 46141 | L32: 65 | M32: ESTEFANY05CAMPUS | N32: TRUE | O32: FALSE | P32: TRUE | Q32: lara.beffasti@gmail.com | R32: BENEDICT BERGER GIULIA PETRONE Renato Grasso | S32: 3392262465 3240971658 | T32: CON GRASSO ANDREA
A33: Nura | B33: SEDE Nura | C33: 45783 | D33: AQUINO FERNANDES | E33: SOFIA | F33: 3446802240 | G33: 10 | H33: // | I33: // | J33: 25 | K33: 45783 | L33: 65 | M33: NURA05CAMPUS | N33: FALSE | O33: TRUE | P33: TRUE | Q33: vivianasil@gmail.com | R33: mamma e papa | S33: 3446802240 | T33: Non parlano italiano (sono qui x 2 mesi )
A34: Nura | B34: SEDE Nura | C34: 45783 | D34: AQUINO FERNANEDS | E34: ALEXANDRE | F34: 3446802240 | G34: 7 | H34: // | I34: // | J34: 25 | K34: 45783 | L34: 65 | M34: NURA05CAMPUS | N34: FALSE | O34: TRUE | P34: TRUE | Q34: vivianasil@gmail.com | R34: mamma e papa | S34: 3446802240 | T34: Non parlano italiano (sono qui x 2 mesi )
A35: Nura | B35: SEDE Nura | C35: 45783 | D35: AQUINO FERNANDES | E35: SARAH | F35: 3446802240 | G35: 10 | H35: // | I35: // | J35: 25 | K35: 45783 | L35: 65 | M35: NURA05CAMPUS | N35: FALSE | O35: TRUE | P35: TRUE | Q35: vivianasil@gmail.com | R35: mamma e papa | S35: 3446802240 | T35: Non parlano italiano (sono qui x 2 mesi )
A36: Alexandra | B36: SEDE Alexandra | C36: 45793 | D36: DI AGOSTINO | E36: MIA | F36: 3481608088 Mamma | G36: 7 | H36: 2B | I36: PORTA AGNESI | J36: 0 | K36: 45933 | L36: 70 | M36: ALEXANDRA05CAMPUS | N36: TRUE | O36: TRUE | P36: TRUE | Q36: yazahussain@gmail.com | R36: mamma e papa
A37: Joel | B37: SEDE Joel | C37: 45807 | D37: MUTHUKUDA ARACHCHIGE | E37: ELISA MICHELLE | F37: 3889718820 PAPA' | G37: 8 | H37: 2A | K37: 45912 | L37: 70 | M37: JOEL05CAMPUS | N37: TRUE | O37: TRUE | P37: TRUE | Q37: mail2sumudu@gmail.com | R37: MAMMA E PAPA' | S37: 3889718820 3248680783
A38: Nura | B38: SEDE Nura | C38: 45811 | D38: CIONI | E38: BIANCA | F38: 3385785259 | K38: 46175 | L38: 95 | M38: JOEL05CAMPUS | N38: TRUE | O38: TRUE | P38: FALSE
N39: FALSE | O39: FALSE | P39: FALSE
A40: Joel | B40: ONLINE | C40: 45813 | D40: CIONI | E40: THEO | F40: 3385785259 | G40: 10 | H40: 4C | I40: BAROZZI | J40: 25 | K40: 46177 | L40: 95 | M40: JOEL05CAMPUS | N40: TRUE | O40: FALSE | P40: TRUE | Q40: ariagrimaldi@gmail.com | R40: SERENA BUCCI | S40: 3494909989 | T40: con de donno beatrice/ santoro silvia/ cioni bianca
...

Sheet CAMPUS_DANZA
A1: CAMPUS ESTIVO DANZA - (FINO AL 30/04: 1 settimana = €85; 2 settimane = €155 ⚫ DAL 01/05: 1 settimana = €120; 2 settimane = €180)
A2: CHI SCRIVE | B2: VENDITA E PAGAMENTO | C2: DATA PAGAMENTO | D2: COGNOME | E2: NOME | F2: TELEFONO | G2: ETA' | H2: CLASSE | I2: SCUOLA | J2: QUOTA TESS. | K2: SCADENZA TESSERA | L2: QUOTA CAMPUS | M2: CODICE SCONTO | N2: CERTIFICATO | O2: MODULO | P2: PARCO | Q2: EMAIL | R2: DELEGA x RITIRO | S2: CONTATTO/I RITIRANTE/I | T2: NOTE
A3: PRIMA SETTIMANA dal 09 al 13 giugno 2025
A4: Estefany | B4: ONLINE | C4: 45756 | D4: DEL PESCO | E4: VALERY NATALYA MARIA | F4: 3382364460 | G4: 11 | H4: 5E | I4: F.S CABRINI | J4: 25 | K4: 46172 | L4: 85 | N4: TRUE | O4: TRUE | P4: TRUE | Q4: info@andreadelpesco.it | R4: Sig. Canzi Piero Sig. Del pesco Antio | S4: 3333878166 3397949903 | T4: Bambina adottata Fa sapere se può fare le foto
A5: Alexandra | B5: SEDE Alexandra | C5: 45759 | D5: UBOLDI | E5: GRETA | F5: 3483902953 | G5: 12 | H5: 2A MEDIA | I5: ZACCARIA | J5: 25 | K5: 46137 | L5: 75 | M5: ALEXANDRA05CAMPUS | N5: TRUE | O5: TRUE | P5: TRUE | Q5: lucia_tv@yahoo.it | R5: Signora Mariz Bueno | S5: 3518219309
A6: Estefany | B6: SEDE Estefany | C6: 45769 | D6: DE LEONARDIS | E6: ALEXANDRA | F6: 3931092182 | G6: 12 | H6: 2C | I6: MAJNO | J6: 0 | K6: 45922 | L6: 75 | M6: ESTEFANY05CAMPUS | N6: TRUE | O6: TRUE | P6: TRUE | Q6: diana.butenko@alice.it | R6: VIKTOR BUTENKO | S6: 3886458717 | T6: USCITA AUTONOMA
A7: Joel | B7: SEDE Joel | C7: 45775 | D7: COLANGELO | E7: MARIA VITTORIA | F7: 3388208080 | G7: 9 | H7: 4A | I7: LA ZOLLA | J7: 0 | K7: 45947 | L7: 75 | M7: ESTEFANY05CAMPUS | N7: TRUE | O7: TRUE | P7: TRUE | Q7: cristyvittoria@gmail.com
A8: Giuditta | B8: ONLINE | C8: 45773 | D8: CALZOLARI | E8: MADDALENA | F8: 3288392632 | G8: 9 | H8: 4A | I8: G. ROMANO | J8: 0 | K8: 45939 | L8: 85 | N8: TRUE | O8: TRUE | P8: TRUE | Q8: sara.longoni@hotmail.com | R8: FERNANDA DE ARRUDA | S8: 3384468600
A9: Giuditta | B9: ONLINE | C9: 45776 | D9: SCALIA | E9: CAMILLA | F9: 3311889996 3420319120 papà | G9: 10 | H9: 4 C | I9: PORTA AGNESI | J9: 0 | K9: 45916 | L9: 80 | M9: GIUDITTA05CAMPUS | N9: TRUE | O9: TRUE | P9: TRUE | Q9: emanuela.ambrosino.news@skytv.it
A10: Joel | B10: SEDE Joel | C10: 45803 | D10: CAPITANIO | E10: EVA | F10: 3923150058 | G10: 8 | H10: 3C | I10: PORTA AGNESI | J10: 25 | K10: 46166 | L10: 115 | M10: JOEL05CAMPUS | N10: TRUE | O10: TRUE | P10: TRUE | Q10: jody.capitanio@gmail.com | R10: ASPERTI FELICITA 3479025549 | S10: 3479025549 3923150058
A11: Estefany | B11: ONLINE | C11: 45817 | D11: DELVO | E11: BENEDETTA | F11: 3476422978 | J11: 0 | K11: 45932 | L11: 105 | N11: FALSE | O11: TRUE | P11: FALSE | Q11: Moltonisimona@gmail.com
N12: FALSE | O12: FALSE | P12: FALSE
N13: FALSE | O13: FALSE | P13: FALSE
N14: FALSE | O14: FALSE | P14: FALSE
N15: FALSE | O15: FALSE | P15: FALSE
N16: FALSE | O16: FALSE | P16: FALSE
N17: FALSE | O17: FALSE | P17: FALSE
N18: FALSE | O18: FALSE | P18: FALSE
N19: FALSE | O19: FALSE | P19: FALSE
N20: FALSE | O20: FALSE | P20: FALSE
N21: FALSE | O21: FALSE | P21: FALSE
N22: FALSE | O22: FALSE | P22: FALSE
N23: FALSE | O23: FALSE | P23: FALSE
... N45: FALSE | O45: FALSE | P45: FALSE
B46: =COUNTIF(B4:B45, "*") -> 8 | C46: TOTALE | D46: =COUNTIF(D4:D45,"<>") -> 8 | I46: TOTALE | J46: =SUM(J2:J45) -> 75 | L46: =SUM(L4:L45) -> 695 | M46: =COUNTIF(M4:M45, "*") -> 5 | N46: =SUMPRODUCT(--N4:N45) -> 7 | O46: =SUMPRODUCT(--O4:O45) -> 8 | P46: =SUMPRODUCT(--P4:P45) -> 7
A47: SEDE | B47: =COUNTIF(B4:B45, "SEDE*") -> 4
A48: ONLINE | B48: =COUNTIF(B4:B45, "ONLINE") -> 4
A49: SECONDA SETTIMANA dal 16 al 20 giugno 2025
A51: Alexandra | B51: SEDE Alexandra | C51: 45759 | D51: UBOLDI | E51: GRETA | F51: 3483902953 | G51: 12 | H51: 2A MEDIA | I51: ZACCARIA | J51: 0 | K51: 46137 | L51: 75 | N51: FALSE | O51: TRUE | P51: TRUE | Q51: lucia_tvòyahoo..it | R51: Signora Mariz Bueno | S51: 3518219309
A52: Estefany | B52: SEDE Estefany | C52: 45769 | D52: DE LEONARDIS | E52: ALEXANDRA | F52: 3931092182 | G52: 12 | J52: 0 | K52: 45922 | L52: 75 | N52: TRUE | O52: TRUE | P52: TRUE | T52: USCITA AUTONOMA
A53: Joel | B53: SEDE Joel | C53: 45775 | D53: COLANGELO | E53: MARIA VITTORIA | F53: 3388208080 | G53: 9 | H53: 4A | I53: LA ZOLLA | J53: 0 | K53: 45947 | L53: 75 | N53: TRUE | O53: TRUE | P53: TRUE | Q53: cristyvittoria@gmail.com
A54: Estefany | B54: ONLINE | C54: 45803 | D54: TONTINI | E54: ZOE | F54: 3495921431 | G54: 7 | H54: 2A | I54: A. DIAZ | J54: 25 | K54: 46167 | L54: 115 | M54: NURA05CAMPUS | N54: FALSE | O54: TRUE | P54: TRUE | Q54: franchinimia@gmail.com | R54: 3495921431
A55: Estefany | B55: ONLINE | C55: 45817 | D55: DELVO | E55: BENEDETTA | F55: 3476422978 | J55: 0 | K55: 45932 | L55: 105 | N55: FALSE | O55: TRUE | P55: FALSE | Q55: Moltonisimona@gmail.com
N56: FALSE | O56: FALSE | P56: FALSE
N57: FALSE | O57: FALSE | P57: FALSE
N58: FALSE | O58: FALSE | P58: FALSE
N59: FALSE | O59: FALSE | P59: FALSE
N60: FALSE | O60: FALSE | P60: FALSE
N61: FALSE | O61: FALSE | P61: FALSE
N62: FALSE | O62: FALSE | P62: FALSE
...

Sheet PRESENZE CLASSI DIVISE PER COLO
A1: ENTRATA | F1: DATI MINORE | K1: USCITA | P1: RITIRO (delega)
A2: 45817 | B2: 45818 | C2: 45819 | D2: 45820 | E2: 45456 | F2: COGNOME | G2: NOME | H2: TELEFONO | I2: ETA | J2: NOTE | K2: 45817 | L2: 45818 | M2: 45819 | N2: 45820 | O2: 45456
A3: TRUE | B3: FALSE | C3: FALSE | D3: FALSE | E3: FALSE | F3: AQUINO FERNANDES | G3: SOFIA | H3: 3446802240 | I3: 10 | J3: Non parlano italiano (sono qui x 2 mesi ) | K3: FALSE | L3: FALSE | M3: FALSE | N3: FALSE | O3: FALSE | P3: mamma e papa
A4: TRUE | B4: FALSE | C4: FALSE | D4: FALSE | E4: FALSE | F4: AQUINO FERNANDES | G4: SARAH | H4: 3446802240 | I4: 10 | J4: Non parlano italiano (sono qui x 2 mesi ) | K4: FALSE | L4: FALSE | M4: FALSE | N4: FALSE | O4: FALSE | P4: mamma e papa
A5: TRUE | B5: FALSE | C5: FALSE | D5: FALSE | E5: FALSE | F5: AQUINO FERNANEDS | G5: ALEXANDRE | H5: 3446802240 | I5: 7 | J5: Non parlano italiano (sono qui x 2 mesi ) | K5: FALSE | L5: FALSE | M5: FALSE | N5: FALSE | O5: FALSE | P5: mamma e papa
A6: TRUE | B6: FALSE | C6: FALSE | D6: FALSE | E6: FALSE | F6: BEFFASTI CAMPO | G6: LEA | H6: 3394587986 | J6: CON GRASSO ANDREA | K6: FALSE | L6: FALSE | M6: FALSE | N6: FALSE | O6: FALSE
A7: TRUE | B7: FALSE | C7: FALSE | D7: FALSE | E7: FALSE | F7: CALZOLARI | G7: MADDALENA | H7: 3288392632 | I7: 9 | K7: FALSE | L7: FALSE | M7: FALSE | N7: FALSE | O7: FALSE
A8: TRUE | B8: FALSE | C8: FALSE | D8: FALSE | E8: FALSE | F8: CAPALBO | G8: EMMA | H8: 3343517193 | I8: 10 | J8: NO FOTO (modulo non acconsente) | K8: FALSE | L8: FALSE | M8: FALSE | N8: FALSE | O8: FALSE | P8: RUGGIERO MARCELLO
A9: TRUE | B9: FALSE | C9: FALSE | D9: FALSE | E9: FALSE | F9: CAPITANIO | G9: EVA | H9: 3923150058 | I9: 8 | K9: FALSE | L9: FALSE | M9: FALSE | N9: FALSE | O9: FALSE
A10: TRUE | B10: FALSE | C10: FALSE | D10: FALSE | E10: FALSE | F10: CARLONI | G10: EMMA | H10: 3391676729 | I10: 10 | K10: FALSE | L10: FALSE | M10: FALSE | N10: FALSE | O10: FALSE
A11: TRUE | B11: FALSE | C11: FALSE | D11: FALSE | E11: FALSE | F11: CASTALDO | G11: CHRISTIAN | H11: 3470407484 | I11: 9 | K11: FALSE | L11: FALSE | M11: FALSE | N11: FALSE | O11: FALSE
A12: TRUE | B12: FALSE | C12: FALSE | D12: FALSE | E12: FALSE | F12: CIONI | G12: BIANCA | H12: 3385785259 | K12: FALSE | L12: FALSE | M12: FALSE | N12: FALSE | O12: FALSE
A13: TRUE | B13: FALSE | C13: FALSE | D13: FALSE | E13: FALSE | F13: CIONI | G13: THEO | H13: 3385785259 | I13: 10 | K13: FALSE | L13: FALSE | M13: FALSE | N13: FALSE | O13: FALSE
A14: TRUE | B14: FALSE | C14: FALSE | D14: FALSE | E14: FALSE | F14: COLANGELO | G14: MARIA VITTORIA | H14: 3388208080 | I14: 9 | K14: FALSE | L14: FALSE | M14: FALSE | N14: FALSE | O14: FALSE
A15: TRUE | B15: FALSE | C15: FALSE | D15: FALSE | E15: FALSE | F15: DE DONNO | G15: BEATRICE | H15: 3496200511 | I15: 9 | J15: con Silvia Santoro e Bianca PAKUSEVSKIJ | K15: FALSE | L15: FALSE | M15: FALSE | N15: FALSE | O15: FALSE
A16: TRUE | B16: FALSE | C16: FALSE | D16: FALSE | E16: FALSE | F16: DE LEONARDIS | G16: ALEXANDRA | H16: 3931092182 | I16: 12 | K16: FALSE | L16: FALSE | M16: FALSE | N16: FALSE | O16: FALSE
A17: FALSE | B17: FALSE | C17: FALSE | D17: FALSE | E17: FALSE | F17: DE LUCA | G17: VITTORIA | H17: 3931644344 | I17: 8 | K17: FALSE | L17: FALSE | M17: FALSE | N17: FALSE | O17: FALSE
A18: TRUE | B18: FALSE | C18: FALSE | D18: FALSE | E18: FALSE | F18: DEL PESCO | G18: VALERY NATALYA MARIA | H18: 3382364460 | I18: 11 | K18: FALSE | L18: FALSE | M18: FALSE | N18: FALSE | O18: FALSE
A19: TRUE | B19: FALSE | C19: FALSE | D19: FALSE | E19: FALSE | F19: DELPERO | G19: OLIVIA | H19: 3471193300 | I19: 9 | K19: FALSE | L19: FALSE | M19: FALSE | N19: FALSE | O19: FALSE
A20: TRUE | B20: FALSE | C20: FALSE | D20: FALSE | E20: FALSE | F20: DELPERO | G20: ANITA | H20: 3471193300 | I20: 11 | K20: FALSE | L20: FALSE | M20: FALSE | N20: FALSE | O20: FALSE
A21: TRUE | B21: FALSE | C21: FALSE | D21: FALSE | E21: FALSE | F21: DI AGOSTINO | G21: MIA | H21: 3481608088 Mamma | I21: 7 | K21: FALSE | L21: FALSE | M21: FALSE | N21: FALSE | O21: FALSE | P21: mamma e papa
A22: TRUE | B22: FALSE | C22: FALSE | D22: FALSE | E22: FALSE | F22: DI NEPI | G22: ANNA | H22: 3286850883 | I22: 7 | K22: FALSE | L22: FALSE | M22: FALSE | N22: FALSE | O22: FALSE | P22: JESURUM RACHELE
A23: TRUE | B23: FALSE | C23: FALSE | D23: FALSE | E23: FALSE | F23: ELIA | G23: LUNA | H23: 3420327443 | I23: 8 | K23: FALSE | L23: FALSE | M23: FALSE | N23: FALSE | O23: FALSE | P23: NESSUNO
A24: TRUE | B24: FALSE | C24: FALSE | D24: FALSE | E24: FALSE | F24: ERCOLI | G24: ANNA | H24: 3737434143 | I24: 10 | K24: FALSE | L24: FALSE | M24: FALSE | N24: FALSE | O24: FALSE
A25: TRUE | B25: FALSE | C25: FALSE | D25: FALSE | E25: FALSE | F25: ESPOSITO | G25: GIULIA MARIA CHARLOTTE | H25: 3475476654 | I25: 11 | K25: FALSE | L25: FALSE | M25: FALSE | N25: FALSE | O25: FALSE
A26: TRUE | B26: FALSE | C26: FALSE | D26: FALSE | E26: FALSE | F26: FERRARI | G26: ADELE | H26: 3286513622 | I26: 9 | K26: FALSE | L26: FALSE | M26: FALSE | N26: FALSE | O26: FALSE | P26: RAMOS MILAGRO
A27: TRUE | B27: FALSE | C27: FALSE | D27: FALSE | E27: FALSE | F27: FERRARI | G27: MATILDE | H27: 3286513622 | I27: 9 | K27: FALSE | L27: FALSE | M27: FALSE | N27: FALSE | O27: FALSE | P27: RAMOS MILAGRO
A28: TRUE | B28: FALSE | C28: FALSE | D28: FALSE | E28: FALSE | F28: FEZZI | G28: ANNA | H28: 3385096459 | I28: 7 | K28: FALSE | L28: FALSE | M28: FALSE | N28: FALSE | O28: FALSE | P28: CARLA BIAGI
A29: TRUE | B29: FALSE | C29: FALSE | D29: FALSE | E29: FALSE | F29: FOSSATI BELLANI | G29: FRANCESCO | H29: 3358125176 | I29: 9 | K29: FALSE | L29: FALSE | M29: FALSE | N29: FALSE | O29: FALSE
A30: TRUE | B30: FALSE | C30: FALSE | D30: FALSE | E30: FALSE | F30: GRASSO | G30: ANDREA | H30: 3392262465 | I30: 10 | K30: FALSE | L30: FALSE | M30: FALSE | N30: FALSE | O30: FALSE | P30: GRASSO RENATO
A31: TRUE | B31: FALSE | C31: FALSE | D31: FALSE | E31: FALSE | F31: KUDHI | G31: CHIARA | H31: 3289715050 | I31: 7 | K31: FALSE | L31: FALSE | M31: FALSE | N31: FALSE | O31: FALSE | P31: kudhi sofia (la sorella) manca solo il documento
A32: TRUE | B32: FALSE | C32: FALSE | D32: FALSE | E32: FALSE | F32: LAVATELLI | G32: ALBA | H32: 3473685878 | I32: 7 | J32: MANCA TUTTO | K32: FALSE | L32: FALSE | M32: FALSE | N32: FALSE | O32: FALSE
A33: TRUE | B33: FALSE | C33: FALSE | D33: FALSE | E33: FALSE | F33: MACCHIARULO | G33: VIOLA SARAH | H33: 3446218084 | I33: 6 | K33: FALSE | L33: FALSE | M33: FALSE | N33: FALSE | O33: FALSE
A34: TRUE | B34: FALSE | C34: FALSE | D34: FALSE | E34: FALSE | F34: MANCINO | G34: BIANCA | H34: 3384272229 | I34: 6 | K34: FALSE | L34: FALSE | M34: FALSE | N34: FALSE | O34: FALSE | P34: PATRIZIA CIDDA (TATA) ATTILIO ANDENA (NONNO) FRANCESCA BONACCORDI (NONNA)
A35: TRUE | B35: FALSE | C35: FALSE | D35: FALSE | E35: FALSE | F35: MUTHUKUDA ARACHCHIGE | G35: ELISA MICHELLE | H35: 3889718820 PAPA' | I35: 8 | K35: FALSE | L35: FALSE | M35: FALSE | N35: FALSE | O35: FALSE | P35: MAMMA E PAPA'
A36: TRUE | B36: FALSE | C36: FALSE | D36: FALSE | E36: FALSE | F36: NIBALI | G36: CAROLA | H36: 3921028476 | I36: 9 | K36: FALSE | L36: FALSE | M36: FALSE | N36: FALSE | O36: FALSE
A37: TRUE | B37: FALSE | C37: FALSE | D37: FALSE | E37: FALSE | F37: PAKUSEVSKIJ | G37: BIANCA | H37: 3338026678 | I37: 9 | K37: FALSE | L37: FALSE | M37: FALSE | N37: FALSE | O37: FALSE
A38: TRUE | B38: FALSE | C38: FALSE | D38: FALSE | E38: FALSE | F38: RACCA | G38: IRENE | H38: 3319851991 | I38: 7 | K38: FALSE | L38: FALSE | M38: FALSE | N38: FALSE | O38: FALSE | P38: DI CREDDO JULIA
A39: TRUE | B39: FALSE | C39: FALSE | D39: FALSE | E39: FALSE | F39: SANTORO | G39: SILVIA | H39: 3485299498 | I39: 10 | J39: con de donno Beatrice e Bianca PAKUSEVSKIJ | K39: FALSE | L39: FALSE | M39: FALSE | N39: FALSE | O39: FALSE
A40: TRUE | B40: FALSE | C40: FALSE | D40: FALSE | E40: FALSE | F40: SANTORO | G40: GRETA | H40: 3381337223 | I40: 9 | K40: FALSE | L40: FALSE | M40: FALSE | N40: FALSE | O40: FALSE | P40: cristina monteverdi (mamma di colangelo)
...

Sheet  PRESENZE CLASSI DIVISE PER COL
A1: ENTRATA | F1: DATI MINORE | K1: USCITA | P1: RITIRO (delega)
A2: 45824 | B2: 45825 | C2: 45826 | D2: 45827 | E2: 45828 | F2: COGNOME | G2: NOME | H2: TELEFONO | I2: ETA | J2: NOTE | K2: 45824 | L2: 45825 | M2: 45826 | N2: 45827 | O2: 45828
F3: ANDRIOLLO | G3: GIORGIA | H3: 3496004118 mamma 3333207957 papà | I3: 11 | K3: FALSE | L3: FALSE | M3: FALSE
F4: ANTONELLI | G4: VIOLA | H4: 3336388468 | I4: 10 | K4: FALSE | L4: FALSE | M4: FALSE
F5: AQUINDO FERNANEDS | G5: SARAH | H5: 3446802240 | I5: 10 | J5: Non parlano italiano (sono qui x 2 mesi ) | K5: FALSE | L5: FALSE | M5: FALSE
F6: AQUINO FERNANDES | G6: SOFIA | H6: 3446802240 | I6: 10 | J6: Non parlano italiano (sono qui x 2 mesi ) | K6: FALSE | L6: FALSE | M6: FALSE
F7: AQUINO FERNANEDS | G7: ALEXANDRE | H7: 3446802240 | I7: 7 | J7: Non parlano italiano (sono qui x 2 mesi ) | K7: FALSE | L7: FALSE | M7: FALSE
F8: ASPRIELLO | G8: EVA | H8: 3386034714 | I8: 6 | K8: FALSE | L8: FALSE | M8: FALSE
F9: BERMONE | G9: CARLOTTA | H9: 3474852332 | I9: 7 | K9: FALSE | L9: FALSE | M9: FALSE
F10: BOCCHESE | G10: ALESSIA | H10: 3338090911 | I10: 8 | K10: FALSE | L10: FALSE | M10: FALSE
F11: BUZZETTI | G11: DARIO | H11: 3494112527 | I11: 10 | J11: USCITA AUTONOMA IN CLASSE CON TURCCONI | K11: FALSE | L11: FALSE | M11: FALSE
F12: CAPALBO | G12: EMMA | H12: 3343517193 | I12: 10 | J12: NO FOTO (modulo non acconsente) | K12: FALSE | L12: FALSE | M12: FALSE
F13: CASAROTTI | G13: CLOTILDE TERESA | H13: 3338736937 | I13: 8 | K13: FALSE | L13: FALSE | M13: FALSE
F14: CASTALDO | G14: CHRISTIAN | H14: 3470407484 | I14: 9 | K14: FALSE | L14: FALSE | M14: FALSE
F15: COLANGELO | G15: MARIA VITTORIA | H15: 3388208080 | I15: 9 | K15: FALSE | L15: FALSE | M15: FALSE
F16: D'ELIA | G16: AMARANTA | H16: 3473891154 | I16: 8 | K16: FALSE | L16: FALSE | M16: FALSE
F17: DE DONNO | G17: BEATRICE | H17: 3496200511 | I17: 9 | K17: FALSE | L17: FALSE | M17: FALSE
F18: DE LEONARDIS | G18: ALEXANDRA | H18: 3931092182 | I18: 12 | J18: USCITA AUTONOMA | K18: FALSE | L18: FALSE | M18: FALSE
F19: DELPERO | G19: OLIVIA | H19: 3471193300 | I19: 9 | K19: FALSE | L19: FALSE | M19: FALSE
F20: DELPERO | G20: ANITA | H20: 3471193300 | I20: 11 | K20: FALSE | L20: FALSE | M20: FALSE
F21: DELVO | G21: BENEDETTA | H21: 3476422978 | J21: USCITA AUTONOMA | K21: FALSE | L21: FALSE | M21: FALSE
F22: DI AGOSTINO | G22: MIA | H22: 3481608088 Mamma | I22: 7 | K22: FALSE | L22: FALSE | M22: FALSE
F23: ESPOSITO | G23: GIULIA MARIA CHARLOTTE | H23: 3475476654 | I23: 11 | K23: FALSE | L23: FALSE | M23: FALSE
F24: FERMIN | G24: LIAM | I24: 8 | K24: FALSE | L24: FALSE | M24: FALSE
F25: FERMOIN | G25: KATALEYA | I25: 10 | K25: FALSE | L25: FALSE | M25: FALSE
F26: FERRARI | G26: ADELE | H26: 3286513622 | I26: 9 | K26: FALSE | L26: FALSE | M26: FALSE
F27: FERRARI | G27: MATILDE | H27: 3286513622 | I27: 9 | K27: FALSE | L27: FALSE | M27: FALSE
F28: FERRARO | G28: CLARA | H28: 3494909989 | I28: 7 | K28: FALSE | L28: FALSE | M28: FALSE
F29: FIGLIUOLO | G29: CLELIA LUCREZIA | H29: 3496010187 mamma 3206377251 papà | I29: 8 | K29: FALSE | L29: FALSE | M29: FALSE
F30: GRASSO | G30: ANDREA | H30: 3392262465 | I30: 11 | J30: chiedono di essere messe con le bimbe delle medie la seconda settimana arriverà alle 13:00 (tutta la seconda settimana) | K30: FALSE | L30: FALSE | M30: FALSE | P30: π
F31: IRAOUI | G31: NORA | H31: 3476933574 mamma | I31: 9 | K31: FALSE | L31: FALSE | M31: FALSE
F32: KALLIKOURDIS FAKIOLA | G32: ATHENA | H32: 3476546450 | I32: 6 | K32: FALSE | L32: FALSE | M32: FALSE
F33: KUDHUI | G33: CHIARA | H33: 3289715050 | I33: 7 | K33: FALSE | L33: FALSE | M33: FALSE
F34: LAVATELLI | G34: ALBA | H34: 3473685878 | I34: 7 | K34: FALSE | L34: FALSE | M34: FALSE
F35: LUSARDI | G35: SARA | H35: 3470852000 | I35: 11 | K35: FALSE | L35: FALSE | M35: FALSE
F36: MACCHIARULO | G36: VIOLA SARAH | H36: 3446218084 | I36: 6 | K36: FALSE | L36: FALSE | M36: FALSE
F37: MANCINO | G37: BIANCA | H37: 3384272229 | I37: 6 | K37: FALSE | L37: FALSE | M37: FALSE
F38: MURATORE | G38: VIOLA | H38: 3925357044 mamma 3289526050 papà | I38: 8 | K38: FALSE | L38: FALSE | M38: FALSE
F39: MUTHUKUDA ARACHCHIGE | G39: ELISA MICHELLE | H39: 3889718820 PAPA' | I39: 8 | K39: FALSE | L39: FALSE | M39: FALSE
B40: TRUE | F40: NIBALI | G40: CAROLA | H40: 3921028476 | I40: 9 | J40: LUNEDI PORTA MODULO CAMPUS | K40: FALSE | L40: FALSE | M40: FALSE
...

Sheet Foglio8
A1: ENTRATA | F1: DATI MINORE | K1: USCITA | P1: RITIRO (delega)
A2: 45831 | B2: 45832 | C2: 45833 | D2: 45834 | E2: 45835 | F2: COGNOME | G2: NOME | H2: TELEFONO | I2: ETA | J2: NOTE | K2: 45831 | L2: 45832 | M2: 45833 | N2: 45834 | O2: 45835
A3: FALSE | B3: FALSE | C3: FALSE | D3: FALSE | E3: FALSE | F3: ANDRIOLLO | G3: GIORGIA | H3: 3496004118 mamma 3333207957 papà | I3: 11 | K3: FALSE | L3: FALSE | M3: FALSE | N3: FALSE | O3: FALSE
A4: FALSE | B4: FALSE | C4: FALSE | D4: FALSE | E4: FALSE | F4: ANTONELLI | G4: VIOLA | H4: 3336388468 | I4: 10 | K4: FALSE | L4: FALSE | M4: FALSE | N4: FALSE | O4: FALSE
A5: FALSE | B5: FALSE | C5: FALSE | D5: FALSE | E5: FALSE | F5: AQUINDO FERNANEDS | G5: SARAH | H5: 3446802240 | I5: 10 | K5: FALSE | L5: FALSE | M5: FALSE | N5: FALSE | O5: FALSE
A6: FALSE | B6: FALSE | C6: FALSE | D6: FALSE | E6: FALSE | F6: AQUINO FERNANDES | G6: SOFIA | H6: 3446802240 | I6: 10 | K6: FALSE | L6: FALSE | M6: FALSE | N6: FALSE | O6: FALSE
A7: FALSE | B7: FALSE | C7: FALSE | D7: FALSE | E7: FALSE | F7: AQUINO FERNANEDS | G7: ALEXANDRE | H7: 3446802240 | I7: 7 | K7: FALSE | L7: FALSE | M7: FALSE | N7: FALSE | O7: FALSE
A8: FALSE | B8: FALSE | C8: FALSE | D8: FALSE | E8: FALSE | F8: ASPRIELLO | G8: EVA | H8: 3386034714 | I8: 6 | K8: FALSE | L8: FALSE | M8: FALSE | N8: FALSE | O8: FALSE
A9: FALSE | B9: FALSE | C9: FALSE | D9: FALSE | E9: FALSE | F9: BRAULIN | G9: CAMILLA | H9: 3388377033 3478486860 PAPA' | I9: 12 | K9: FALSE | L9: FALSE | M9: FALSE | N9: FALSE | O9: FALSE
A10: FALSE | B10: FALSE | C10: FALSE | D10: FALSE | E10: FALSE | F10: CAPATO | G10: EVA | H10: 3477810049 | I10: 13 | J10: USCITA AUTONOMA | K10: FALSE | L10: FALSE | M10: FALSE | N10: FALSE | O10: FALSE
A11: FALSE | B11: FALSE | C11: FALSE | D11: FALSE | E11: FALSE | F11: CASAROTTI | G11: CLOTILDE TERESA | H11: 3338736937 | I11: 8 | K11: FALSE | L11: FALSE | M11: FALSE | N11: FALSE | O11: FALSE
A12: FALSE | B12: FALSE | C12: FALSE | D12: FALSE | E12: FALSE | F12: CASTALDO | G12: CHRISTIAN | H12: 3470407484 | I12: 9 | K12: FALSE | L12: FALSE | M12: FALSE | N12: FALSE | O12: FALSE
A13: FALSE | B13: FALSE | C13: FALSE | D13: FALSE | E13: FALSE | F13: DE FRANCESCO | G13: MARTINA | H13: 3209250558 | I13: 8 | K13: FALSE | L13: FALSE | M13: FALSE | N13: FALSE | O13: FALSE
A14: FALSE | B14: FALSE | C14: FALSE | D14: FALSE | E14: FALSE | F14: DE LEON | G14: LIAM | K14: FALSE | L14: FALSE | M14: FALSE | N14: FALSE | O14: FALSE
A15: FALSE | B15: FALSE | C15: FALSE | D15: FALSE | E15: FALSE | F15: DELPERO | G15: OLIVIA | H15: 3471193300 | I15: 9 | K15: FALSE | L15: FALSE | M15: FALSE | N15: FALSE | O15: FALSE
A16: FALSE | B16: FALSE | C16: FALSE | D16: FALSE | E16: FALSE | F16: DELPERO | G16: ANITA | H16: 3471193300 | I16: 11 | K16: FALSE | L16: FALSE | M16: FALSE | N16: FALSE | O16: FALSE
A17: FALSE | B17: FALSE | C17: FALSE | D17: FALSE | E17: FALSE | F17: DI AGOSTINO | G17: MIA | H17: 3481608088 Mamma | I17: 7 | K17: FALSE | L17: FALSE | M17: FALSE | N17: FALSE | O17: FALSE
A18: FALSE | B18: FALSE | C18: FALSE | D18: FALSE | E18: FALSE | F18: DONADI | G18: GAIA | H18: 3479808739 | I18: 13 | J18: USCITA DA SOLA | K18: FALSE | L18: FALSE | M18: FALSE | N18: FALSE | O18: FALSE
A19: FALSE | B19: FALSE | C19: FALSE | D19: FALSE | E19: FALSE | F19: DONADI | G19: LUNA | H19: 3479808739 | I19: 11 | J19: USCITA DA SOLA | K19: FALSE | L19: FALSE | M19: FALSE | N19: FALSE | O19: FALSE
A20: FALSE | B20: FALSE | C20: FALSE | D20: FALSE | E20: FALSE | F20: FOSSATI | G20: FRANCESCO | H20: 3358125176 | I20: 9 | K20: FALSE | L20: FALSE | M20: FALSE | N20: FALSE | O20: FALSE
A21: FALSE | B21: FALSE | C21: FALSE | D21: FALSE | E21: FALSE | F21: GERASI | G21: AIDA | H21: 3333169745 | I21: 10 | K21: FALSE | L21: FALSE | M21: FALSE | N21: FALSE | O21: FALSE
A22: FALSE | B22: FALSE | C22: FALSE | D22: FALSE | E22: FALSE | F22: GUSTATO | G22: BEATRICE | H22: 3484483497 | I22: 9 | K22: FALSE | L22: FALSE | M22: FALSE | N22: FALSE | O22: FALSE
A23: FALSE | B23: FALSE | C23: FALSE | D23: FALSE | E23: FALSE | F23: KALLIKOURDIS | G23: ATHENA FAKIOLA | H23: 3476546450 | I23: 6 | K23: FALSE | L23: FALSE | M23: FALSE | N23: FALSE | O23: FALSE
A24: FALSE | B24: FALSE | C24: FALSE | D24: FALSE | E24: FALSE | F24: LUSARDI | G24: SARA | H24: 3470852000 | I24: 11 | K24: FALSE | M24: FALSE | N24: FALSE | O24: FALSE
A25: FALSE | B25: FALSE | C25: FALSE | D25: FALSE | E25: FALSE | F25: MORALES | G25: DALIA | H25: 3336901656 | I25: 8 | K25: FALSE | L25: FALSE | M25: FALSE | N25: FALSE | O25: FALSE
A26: FALSE | B26: FALSE | C26: FALSE | D26: FALSE | E26: FALSE | F26: MORALES | G26: NINA | H26: 3336901656 | I26: 11 | K26: FALSE | L26: FALSE | M26: FALSE | N26: FALSE | O26: FALSE
A27: FALSE | B27: FALSE | C27: FALSE | D27: FALSE | E27: FALSE | F27: MUTHUKUDA ARACHCHIGE | G27: ELISA MICHELLE | H27: 3889718820 PAPA' | I27: 8 | K27: FALSE | L27: FALSE | M27: FALSE | N27: FALSE | O27: FALSE
A28: FALSE | B28: FALSE | C28: FALSE | D28: FALSE | E28: FALSE | F28: NIBALI | G28: CAROLA | H28: 3921028476 | I28: 9 | K28: FALSE | L28: FALSE | M28: FALSE | N28: FALSE | O28: FALSE
A29: FALSE | B29: FALSE | C29: FALSE | D29: FALSE | E29: FALSE | F29: NIBALI | G29: ETTORE | H29: 3921028476 | I29: 8 | K29: FALSE | L29: FALSE | M29: FALSE | N29: FALSE | O29: FALSE
A30: FALSE | B30: FALSE | C30: FALSE | D30: FALSE | E30: FALSE | F30: PRICHARD SALARDI | G30: OLIVIA | H30: 3478413173 mamma 3467050499 papà | I30: 8 | K30: FALSE | L30: FALSE | M30: FALSE | N30: FALSE | O30: FALSE
A31: FALSE | B31: FALSE | C31: FALSE | D31: FALSE | E31: FALSE | F31: ROSSI | G31: ARIANNA MIA | H31: 3468199436 MAMMA 3313787793 PAPA' | I31: 8 | K31: FALSE | L31: FALSE | M31: FALSE | N31: FALSE | O31: FALSE
A32: FALSE | B32: FALSE | C32: FALSE | D32: FALSE | E32: FALSE | F32: SQUERZONI | G32: REBECCA | H32: 3487681579 | I32: 9 | K32: FALSE | L32: FALSE | M32: FALSE | N32: FALSE | O32: FALSE
A33: FALSE | B33: FALSE | C33: FALSE | D33: FALSE | E33: FALSE | F33: VELTRI | G33: FRANCESCO | H33: 3342661250 | I33: 11 | J33: USCITA AUTONOMA | K33: FALSE | L33: FALSE | M33: FALSE | N33: FALSE | O33: FALSE
A34: FALSE | B34: FALSE | C34: FALSE | D34: FALSE | E34: FALSE | F34: VELTRI | G34: GRETA | H34: 3342661250 | I34: 13 | J34: USCITA AUTONOMA | K34: FALSE | L34: FALSE | M34: FALSE | N34: FALSE | O34: FALSE
A35: FALSE | B35: FALSE | C35: FALSE | D35: FALSE | E35: FALSE | F35: ZAMBRANO BETTONI | G35: EMMA | H35: 3331084834 mamma 3383875903 papà | I35: 8 | K35: FALSE | L35: FALSE | M35: FALSE | N35: FALSE | O35: FALSE
A36: FALSE | B36: FALSE | C36: FALSE | D36: FALSE | E36: FALSE | K36: FALSE | L36: FALSE | M36: FALSE | N36: FALSE | O36: FALSE
A37: FALSE | B37: FALSE | C37: FALSE | D37: FALSE | E37: FALSE | K37: FALSE | L37: FALSE | M37: FALSE | N37: FALSE | O37: FALSE
A38: FALSE | B38: FALSE | C38: FALSE | D38: FALSE | E38: FALSE | K38: FALSE | L38: FALSE | M38: FALSE | N38: FALSE | O38: FALSE
A39: FALSE | B39: FALSE | C39: FALSE | D39: FALSE | E39: FALSE | K39: FALSE | L39: FALSE | M39: FALSE | N39: FALSE | O39: FALSE
A40: FALSE | B40: FALSE | C40: FALSE | D40: FALSE | E40: FALSE | K40: FALSE | L40: FALSE | M40: FALSE | N40: FALSE | O40: FALSE
...

Sheet ResocontoCampus
C1: ALEXANDRA | E1: ESTEFANY | G1: GIUDITTA | I1: NURA | K1: JOEL | M1: aa | O1: SANTO | P1: SARA | Q1: MASSI | R1: STAFF | S1: STAFF2 | T1: aa | U1: aa | V1: aa | W1: aa | X1: aa | Y1: aa | Z1: aa | AA1: aa | AB1: aa | AC1: aa
A2: DATA EVENTO | B2: DESCRIZIONE | C2: Sede | D2: Codice | E2: Sede | F2: Codice | G2: Sede | H2: Codice | I2: Sede | J2: Codice | K2: Sede | L2: Codice | M2: Sede | N2: Codice | O2: Codice | P2: Codice | Q2: Codice | R2: Codice | S2: Codice | T2: Codice | U2: Codice | V2: Codice | W2: Codice | X2: Codice | Y2: Codice | Z2: Codice | AA2: Codice | AB2: Codice | AC2: Codice | AD2: TOTALE Sede e Codice | AE2: Bonus Team Vendita
A3: 45817 | B3: CAMPUS_ESTIVO | C3: =COUNTIF(INDIRECT("'"&$B3&"'!$B:$B"),"*"&C$1&"*")- COUNTIFS(INDIRECT("'"&$B3&"'!$B:$B"),"*"&C$1&"*",INDIRECT("'"&$B3&"'!$M:$M"),"*") -> 5 | D3: =COUNTIF(INDIRECT("'"&$B3&"'!$M:$M"),"*"&C$1&"*") -> 12 | E3: =COUNTIF(INDIRECT("'"&$B3&"'!$B:$B"),"*"&E$1&"*")- COUNTIFS(INDIRECT("'"&$B3&"'!$B:$B"),"*"&E$1&"*",INDIRECT("'"&$B3&"'!$M:$M"),"*") -> 6 | F3: =COUNTIF(INDIRECT("'"&$B3&"'!$M:$M"),"*"&E$1&"*") -> 13 | G3: =COUNTIF(INDIRECT("'"&$B3&"'!$B:$B"),"*"&G$1&"*")- COUNTIFS(INDIRECT("'"&$B3&"'!$B:$B"),"*"&G$1&"*",INDIRECT("'"&$B3&"'!$M:$M"),"*") -> 4 | H3: =COUNTIF(INDIRECT("'"&$B3&"'!$M:$M"),"*"&G$1&"*") -> 9 | I3: =COUNTIF(INDIRECT("'"&$B3&"'!$B:$B"),"*"&I$1&"*")- COUNTIFS(INDIRECT("'"&$B3&"'!$B:$B"),"*"&I$1&"*",INDIRECT("'"&$B3&"'!$M:$M"),"*") -> 10 | J3: =COUNTIF(INDIRECT("'"&$B3&"'!$M:$M"),"*"&I$1&"*") -> 10 | K3: =COUNTIF(INDIRECT("'"&$B3&"'!$B:$B"),"*"&K$1&"*")- COUNTIFS(INDIRECT("'"&$B3&"'!$B:$B"),"*"&K$1&"*",INDIRECT("'"&$B3&"'!$M:$M"),"*") -> 7 | L3: =COUNTIF(INDIRECT("'"&$B3&"'!$M:$M"),"*"&K$1&"*") -> 8 | M3: =COUNTIF(INDIRECT("'"&$B3&"'!$B:$B"),"*"&M$1&"*")- COUNTIFS(INDIRECT("'"&$B3&"'!$B:$B"),"*"&M$1&"*",INDIRECT("'"&$B3&"'!$M:$M"),"*") -> 0 | N3: =COUNTIF(INDIRECT("'"&$B3&"'!$M:$M"),"*"&M$1&"*") -> 0 | O3: =COUNTIF(INDIRECT("'"&$B3&"'!$M:$M"),"*"&O$1&"*") -> 0 | P3: =COUNTIF(INDIRECT("'"&$B3&"'!$M:$M"),"*"&P$1&"*") -> 0 | Q3: =COUNTIF(INDIRECT("'"&$B3&"'!$M:$M"),"*"&Q$1&"*") -> 0 | R3: =COUNTIF(INDIRECT("'"&$B3&"'!$M:$M"),"*"&R$1&"*") -> 0 | S3: =COUNTIF(INDIRECT("'"&$B3&"'!$M:$M"),"*"&S$1&"*") -> 0 | AD3: =SUM(C3:AC3) -> 84 | AE3: =AD3*1 -> 84
A4: 45817 | B4: CAMPUS_DANZA | C4: =COUNTIF(INDIRECT("'"&$B4&"'!$B:$B"),"*"&C$1&"*")- COUNTIFS(INDIRECT("'"&$B4&"'!$B:$B"),"*"&C$1&"*",INDIRECT("'"&$B4&"'!$M:$M"),"*") -> 1 | D4: =COUNTIF(INDIRECT("'"&$B4&"'!$M:$M"),"*"&C$1&"*") -> 1 | E4: =COUNTIF(INDIRECT("'"&$B4&"'!$B:$B"),"*"&E$1&"*")- COUNTIFS(INDIRECT("'"&$B4&"'!$B:$B"),"*"&E$1&"*",INDIRECT("'"&$B4&"'!$M:$M"),"*") -> 1 | F4: =COUNTIF(INDIRECT("'"&$B4&"'!$M:$M"),"*"&E$1&"*") -> 2 | G4: =COUNTIF(INDIRECT("'"&$B4&"'!$B:$B"),"*"&G$1&"*")- COUNTIFS(INDIRECT("'"&$B4&"'!$B:$B"),"*"&G$1&"*",INDIRECT("'"&$B4&"'!$M:$M"),"*") -> 0 | H4: =COUNTIF(INDIRECT("'"&$B4&"'!$M:$M"),"*"&G$1&"*") -> 1 | I4: =COUNTIF(INDIRECT("'"&$B4&"'!$B:$B"),"*"&I$1&"*")- COUNTIFS(INDIRECT("'"&$B4&"'!$B:$B"),"*"&I$1&"*",INDIRECT("'"&$B4&"'!$M:$M"),"*") -> 0 | J4: =COUNTIF(INDIRECT("'"&$B4&"'!$M:$M"),"*"&I$1&"*") -> 1 | K4: =COUNTIF(INDIRECT("'"&$B4&"'!$B:$B"),"*"&K$1&"*")- COUNTIFS(INDIRECT("'"&$B4&"'!$B:$B"),"*"&K$1&"*",INDIRECT("'"&$B4&"'!$M:$M"),"*") -> 1 | L4: =COUNTIF(INDIRECT("'"&$B4&"'!$M:$M"),"*"&K$1&"*") -> 1 | M4: =COUNTIF(INDIRECT("'"&$B4&"'!$B:$B"),"*"&M$1&"*")- COUNTIFS(INDIRECT("'"&$B4&"'!$B:$B"),"*"&M$1&"*",INDIRECT("'"&$B4&"'!$M:$M"),"*") -> 0 | N4: =COUNTIF(INDIRECT("'"&$B4&"'!$M:$M"),"*"&M$1&"*") -> 0 | O4: =COUNTIF(INDIRECT("'"&$B4&"'!$M:$M"),"*"&O$1&"*") -> 0 | P4: =COUNTIF(INDIRECT("'"&$B4&"'!$M:$M"),"*"&P$1&"*") -> 0 | Q4: =COUNTIF(INDIRECT("'"&$B4&"'!$M:$M"),"*"&Q$1&"*") -> 0 | R4: =COUNTIF(INDIRECT("'"&$B4&"'!$M:$M"),"*"&R$1&"*") -> 0 | S4: =COUNTIF(INDIRECT("'"&$B4&"'!$M:$M"),"*"&S$1&"*") -> 0 | AD4: =SUM(C4:AC4) -> 9 | AE4: =AD4*1 -> 9
AD5: =SUM(C5:AC5) -> 0 | AE5: =AD5*1 -> 0
AD6: =SUM(C6:AC6) -> 0 | AE6: =AD6*1 -> 0
AD7: =SUM(C7:AC7) -> 0 | AE7: =AD7*1 -> 0
AD8: =SUM(C8:AC8) -> 0 | AE8: =AD8*1 -> 0
AD9: =SUM(C9:AC9) -> 0 | AE9: =AD9*1 -> 0
AD10: =SUM(C10:AC10) -> 0 | AE10: =AD10*1 -> 0
AD11: =SUM(C11:AC11) -> 0 | AE11: =AD11*1 -> 0
AD12: =SUM(C12:AC12) -> 0 | AE12: =AD12*1 -> 0
AD13: =SUM(C13:AC13) -> 0 | AE13: =AD13*1 -> 0
AD14: =SUM(C14:AC14) -> 0 | AE14: =AD14*1 -> 0
AD15: =SUM(C15:AC15) -> 0 | AE15: =AD15*1 -> 0
AD16: =SUM(C16:AC16) -> 0 | AE16: =AD16*1 -> 0
... AD29: =SUM(C29:AC29) -> 0 | AE29: =AD29*1 -> 0
B30: punti TOTALE | C30: =SUM(C3:C29) -> 6 | D30: =SUM(D3:D29) -> 13 | E30: =SUM(E3:E29) -> 7 | F30: =SUM(F3:F29) -> 15 | G30: =SUM(G3:G29) -> 4 | H30: =SUM(H3:H29) -> 10 | I30: =SUM(I3:I29) -> 10 | J30: =SUM(J3:J29) -> 11 | ... L30: =SUM(L3:L29) -> 9 | O30: =SUM(O3:O29) -> 0 | P30: =SUM(P3:P29) -> 0 | Q30: =SUM(Q3:Q29) -> 0 | R30: =SUM(R3:R29) -> 0 | S30: =SUM(S3:S29) -> 0 | AD30: =SUM(AD3:AD29) -> 93 | AE30: =SUM(AE3:AE29) -> 93
B31: subTOTALE | C31: =C30*1.5 -> 9 | D31: =D30*1 -> 13 | E31: =E30*1.5 -> 10.5 | F31: =F30*1 -> 15 | G31: =G30*1.5 -> 6 | H31: =H30*1 -> 10 | I31: =I30*1.5 -> 15 | J31: =J30*1 -> 11 | K31: =K30*1.5 -> 12 | L31: =L30*1 -> 9 | O31: =O30*1 -> 0 | P31: =P30*1 -> 0 | Q31: =Q30*1 -> 0 | R31: =R30*1 -> 0 | S31: =S30*1.5 -> 0
B32: TOTALE | C32: =C31+D31 -> 22 | E32: =E31+F31 -> 25.5 | G32: =G31+H31 -> 16 | I32: =I31+J31 -> 26 | K32: =K31+L31 -> 21 | O32: =O31 -> 0 | P32: =P31 -> 0 | Q32: =Q31 -> 0 | R32: =R31 -> 0 | S32: =S31 -> 0 | AE32: =SUM(C32:S32) -> 110.5
A33: Legenda: | B33: 1 sede = € 1,50 | C33: 1 codice = € 1,00 | E33: 1 bonus Team = €1,00 | G33: Il saldo verrà liquidato a metà luglio 2025 in contanti
B34: SEDE: | C34: la colonna SEDE conta solo se un nome si trova nella colonna che si chiama VENDITA e PAGAMENTO di qualsiasi file collegato a questo Resoconto
B35: CODICE: | C35: la colonna CODICE conta solo se un nome si trova nella colonna che si chiama CODICE SCONTO di qualsiasi file collegato a questo Resoconto

Sheet elenchi
A1: COME HA RICHIESTO INFORMAZIONI | B1: COME CI HA CONOSCIUTO | C1: TIPO DI RICHIESTA | D1: =IFERROR(__xludf.DUMMYFUNCTION("IMPORTRANGE(""https://docs.google.com/spreadsheets/d/1rXtcffIE32PTdNYBTG2gdh1aoNZ5cmFHr018KdFpoiM/edit?gid=1117629718#gid=1117629718"", ""elenchi!M1:M30"")"),"CHI SCRIVE") -> CHI SCRIVE | E1: CODICI PROMO
A2: Telefono | B2: CONVENZIONATI | C2: AERIAL | D2: =IFERROR(__xludf.DUMMYFUNCTION("""COMPUTED_VALUE"""),"Alexandra") -> Alexandra | E2: ALEXANDRA05CAMPUS
A3: Email | B3: EX TESSERATO | C3: BALLO DI COPPIA | D3: =IFERROR(__xludf.DUMMYFUNCTION("""COMPUTED_VALUE"""),"AMM-NE") -> AMM-NE | E3: SANTO05CAMPUS
A4: Sede | B4: FB | C4: BAMBINI | D4: =IFERROR(__xludf.DUMMYFUNCTION("""COMPUTED_VALUE"""),"Estefany") -> Estefany | E4: ESTEFANY05CAMPUS
B5: GOOGLE | C5: BAMBINI E RAGAZZI | D5: =IFERROR(__xludf.DUMMYFUNCTION("""COMPUTED_VALUE"""),"Giuditta") -> Giuditta | E5: GIUDITTA05CAMPUS
B6: HA UN'ATTIVITÀ IN ZONA | C6: DANZA | D6: =IFERROR(__xludf.DUMMYFUNCTION("""COMPUTED_VALUE"""),"Joel") -> Joel | E6: JOEL05CAMPUS
B7: INSEGNANTI | C7: FITNESS | D7: =IFERROR(__xludf.DUMMYFUNCTION("""COMPUTED_VALUE"""),"Massi") -> Massi | E7: MASSI05CAMPUS
B8: INSTAGRAM | D8: =IFERROR(__xludf.DUMMYFUNCTION("""COMPUTED_VALUE"""),"Nura") -> Nura | E8: NURA05CAMPUS
B9: LAVORO | D9: =IFERROR(__xludf.DUMMYFUNCTION("""COMPUTED_VALUE"""),"Sara") -> Sara | E9: SARA05CAMPUS
B10: PASSAPAROLA | D10: =IFERROR(__xludf.DUMMYFUNCTION("""COMPUTED_VALUE"""),"Elisa") -> Elisa | E10: STAFF05CAMPUS
B11: SCUOLA | D11: =IFERROR(__xludf.DUMMYFUNCTION("""COMPUTED_VALUE"""),"Kevin") -> Kevin
B12: SEGRETERIA | D12: =IFERROR(__xludf.DUMMYFUNCTION("""COMPUTED_VALUE"""),"Zoila") -> Zoila
B13: SITO | D13: =IFERROR(__xludf.DUMMYFUNCTION("""COMPUTED_VALUE"""),"Jasir") -> Jasir
B14: SOCIAL
B15: TESSERATI
B16: TRAM
B17: VOLANTINO
B18: ABITA IN ZONA
B19: STAGE
