Workbook

Sheet LISTA
C1: CODICE CORSO | G1: STUDIO | J1: GIORNO | L1: ORA INIZIO | N1: DATA INIZIO | P1: TERMINE CORSO | R1: N. LEZIONI | T1: FASCIA ETÀ | V1: LIVELLO | X1: INSEGNANTE 1 | AB1: INSEGNANTE 2 | AF1: DETTAGLIO ISCRIZIONI: | AH1: =CONCATENATE(COUNTIF(L5:L86,"iscritto Donna")," ID + ",COUNTIF(L5:L86,"deve pagare D")," DPD + ",COUNTIF(L5:L86,"prova Donna")," PD + ",COUNTIF(L5:L86,"iscritto Uomo")," IU + ",COUNTIF(L5:L86,"deve pagare U")," DPU + ",COUNTIF(L5:L86,"prova Uomo")," PU") -> 18 ID + 1 DPD + 0 PD + 24 IU + 0 DPU + 0 PU | AL1: OMAGGI: | AM1: =CONCATENATE(COUNTIF(L5:L86,"omaggio D")," OD + ",COUNTIF(L5:L86,"omaggio U")," OU") -> 0 OD + 0 OU | AO1: CALENDARIO e MASTER
A2: 25-26 STAGIONE | C2: ANAGRAFICA | G2: ANAGRAFICA | L2: PAGAMENTI -> I - Sezione 1 | S2: II - Sezione 2 | Y2: III - Sezione 3 | AE2: IV - Sezione 4 | AL2: TESSERE | AU2: CONTROLLO 1
A3: chi scrive (A) | B3: vendita (B) | C3: id anagrafica (C) | D3: data inserimento (D) | E3: cognome (E) | F3: nome (F) | G3: età (G) | H3: sesso (H) | I3: telefono (I) | J3: cod fiscale (J) | K3: email (K) | L3: dettaglio iscrizione (N) | M3: descrizione quota (Q) | N3: periodo (R) | O3: data pag. lez. prova (W) | P3: acconto lez.prova (X) | Q3: data pag. saldo ann. (Z) | R3: saldo annuale (AA) | S3: descrizione quota (AD) | T3: periodo (AE) | U3: data pag. lez. prova (AJ) | V3: acconto lez.prova (AK) | W3: data pag. saldo ann. (AM) | X3: saldo annuale (AN) | Y3: descrizione quota (AQ) | Z3: periodo (AR) | AA3: data pag. lez.prova (AW) | AB3: acconto lez.prova (AX) | AC3: data pag. saldo ann. (AZ) | AD3: saldo annuale (BA) | AE3: descrizione quota (BD) | AF3: periodo (BE) | AG3: data pag. lez. prova quad. (BJ) | AH3: acconto lez.prova quad. (BK) | AI3: data pag. saldo quad. (BM) | AJ3: saldo quad. (BN) | AK3: saldo totale (BO) | AL3: quota tessera (BY) | AM3: data emissione pagamento tessera (BZ) | AN3: data scad quota tessera (CB) | AO3: n.tessera (CC) | AP3: domanda di tesseramento (CE) | AQ3: data scad cert. medico (CF) | AR3: importo singolo corso (CS) | AS3: presenze - prove pagate e lezioni singole (CT) | AT3: welfare presenze (CU) | AU3: controllo (CY) | AV3: obbligo di riempire (CZ) | AW3: NOTE (DE) | AX3: INVIARE EMAIL o SMS (DF) | AY3: legenda: (DL)
A4: DONNE | D4: Totale | E4: =COUNTIF(E5:E44,"*") -> 20 | F4: DONNE
A5: Giuditta | B5: BONIFICO | C5: ID-000693 | D5: 45824 | E5: BATTISTI | F5: VALERIA | G5: 56 | H5: Donna | I5: 3356848965 | J5: BTTVRM69M44F952J | K5: valeria.battisti@tiscali.it | L5: iscritto Donna | M5: 1 OPEN BALLO, 1 QUOTA TESSERA | N5: SETTEMBRE - OTTOBRE (2025) | Q5: 45827 | R5: 1300 | AK5: 1325 | AM5: 45827 | AN5: 46174 | AO5: 2425-000693 | AP5: COMPILATA | AQ5: 46218 | AU5: 🆗 | AV5: ✅
A6: Giuditta | B6: SEDE Giuditta | C6: ID-001740 | D6: 45902 | E6: CLEMENTE | F6: ISABELLA | G6: 28 | H6: Donna | I6: 3284148303 | J6: CLMSLL97L49A783A | K6: ISABELLA.CLEMENTE09@GMAIL.COM | L6: iscritto Donna | M6: 2 CORSI Adulti, 1 QUOTA TESSERA | N6: SETTEMBRE - OTTOBRE (2025) | Q6: 45902 | R6: 680 | AK6: 705 | AM6: 45902 | AN6: 46296 | AO6: 2526-001740 | AP6: COMPILATA | AQ6: 45959 | AU6: 🆗 | AV6: ✅
A10: Nura | B10: SEDE Nura | C10: ID-000357 | D10: 45817 | E10: FELICI | F10: ARIANNA | G10: 21 | H10: Donna | I10: 3318840068 | J10: FLCRNN04B50F205J | K10: ariannafelici1@gmail.com | L10: iscritto Donna | M10: 1 CORSO Adulti, 1 QUOTA TESSERA | N10: SETTEMBRE - OTTOBRE (2025) | Q10: 45817 | R10: 312 | AK10: 337 | AM10: 45817 | AN10: 46266 | AO10: 2425-000357 | AP10: COMPILATA | AQ10: 45937 | AU10: 🆗 | AV10: ✅
A11: Alexandra | B11: SEDE Alexandra | C11: ID-000029 | D11: 45792 | E11: FERNANDO MATARAKIRI | F11: MELANY SERENA TRACY | G11: 35 | H11: Donna | I11: 3517619123 | J11: FRNMNY90M55F205E | K11: melany_serena@hotmail.it | L11: iscritto Donna | M11: 1 QUOTA TESSERA, 1 OPEN BALLO | N11: SETTEMBRE - OTTOBRE (2025) | Q11: 45792 | R11: 1300 | AK11: 1325 | AM11: 45792 | AN11: 46174 | AO11: 2425-000029 | AP11: COMPILATA | AQ11: 46211 | AU11: 🆗 | AV11: ✅
A12: Nura, Joel | B12: EMAIL, SEDE Joel | C12: ID-001115 | D12: 45867 | E12: GRISI | F12: BEATRICE | G12: 33 | H12: Donna | I12: 3408671887 | J12: GRSBRC92H49L400L | K12: bea.grisi92@gmail.com | L12: iscritto Donna | M12: 1 LEZIONE Prova, 1 CORSO Adulti, 1 QUOTA TESSERA | N12: SETTEMBRE - OTTOBRE (2025) | O12: 45922 | P12: 20 | Q12: 45922 | R12: 370 | AK12: 415 | AM12: 45922 | AN12: 46266 | AO12: 2526-001115 | AP12: COMPILATA | AQ12: 36526 | AU12: 🆗 | AV12: ✅
A13: Alexandra | B13: EMAIL, BONIFICO | C13: ID-001082 | D13: 45862 | E13: URBANO | F13: CLAUDIA | G13: 55 | H13: Donna | I13: 3478249977 | J13: RBNCDP70H52F205Q | K13: claudiaurbano@alice.it | L13: prova pagata D | M13: 1 CORSO Adulti | N13: SETTEMBRE - OTTOBRE (2025) | Q13: 45862 | R13: 390 | AK13: 390 | AM13: 45835 | AN13: 46174 | AO13: 2425-001082 | AP13: COMPILATA | AQ13: 46197 | AU13: 🆗 | AV13: ✅
A14: Joel, Nura | B14: SEDE Joel, SEDE Nura | C14: ID-000354 | D14: 45817 | E14: DE MARTINO | F14: LUCIA | G14: 53 | H14: Donna | I14: 3488710026 | J14: DMRLCU72A69G230V | K14: lucia.de.martino@snam.it | L14: iscritto Donna | M14: 1 CORSO Adulti, 1 QUOTA TESSERA | N14: SETTEMBRE - OTTOBRE (2025) | Q14: 45817 | R14: 312 | S14: 1 CORSO Adulti | T14: SETTEMBRE - OTTOBRE (2025) | W14: 45922 | X14: 370.5 | AK14: 707.5 | AM14: 45974 | AN14: 46296 | AO14: 2526-000354 | AP14: COMPILATA | AQ14: 45974 | AU14: 🆗 | AV14: ✅
A16: Nura, Estefany | B16: SEDE Nura, SEDE Estefany | C16: ID-000378 | D16: 45817 | E16: PALADINI | F16: MARIA CHIARA | G16: 36 | H16: Donna | I16: 3202979792 | J16: PLDMCH89L68B180I | K16: mariachiarapaladini@gmail.com | L16: deve pagare D | M16: 1 CORSO Adulti, 1 QUOTA TESSERA | N16: SETTEMBRE - OTTOBRE (2025) | Q16: 45817 | R16: 312 | S16: 1 CORSO Adulti | T16: SETTEMBRE - OTTOBRE (2025) | W16: 45911 | X16: 390 | AK16: 727 | AM16: 45817 | AN16: 46174 | AO16: 2425-000378 | AP16: COMPILATA | AQ16: 46293 | AU16: 🆗 | AV16: ✅
A21: Joel | B21: SEDE Joel | C21: ID-000381 | D21: 45817 | E21: RISSO | F21: NAILA | G21: 28 | H21: Donna | I21: 3466348305 | J21: RSSNLA97B41Z133S | K21: naila.risso@live.it | L21: iscritto Donna | M21: 1 CORSO Adulti, 1 QUOTA TESSERA | N21: SETTEMBRE - OTTOBRE (2025) | Q21: 45817 | R21: 312 | AK21: 337 | AM21: 45817 | AN21: 46174 | AO21: 2425-000381 | AP21: COMPILATA | AQ21: 46104 | AU21: 🆗 | AV21: ✅
A22: sito, Estefany | B22: SEDE Estefany | C22: ID-001777 | D22: 45902 | E22: RASTRELLI | F22: GIORGIA | G22: 25 | H22: Donna | I22: 3404224454 | J22: RSTGRG99T41F205B | K22: giorgiarastrelli@gmail.com | L22: iscritto Donna | M22: 1 CORSO Adulti | N22: SETTEMBRE - OTTOBRE (2025) | Q22: 45917 | R22: 390 | AK22: 390 | AM22: 45664 | AN22: 46023 | AO22: 2425-001777 | AP22: COMPILATA | AQ22: 46097 | AU22: 🆗 | AV22: ✅
A23: Nura | B23: SEDE Nura, TELEFONO | C23: ID-001518 | D23: 45897 | E23: RUVIO | F23: EMAUELA | G23: 24 | H23: Donna | I23: 3454578085 | J23: RVUMNL01H44I441L | K23: emaruvio01@gmail.com | L23: iscritto Donna | M23: 1 CORSO Adulti, 1 QUOTA TESSERA | N23: SETTEMBRE - OTTOBRE (2025) | Q23: 45897 | R23: 390 | AK23: 415 | AM23: 45897 | AN23: 46266 | AO23: 2425-001518 | AP23: COMPILATA | AQ23: 45985 | AU23: 🆗 | AV23: ✅
A24: Nura | B24: BONIFICO | C24: ID-001021 | D24: 45853 | E24: STICOTTI | F24: BEATRICE | G24: 26 | H24: Donna | I24: 3487482398 | J24: STCBRC99A58F205V | K24: beatrice.sticotti@gmail.com | L24: iscritto Donna | M24: 1 CORSO Adulti | N24: SETTEMBRE - OTTOBRE (2025) | Q24: 45853 | R24: 351 | AK24: 351 | AM24: 45320 | AN24: 45658 | AO24: 2324-001021 | AP24: COMPILATA | AQ24: 45825 | AU24: 🆗 | AV24: ✅
A25: Nura | B25: BONIFICO | C25: ID-001022 | D25: 45853 | E25: STICOTTI | F25: CAMILLA | G25: 24 | H25: Donna | I25: 3342900479 | J25: STCCLL01H41F205V | K25: camilla.sticotti@gmail.com | L25: iscritto Donna | M25: 1 CORSO Adulti, 1 QUOTA TESSERA | N25: SETTEMBRE - OTTOBRE (2025) | Q25: 45853 | R25: 351 | AK25: 376 | AM25: 45853 | AN25: 46204 | AO25: 2425-001022 | AP25: COMPILATA | AQ25: 36526 | AU25: 🆗 | AV25: ✅
A26: Joel | B26: SEDE Joel | C26: ID-000387 | D26: 45817 | E26: STARACE | F26: PAOLA | G26: 30 | H26: Donna | I26: 3356727378 | J26: STRPLA95C42F839Q | K26: pao.starace@gmail.com | L26: iscritto Donna | M26: 3 CORSI Adulti, 1 QUOTA TESSERA | N26: SETTEMBRE - OTTOBRE (2025) | Q26: 45817 | R26: 864 | AK26: 889 | AM26: 45817 | AN26: 46174 | AO26: 2425-000387 | AP26: COMPILATA | AQ26: 45936 | AU26: 🆗 | AV26: ✅
A27: Alexandra | B27: BONIFICO | C27: ID-000759 | D27: 45827 | E27: VASTA | F27: MARIA GRAZIA | G27: 32 | H27: Donna | I27: 3208838711 | J27: VSTMGR93A45C351M | K27: marziavasta@virgilio.it | L27: iscritto Donna | M27: 2 CORSI Adulti, 1 QUOTA TESSERA | N27: SETTEMBRE - OTTOBRE (2025) | Q27: 45834 | R27: 612 | AK27: 637 | AM27: 45834 | AN27: 46266 | AO27: 2425-000759 | AP27: NON COMPILATA | AQ27: 45969 | AU27: 🆗 | AV27: ✅
A28: Estefany | B28: BONIFICO, EMAIL | C28: ID-001391 | D28: 45894 | E28: ZANOTTO | F28: BEATRICE AMBRA | G28: 31 | H28: Donna | I28: 3470636797 | J28: ZNTBRC94E55F205G | K28: info@beatriceambra.it | L28: iscritto Donna | M28: 1 CORSO Adulti Quadrimestre | N28: SETTEMBRE - OTTOBRE (2025) | Q28: 45929 | R28: 280 | AK28: 280 | AM28: 45735 | AN28: 46082 | AO28: 2425-001391 | AP28: COMPILATA | AQ28: 46126 | AU28: 🆗 | AV28: ✅
A29: Estefany, Giuditta | B29: BONIFICO, EMAIL | C29: ID-001349 | D29: 45894 | E29: BACCHI | F29: CHIARA | G29: 36 | H29: Donna | I29: 3393139039 | J29: BCCCHR89E63F257V | K29: chiarabacchi6@gmail.com | L29: iscritto Donna | M29: 1 CORSO Adulti Quadrimestre | N29: SETTEMBRE - OTTOBRE (2025) | Q29: 45894 | R29: 280 | AK29: 280 | AM29: 45707 | AN29: 46054 | AO29: 2425-001349 | AP29: COMPILATA | AQ29: 45985 | AU29: 🆗 | AV29: ✅
A31: Alexandra | B31: TELEFONO, SEDE Alexandra | C31: ID-001099 | D31: 45866 | E31: PALACIOS HUANCA | F31: ESTHER | G31: 47 | H31: Donna | I31: 3343267311 | J31: PLCSHR78M52Z611J | K31: tehiph4@hotmail.com | L31: iscritto Donna | M31: 1 CORSO Adulti, 1 QUOTA TESSERA | N31: SETTEMBRE - OTTOBRE (2025) | Q31: 45920 | R31: 390 | AK31: 415 | AM31: 45920 | AN31: 46266 | AO31: 2526-001099 | AP31: NON COMPILATA | AQ31: 01/01/0200 | AU31: 🆗 | AV31: ✅
A33: Nura | B33: SEDE Nura | C33: ID-003411 | D33: 45940 | E33: LEVY | F33: TOVA MICHELLE | G33: 49 | H33: Donna | I33: 3391141288 | J33: LVYTMC76C63F205W | K33: michelle1976@hotmail.it | L33: iscritto Donna | M33: 1 CORSO Adulti, 1 QUOTA TESSERA | N33: SETTEMBRE - OTTOBRE (2025) | Q33: 45940 | R33: 390 | AK33: 415 | AM33: 45940 | AN33: 46296 | AO33: 2526-003411 | AP33: COMPILATA | AQ33: 46100 | AU33: 🆗 | AV33: ✅
A34: Nura | B34: SEDE Nura | C34: ID-000458 | D34: 45819 | E34: MAFFIOLI | F34: SOFIA | G34: 29 | H34: Donna | I34: 3348824609 | J34: MFFSFO95R65F205B | K34: smsofy@gmail.com | L34: iscritto Donna | M34: 1 CORSO Adulti | N34: SETTEMBRE - OTTOBRE (2025) | Q34: 45819 | R34: 312 | AK34: 312 | AM34: 45799 | AN34: 46143 | AO34: 2425-000458 | AP34: COMPILATA | AQ34: 45953 | AU34: 🆗 | AV34: ✅
A45: UOMINI | D45: Totale | E45: =COUNTIF(E46:E86,"*") -> 24 | F45: UOMINI
A47: Alexandra | B47: SEDE Alexandra | C47: ID-003233 | D47: 45933 | E47: BELVERDE | F47: MASSIMO | G47: 59 | H47: Uomo | I47: 3332977607 | J47: BLVMSM65S20G624U | L47: iscritto Uomo | M47: 1 CORSO Adulti, 1 QUOTA TESSERA | N47: SETTEMBRE - OTTOBRE (2025) | Q47: 45933 | R47: 195 | AK47: 220 | AM47: 45933 | AN47: 46296 | AO47: 2526-003233 | AP47: NON COMPILATA | AQ47: 36526 | AU47: ERRORE | AV47: K3299
A48: Estefany | B48: EMAIL | C48: ID-001128 | D48: 45868 | E48: CIGOGNINI | F48: ANDREA | G48: 27 | H48: Uomo | I48: 3459555629 | J48: CGGNDR98D03C816N | K48: andrecigo3@gmail.com | L48: iscritto Uomo | M48: 1 CORSO Adulti, 1 QUOTA TESSERA | N48: SETTEMBRE - OTTOBRE (2025) | Q48: 45894 | R48: 390 | AK48: 415 | AM48: 45894 | AN48: 46266 | AO48: 2425-001128 | AP48: COMPILATA | AQ48: 01/01/0200 | AU48: 🆗 | AV48: ✅
A49: Nura | B49: EMAIL, SEDE Nura | C49: ID-002653 | D49: 45916 | E49: CESTOLA | F49: LORENZO | G49: 33 | H49: Uomo | I49: 3338172128 | J49: CSTLNZ92D26C770L | K49: lorenzo.cestola26@gmail.com | L49: iscritto Uomo | M49: 1 CORSO Adulti, 1 QUOTA TESSERA | N49: SETTEMBRE - OTTOBRE (2025) | Q49: 45916 | R49: 390 | AK49: 415 | AM49: 45916 | AN49: 46296 | AO49: 2526-002653 | AP49: COMPILATA | AQ49: 36526 | AU49: 🆗 | AV49: ✅
A50: Joel, Nura | B50: BONIFICO, SEDE Nura | C50: ID-000951 | D50: 45852 | E50: DI NAPOLI | F50: ALESSIO | G50: 40 | H50: Uomo | I50: 3884669524 | J50: DNPLSS84R16A940H | K50: dinapolialessio@gmail.com | L50: iscritto Uomo | M50: 3 CORSI Adulti | N50: SETTEMBRE - OTTOBRE (2025) | Q50: 45853 | R50: 912 | S50: 1 CORSO Adulti | T50: SETTEMBRE - OTTOBRE (2025) | W50: 45919 | X50: 390 | AK50: 1302 | AM50: 45793 | AN50: 46143 | AO50: 2425-000951 | AP50: COMPILATA | AQ50: 46143 | AU50: 🆗 | AV50: ✅
A51: Estefany, sito | B51: ONLINE | C51: ID-002249 | D51: 45909 | E51: GAGNO | F51: LUCA | G51: 29 | H51: Uomo | I51: 3771353177 | J51: GGNLCU96A09L736Q | K51: lucagagno@gmail.com | L51: iscritto Uomo | M51: 1 CORSO Adulti, 1 QUOTA TESSERA | N51: SETTEMBRE - OTTOBRE (2025) | Q51: 45909 | R51: 390 | AK51: 415 | AM51: 45909 | AN51: 46266 | AO51: 2526-002249 | AP51: NON COMPILATA | AQ51: 45985 | AU51: 🆗 | AV51: ✅
A52: Alexandra | B52: EMAIL, BONIFICO | C52: ID-001076 | D52: 45862 | E52: GIOIA | F52: RICCARDO | G52: 56 | H52: Uomo | I52: 3472538771 | J52: GIORCR69A19F205N | K52: r.gioia@me.com | L52: iscritto Uomo | M52: 1 CORSO Adulti | N52: SETTEMBRE - OTTOBRE (2025) | Q52: 45862 | R52: 390 | AK52: 390 | AM52: 45835 | AN52: 46174 | AO52: 2425-001076 | AP52: COMPILATA | AQ52: 46147 | AU52: 🆗 | AV52: ✅
A53: Nura | B53: BONIFICO | C53: ID-000114 | D53: 45799 | E53: LUCENTI | F53: RICCARDO | G53: 53 | H53: Uomo | I53: 3701006439 | J53: LCNRCR71T07F205H | K53: riccardo@claudiobonoldi.com | L53: iscritto Uomo | M53: 1 OPEN BALLO | N53: SETTEMBRE - OTTOBRE (2025) | Q53: 45818 | R53: 1300 | AK53: 1300 | AM53: 45681 | AN53: 46023 | AO53: 2425-000114 | AP53: NON COMPILATA | AQ53: 46070 | AU53: 🆗 | AV53: ✅
A54: Estefany | B54: SEDE Estefany | C54: ID-000520 | D54: 45820 | E54: EL SERAFI | F54: ADRE ANWAR | G54: 31 | H54: Uomo | I54: 3462478052 | J54: LSRDNW94D20F205D | K54: lalla.cesari@gmail.com | L54: iscritto Uomo | M54: 1 CORSO Adulti, 1 CORSO Adulti VENERDI O SABATO, 1 QUOTA TESSERA | N54: SETTEMBRE - OTTOBRE (2025) | Q54: 45820 | R54: 560 | AK54: 585 | AM54: 45820 | AN54: 46174 | AO54: 2425-000520 | AP54: COMPILATA | AQ54: 45987 | AU54: 🆗 | AV54: ✅
A56: Nura | B56: SEDE Nura | C56: ID-000370 | D56: 45817 | E56: MALAVOLTA | F56: LORENZO | G56: 22 | H56: Uomo | I56: 3755052322 | J56: MLVLNZ03C21F205Z | K56: lorenz.malavolta@gmail.com | L56: iscritto Uomo | M56: 1 CORSO Adulti, 1 QUOTA TESSERA | N56: SETTEMBRE - OTTOBRE (2025) | Q56: 45817 | R56: 312 | AK56: 337 | AM56: 45817 | AN56: 46174 | AO56: 2425-000370 | AP56: COMPILATA | AQ56: 46087 | AU56: 🆗 | AV56: ✅
A57: Nura | B57: EMAIL, BONIFICO | C57: ID-001365 | D57: 45894 | E57: MORABITO | F57: MICHELE | G57: 34 | H57: Uomo | I57: 3440484102 | J57: MRBMHL90T22F205K | K57: morabitomichele7@gmail.com | L57: iscritto Uomo | M57: 1 CORSO Adulti, 1 QUOTA TESSERA | N57: SETTEMBRE - OTTOBRE (2025) | Q57: 45897 | R57: 390 | AK57: 415 | AM57: 45897 | AN57: 46235 | AO57: 2425-001365 | AP57: COMPILATA | AQ57: 45974 | AU57: 🆗 | AV57: ✅
A58: Nura | B58: SEDE Nura | C58: ID-000373 | D58: 45817 | E58: MUSCILLO | F58: FLAVIO | G58: 56 | H58: Uomo | I58: 3466643002 | J58: MSCFLV69D29F205S | K58: flavioeco.fm@libero.it | L58: iscritto Uomo | M58: 2 CORSI Adulti, 1 QUOTA TESSERA | N58: SETTEMBRE - OTTOBRE (2025) | Q58: 45817 | R58: 612 | AK58: 637 | AM58: 45817 | AN58: 46174 | AO58: 2425-000373 | AP58: COMPILATA | AQ58: 46274 | AU58: 🆗 | AV58: ✅
A59: Alexandra | B59: SEDE Alexandra | C59: ID-000927 | D59: 45849 | E59: NIBALI | F59: LUIGI GIOVANNNI | G59: 45 | H59: Uomo | I59: 3490527464 | J59: NBLLGV80M02A089O | K59: luiginibali@tiscali.it | L59: iscritto Uomo | M59: 1 CORSO Adulti | N59: SETTEMBRE - OTTOBRE (2025) | Q59: 45849 | R59: 351 | AK59: 351 | AM59: 45685 | AN59: 46023 | AO59: 2425-000927 | AP59: COMPILATA | AQ59: 46097 | AU59: 🆗 | AV59: ✅
A60: Giuditta | B60: SEDE Giuditta | C60: ID-000876 | D60: 45846 | E60: PINTO | F60: ANGELO | G60: 24 | H60: Uomo | I60: 3291815129 | J60: PNTNGL01C10A662A | K60: angelopinto72@gmail.com | L60: iscritto Uomo | M60: 1 CORSO Adulti | N60: SETTEMBRE - OTTOBRE (2025) | Q60: 45846 | R60: 351 | AK60: 351 | AM60: 45829 | AN60: 46174 | AO60: 2425-000876 | AP60: COMPILATA | AQ60: 45975 | AU60: 🆗 | AV60: ✅
A61: Nura | B61: SEDE Nura | C61: ID-000380 | D61: 45817 | E61: PORCHERA | F61: GIOVANNI | G61: 63 | H61: Uomo | I61: 3382826724 | J61: PRCGNN62M07F205J | K61: porchera@me.com | L61: iscritto Uomo | M61: 1 QUOTA TESSERA, 4 CORSI Adulti | N61: SETTEMBRE - OTTOBRE (2025) | Q61: 45817 | R61: 1007 | AK61: 1032 | AM61: 45817 | AN61: 46174 | AO61: 2425-000380 | AP61: COMPILATA | AQ61: 45922 | AU61: 🆗 | AV61: ✅
A62: Nura | B62: TELEFONO, SEDE Nura | C62: ID-001512 | D62: 45897 | E62: PROVASI | F62: ANDREA | G62: 23 | H62: Uomo | I62: 3465467219 | J62: PRVNDR01T03F205J | K62: provasiandrea@gmail.com | L62: iscritto Uomo | M62: 1 CORSO Adulti, 1 QUOTA TESSERA | N62: SETTEMBRE - OTTOBRE (2025) | Q62: 45897 | R62: 390 | AK62: 415 | AM62: 45897 | AN62: 46266 | AO62: 2425-001512 | AP62: COMPILATA | AQ62: 46097 | AU62: 🆗 | AV62: ✅
...

Sheet PRESENZE
A1: {=LISTA!C3:C86} -> id anagrafica (C) | B1: {=LISTA!E3:F86} -> cognome (E) | C1: nome (F) | D1: =IFERROR(__xludf.DUMMYFUNCTION("ARRAYFORMULA(IMPORTRANGE(""18iHbFEZ6msv3IU3InH0K5SEgnjM_8H0uHajc7c4fMiQ"", ""elenchi!AB2""))"),"lun - 01/09/25") -> lun - 01/09/25 | E1: =IFERROR(__xludf.DUMMYFUNCTION("ARRAYFORMULA(IMPORTRANGE(""18iHbFEZ6msv3IU3InH0K5SEgnjM_8H0uHajc7c4fMiQ"", ""elenchi!AB3""))"),"lun - 08/09/25 PROVA FITNESS PROVA DANZA") -> lun - 08/09/25 PROVA FITNESS PROVA DANZA | F1: =IFERROR(__xludf.DUMMYFUNCTION("ARRAYFORMULA(IMPORTRANGE(""18iHbFEZ6msv3IU3InH0K5SEgnjM_8H0uHajc7c4fMiQ"", ""elenchi!AB4""))"),"lun - 15/09/25 PROVA BALLO PROVA AERIAL") -> lun - 15/09/25 PROVA BALLO PROVA AERIAL | G1: =IFERROR(__xludf.DUMMYFUNCTION("ARRAYFORMULA(IMPORTRANGE(""18iHbFEZ6msv3IU3InH0K5SEgnjM_8H0uHajc7c4fMiQ"", ""elenchi!AB5""))"),"lun - 22/09/25 PROVA BAMBINI E RAGAZZI") -> lun - 22/09/25 PROVA BAMBINI E RAGAZZI | H1: =IFERROR(__xludf.DUMMYFUNCTION("ARRAYFORMULA(IMPORTRANGE(""18iHbFEZ6msv3IU3InH0K5SEgnjM_8H0uHajc7c4fMiQ"", ""elenchi!AB6""))"),"lun - 29/09/25") -> lun - 29/09/25 | I1: =IFERROR(__xludf.DUMMYFUNCTION("ARRAYFORMULA(IMPORTRANGE(""18iHbFEZ6msv3IU3InH0K5SEgnjM_8H0uHajc7c4fMiQ"", ""elenchi!AB7""))"),"lun - 06/10/25") -> lun - 06/10/25 | J1: =IFERROR(__xludf.DUMMYFUNCTION("ARRAYFORMULA(IMPORTRANGE(""18iHbFEZ6msv3IU3InH0K5SEgnjM_8H0uHajc7c4fMiQ"", ""elenchi!AB8""))"),"lun - 13/10/25") -> lun - 13/10/25 | K1: =IFERROR(__xludf.DUMMYFUNCTION("ARRAYFORMULA(IMPORTRANGE(""18iHbFEZ6msv3IU3InH0K5SEgnjM_8H0uHajc7c4fMiQ"", ""elenchi!AB9""))"),"lun - 20/10/25") -> lun - 20/10/25 | L1: =IFERROR(__xludf.DUMMYFUNCTION("ARRAYFORMULA(IMPORTRANGE(""18iHbFEZ6msv3IU3InH0K5SEgnjM_8H0uHajc7c4fMiQ"", ""elenchi!AB10""))"),"lun - 27/10/25") -> lun - 27/10/25 | M1: =IFERROR(__xludf.DUMMYFUNCTION("ARRAYFORMULA(IMPORTRANGE(""18iHbFEZ6msv3IU3InH0K5SEgnjM_8H0uHajc7c4fMiQ"", ""elenchi!AB11""))"),"lun - 03/11/25") -> lun - 03/11/25 | N1: =IFERROR(__xludf.DUMMYFUNCTION("ARRAYFORMULA(IMPORTRANGE(""18iHbFEZ6msv3IU3InH0K5SEgnjM_8H0uHajc7c4fMiQ"", ""elenchi!AB12""))"),"lun - 10/11/25") -> lun - 10/11/25 | O1: =IFERROR(__xludf.DUMMYFUNCTION("ARRAYFORMULA(IMPORTRANGE(""18iHbFEZ6msv3IU3InH0K5SEgnjM_8H0uHajc7c4fMiQ"", ""elenchi!AB13""))"),"lun - 17/11/25") -> lun - 17/11/25 | P1: =IFERROR(__xludf.DUMMYFUNCTION("ARRAYFORMULA(IMPORTRANGE(""18iHbFEZ6msv3IU3InH0K5SEgnjM_8H0uHajc7c4fMiQ"", ""elenchi!AB14""))"),"lun - 24/11/25") -> lun - 24/11/25 | Q1: =IFERROR(__xludf.DUMMYFUNCTION("ARRAYFORMULA(IMPORTRANGE(""18iHbFEZ6msv3IU3InH0K5SEgnjM_8H0uHajc7c4fMiQ"", ""elenchi!AB15""))"),"lun - 01/12/25") -> lun - 01/12/25 | R1: =IFERROR(__xludf.DUMMYFUNCTION("ARRAYFORMULA(IMPORTRANGE(""18iHbFEZ6msv3IU3InH0K5SEgnjM_8H0uHajc7c4fMiQ"", ""elenchi!AB16""))"),"lun - 08/12/25 CHIUSO") -> lun - 08/12/25 CHIUSO | S1: =IFERROR(__xludf.DUMMYFUNCTION("ARRAYFORMULA(IMPORTRANGE(""18iHbFEZ6msv3IU3InH0K5SEgnjM_8H0uHajc7c4fMiQ"", ""elenchi!AB17""))"),"lun - 15/12/25") -> lun - 15/12/25 | T1: =IFERROR(__xludf.DUMMYFUNCTION("ARRAYFORMULA(IMPORTRANGE(""18iHbFEZ6msv3IU3InH0K5SEgnjM_8H0uHajc7c4fMiQ"", ""elenchi!AB18""))"),"lun - 22/12/25 NO BAMBINI") -> lun - 22/12/25 NO BAMBINI | U1: =IFERROR(__xludf.DUMMYFUNCTION("ARRAYFORMULA(IMPORTRANGE(""18iHbFEZ6msv3IU3InH0K5SEgnjM_8H0uHajc7c4fMiQ"", ""elenchi!AB19""))"),"lun - 29/12/25 NO CORSI") -> lun - 29/12/25 NO CORSI | V1: =IFERROR(__xludf.DUMMYFUNCTION("ARRAYFORMULA(IMPORTRANGE(""18iHbFEZ6msv3IU3InH0K5SEgnjM_8H0uHajc7c4fMiQ"", ""elenchi!AB20""))"),"lun - 05/01/26 NO CORSI") -> lun - 05/01/26 NO CORSI | W1: =IFERROR(__xludf.DUMMYFUNCTION("ARRAYFORMULA(IMPORTRANGE(""18iHbFEZ6msv3IU3InH0K5SEgnjM_8H0uHajc7c4fMiQ"", ""elenchi!AB21""))"),"lun - 12/01/26") -> lun - 12/01/26 | X1: =IFERROR(__xludf.DUMMYFUNCTION("ARRAYFORMULA(IMPORTRANGE(""18iHbFEZ6msv3IU3InH0K5SEgnjM_8H0uHajc7c4fMiQ"", ""elenchi!AB22""))"),"lun - 19/01/26") -> lun - 19/01/26 | Y1: =IFERROR(__xludf.DUMMYFUNCTION("ARRAYFORMULA(IMPORTRANGE(""18iHbFEZ6msv3IU3InH0K5SEgnjM_8H0uHajc7c4fMiQ"", ""elenchi!AB23""))"),"lun - 26/01/26") -> lun - 26/01/26 | Z1: =IFERROR(__xludf.DUMMYFUNCTION("ARRAYFORMULA(IMPORTRANGE(""18iHbFEZ6msv3IU3InH0K5SEgnjM_8H0uHajc7c4fMiQ"", ""elenchi!AB24""))"),"lun - 02/02/26") -> lun - 02/02/26 | AA1: =IFERROR(__xludf.DUMMYFUNCTION("ARRAYFORMULA(IMPORTRANGE(""18iHbFEZ6msv3IU3InH0K5SEgnjM_8H0uHajc7c4fMiQ"", ""elenchi!AB25""))"),"lun - 09/02/26") -> lun - 09/02/26 | AB1: =IFERROR(__xludf.DUMMYFUNCTION("ARRAYFORMULA(IMPORTRANGE(""18iHbFEZ6msv3IU3InH0K5SEgnjM_8H0uHajc7c4fMiQ"", ""elenchi!AB26""))"),"lun - 16/02/26") -> lun - 16/02/26 | AC1: =IFERROR(__xludf.DUMMYFUNCTION("ARRAYFORMULA(IMPORTRANGE(""18iHbFEZ6msv3IU3InH0K5SEgnjM_8H0uHajc7c4fMiQ"", ""elenchi!AB27""))"),"lun - 23/02/26") -> lun - 23/02/26 | AD1: =IFERROR(__xludf.DUMMYFUNCTION("ARRAYFORMULA(IMPORTRANGE(""18iHbFEZ6msv3IU3InH0K5SEgnjM_8H0uHajc7c4fMiQ"", ""elenchi!AB28""))"),"lun - 02/03/26") -> lun - 02/03/26 | AE1: =IFERROR(__xludf.DUMMYFUNCTION("ARRAYFORMULA(IMPORTRANGE(""18iHbFEZ6msv3IU3InH0K5SEgnjM_8H0uHajc7c4fMiQ"", ""elenchi!AB29""))"),"lun - 09/03/26") -> lun - 09/03/26 | AF1: =IFERROR(__xludf.DUMMYFUNCTION("ARRAYFORMULA(IMPORTRANGE(""18iHbFEZ6msv3IU3InH0K5SEgnjM_8H0uHajc7c4fMiQ"", ""elenchi!AB30""))"),"lun - 16/03/26") -> lun - 16/03/26 | AG1: =IFERROR(__xludf.DUMMYFUNCTION("ARRAYFORMULA(IMPORTRANGE(""18iHbFEZ6msv3IU3InH0K5SEgnjM_8H0uHajc7c4fMiQ"", ""elenchi!AB31""))"),"lun - 23/03/26") -> lun - 23/03/26 | AH1: =IFERROR(__xludf.DUMMYFUNCTION("ARRAYFORMULA(IMPORTRANGE(""18iHbFEZ6msv3IU3InH0K5SEgnjM_8H0uHajc7c4fMiQ"", ""elenchi!AB32""))"),"lun - 30/03/26") -> lun - 30/03/26 | AI1: =IFERROR(__xludf.DUMMYFUNCTION("ARRAYFORMULA(IMPORTRANGE(""18iHbFEZ6msv3IU3InH0K5SEgnjM_8H0uHajc7c4fMiQ"", ""elenchi!AB33""))"),"lun - 06/04/26 CHIUSO") -> lun - 06/04/26 CHIUSO | AJ1: =IFERROR(__xludf.DUMMYFUNCTION("ARRAYFORMULA(IMPORTRANGE(""18iHbFEZ6msv3IU3InH0K5SEgnjM_8H0uHajc7c4fMiQ"", ""elenchi!AB34""))"),"lun - 13/04/26") -> lun - 13/04/26 | AK1: =IFERROR(__xludf.DUMMYFUNCTION("ARRAYFORMULA(IMPORTRANGE(""18iHbFEZ6msv3IU3InH0K5SEgnjM_8H0uHajc7c4fMiQ"", ""elenchi!AB35""))"),"lun - 20/04/26") -> lun - 20/04/26 | AL1: =IFERROR(__xludf.DUMMYFUNCTION("ARRAYFORMULA(IMPORTRANGE(""18iHbFEZ6msv3IU3InH0K5SEgnjM_8H0uHajc7c4fMiQ"", ""elenchi!AB36""))"),"lun - 27/04/26") -> lun - 27/04/26 | AM1: =IFERROR(__xludf.DUMMYFUNCTION("ARRAYFORMULA(IMPORTRANGE(""18iHbFEZ6msv3IU3InH0K5SEgnjM_8H0uHajc7c4fMiQ"", ""elenchi!AB37""))"),"lun - 04/05/26") -> lun - 04/05/26 | AN1: =IFERROR(__xludf.DUMMYFUNCTION("ARRAYFORMULA(IMPORTRANGE(""18iHbFEZ6msv3IU3InH0K5SEgnjM_8H0uHajc7c4fMiQ"", ""elenchi!AB38""))"),"lun - 11/05/26") -> lun - 11/05/26 | AO1: =IFERROR(__xludf.DUMMYFUNCTION("ARRAYFORMULA(IMPORTRANGE(""18iHbFEZ6msv3IU3InH0K5SEgnjM_8H0uHajc7c4fMiQ"", ""elenchi!AB39""))"),"lun - 18/05/26") -> lun - 18/05/26 | AP1: =IFERROR(__xludf.DUMMYFUNCTION("ARRAYFORMULA(IMPORTRANGE(""18iHbFEZ6msv3IU3InH0K5SEgnjM_8H0uHajc7c4fMiQ"", ""elenchi!AB40""))"),"lun - 25/05/26") -> lun - 25/05/26 | AQ1: =IFERROR(__xludf.DUMMYFUNCTION("ARRAYFORMULA(IMPORTRANGE(""18iHbFEZ6msv3IU3InH0K5SEgnjM_8H0uHajc7c4fMiQ"", ""elenchi!AB41""))"),"lun - 01/06/26 CHIUSO") -> lun - 01/06/26 CHIUSO | AR1: =IFERROR(__xludf.DUMMYFUNCTION("ARRAYFORMULA(IMPORTRANGE(""18iHbFEZ6msv3IU3InH0K5SEgnjM_8H0uHajc7c4fMiQ"", ""elenchi!AB42""))"),"lun - 08/06/26 NO BAMBINI") -> lun - 08/06/26 NO BAMBINI | AS1: =IFERROR(__xludf.DUMMYFUNCTION("ARRAYFORMULA(IMPORTRANGE(""18iHbFEZ6msv3IU3InH0K5SEgnjM_8H0uHajc7c4fMiQ"", ""elenchi!AB43""))"),"lun - 15/06/26 NO BAMBINI") -> lun - 15/06/26 NO BAMBINI | AT1: =IFERROR(__xludf.DUMMYFUNCTION("ARRAYFORMULA(IMPORTRANGE(""18iHbFEZ6msv3IU3InH0K5SEgnjM_8H0uHajc7c4fMiQ"", ""elenchi!AB44""))"),"lun - 22/06/26 NO BAMBINI") -> lun - 22/06/26 NO BAMBINI | AU1: =IFERROR(__xludf.DUMMYFUNCTION("ARRAYFORMULA(IMPORTRANGE(""18iHbFEZ6msv3IU3InH0K5SEgnjM_8H0uHajc7c4fMiQ"", ""elenchi!AB45""))"),"lun - 29/06/26 NO BAMBINI") -> lun - 29/06/26 NO BAMBINI | AV1: =IFERROR(__xludf.DUMMYFUNCTION("ARRAYFORMULA(IMPORTRANGE(""18iHbFEZ6msv3IU3InH0K5SEgnjM_8H0uHajc7c4fMiQ"", ""elenchi!AB46""))"),"") | AW1: =IFERROR(__xludf.DUMMYFUNCTION("ARRAYFORMULA(IMPORTRANGE(""18iHbFEZ6msv3IU3InH0K5SEgnjM_8H0uHajc7c4fMiQ"", ""elenchi!AB47""))"),"") | AX1: =IFERROR(__xludf.DUMMYFUNCTION("ARRAYFORMULA(IMPORTRANGE(""18iHbFEZ6msv3IU3InH0K5SEgnjM_8H0uHajc7c4fMiQ"", ""elenchi!AB48""))"),"") | AY1: =IFERROR(__xludf.DUMMYFUNCTION("ARRAYFORMULA(IMPORTRANGE(""18iHbFEZ6msv3IU3InH0K5SEgnjM_8H0uHajc7c4fMiQ"", ""elenchi!AB49""))"),"") | AZ1: TOTALE | BA1: {=LISTA!L3:L86} -> dettaglio iscrizione (N) | BB1: {=LISTA!AK3:AK86} -> saldo totale (BO) | BC1: {=LISTA!AN3:AN86} -> data scad quota tessera (CB) | BD1: {=LISTA!AQ3:AQ86} -> data scad cert. medico (CF)
B2: 20 | C2: DONNE | D2: =C2 -> DONNE
A3: ID-000693 | B3: BATTISTI | C3: VALERIA | D3: FALSE | E3: FALSE | F3: FALSE | G3: FALSE | H3: FALSE | I3: FALSE | J3: FALSE | K3: FALSE | L3: FALSE | M3: FALSE | N3: FALSE | O3: FALSE | P3: FALSE | Q3: FALSE | R3: FALSE | S3: FALSE | T3: FALSE | U3: FALSE | V3: FALSE | W3: FALSE | X3: FALSE | Y3: FALSE | Z3: FALSE | AA3: FALSE | AB3: FALSE | AC3: FALSE | AD3: FALSE | AE3: FALSE | AF3: FALSE | AG3: FALSE | AH3: FALSE | AI3: FALSE | AJ3: FALSE | AK3: FALSE | AL3: FALSE | AM3: FALSE | AN3: FALSE | AO3: FALSE | AP3: FALSE | AQ3: FALSE | AR3: FALSE | AS3: FALSE | AT3: FALSE | AU3: FALSE | AV3: FALSE | AW3: FALSE | AX3: FALSE | AY3: FALSE | AZ3: =SUMPRODUCT(--D3:AY3) -> 0 | BA3: iscritto Donna | BB3: 1325 | BC3: 46174 | BD3: 46218
A4: ID-001740 | B4: CLEMENTE | C4: ISABELLA | D4: FALSE | E4: TRUE | F4: TRUE | G4: TRUE | H4: FALSE | I4: TRUE | J4: TRUE | K4: FALSE | L4: FALSE | M4: FALSE | N4: FALSE | O4: FALSE | P4: FALSE | Q4: FALSE | R4: FALSE | S4: FALSE | T4: FALSE | U4: FALSE | V4: FALSE | W4: FALSE | X4: FALSE | Y4: FALSE | Z4: FALSE | AA4: FALSE | AB4: FALSE | AC4: FALSE | AD4: FALSE | AE4: FALSE | AF4: FALSE | AG4: FALSE | AH4: FALSE | AI4: FALSE | AJ4: FALSE | AK4: FALSE | AL4: FALSE | AM4: FALSE | AN4: FALSE | AO4: FALSE | AP4: FALSE | AQ4: FALSE | AR4: FALSE | AS4: FALSE | AT4: FALSE | AU4: FALSE | AV4: FALSE | AW4: FALSE | AX4: FALSE | AY4: FALSE | AZ4: =SUMPRODUCT(--D4:AY4) -> 5 | BA4: iscritto Donna | BB4: 705 | BC4: 46296 | BD4: 45959
D5: FALSE | E5: FALSE | F5: FALSE | G5: FALSE | H5: FALSE | I5: FALSE | J5: FALSE | K5: FALSE | L5: FALSE | M5: FALSE | N5: FALSE | O5: FALSE | P5: FALSE | Q5: FALSE | R5: FALSE | S5: FALSE | T5: FALSE | U5: FALSE | V5: FALSE | W5: FALSE | X5: FALSE | Y5: FALSE | Z5: FALSE | AA5: FALSE | AB5: FALSE | AC5: FALSE | AD5: FALSE | AE5: FALSE | AF5: FALSE | AG5: FALSE | AH5: FALSE | AI5: FALSE | AJ5: FALSE | AK5: FALSE | AL5: FALSE | AM5: FALSE | AN5: FALSE | AO5: FALSE | AP5: FALSE | AQ5: FALSE | AR5: FALSE | AS5: FALSE | AT5: FALSE | AU5: FALSE | AV5: FALSE | AW5: FALSE | AX5: FALSE | AY5: FALSE | AZ5: =SUMPRODUCT(--D5:AY5) -> 0
D6: FALSE | E6: FALSE | F6: FALSE | G6: FALSE | H6: FALSE | I6: FALSE | J6: FALSE | K6: FALSE | L6: FALSE | M6: FALSE | N6: FALSE | O6: FALSE | P6: FALSE | Q6: FALSE | R6: FALSE | S6: FALSE | T6: FALSE | U6: FALSE | V6: FALSE | W6: FALSE | X6: FALSE | Y6: FALSE | Z6: FALSE | AA6: FALSE | AB6: FALSE | AC6: FALSE | AD6: FALSE | AE6: FALSE | AF6: FALSE | AG6: FALSE | AH6: FALSE | AI6: FALSE | AJ6: FALSE | AK6: FALSE | AL6: FALSE | AM6: FALSE | AN6: FALSE | AO6: FALSE | AP6: FALSE | AQ6: FALSE | AR6: FALSE | AS6: FALSE | AT6: FALSE | AU6: FALSE | AV6: FALSE | AW6: FALSE | AX6: FALSE | AY6: FALSE | AZ6: =SUMPRODUCT(--D6:AY6) -> 0
D7: FALSE | E7: FALSE | F7: FALSE | G7: FALSE | H7: FALSE | I7: FALSE | J7: FALSE | K7: FALSE | L7: FALSE | M7: FALSE | N7: FALSE | O7: FALSE | P7: FALSE | Q7: FALSE | R7: FALSE | S7: FALSE | T7: FALSE | U7: FALSE | V7: FALSE | W7: FALSE | X7: FALSE | Y7: FALSE | Z7: FALSE | AA7: FALSE | AB7: FALSE | AC7: FALSE | AD7: FALSE | AE7: FALSE | AF7: FALSE | AG7: FALSE | AH7: FALSE | AI7: FALSE | AJ7: FALSE | AK7: FALSE | AL7: FALSE | AM7: FALSE | AN7: FALSE | AO7: FALSE | AP7: FALSE | AQ7: FALSE | AR7: FALSE | AS7: FALSE | AT7: FALSE | AU7: FALSE | AV7: FALSE | AW7: FALSE | AX7: FALSE | AY7: FALSE | AZ7: =SUMPRODUCT(--D7:AY7) -> 0
A8: ID-000357 | B8: FELICI | C8: ARIANNA | D8: FALSE | E8: FALSE | F8: FALSE | G8: FALSE | H8: FALSE | I8: FALSE | J8: FALSE | K8: FALSE | L8: FALSE | M8: FALSE | N8: FALSE | O8: FALSE | P8: FALSE | Q8: FALSE | R8: FALSE | S8: FALSE | T8: FALSE | U8: FALSE | V8: FALSE | W8: FALSE | X8: FALSE | Y8: FALSE | Z8: FALSE | AA8: FALSE | AB8: FALSE | AC8: FALSE | AD8: FALSE | AE8: FALSE | AF8: FALSE | AG8: FALSE | AH8: FALSE | AI8: FALSE | AJ8: FALSE | AK8: FALSE | AL8: FALSE | AM8: FALSE | AN8: FALSE | AO8: FALSE | AP8: FALSE | AQ8: FALSE | AR8: FALSE | AS8: FALSE | AT8: FALSE | AU8: FALSE | AV8: FALSE | AW8: FALSE | AX8: FALSE | AY8: FALSE | AZ8: =SUMPRODUCT(--D8:AY8) -> 0 | BA8: iscritto Donna | BB8: 337 | BC8: 46266 | BD8: 45937
A9: ID-000029 | B9: FERNANDO MATARAKIRI | C9: MELANY SERENA TRACY | D9: FALSE | E9: FALSE | F9: FALSE | G9: FALSE | H9: FALSE | I9: FALSE | J9: FALSE | K9: FALSE | L9: FALSE | M9: FALSE | N9: FALSE | O9: FALSE | P9: FALSE | Q9: FALSE | R9: FALSE | S9: FALSE | T9: FALSE | U9: FALSE | V9: FALSE | W9: FALSE | X9: FALSE | Y9: FALSE | Z9: FALSE | AA9: FALSE | AB9: FALSE | AC9: FALSE | AD9: FALSE | AE9: FALSE | AF9: FALSE | AG9: FALSE | AH9: FALSE | AI9: FALSE | AJ9: FALSE | AK9: FALSE | AL9: FALSE | AM9: FALSE | AN9: FALSE | AO9: FALSE | AP9: FALSE | AQ9: FALSE | AR9: FALSE | AS9: FALSE | AT9: FALSE | AU9: FALSE | AV9: FALSE | AW9: FALSE | AX9: FALSE | AY9: FALSE | AZ9: =SUMPRODUCT(--D9:AY9) -> 0 | BA9: iscritto Donna | BB9: 1325 | BC9: 46174 | BD9: 46211
A10: ID-001115 | B10: GRISI | C10: BEATRICE | D10: FALSE | E10: TRUE | F10: TRUE | G10: TRUE | H10: TRUE | I10: TRUE | J10: FALSE | K10: FALSE | L10: FALSE | M10: FALSE | N10: FALSE | O10: FALSE | P10: FALSE | Q10: FALSE | R10: FALSE | S10: FALSE | T10: FALSE | U10: FALSE | V10: FALSE | W10: FALSE | X10: FALSE | Y10: FALSE | Z10: FALSE | AA10: FALSE | AB10: FALSE | AC10: FALSE | AD10: FALSE | AE10: FALSE | AF10: FALSE | AG10: FALSE | AH10: FALSE | AI10: FALSE | AJ10: FALSE | AK10: FALSE | AL10: FALSE | AM10: FALSE | AN10: FALSE | AO10: FALSE | AP10: FALSE | AQ10: FALSE | AR10: FALSE | AS10: FALSE | AT10: FALSE | AU10: FALSE | AV10: FALSE | AW10: FALSE | AX10: FALSE | AY10: FALSE | AZ10: =SUMPRODUCT(--D10:AY10) -> 5 | BA10: iscritto Donna | BB10: 415 | BC10: 46266 | BD10: 36526
A11: ID-001082 | B11: URBANO | C11: CLAUDIA | D11: FALSE | E11: FALSE | F11: TRUE | G11: TRUE | H11: TRUE | I11: TRUE | J11: FALSE | K11: TRUE | L11: TRUE | M11: FALSE | N11: FALSE | O11: FALSE | P11: FALSE | Q11: FALSE | R11: FALSE | S11: FALSE | T11: FALSE | U11: FALSE | V11: FALSE | W11: FALSE | X11: FALSE | Y11: FALSE | Z11: FALSE | AA11: FALSE | AB11: FALSE | AC11: FALSE | AD11: FALSE | AE11: FALSE | AF11: FALSE | AG11: FALSE | AH11: FALSE | AI11: FALSE | AJ11: FALSE | AK11: FALSE | AL11: FALSE | AM11: FALSE | AN11: FALSE | AO11: FALSE | AP11: FALSE | AQ11: FALSE | AR11: FALSE | AS11: FALSE | AT11: FALSE | AU11: FALSE | AV11: FALSE | AW11: FALSE | AX11: FALSE | AY11: FALSE | AZ11: =SUMPRODUCT(--D11:AY11) -> 6 | BA11: prova pagata D | BB11: 390 | BC11: 46174 | BD11: 46197
A12: ID-000354 | B12: DE MARTINO | C12: LUCIA | D12: TRUE | E12: TRUE | F12: TRUE | G12: FALSE | H12: FALSE | I12: TRUE | J12: FALSE | K12: FALSE | L12: FALSE | M12: FALSE | N12: FALSE | O12: FALSE | P12: FALSE | Q12: FALSE | R12: FALSE | S12: FALSE | T12: FALSE | U12: FALSE | V12: FALSE | W12: FALSE | X12: FALSE | Y12: FALSE | Z12: FALSE | AA12: FALSE | AB12: FALSE | AC12: FALSE | AD12: FALSE | AE12: FALSE | AF12: FALSE | AG12: FALSE | AH12: FALSE | AI12: FALSE | AJ12: FALSE | AK12: FALSE | AL12: FALSE | AM12: FALSE | AN12: FALSE | AO12: FALSE | AP12: FALSE | AQ12: FALSE | AR12: FALSE | AS12: FALSE | AT12: FALSE | AU12: FALSE | AV12: FALSE | AW12: FALSE | AX12: FALSE | AY12: FALSE | AZ12: =SUMPRODUCT(--D12:AY12) -> 4 | BA12: iscritto Donna | BB12: 707.5 | BC12: 46296 | BD12: 45974
D13: FALSE | E13: FALSE | F13: FALSE | G13: FALSE | H13: FALSE | I13: FALSE | J13: FALSE | K13: FALSE | L13: FALSE | M13: FALSE | N13: FALSE | O13: FALSE | P13: FALSE | Q13: FALSE | R13: FALSE | S13: FALSE | T13: FALSE | U13: FALSE | V13: FALSE | W13: FALSE | X13: FALSE | Y13: FALSE | Z13: FALSE | AA13: FALSE | AB13: FALSE | AC13: FALSE | AD13: FALSE | AE13: FALSE | AF13: FALSE | AG13: FALSE | AH13: FALSE | AI13: FALSE | AJ13: FALSE | AK13: FALSE | AL13: FALSE | AM13: FALSE | AN13: FALSE | AO13: FALSE | AP13: FALSE | AQ13: FALSE | AR13: FALSE | AS13: FALSE | AT13: FALSE | AU13: FALSE | AV13: FALSE | AW13: FALSE | AX13: FALSE | AY13: FALSE | AZ13: =SUMPRODUCT(--D13:AY13) -> 0
A14: ID-000378 | B14: PALADINI | C14: MARIA CHIARA | D14: TRUE | E14: TRUE | F14: TRUE | G14: TRUE | H14: TRUE | I14: TRUE | J14: TRUE | K14: TRUE | L14: TRUE | M14: FALSE | N14: FALSE | O14: FALSE | P14: FALSE | Q14: FALSE | R14: FALSE | S14: FALSE | T14: FALSE | U14: FALSE | V14: FALSE | W14: FALSE | X14: FALSE | Y14: FALSE | Z14: FALSE | AA14: FALSE | AB14: FALSE | AC14: FALSE | AD14: FALSE | AE14: FALSE | AF14: FALSE | AG14: FALSE | AH14: FALSE | AI14: FALSE | AJ14: FALSE | AK14: FALSE | AL14: FALSE | AM14: FALSE | AN14: FALSE | AO14: FALSE | AP14: FALSE | AQ14: FALSE | AR14: FALSE | AS14: FALSE | AT14: FALSE | AU14: FALSE | AV14: FALSE | AW14: FALSE | AX14: FALSE | AY14: FALSE | AZ14: =SUMPRODUCT(--D14:AY14) -> 9 | BA14: deve pagare D | BB14: 727 | BC14: 46174 | BD14: 46293
D15: FALSE | E15: FALSE | F15: FALSE | G15: FALSE | H15: FALSE | I15: FALSE | J15: FALSE | K15: FALSE | L15: FALSE | M15: FALSE | N15: FALSE | O15: FALSE | P15: FALSE | Q15: FALSE | R15: FALSE | S15: FALSE | T15: FALSE | U15: FALSE | V15: FALSE | W15: FALSE | X15: FALSE | Y15: FALSE | Z15: FALSE | AA15: FALSE | AB15: FALSE | AC15: FALSE | AD15: FALSE | AE15: FALSE | AF15: FALSE | AG15: FALSE | AH15: FALSE | AI15: FALSE | AJ15: FALSE | AK15: FALSE | AL15: FALSE | AM15: FALSE | AN15: FALSE | AO15: FALSE | AP15: FALSE | AQ15: FALSE | AR15: FALSE | AS15: FALSE | AT15: FALSE | AU15: FALSE | AV15: FALSE | AW15: FALSE | AX15: FALSE | AY15: FALSE | AZ15: =SUMPRODUCT(--D15:AY15) -> 0
D16: FALSE | E16: FALSE | F16: FALSE | G16: FALSE | H16: FALSE | I16: FALSE | J16: FALSE | K16: FALSE | L16: FALSE | M16: FALSE | N16: FALSE | O16: FALSE | P16: FALSE | Q16: FALSE | R16: FALSE | S16: FALSE | T16: FALSE | U16: FALSE | V16: FALSE | W16: FALSE | X16: FALSE | Y16: FALSE | Z16: FALSE | AA16: FALSE | AB16: FALSE | AC16: FALSE | AD16: FALSE | AE16: FALSE | AF16: FALSE | AG16: FALSE | AH16: FALSE | AI16: FALSE | AJ16: FALSE | AK16: FALSE | AL16: FALSE | AM16: FALSE | AN16: FALSE | AO16: FALSE | AP16: FALSE | AQ16: FALSE | AR16: FALSE | AS16: FALSE | AT16: FALSE | AU16: FALSE | AV16: FALSE | AW16: FALSE | AX16: FALSE | AY16: FALSE | AZ16: =SUMPRODUCT(--D16:AY16) -> 0
D17: FALSE | E17: FALSE | F17: FALSE | G17: FALSE | H17: FALSE | I17: FALSE | J17: FALSE | K17: FALSE | L17: FALSE | M17: FALSE | N17: FALSE | O17: FALSE | P17: FALSE | Q17: FALSE | R17: FALSE | S17: FALSE | T17: FALSE | U17: FALSE | V17: FALSE | W17: FALSE | X17: FALSE | Y17: FALSE | Z17: FALSE | AA17: FALSE | AB17: FALSE | AC17: FALSE | AD17: FALSE | AE17: FALSE | AF17: FALSE | AG17: FALSE | AH17: FALSE | AI17: FALSE | AJ17: FALSE | AK17: FALSE | AL17: FALSE | AM17: FALSE | AN17: FALSE | AO17: FALSE | AP17: FALSE | AQ17: FALSE | AR17: FALSE | AS17: FALSE | AT17: FALSE | AU17: FALSE | AV17: FALSE | AW17: FALSE | AX17: FALSE | AY17: FALSE | AZ17: =SUMPRODUCT(--D17:AY17) -> 0
D18: FALSE | E18: FALSE | F18: FALSE | G18: FALSE | H18: FALSE | I18: FALSE | J18: FALSE | K18: FALSE | L18: FALSE | M18: FALSE | N18: FALSE | O18: FALSE | P18: FALSE | Q18: FALSE | R18: FALSE | S18: FALSE | T18: FALSE | U18: FALSE | V18: FALSE | W18: FALSE | X18: FALSE | Y18: FALSE | Z18: FALSE | AA18: FALSE | AB18: FALSE | AC18: FALSE | AD18: FALSE | AE18: FALSE | AF18: FALSE | AG18: FALSE | AH18: FALSE | AI18: FALSE | AJ18: FALSE | AK18: FALSE | AL18: FALSE | AM18: FALSE | AN18: FALSE | AO18: FALSE | AP18: FALSE | AQ18: FALSE | AR18: FALSE | AS18: FALSE | AT18: FALSE | AU18: FALSE | AV18: FALSE | AW18: FALSE | AX18: FALSE | AY18: FALSE | AZ18: =SUMPRODUCT(--D18:AY18) -> 0
A19: ID-000381 | B19: RISSO | C19: NAILA | D19: FALSE | E19: FALSE | F19: FALSE | G19: FALSE | H19: FALSE | I19: FALSE | J19: FALSE | K19: FALSE | L19: FALSE | M19: FALSE | N19: FALSE | O19: FALSE | P19: FALSE | Q19: FALSE | R19: FALSE | S19: FALSE | T19: FALSE | U19: FALSE | V19: FALSE | W19: FALSE | X19: FALSE | Y19: FALSE | Z19: FALSE | AA19: FALSE | AB19: FALSE | AC19: FALSE | AD19: FALSE | AE19: FALSE | AF19: FALSE | AG19: FALSE | AH19: FALSE | AI19: FALSE | AJ19: FALSE | AK19: FALSE | AL19: FALSE | AM19: FALSE | AN19: FALSE | AO19: FALSE | AP19: FALSE | AQ19: FALSE | AR19: FALSE | AS19: FALSE | AT19: FALSE | AU19: FALSE | AV19: FALSE | AW19: FALSE | AX19: FALSE | AY19: FALSE | AZ19: =SUMPRODUCT(--D19:AY19) -> 0 | BA19: iscritto Donna | BB19: 337 | BC19: 46174 | BD19: 46104
A20: ID-001777 | B20: RASTRELLI | C20: GIORGIA | D20: FALSE | E20: FALSE | F20: FALSE | G20: FALSE | H20: FALSE | I20: FALSE | J20: FALSE | K20: FALSE | L20: FALSE | M20: FALSE | N20: FALSE | O20: FALSE | P20: FALSE | Q20: FALSE | R20: FALSE | S20: FALSE | T20: FALSE | U20: FALSE | V20: FALSE | W20: FALSE | X20: FALSE | Y20: FALSE | Z20: FALSE | AA20: FALSE | AB20: FALSE | AC20: FALSE | AD20: FALSE | AE20: FALSE | AF20: FALSE | AG20: FALSE | AH20: FALSE | AI20: FALSE | AJ20: FALSE | AK20: FALSE | AL20: FALSE | AM20: FALSE | AN20: FALSE | AO20: FALSE | AP20: FALSE | AQ20: FALSE | AR20: FALSE | AS20: FALSE | AT20: FALSE | AU20: FALSE | AV20: FALSE | AW20: FALSE | AX20: FALSE | AY20: FALSE | AZ20: =SUMPRODUCT(--D20:AY20) -> 0 | BA20: iscritto Donna | BB20: 390 | BC20: 46023 | BD20: 46097
A21: ID-001518 | B21: RUVIO | C21: EMAUELA | D21: FALSE | E21: FALSE | F21: FALSE | G21: FALSE | H21: FALSE | I21: FALSE | J21: FALSE | K21: FALSE | L21: FALSE | M21: FALSE | N21: FALSE | O21: FALSE | P21: FALSE | Q21: FALSE | R21: FALSE | S21: FALSE | T21: FALSE | U21: FALSE | V21: FALSE | W21: FALSE | X21: FALSE | Y21: FALSE | Z21: FALSE | AA21: FALSE | AB21: FALSE | AC21: FALSE | AD21: FALSE | AE21: FALSE | AF21: FALSE | AG21: FALSE | AH21: FALSE | AI21: FALSE | AJ21: FALSE | AK21: FALSE | AL21: FALSE | AM21: FALSE | AN21: FALSE | AO21: FALSE | AP21: FALSE | AQ21: FALSE | AR21: FALSE | AS21: FALSE | AT21: FALSE | AU21: FALSE | AV21: FALSE | AW21: FALSE | AX21: FALSE | AY21: FALSE | AZ21: =SUMPRODUCT(--D21:AY21) -> 0 | BA21: iscritto Donna | BB21: 415 | BC21: 46266 | BD21: 45985
A22: ID-001021 | B22: STICOTTI | C22: BEATRICE | D22: FALSE | E22: FALSE | F22: FALSE | G22: FALSE | H22: FALSE | I22: FALSE | J22: FALSE | K22: FALSE | L22: FALSE | M22: FALSE | N22: FALSE | O22: FALSE | P22: FALSE | Q22: FALSE | R22: FALSE | S22: FALSE | T22: FALSE | U22: FALSE | V22: FALSE | W22: FALSE | X22: FALSE | Y22: FALSE | Z22: FALSE | AA22: FALSE | AB22: FALSE | AC22: FALSE | AD22: FALSE | AE22: FALSE | AF22: FALSE | AG22: FALSE | AH22: FALSE | AI22: FALSE | AJ22: FALSE | AK22: FALSE | AL22: FALSE | AM22: FALSE | AN22: FALSE | AO22: FALSE | AP22: FALSE | AQ22: FALSE | AR22: FALSE | AS22: FALSE | AT22: FALSE | AU22: FALSE | AV22: FALSE | AW22: FALSE | AX22: FALSE | AY22: FALSE | AZ22: =SUMPRODUCT(--D22:AY22) -> 0 | BA22: iscritto Donna | BB22: 351 | BC22: 45658 | BD22: 45825
A23: ID-001022 | B23: STICOTTI | C23: CAMILLA | D23: FALSE | E23: FALSE | F23: FALSE | G23: FALSE | H23: FALSE | I23: FALSE | J23: FALSE | K23: FALSE | L23: FALSE | M23: FALSE | N23: FALSE | O23: FALSE | P23: FALSE | Q23: FALSE | R23: FALSE | S23: FALSE | T23: FALSE | U23: FALSE | V23: FALSE | W23: FALSE | X23: FALSE | Y23: FALSE | Z23: FALSE | AA23: FALSE | AB23: FALSE | AC23: FALSE | AD23: FALSE | AE23: FALSE | AF23: FALSE | AG23: FALSE | AH23: FALSE | AI23: FALSE | AJ23: FALSE | AK23: FALSE | AL23: FALSE | AM23: FALSE | AN23: FALSE | AO23: FALSE | AP23: FALSE | AQ23: FALSE | AR23: FALSE | AS23: FALSE | AT23: FALSE | AU23: FALSE | AV23: FALSE | AW23: FALSE | AX23: FALSE | AY23: FALSE | AZ23: =SUMPRODUCT(--D23:AY23) -> 0 | BA23: iscritto Donna | BB23: 376 | BC23: 46204 | BD23: 36526
A24: ID-000387 | B24: STARACE | C24: PAOLA | D24: FALSE | E24: FALSE | F24: FALSE | G24: FALSE | H24: FALSE | I24: FALSE | J24: FALSE | K24: FALSE | L24: FALSE | M24: FALSE | N24: FALSE | O24: FALSE | P24: FALSE | Q24: FALSE | R24: FALSE | S24: FALSE | T24: FALSE | U24: FALSE | V24: FALSE | W24: FALSE | X24: FALSE | Y24: FALSE | Z24: FALSE | AA24: FALSE | AB24: FALSE | AC24: FALSE | AD24: FALSE | AE24: FALSE | AF24: FALSE | AG24: FALSE | AH24: FALSE | AI24: FALSE | AJ24: FALSE | AK24: FALSE | AL24: FALSE | AM24: FALSE | AN24: FALSE | AO24: FALSE | AP24: FALSE | AQ24: FALSE | AR24: FALSE | AS24: FALSE | AT24: FALSE | AU24: FALSE | AV24: FALSE | AW24: FALSE | AX24: FALSE | AY24: FALSE | AZ24: =SUMPRODUCT(--D24:AY24) -> 0 | BA24: iscritto Donna | BB24: 889 | BC24: 46174 | BD24: 45936
A25: ID-000759 | B25: VASTA | C25: MARIA GRAZIA | D25: TRUE | E25: TRUE | F25: FALSE | G25: FALSE | H25: FALSE | I25: FALSE | J25: FALSE | K25: FALSE | L25: FALSE | M25: FALSE | N25: FALSE | O25: FALSE | P25: FALSE | Q25: FALSE | R25: FALSE | S25: FALSE | T25: FALSE | U25: FALSE | V25: FALSE | W25: FALSE | X25: FALSE | Y25: FALSE | Z25: FALSE | AA25: FALSE | AB25: FALSE | AC25: FALSE | AD25: FALSE | AE25: FALSE | AF25: FALSE | AG25: FALSE | AH25: FALSE | AI25: FALSE | AJ25: FALSE | AK25: FALSE | AL25: FALSE | AM25: FALSE | AN25: FALSE | AO25: FALSE | AP25: FALSE | AQ25: FALSE | AR25: FALSE | AS25: FALSE | AT25: FALSE | AU25: FALSE | AV25: FALSE | AW25: FALSE | AX25: FALSE | AY25: FALSE | AZ25: =SUMPRODUCT(--D25:AY25) -> 2 | BA25: iscritto Donna | BB25: 637 | BC25: 46266 | BD25: 45969
A26: ID-001391 | B26: ZANOTTO | C26: BEATRICE AMBRA | D26: FALSE | E26: FALSE | F26: FALSE | G26: FALSE | H26: FALSE | I26: FALSE | J26: FALSE | K26: FALSE | L26: FALSE | M26: FALSE | N26: FALSE | O26: FALSE | P26: FALSE | Q26: FALSE | R26: FALSE | S26: FALSE | T26: FALSE | U26: FALSE | V26: FALSE | W26: FALSE | X26: FALSE | Y26: FALSE | Z26: FALSE | AA26: FALSE | AB26: FALSE | AC26: FALSE | AD26: FALSE | AE26: FALSE | AF26: FALSE | AG26: FALSE | AH26: FALSE | AI26: FALSE | AJ26: FALSE | AK26: FALSE | AL26: FALSE | AM26: FALSE | AN26: FALSE | AO26: FALSE | AP26: FALSE | AQ26: FALSE | AR26: FALSE | AS26: FALSE | AT26: FALSE | AU26: FALSE | AV26: FALSE | AW26: FALSE | AX26: FALSE | AY26: FALSE | AZ26: =SUMPRODUCT(--D26:AY26) -> 0 | BA26: iscritto Donna | BB26: 280 | BC26: 46082 | BD26: 46126
A27: ID-001349 | B27: BACCHI | C27: CHIARA | D27: FALSE | E27: FALSE | F27: FALSE | G27: FALSE | H27: FALSE | I27: FALSE | J27: FALSE | K27: FALSE | L27: FALSE | M27: FALSE | N27: FALSE | O27: FALSE | P27: FALSE | Q27: FALSE | R27: FALSE | S27: FALSE | T27: FALSE | U27: FALSE | V27: FALSE | W27: FALSE | X27: FALSE | Y27: FALSE | Z27: FALSE | AA27: FALSE | AB27: FALSE | AC27: FALSE | AD27: FALSE | AE27: FALSE | AF27: FALSE | AG27: FALSE | AH27: FALSE | AI27: FALSE | AJ27: FALSE | AK27: FALSE | AL27: FALSE | AM27: FALSE | AN27: FALSE | AO27: FALSE | AP27: FALSE | AQ27: FALSE | AR27: FALSE | AS27: FALSE | AT27: FALSE | AU27: FALSE | AV27: FALSE | AW27: FALSE | AX27: FALSE | AY27: FALSE | AZ27: =SUMPRODUCT(--D27:AY27) -> 0 | BA27: iscritto Donna | BB27: 280 | BC27: 46054 | BD27: 45985
D28: FALSE | E28: FALSE | F28: FALSE | G28: FALSE | H28: FALSE | I28: FALSE | J28: FALSE | K28: FALSE | L28: FALSE | M28: FALSE | N28: FALSE | O28: FALSE | P28: FALSE | Q28: FALSE | R28: FALSE | S28: FALSE | T28: FALSE | U28: FALSE | V28: FALSE | W28: FALSE | X28: FALSE | Y28: FALSE | Z28: FALSE | AA28: FALSE | AB28: FALSE | AC28: FALSE | AD28: FALSE | AE28: FALSE | AF28: FALSE | AG28: FALSE | AH28: FALSE | AI28: FALSE | AJ28: FALSE | AK28: FALSE | AL28: FALSE | AM28: FALSE | AN28: FALSE | AO28: FALSE | AP28: FALSE | AQ28: FALSE | AR28: FALSE | AS28: FALSE | AT28: FALSE | AU28: FALSE | AV28: FALSE | AW28: FALSE | AX28: FALSE | AY28: FALSE | AZ28: =SUMPRODUCT(--D28:AY28) -> 0
A29: ID-001099 | B29: PALACIOS HUANCA | C29: ESTHER | D29: FALSE | E29: FALSE | F29: FALSE | G29: FALSE | H29: FALSE | I29: FALSE | J29: FALSE | K29: FALSE | L29: FALSE | M29: FALSE | N29: FALSE | O29: FALSE | P29: FALSE | Q29: FALSE | R29: FALSE | S29: FALSE | T29: FALSE | U29: FALSE | V29: FALSE | W29: FALSE | X29: FALSE | Y29: FALSE | Z29: FALSE | AA29: FALSE | AB29: FALSE | AC29: FALSE | AD29: FALSE | AE29: FALSE | AF29: FALSE | AG29: FALSE | AH29: FALSE | AI29: FALSE | AJ29: FALSE | AK29: FALSE | AL29: FALSE | AM29: FALSE | AN29: FALSE | AO29: FALSE | AP29: FALSE | AQ29: FALSE | AR29: FALSE | AS29: FALSE | AT29: FALSE | AU29: FALSE | AV29: FALSE | AW29: FALSE | AX29: FALSE | AY29: FALSE | AZ29: =SUMPRODUCT(--D29:AY29) -> 0 | BA29: iscritto Donna | BB29: 415 | BC29: 46266 | BD29: 01/01/0200
D30: FALSE | E30: FALSE | F30: FALSE | G30: FALSE | H30: FALSE | I30: FALSE | J30: FALSE | K30: FALSE | L30: FALSE | M30: FALSE | N30: FALSE | O30: FALSE | P30: FALSE | Q30: FALSE | R30: FALSE | S30: FALSE | T30: FALSE | U30: FALSE | V30: FALSE | W30: FALSE | X30: FALSE | Y30: FALSE | Z30: FALSE | AA30: FALSE | AB30: FALSE | AC30: FALSE | AD30: FALSE | AE30: FALSE | AF30: FALSE | AG30: FALSE | AH30: FALSE | AI30: FALSE | AJ30: FALSE | AK30: FALSE | AL30: FALSE | AM30: FALSE | AN30: FALSE | AO30: FALSE | AP30: FALSE | AQ30: FALSE | AR30: FALSE | AS30: FALSE | AT30: FALSE | AU30: FALSE | AV30: FALSE | AW30: FALSE | AX30: FALSE | AY30: FALSE | AZ30: =SUMPRODUCT(--D30:AY30) -> 0
A31: ID-003411 | B31: LEVY | C31: TOVA MICHELLE | D31: FALSE | E31: FALSE | F31: FALSE | G31: FALSE | H31: FALSE | I31: FALSE | J31: FALSE | K31: FALSE | L31: FALSE | M31: FALSE | N31: FALSE | O31: FALSE | P31: FALSE | Q31: FALSE | R31: FALSE | S31: FALSE | T31: FALSE | U31: FALSE | V31: FALSE | W31: FALSE | X31: FALSE | Y31: FALSE | Z31: FALSE | AA31: FALSE | AB31: FALSE | AC31: FALSE | AD31: FALSE | AE31: FALSE | AF31: FALSE | AG31: FALSE | AH31: FALSE | AI31: FALSE | AJ31: FALSE | AK31: FALSE | AL31: FALSE | AM31: FALSE | AN31: FALSE | AO31: FALSE | AP31: FALSE | AQ31: FALSE | AR31: FALSE | AS31: FALSE | AT31: FALSE | AU31: FALSE | AV31: FALSE | AW31: FALSE | AX31: FALSE | AY31: FALSE | AZ31: =SUMPRODUCT(--D31:AY31) -> 0 | BA31: iscritto Donna | BB31: 415 | BC31: 46296 | BD31: 46100
A32: ID-000458 | B32: MAFFIOLI | C32: SOFIA | D32: FALSE | E32: FALSE | F32: FALSE | G32: FALSE | H32: FALSE | I32: FALSE | J32: FALSE | K32: FALSE | L32: FALSE | M32: FALSE | N32: FALSE | O32: FALSE | P32: FALSE | Q32: FALSE | R32: FALSE | S32: FALSE | T32: FALSE | U32: FALSE | V32: FALSE | W32: FALSE | X32: FALSE | Y32: FALSE | Z32: FALSE | AA32: FALSE | AB32: FALSE | AC32: FALSE | AD32: FALSE | AE32: FALSE | AF32: FALSE | AG32: FALSE | AH32: FALSE | AI32: FALSE | AJ32: FALSE | AK32: FALSE | AL32: FALSE | AM32: FALSE | AN32: FALSE | AO32: FALSE | AP32: FALSE | AQ32: FALSE | AR32: FALSE | AS32: FALSE | AT32: FALSE | AU32: FALSE | AV32: FALSE | AW32: FALSE | AX32: FALSE | AY32: FALSE | AZ32: =SUMPRODUCT(--D32:AY32) -> 0 | BA32: iscritto Donna | BB32: 312 | BC32: 46143 | BD32: 45953
D33: FALSE | E33: FALSE | F33: FALSE | G33: FALSE | H33: FALSE | I33: FALSE | J33: FALSE | K33: FALSE | L33: FALSE | M33: FALSE | N33: FALSE | O33: FALSE | P33: FALSE | Q33: FALSE | R33: FALSE | S33: FALSE | T33: FALSE | U33: FALSE | V33: FALSE | W33: FALSE | X33: FALSE | Y33: FALSE | Z33: FALSE | AA33: FALSE | AB33: FALSE | AC33: FALSE | AD33: FALSE | AE33: FALSE | AF33: FALSE | AG33: FALSE | AH33: FALSE | AI33: FALSE | AJ33: FALSE | AK33: FALSE | AL33: FALSE | AM33: FALSE | AN33: FALSE | AO33: FALSE | AP33: FALSE | AQ33: FALSE | AR33: FALSE | AS33: FALSE | AT33: FALSE | AU33: FALSE | AV33: FALSE | AW33: FALSE | AX33: FALSE | AY33: FALSE | AZ33: =SUMPRODUCT(--D33:AY33) -> 0
D34: FALSE | E34: FALSE | F34: FALSE | G34: FALSE | H34: FALSE | I34: FALSE | J34: FALSE | K34: FALSE | L34: FALSE | M34: FALSE | N34: FALSE | O34: FALSE | P34: FALSE | Q34: FALSE | R34: FALSE | S34: FALSE | T34: FALSE | U34: FALSE | V34: FALSE | W34: FALSE | X34: FALSE | Y34: FALSE | Z34: FALSE | AA34: FALSE | AB34: FALSE | AC34: FALSE | AD34: FALSE | AE34: FALSE | AF34: FALSE | AG34: FALSE | AH34: FALSE | AI34: FALSE | AJ34: FALSE | AK34: FALSE | AL34: FALSE | AM34: FALSE | AN34: FALSE | AO34: FALSE | AP34: FALSE | AQ34: FALSE | AR34: FALSE | AS34: FALSE | AT34: FALSE | AU34: FALSE | AV34: FALSE | AW34: FALSE | AX34: FALSE | AY34: FALSE | AZ34: =SUMPRODUCT(--D34:AY34) -> 0
D35: FALSE | E35: FALSE | F35: FALSE | G35: FALSE | H35: FALSE | I35: FALSE | J35: FALSE | K35: FALSE | L35: FALSE | M35: FALSE | N35: FALSE | O35: FALSE | P35: FALSE | Q35: FALSE | R35: FALSE | S35: FALSE | T35: FALSE | U35: FALSE | V35: FALSE | W35: FALSE | X35: FALSE | Y35: FALSE | Z35: FALSE | AA35: FALSE | AB35: FALSE | AC35: FALSE | AD35: FALSE | AE35: FALSE | AF35: FALSE | AG35: FALSE | AH35: FALSE | AI35: FALSE | AJ35: FALSE | AK35: FALSE | AL35: FALSE | AM35: FALSE | AN35: FALSE | AO35: FALSE | AP35: FALSE | AQ35: FALSE | AR35: FALSE | AS35: FALSE | AT35: FALSE | AU35: FALSE | AV35: FALSE | AW35: FALSE | AX35: FALSE | AY35: FALSE | AZ35: =SUMPRODUCT(--D35:AY35) -> 0
D36: FALSE | E36: FALSE | F36: FALSE | G36: FALSE | H36: FALSE | I36: FALSE | J36: FALSE | K36: FALSE | L36: FALSE | M36: FALSE | N36: FALSE | O36: FALSE | P36: FALSE | Q36: FALSE | R36: FALSE | S36: FALSE | T36: FALSE | U36: FALSE | V36: FALSE | W36: FALSE | X36: FALSE | Y36: FALSE | Z36: FALSE | AA36: FALSE | AB36: FALSE | AC36: FALSE | AD36: FALSE | AE36: FALSE | AF36: FALSE | AG36: FALSE | AH36: FALSE | AI36: FALSE | AJ36: FALSE | AK36: FALSE | AL36: FALSE | AM36: FALSE | AN36: FALSE | AO36: FALSE | AP36: FALSE | AQ36: FALSE | AR36: FALSE | AS36: FALSE | AT36: FALSE | AU36: FALSE | AV36: FALSE | AW36: FALSE | AX36: FALSE | AY36: FALSE | AZ36: =SUMPRODUCT(--D36:AY36) -> 0
D37: FALSE | E37: FALSE | F37: FALSE | G37: FALSE | H37: FALSE | I37: FALSE | J37: FALSE | K37: FALSE | L37: FALSE | M37: FALSE | N37: FALSE | O37: FALSE | P37: FALSE | Q37: FALSE | R37: FALSE | S37: FALSE | T37: FALSE | U37: FALSE | V37: FALSE | W37: FALSE | X37: FALSE | Y37: FALSE | Z37: FALSE | AA37: FALSE | AB37: FALSE | AC37: FALSE | AD37: FALSE | AE37: FALSE | AF37: FALSE | AG37: FALSE | AH37: FALSE | AI37: FALSE | AJ37: FALSE | AK37: FALSE | AL37: FALSE | AM37: FALSE | AN37: FALSE | AO37: FALSE | AP37: FALSE | AQ37: FALSE | AR37: FALSE | AS37: FALSE | AT37: FALSE | AU37: FALSE | AV37: FALSE | AW37: FALSE | AX37: FALSE | AY37: FALSE | AZ37: =SUMPRODUCT(--D37:AY37) -> 0
D38: FALSE | E38: FALSE | F38: FALSE | G38: FALSE | H38: FALSE | I38: FALSE | J38: FALSE | K38: FALSE | L38: FALSE | M38: FALSE | N38: FALSE | O38: FALSE | P38: FALSE | Q38: FALSE | R38: FALSE | S38: FALSE | T38: FALSE | U38: FALSE | V38: FALSE | W38: FALSE | X38: FALSE | Y38: FALSE | Z38: FALSE | AA38: FALSE | AB38: FALSE | AC38: FALSE | AD38: FALSE | AE38: FALSE | AF38: FALSE | AG38: FALSE | AH38: FALSE | AI38: FALSE | AJ38: FALSE | AK38: FALSE | AL38: FALSE | AM38: FALSE | AN38: FALSE | AO38: FALSE | AP38: FALSE | AQ38: FALSE | AR38: FALSE | AS38: FALSE | AT38: FALSE | AU38: FALSE | AV38: FALSE | AW38: FALSE | AX38: FALSE | AY38: FALSE | AZ38: =SUMPRODUCT(--D38:AY38) -> 0
D39: FALSE | E39: FALSE | F39: FALSE | G39: FALSE | H39: FALSE | I39: FALSE | J39: FALSE | K39: FALSE | L39: FALSE | M39: FALSE | N39: FALSE | O39: FALSE | P39: FALSE | Q39: FALSE | R39: FALSE | S39: FALSE | T39: FALSE | U39: FALSE | V39: FALSE | W39: FALSE | X39: FALSE | Y39: FALSE | Z39: FALSE | AA39: FALSE | AB39: FALSE | AC39: FALSE | AD39: FALSE | AE39: FALSE | AF39: FALSE | AG39: FALSE | AH39: FALSE | AI39: FALSE | AJ39: FALSE | AK39: FALSE | AL39: FALSE | AM39: FALSE | AN39: FALSE | AO39: FALSE | AP39: FALSE | AQ39: FALSE | AR39: FALSE | AS39: FALSE | AT39: FALSE | AU39: FALSE | AV39: FALSE | AW39: FALSE | AX39: FALSE | AY39: FALSE | AZ39: =SUMPRODUCT(--D39:AY39) -> 0
D40: FALSE | E40: FALSE | F40: FALSE | G40: FALSE | H40: FALSE | I40: FALSE | J40: FALSE | K40: FALSE | L40: FALSE | M40: FALSE | N40: FALSE | O40: FALSE | P40: FALSE | Q40: FALSE | R40: FALSE | S40: FALSE | T40: FALSE | U40: FALSE | V40: FALSE | W40: FALSE | X40: FALSE | Y40: FALSE | Z40: FALSE | AA40: FALSE | AB40: FALSE | AC40: FALSE | AD40: FALSE | AE40: FALSE | AF40: FALSE | AG40: FALSE | AH40: FALSE | AI40: FALSE | AJ40: FALSE | AK40: FALSE | AL40: FALSE | AM40: FALSE | AN40: FALSE | AO40: FALSE | AP40: FALSE | AQ40: FALSE | AR40: FALSE | AS40: FALSE | AT40: FALSE | AU40: FALSE | AV40: FALSE | AW40: FALSE | AX40: FALSE | AY40: FALSE | AZ40: =SUMPRODUCT(--D40:AY40) -> 0
...

Sheet PRESENZE_DB
A1: ID | B1: lun - 01/09/25 | C1: lun - 08/09/25 PROVA FITNESS PROVA DANZA | D1: lun - 15/09/25 PROVA BALLO PROVA AERIAL | E1: lun - 22/09/25 PROVA BAMBINI E RAGAZZI | F1: lun - 29/09/25 | G1: lun - 06/10/25 | H1: lun - 13/10/25 | I1: lun - 20/10/25 | J1: lun - 27/10/25 | K1: lun - 03/11/25 | L1: lun - 10/11/25 | M1: lun - 10/11/25 | N1: lun - 17/11/25 | O1: lun - 24/11/25 | P1: lun - 01/12/25 | Q1: lun - 08/12/25 CHIUSO | R1: lun - 15/12/25 | S1: lun - 22/12/25 | T1: lun - 29/12/25 NO CORSI | U1: lun - 29/12/25 NO CORSI | V1: lun - 05/01/26 NO CORSI | W1: lun - 12/01/26 | X1: lun - 26/01/26 | Y1: lun - 26/01/26 | Z1: lun - 02/02/26 | AA1: lun - 09/02/26 | AB1: lun - 23/02/26 | AC1: lun - 23/02/26 | AD1: lun - 09/03/26 | AE1: lun - 09/03/26 | AF1: lun - 23/03/26 | AG1: lun - 23/03/26 | AH1: lun - 06/04/26 CHIUSO | AI1: lun - 06/04/26 CHIUSO | AJ1: lun - 13/04/26 | AK1: lun - 20/04/26 | AL1: lun - 27/04/26 | AM1: lun - 04/05/26 | AN1: lun - 11/05/26 | AO1: lun - 18/05/26 | AP1: lun - 25/05/26 | AQ1: lun - 01/06/26 CHIUSO | AR1: lun - 08/06/26 NO BAMBINI | AS1: lun - 15/06/26 NO BAMBINI | AT1: lun - 22/06/26 NO BAMBINI | AU1: lun - 29/06/26 NO BAMBINI | AW1: lun - 19/01/26 | AX1: lun - 16/02/26 | AY1: lun - 02/03/26 | AZ1: lun - 16/03/26 | BA1: lun - 30/03/26 | BB1: lun - 30/03/26
A2: ID-000693 | B2: FALSE | C2: FALSE | D2: FALSE | E2: FALSE | F2: FALSE | G2: FALSE | H2: FALSE | I2: FALSE | J2: FALSE | K2: FALSE | L2: FALSE | M2: FALSE | N2: FALSE | O2: FALSE | P2: FALSE | Q2: FALSE | R2: FALSE | S2: FALSE | U2: FALSE | V2: FALSE | W2: FALSE | X2: FALSE | Y2: FALSE | Z2: FALSE | AA2: FALSE | AB2: FALSE | AC2: FALSE | AD2: FALSE | AE2: FALSE | AF2: FALSE | AG2: FALSE | AH2: FALSE | AI2: FALSE | AJ2: FALSE | AK2: FALSE | AL2: FALSE | AM2: FALSE | AN2: FALSE | AO2: FALSE | AP2: FALSE | AQ2: FALSE | AR2: FALSE | AS2: FALSE | AT2: FALSE | AU2: FALSE | AV2: FALSE | AW2: FALSE | AX2: FALSE | AY2: FALSE | AZ2: FALSE | BB2: FALSE
A3: ID-001740 | B3: FALSE | C3: TRUE | D3: TRUE | E3: TRUE | F3: FALSE | G3: TRUE | H3: TRUE | I3: FALSE | J3: FALSE | K3: FALSE | L3: FALSE | M3: FALSE | N3: FALSE | O3: FALSE | P3: FALSE | Q3: FALSE | R3: FALSE | S3: FALSE | U3: FALSE | V3: FALSE | W3: FALSE | X3: FALSE | Y3: FALSE | Z3: FALSE | AA3: FALSE | AB3: FALSE | AC3: FALSE | AD3: FALSE | AE3: FALSE | AF3: FALSE | AG3: FALSE | AH3: FALSE | AI3: FALSE | AJ3: FALSE | AK3: FALSE | AL3: FALSE | AM3: FALSE | AN3: FALSE | AO3: FALSE | AP3: FALSE | AQ3: FALSE | AR3: FALSE | AS3: FALSE | AT3: FALSE | AU3: FALSE | AV3: FALSE | AW3: FALSE | AX3: FALSE | AY3: FALSE | AZ3: FALSE | BB3: FALSE
A4: ID-000354 | B4: TRUE | C4: TRUE | D4: TRUE | E4: FALSE | F4: FALSE | G4: TRUE | H4: FALSE | I4: FALSE | J4: FALSE | K4: FALSE | L4: FALSE | M4: FALSE | N4: FALSE | O4: FALSE | P4: FALSE | Q4: FALSE | R4: FALSE | S4: FALSE | U4: FALSE | V4: FALSE | W4: FALSE | X4: FALSE | Y4: FALSE | Z4: FALSE | AA4: FALSE | AB4: FALSE | AC4: FALSE | AD4: FALSE | AE4: FALSE | AF4: FALSE | AG4: FALSE | AH4: FALSE | AI4: FALSE | AJ4: FALSE | AK4: FALSE | AL4: FALSE | AM4: FALSE | AN4: FALSE | AO4: FALSE | AP4: FALSE | AQ4: FALSE | AR4: FALSE | AS4: FALSE | AT4: FALSE | AU4: FALSE | AV4: FALSE | AW4: FALSE | AX4: FALSE | AY4: FALSE | AZ4: FALSE | BB4: FALSE
A5: ID-000357 | B5: FALSE | C5: FALSE | D5: FALSE | E5: FALSE | F5: FALSE | G5: FALSE | H5: FALSE | I5: FALSE | J5: FALSE | K5: FALSE | L5: FALSE | M5: FALSE | N5: FALSE | O5: FALSE | P5: FALSE | Q5: FALSE | R5: FALSE | S5: FALSE | U5: FALSE | V5: FALSE | W5: FALSE | X5: FALSE | Y5: FALSE | Z5: FALSE | AA5: FALSE | AB5: FALSE | AC5: FALSE | AD5: FALSE | AE5: FALSE | AF5: FALSE | AG5: FALSE | AH5: FALSE | AI5: FALSE | AJ5: FALSE | AK5: FALSE | AL5: FALSE | AM5: FALSE | AN5: FALSE | AO5: FALSE | AP5: FALSE | AQ5: FALSE | AR5: FALSE | AS5: FALSE | AT5: FALSE | AU5: FALSE | AV5: FALSE | AW5: FALSE | AX5: FALSE | AY5: FALSE | AZ5: FALSE | BB5: FALSE
A6: ID-000029 | B6: FALSE | C6: FALSE | D6: FALSE | E6: FALSE | F6: FALSE | G6: FALSE | H6: FALSE | I6: FALSE | J6: FALSE | K6: FALSE | L6: FALSE | M6: FALSE | N6: FALSE | O6: FALSE | P6: FALSE | Q6: FALSE | R6: FALSE | S6: FALSE | U6: FALSE | V6: FALSE | W6: FALSE | X6: FALSE | Y6: FALSE | Z6: FALSE | AA6: FALSE | AB6: FALSE | AC6: FALSE | AD6: FALSE | AE6: FALSE | AF6: FALSE | AG6: FALSE | AH6: FALSE | AI6: FALSE | AJ6: FALSE | AK6: FALSE | AL6: FALSE | AM6: FALSE | AN6: FALSE | AO6: FALSE | AP6: FALSE | AQ6: FALSE | AR6: FALSE | AS6: FALSE | AT6: FALSE | AU6: FALSE | AV6: FALSE | AW6: FALSE | AX6: FALSE | AY6: FALSE | AZ6: FALSE | BB6: FALSE
A7: ID-001115 | B7: FALSE | C7: TRUE | D7: TRUE | E7: TRUE | F7: TRUE | G7: TRUE | H7: FALSE | I7: FALSE | J7: FALSE | K7: FALSE | L7: FALSE | M7: FALSE | N7: FALSE | O7: FALSE | P7: FALSE | Q7: FALSE | R7: FALSE | S7: FALSE | U7: FALSE | V7: FALSE | W7: FALSE | X7: FALSE | Y7: FALSE | Z7: FALSE | AA7: FALSE | AB7: FALSE | AC7: FALSE | AD7: FALSE | AE7: FALSE | AF7: FALSE | AG7: FALSE | AH7: FALSE | AI7: FALSE | AJ7: FALSE | AK7: FALSE | AL7: FALSE | AM7: FALSE | AN7: FALSE | AO7: FALSE | AP7: FALSE | AQ7: FALSE | AR7: FALSE | AS7: FALSE | AT7: FALSE | AU7: FALSE | AV7: FALSE | AW7: FALSE | AX7: FALSE | AY7: FALSE | AZ7: FALSE | BB7: FALSE
A8: ID-000378 | B8: TRUE | C8: TRUE | D8: TRUE | E8: TRUE | F8: TRUE | G8: TRUE | H8: TRUE | I8: TRUE | J8: TRUE | K8: FALSE | L8: FALSE | M8: FALSE | N8: FALSE | O8: FALSE | P8: FALSE | Q8: FALSE | R8: FALSE | S8: FALSE | U8: FALSE | V8: FALSE | W8: FALSE | X8: FALSE | Y8: FALSE | Z8: FALSE | AA8: FALSE | AB8: FALSE | AC8: FALSE | AD8: FALSE | AE8: FALSE | AF8: FALSE | AG8: FALSE | AH8: FALSE | AI8: FALSE | AJ8: FALSE | AK8: FALSE | AL8: FALSE | AM8: FALSE | AN8: FALSE | AO8: FALSE | AP8: FALSE | AQ8: FALSE | AR8: FALSE | AS8: FALSE | AT8: FALSE | AU8: FALSE | AV8: FALSE | AW8: FALSE | AX8: FALSE | AY8: FALSE | AZ8: FALSE | BB8: FALSE
