Workbook

Sheet Alexandra
A1: ALEXANDRA >> SEZIONE A <<
A2: ALEXANDRA | B2: =impostazioni!B2 -> CONTANTE | D2: =impostazioni!D2 -> POS POSTA Recep | F2: =impostazioni!F2 -> CARTA POSTA Recep | H2: =impostazioni!H2 -> POS POSTA 2°P | J2: =impostazioni!J2 -> CARTA POSTA 2°P | L2: =impostazioni!L2 -> POS BPM 1°P | N2: =impostazioni!N2 -> CARTA BPM 1°P | P2: =impostazioni!P2 -> B/B | R2: =impostazioni!R2 -> SEDE SCALAPAY | T2: =impostazioni!T2 -> SEDE SATISPAY | V2: =impostazioni!V2 -> ONLINE TESSERATO | X2: =impostazioni!X2 -> ONLINE NON TESSERATO
A3: =impostazioni!A3 -> N° RICEVUTA | B3: =impostazioni!B3 -> CORSI | C3: =impostazioni!C3 -> QUOTA TESS. | D3: =impostazioni!D3 -> CORSI | E3: =impostazioni!E3 -> QUOTA TESS. | F3: =impostazioni!F3 -> CORSI | G3: =impostazioni!G3 -> QUOTA TESS. | H3: =impostazioni!H3 -> CORSI | ... Y3: =impostazioni!Y3 -> QUOTA TESS.
A35: =impostazioni!A35 -> SUB-TOTALE CORSI DIVISO | B35: =SUM(B4:B34) -> 0 | C35: =SUM(C4:C34) -> 0 | D35: =SUM(D4:D34) -> 0 | E35: =SUM(E4:E34) -> 0 | F35: =SUM(F4:F34) -> 0 | G35: =SUM(G4:G34) -> 0 | H35: =SUM(H4:H34) -> 0 | I35: =SUM(I4:I34) -> 0 | ... Y35: =SUM(Y4:Y34) -> 0
A36: =impostazioni!A36 -> TOTALE CORSI UNITO | B36: =SUM(B35:C35) -> 0 | D36: =SUM(D35:E35) -> 0 | F36: =SUM(F35:G35) -> 0 | H36: =SUM(H35:I35) -> 0 | J36: =SUM(J35:K35) -> 0 | L36: =SUM(L35:M35) -> 0 | N36: =SUM(N35:O35) -> 0 | P36: =SUM(P35:Q35) -> 0 | R36: =SUM(R35:S35) -> 0 | T36: =SUM(T35:U35) -> 0 | V36: =SUM(V35:W35) -> 0 | X36: =SUM(X35:Y35) -> 0
A37: =impostazioni!A37 -> SHOP FATTURE (pagato con Pos)
A38: =impostazioni!A38 -> USCITA CONTANTE | D38: =impostazioni!D38 -> NOTE PER USCITA:
A39: =impostazioni!A39 -> TOTALE CASSA CONTANTE ENTRATE-USCITE | B39: =SUM(B36:Y36-B38) -> 0
A41: ALEXANDRA >> SEZIONE B <<
A43: =impostazioni!A43 -> N° RIC. BIANCHE VISITE MEDICHE | C43: =impostazioni!C43 -> € | D43: =impostazioni!D43 -> N° RIC. RICEVUTE BIANCHE ALTRO | G43: =impostazioni!G43 -> € | H43: =impostazioni!H43 -> N° RIC. RICEVUTE BIANCHE ALTRO | K43: =impostazioni!K43 -> €
A62: =impostazioni!A62 -> SUB-TOTALE | C62: =SUM(C44:C61) -> 0 | D62: =impostazioni!D62 -> SUB-TOTALE | G62: =SUM(G44:G61) -> 0 | H62: =impostazioni!H62 -> SUB-TOTALE | K62: =SUM(K44:K61) -> 0 | L62: USCITA | N62: TOTALE | O62: =SUM(C62,G62,K62-M62) -> 0
A64: ALEXANDRA >> SEZIONE C <<
A66: =impostazioni!A66 -> DISTINTA RICEVUTE AZZURRE + BIANCHE | F66: =impostazioni!F66 -> NOTE GENERICHE
A67: =impostazioni!A67 -> TOTALE CONTANTI RIC. AZZURRE | B67: =B36 -> 0
A68: =impostazioni!A68 -> TOTALE CONTANTI RIC. BIANCHE | B68: =SUM(C62,G62,K62) -> 0
A69: =impostazioni!A69 -> USCITA CONTANTE | B69: =SUM(B38+M62) -> 0
A70: =impostazioni!A70 -> TOTALE CASSA | B70: =B67+B68-B69 -> 0 | F70: =IF(B70=B77,"OK","ERRORE") -> OK
A72: ALEXANDRA >> SEZIONE D <<
A74: =impostazioni!A74 -> PEZZI
A75: =impostazioni!A75 -> TAGLIO | B75: 500 | C75: 200 | D75: 100 | E75: 50 | F75: 20 | G75: 10 | H75: 5 | I75: 2 | J75: 1 | K75: 0.5 | L75: 0.2 | M75: 0.1 | N75: 0.05 | O75: 0.02 | P75: 0.01
A76: =impostazioni!A76 -> TOT | B76: =B74*B75 -> 0 | C76: =C74*C75 -> 0 | D76: =D74*D75 -> 0 | E76: =E74*E75 -> 0 | F76: =F74*F75 -> 0 | G76: =G74*G75 -> 0 | H76: =H74*H75 -> 0 | I76: =I74*I75 -> 0 | ... P76: =P74*P75 -> 0
A77: =impostazioni!A77 -> TOTALE CASSA | B77: =SUM(B76:P76) -> 0
A79: =impostazioni!A79 -> ULTIMO ACCESSO: | B79: =impostazioni!B79 -> 46071.676 | E79: =impostazioni!E79 -> CONTROLLO FATTO DA: | G79: ALEXANDRA | H79: FALSE | J79: ELISA Controllo | L79: OK | M79: FALSE | N79: REGIST. | O79: FALSE

Sheet Alexandra-EX
A1: ALEXANDRA - EXTRA >> SEZIONE A <<
A2: ALEXANDRA EXTRA | B2: =impostazioni!B2 -> CONTANTE | D2: =impostazioni!D2 -> POS POSTA Recep | F2: =impostazioni!F2 -> CARTA POSTA Recep | H2: =impostazioni!H2 -> POS POSTA 2°P | J2: =impostazioni!J2 -> CARTA POSTA 2°P | L2: =impostazioni!L2 -> POS BPM 1°P | N2: =impostazioni!N2 -> CARTA BPM 1°P | P2: =impostazioni!P2 -> B/B | R2: =impostazioni!R2 -> SEDE SCALAPAY | T2: =impostazioni!T2 -> SEDE SATISPAY | V2: =impostazioni!V2 -> ONLINE TESSERATO | X2: =impostazioni!X2 -> ONLINE NON TESSERATO
A3: =impostazioni!A3 -> N° RICEVUTA | B3: =impostazioni!B3 -> CORSI | C3: =impostazioni!C3 -> QUOTA TESS. | D3: =impostazioni!D3 -> CORSI | E3: =impostazioni!E3 -> QUOTA TESS. | F3: =impostazioni!F3 -> CORSI | G3: =impostazioni!G3 -> QUOTA TESS. | H3: =impostazioni!H3 -> CORSI | ... Y3: =impostazioni!Y3 -> QUOTA TESS.
A35: =impostazioni!A35 -> SUB-TOTALE CORSI DIVISO | B35: =SUM(B4:B34) -> 0 | C35: =SUM(C4:C34) -> 0 | D35: =SUM(D4:D34) -> 0 | E35: =SUM(E4:E34) -> 0 | F35: =SUM(F4:F34) -> 0 | G35: =SUM(G4:G34) -> 0 | H35: =SUM(H4:H34) -> 0 | I35: =SUM(I4:I34) -> 0 | ... Y35: =SUM(Y4:Y34) -> 0
A36: =impostazioni!A36 -> TOTALE CORSI UNITO | B36: =SUM(B35:C35) -> 0 | D36: =SUM(D35:E35) -> 0 | F36: =SUM(F35:G35) -> 0 | H36: =SUM(H35:I35) -> 0 | J36: =SUM(J35:K35) -> 0 | L36: =SUM(L35:M35) -> 0 | N36: =SUM(N35:O35) -> 0 | P36: =SUM(P35:Q35) -> 0 | R36: =SUM(R35:S35) -> 0 | T36: =SUM(T35:U35) -> 0 | V36: =SUM(V35:W35) -> 0 | X36: =SUM(X35:Y35) -> 0
A37: =impostazioni!A37 -> SHOP FATTURE (pagato con Pos)
A38: =impostazioni!A38 -> USCITA CONTANTE | D38: =impostazioni!D38 -> NOTE PER USCITA:
A39: =impostazioni!A39 -> TOTALE CASSA CONTANTE ENTRATE-USCITE | B39: =SUM(B36:Y36-B38) -> 0
A41: ALEXANDRA - EXTRA >> SEZIONE B <<
A43: =impostazioni!A43 -> N° RIC. BIANCHE VISITE MEDICHE | C43: =impostazioni!C43 -> € | D43: =impostazioni!D43 -> N° RIC. RICEVUTE BIANCHE ALTRO | G43: =impostazioni!G43 -> € | H43: =impostazioni!H43 -> N° RIC. RICEVUTE BIANCHE ALTRO | K43: =impostazioni!K43 -> €
A62: =impostazioni!A62 -> SUB-TOTALE | C62: =SUM(C44:C61) -> 0 | D62: =impostazioni!D62 -> SUB-TOTALE | G62: =SUM(G44:G61) -> 0 | H62: =impostazioni!H62 -> SUB-TOTALE | K62: =SUM(K44:K61) -> 0 | L62: USCITA | N62: TOTALE | O62: =SUM(C62,G62,K62-M62) -> 0
A64: ALEXANDRA - EXTRA >> SEZIONE C <<
A66: =impostazioni!A66 -> DISTINTA RICEVUTE AZZURRE + BIANCHE | F66: =impostazioni!F66 -> NOTE GENERICHE
A67: =impostazioni!A67 -> TOTALE CONTANTI RIC. AZZURRE | B67: =B36 -> 0
A68: =impostazioni!A68 -> TOTALE CONTANTI RIC. BIANCHE | B68: =SUM(C62,G62,K62) -> 0
A69: =impostazioni!A69 -> USCITA CONTANTE | B69: =SUM(B38+M62) -> 0
A70: =impostazioni!A70 -> TOTALE CASSA | B70: =B67+B68-B69 -> 0 | F70: =IF(B70=B77,"OK","ERRORE") -> OK
A72: ALEXANDRA - EXTRA >> SEZIONE D <<
A74: =impostazioni!A74 -> PEZZI
A75: =impostazioni!A75 -> TAGLIO | B75: 500 | C75: 200 | D75: 100 | E75: 50 | F75: 20 | G75: 10 | H75: 5 | I75: 2 | J75: 1 | K75: 0.5 | L75: 0.2 | M75: 0.1 | N75: 0.05 | O75: 0.02 | P75: 0.01
A76: =impostazioni!A76 -> TOT | B76: =B74*B75 -> 0 | C76: =C74*C75 -> 0 | D76: =D74*D75 -> 0 | E76: =E74*E75 -> 0 | F76: =F74*F75 -> 0 | G76: =G74*G75 -> 0 | H76: =H74*H75 -> 0 | I76: =I74*I75 -> 0 | ... P76: =P74*P75 -> 0
A77: =impostazioni!A77 -> TOTALE CASSA | B77: =SUM(B76:P76) -> 0
A79: =impostazioni!A79 -> ULTIMO ACCESSO: | B79: =impostazioni!B79 -> 46071.676 | E79: =impostazioni!E79 -> CONTROLLO FATTO DA: | G79: ALEXANDRA | H79: FALSE | J79: ELISA Controllo | L79: OK | M79: FALSE | N79: REGIST. | O79: FALSE

Sheet Nura
A1: NURA >> SEZIONE A <<
A2: NURA | B2: =impostazioni!B2 -> CONTANTE | D2: =impostazioni!D2 -> POS POSTA Recep | F2: =impostazioni!F2 -> CARTA POSTA Recep | H2: =impostazioni!H2 -> POS POSTA 2°P | J2: =impostazioni!J2 -> CARTA POSTA 2°P | L2: =impostazioni!L2 -> POS BPM 1°P | N2: =impostazioni!N2 -> CARTA BPM 1°P | P2: =impostazioni!P2 -> B/B | R2: =impostazioni!R2 -> SEDE SCALAPAY | T2: =impostazioni!T2 -> SEDE SATISPAY | V2: =impostazioni!V2 -> ONLINE TESSERATO | X2: =impostazioni!X2 -> ONLINE NON TESSERATO
A3: =impostazioni!A3 -> N° RICEVUTA | B3: =impostazioni!B3 -> CORSI | C3: =impostazioni!C3 -> QUOTA TESS. | D3: =impostazioni!D3 -> CORSI | E3: =impostazioni!E3 -> QUOTA TESS. | F3: =impostazioni!F3 -> CORSI | G3: =impostazioni!G3 -> QUOTA TESS. | H3: =impostazioni!H3 -> CORSI | ... Y3: =impostazioni!Y3 -> QUOTA TESS.
A35: =impostazioni!A35 -> SUB-TOTALE CORSI DIVISO | B35: =SUM(B4:B34) -> 0 | C35: =SUM(C4:C34) -> 0 | D35: =SUM(D4:D34) -> 0 | E35: =SUM(E4:E34) -> 0 | F35: =SUM(F4:F34) -> 0 | G35: =SUM(G4:G34) -> 0 | H35: =SUM(H4:H34) -> 0 | I35: =SUM(I4:I34) -> 0 | ... Y35: =SUM(Y4:Y34) -> 0
A36: =impostazioni!A36 -> TOTALE CORSI UNITO | B36: =SUM(B35:C35) -> 0 | D36: =SUM(D35:E35) -> 0 | F36: =SUM(F35:G35) -> 0 | H36: =SUM(H35:I35) -> 0 | J36: =SUM(J35:K35) -> 0 | L36: =SUM(L35:M35) -> 0 | N36: =SUM(N35:O35) -> 0 | P36: =SUM(P35:Q35) -> 0 | R36: =SUM(R35:S35) -> 0 | T36: =SUM(T35:U35) -> 0 | V36: =SUM(V35:W35) -> 0 | X36: =SUM(X35:Y35) -> 0
A37: =impostazioni!A37 -> SHOP FATTURE (pagato con Pos)
A38: =impostazioni!A38 -> USCITA CONTANTE | D38: =impostazioni!D38 -> NOTE PER USCITA:
A39: =impostazioni!A39 -> TOTALE CASSA CONTANTE ENTRATE-USCITE | B39: =SUM(B36:Y36-B38) -> 0
A41: NURA >> SEZIONE B <<
A43: =impostazioni!A43 -> N° RIC. BIANCHE VISITE MEDICHE | C43: =impostazioni!C43 -> € | D43: =impostazioni!D43 -> N° RIC. RICEVUTE BIANCHE ALTRO | G43: =impostazioni!G43 -> € | H43: =impostazioni!H43 -> N° RIC. RICEVUTE BIANCHE ALTRO | K43: =impostazioni!K43 -> €
A62: =impostazioni!A62 -> SUB-TOTALE | C62: =SUM(C44:C61) -> 0 | D62: =impostazioni!D62 -> SUB-TOTALE | G62: =SUM(G44:G61) -> 0 | H62: =impostazioni!H62 -> SUB-TOTALE | K62: =SUM(K44:K61) -> 0 | L62: USCITA | N62: TOTALE | O62: =SUM(C62,G62,K62-M62) -> 0
A64: NURA >> SEZIONE C <<
A66: =impostazioni!A66 -> DISTINTA RICEVUTE AZZURRE + BIANCHE | F66: =impostazioni!F66 -> NOTE GENERICHE
A67: =impostazioni!A67 -> TOTALE CONTANTI RIC. AZZURRE | B67: =B36 -> 0
A68: =impostazioni!A68 -> TOTALE CONTANTI RIC. BIANCHE | B68: =SUM(C62,G62,K62) -> 0
A69: =impostazioni!A69 -> USCITA CONTANTE | B69: =SUM(B38+M62) -> 0
A70: =impostazioni!A70 -> TOTALE CASSA | B70: =B67+B68-B69 -> 0 | F70: =IF(B70=B77,"OK","ERRORE") -> OK
A72: NURA >> SEZIONE D <<
A74: =impostazioni!A74 -> PEZZI
A75: =impostazioni!A75 -> TAGLIO | B75: 500 | C75: 200 | D75: 100 | E75: 50 | F75: 20 | G75: 10 | H75: 5 | I75: 2 | J75: 1 | K75: 0.5 | L75: 0.2 | M75: 0.1 | N75: 0.05 | O75: 0.02 | P75: 0.01
A76: =impostazioni!A76 -> TOT | B76: =B74*B75 -> 0 | C76: =C74*C75 -> 0 | D76: =D74*D75 -> 0 | E76: =E74*E75 -> 0 | F76: =F74*F75 -> 0 | G76: =G74*G75 -> 0 | H76: =H74*H75 -> 0 | I76: =I74*I75 -> 0 | ... P76: =P74*P75 -> 0
A77: =impostazioni!A77 -> TOTALE CASSA | B77: =SUM(B76:P76) -> 0
A79: =impostazioni!A79 -> ULTIMO ACCESSO: | B79: =impostazioni!B79 -> 46071.676 | E79: =impostazioni!E79 -> CONTROLLO FATTO DA: | G79: NURA | H79: FALSE | J79: ELISA Controllo | L79: OK | M79: FALSE | N79: REGIST. | O79: FALSE

Sheet Nura-EX
A1: NURA - EXTRA >> SEZIONE A <<
A2: NURA EXTRA | B2: =impostazioni!B2 -> CONTANTE | D2: =impostazioni!D2 -> POS POSTA Recep | F2: =impostazioni!F2 -> CARTA POSTA Recep | H2: =impostazioni!H2 -> POS POSTA 2°P | J2: =impostazioni!J2 -> CARTA POSTA 2°P | L2: =impostazioni!L2 -> POS BPM 1°P | N2: =impostazioni!N2 -> CARTA BPM 1°P | P2: =impostazioni!P2 -> B/B | R2: =impostazioni!R2 -> SEDE SCALAPAY | T2: =impostazioni!T2 -> SEDE SATISPAY | V2: =impostazioni!V2 -> ONLINE TESSERATO | X2: =impostazioni!X2 -> ONLINE NON TESSERATO
A3: =impostazioni!A3 -> N° RICEVUTA | B3: =impostazioni!B3 -> CORSI | C3: =impostazioni!C3 -> QUOTA TESS. | D3: =impostazioni!D3 -> CORSI | E3: =impostazioni!E3 -> QUOTA TESS. | F3: =impostazioni!F3 -> CORSI | G3: =impostazioni!G3 -> QUOTA TESS. | H3: =impostazioni!H3 -> CORSI | ... Y3: =impostazioni!Y3 -> QUOTA TESS.
A35: =impostazioni!A35 -> SUB-TOTALE CORSI DIVISO | B35: =SUM(B4:B34) -> 0 | C35: =SUM(C4:C34) -> 0 | D35: =SUM(D4:D34) -> 0 | E35: =SUM(E4:E34) -> 0 | F35: =SUM(F4:F34) -> 0 | G35: =SUM(G4:G34) -> 0 | H35: =SUM(H4:H34) -> 0 | I35: =SUM(I4:I34) -> 0 | ... Y35: =SUM(Y4:Y34) -> 0
A36: =impostazioni!A36 -> TOTALE CORSI UNITO | B36: =SUM(B35:C35) -> 0 | D36: =SUM(D35:E35) -> 0 | F36: =SUM(F35:G35) -> 0 | H36: =SUM(H35:I35) -> 0 | J36: =SUM(J35:K35) -> 0 | L36: =SUM(L35:M35) -> 0 | N36: =SUM(N35:O35) -> 0 | P36: =SUM(P35:Q35) -> 0 | R36: =SUM(R35:S35) -> 0 | T36: =SUM(T35:U35) -> 0 | V36: =SUM(V35:W35) -> 0 | X36: =SUM(X35:Y35) -> 0
A37: =impostazioni!A37 -> SHOP FATTURE (pagato con Pos)
A38: =impostazioni!A38 -> USCITA CONTANTE | D38: =impostazioni!D38 -> NOTE PER USCITA:
A39: =impostazioni!A39 -> TOTALE CASSA CONTANTE ENTRATE-USCITE | B39: =SUM(B36:Y36-B38) -> 0
A41: NURA - EXTRA >> SEZIONE B <<
A43: =impostazioni!A43 -> N° RIC. BIANCHE VISITE MEDICHE | C43: =impostazioni!C43 -> € | D43: =impostazioni!D43 -> N° RIC. RICEVUTE BIANCHE ALTRO | G43: =impostazioni!G43 -> € | H43: =impostazioni!H43 -> N° RIC. RICEVUTE BIANCHE ALTRO | K43: =impostazioni!K43 -> €
A62: =impostazioni!A62 -> SUB-TOTALE | C62: =SUM(C44:C61) -> 0 | D62: =impostazioni!D62 -> SUB-TOTALE | G62: =SUM(G44:G61) -> 0 | H62: =impostazioni!H62 -> SUB-TOTALE | K62: =SUM(K44:K61) -> 0 | L62: USCITA | N62: TOTALE | O62: =SUM(C62,G62,K62-M62) -> 0
A64: NURA - EXTRA >> SEZIONE C <<
A66: =impostazioni!A66 -> DISTINTA RICEVUTE AZZURRE + BIANCHE | F66: =impostazioni!F66 -> NOTE GENERICHE
A67: =impostazioni!A67 -> TOTALE CONTANTI RIC. AZZURRE | B67: =B36 -> 0
A68: =impostazioni!A68 -> TOTALE CONTANTI RIC. BIANCHE | B68: =SUM(C62,G62,K62) -> 0
A69: =impostazioni!A69 -> USCITA CONTANTE | B69: =SUM(B38+M62) -> 0
A70: =impostazioni!A70 -> TOTALE CASSA | B70: =B67+B68-B69 -> 0 | F70: =IF(B70=B77,"OK","ERRORE") -> OK
A72: NURA - EXTRA >> SEZIONE D <<
A74: =impostazioni!A74 -> PEZZI
A75: =impostazioni!A75 -> TAGLIO | B75: 500 | C75: 200 | D75: 100 | E75: 50 | F75: 20 | G75: 10 | H75: 5 | I75: 2 | J75: 1 | K75: 0.5 | L75: 0.2 | M75: 0.1 | N75: 0.05 | O75: 0.02 | P75: 0.01
A76: =impostazioni!A76 -> TOT | B76: =B74*B75 -> 0 | C76: =C74*C75 -> 0 | D76: =D74*D75 -> 0 | E76: =E74*E75 -> 0 | F76: =F74*F75 -> 0 | G76: =G74*G75 -> 0 | H76: =H74*H75 -> 0 | I76: =I74*I75 -> 0 | ... P76: =P74*P75 -> 0
A77: =impostazioni!A77 -> TOTALE CASSA | B77: =SUM(B76:P76) -> 0
A79: =impostazioni!A79 -> ULTIMO ACCESSO: | B79: =impostazioni!B79 -> 46071.676 | E79: =impostazioni!E79 -> CONTROLLO FATTO DA: | G79: NURA | H79: FALSE | J79: ELISA Controllo | L79: OK | M79: FALSE | N79: REGIST. | O79: FALSE

Sheet Giuditta
A1: GIUDITTA >> SEZIONE A <<
A2: GIUDITTA | B2: =impostazioni!B2 -> CONTANTE | D2: =impostazioni!D2 -> POS POSTA Recep | F2: =impostazioni!F2 -> CARTA POSTA Recep | H2: =impostazioni!H2 -> POS POSTA 2°P | J2: =impostazioni!J2 -> CARTA POSTA 2°P | L2: =impostazioni!L2 -> POS BPM 1°P | N2: =impostazioni!N2 -> CARTA BPM 1°P | P2: =impostazioni!P2 -> B/B | R2: =impostazioni!R2 -> SEDE SCALAPAY | T2: =impostazioni!T2 -> SEDE SATISPAY | V2: =impostazioni!V2 -> ONLINE TESSERATO | X2: =impostazioni!X2 -> ONLINE NON TESSERATO
A3: =impostazioni!A3 -> N° RICEVUTA | B3: =impostazioni!B3 -> CORSI | C3: =impostazioni!C3 -> QUOTA TESS. | D3: =impostazioni!D3 -> CORSI | E3: =impostazioni!E3 -> QUOTA TESS. | F3: =impostazioni!F3 -> CORSI | G3: =impostazioni!G3 -> QUOTA TESS. | H3: =impostazioni!H3 -> CORSI | ... Y3: =impostazioni!Y3 -> QUOTA TESS.
A35: =impostazioni!A35 -> SUB-TOTALE CORSI DIVISO | B35: =SUM(B4:B34) -> 0 | C35: =SUM(C4:C34) -> 0 | D35: =SUM(D4:D34) -> 0 | E35: =SUM(E4:E34) -> 0 | F35: =SUM(F4:F34) -> 0 | G35: =SUM(G4:G34) -> 0 | H35: =SUM(H4:H34) -> 0 | I35: =SUM(I4:I34) -> 0 | ... Y35: =SUM(Y4:Y34) -> 0
A36: =impostazioni!A36 -> TOTALE CORSI UNITO | B36: =SUM(B35:C35) -> 0 | D36: =SUM(D35:E35) -> 0 | F36: =SUM(F35:G35) -> 0 | H36: =SUM(H35:I35) -> 0 | J36: =SUM(J35:K35) -> 0 | L36: =SUM(L35:M35) -> 0 | N36: =SUM(N35:O35) -> 0 | P36: =SUM(P35:Q35) -> 0 | R36: =SUM(R35:S35) -> 0 | T36: =SUM(T35:U35) -> 0 | V36: =SUM(V35:W35) -> 0 | X36: =SUM(X35:Y35) -> 0
A37: =impostazioni!A37 -> SHOP FATTURE (pagato con Pos)
A38: =impostazioni!A38 -> USCITA CONTANTE | D38: =impostazioni!D38 -> NOTE PER USCITA:
A39: =impostazioni!A39 -> TOTALE CASSA CONTANTE ENTRATE-USCITE | B39: =SUM(B36:Y36-B38) -> 0
A41: GIUDITTA >> SEZIONE B <<
A43: =impostazioni!A43 -> N° RIC. BIANCHE VISITE MEDICHE | C43: =impostazioni!C43 -> € | D43: =impostazioni!D43 -> N° RIC. RICEVUTE BIANCHE ALTRO | G43: =impostazioni!G43 -> € | H43: =impostazioni!H43 -> N° RIC. RICEVUTE BIANCHE ALTRO | K43: =impostazioni!K43 -> €
A62: =impostazioni!A62 -> SUB-TOTALE | C62: =SUM(C44:C61) -> 0 | D62: =impostazioni!D62 -> SUB-TOTALE | G62: =SUM(G44:G61) -> 0 | H62: =impostazioni!H62 -> SUB-TOTALE | K62: =SUM(K44:K61) -> 0 | L62: USCITA | N62: TOTALE | O62: =SUM(C62,G62,K62-M62) -> 0
A64: GIUDITTA >> SEZIONE C <<
A66: =impostazioni!A66 -> DISTINTA RICEVUTE AZZURRE + BIANCHE | F66: =impostazioni!F66 -> NOTE GENERICHE
A67: =impostazioni!A67 -> TOTALE CONTANTI RIC. AZZURRE | B67: =B36 -> 0
A68: =impostazioni!A68 -> TOTALE CONTANTI RIC. BIANCHE | B68: =SUM(C62,G62,K62) -> 0
A69: =impostazioni!A69 -> USCITA CONTANTE | B69: =SUM(B38+M62) -> 0
A70: =impostazioni!A70 -> TOTALE CASSA | B70: =B67+B68-B69 -> 0 | F70: =IF(B70=B77,"OK","ERRORE") -> OK
A72: GIUDITTA >> SEZIONE D <<
A74: =impostazioni!A74 -> PEZZI
A75: =impostazioni!A75 -> TAGLIO | B75: 500 | C75: 200 | D75: 100 | E75: 50 | F75: 20 | G75: 10 | H75: 5 | I75: 2 | J75: 1 | K75: 0.5 | L75: 0.2 | M75: 0.1 | N75: 0.05 | O75: 0.02 | P75: 0.01
A76: =impostazioni!A76 -> TOT | B76: =B74*B75 -> 0 | C76: =C74*C75 -> 0 | D76: =D74*D75 -> 0 | E76: =E74*E75 -> 0 | F76: =F74*F75 -> 0 | G76: =G74*G75 -> 0 | H76: =H74*H75 -> 0 | I76: =I74*I75 -> 0 | ... P76: =P74*P75 -> 0
A77: =impostazioni!A77 -> TOTALE CASSA | B77: =SUM(B76:P76) -> 0
A79: =impostazioni!A79 -> ULTIMO ACCESSO: | B79: =impostazioni!B79 -> 46071.676 | E79: =impostazioni!E79 -> CONTROLLO FATTO DA: | G79: GIUDITTA | H79: FALSE | J79: ELISA Controllo | L79: OK | M79: FALSE | N79: REGIST. | O79: FALSE

Sheet Giuditta-EX
A1: GIUDITTA - EXTRA >> SEZIONE A <<
A2: GIUDITTA EXTRA | B2: =impostazioni!B2 -> CONTANTE | D2: =impostazioni!D2 -> POS POSTA Recep | F2: =impostazioni!F2 -> CARTA POSTA Recep | H2: =impostazioni!H2 -> POS POSTA 2°P | J2: =impostazioni!J2 -> CARTA POSTA 2°P | L2: =impostazioni!L2 -> POS BPM 1°P | N2: =impostazioni!N2 -> CARTA BPM 1°P | P2: =impostazioni!P2 -> B/B | R2: =impostazioni!R2 -> SEDE SCALAPAY | T2: =impostazioni!T2 -> SEDE SATISPAY | V2: =impostazioni!V2 -> ONLINE TESSERATO | X2: =impostazioni!X2 -> ONLINE NON TESSERATO
A3: =impostazioni!A3 -> N° RICEVUTA | B3: =impostazioni!B3 -> CORSI | C3: =impostazioni!C3 -> QUOTA TESS. | D3: =impostazioni!D3 -> CORSI | E3: =impostazioni!E3 -> QUOTA TESS. | F3: =impostazioni!F3 -> CORSI | G3: =impostazioni!G3 -> QUOTA TESS. | H3: =impostazioni!H3 -> CORSI | ... Y3: =impostazioni!Y3 -> QUOTA TESS.
A35: =impostazioni!A35 -> SUB-TOTALE CORSI DIVISO | B35: =SUM(B4:B34) -> 0 | C35: =SUM(C4:C34) -> 0 | D35: =SUM(D4:D34) -> 0 | E35: =SUM(E4:E34) -> 0 | F35: =SUM(F4:F34) -> 0 | G35: =SUM(G4:G34) -> 0 | H35: =SUM(H4:H34) -> 0 | I35: =SUM(I4:I34) -> 0 | ... Y35: =SUM(Y4:Y34) -> 0
A36: =impostazioni!A36 -> TOTALE CORSI UNITO | B36: =SUM(B35:C35) -> 0 | D36: =SUM(D35:E35) -> 0 | F36: =SUM(F35:G35) -> 0 | H36: =SUM(H35:I35) -> 0 | J36: =SUM(J35:K35) -> 0 | L36: =SUM(L35:M35) -> 0 | N36: =SUM(N35:O35) -> 0 | P36: =SUM(P35:Q35) -> 0 | R36: =SUM(R35:S35) -> 0 | T36: =SUM(T35:U35) -> 0 | V36: =SUM(V35:W35) -> 0 | X36: =SUM(X35:Y35) -> 0
A37: =impostazioni!A37 -> SHOP FATTURE (pagato con Pos)
A38: =impostazioni!A38 -> USCITA CONTANTE | D38: =impostazioni!D38 -> NOTE PER USCITA:
A39: =impostazioni!A39 -> TOTALE CASSA CONTANTE ENTRATE-USCITE | B39: =SUM(B36:Y36-B38) -> 0
A41: GIUDITTA - EXTRA >> SEZIONE B <<
A43: =impostazioni!A43 -> N° RIC. BIANCHE VISITE MEDICHE | C43: =impostazioni!C43 -> € | D43: =impostazioni!D43 -> N° RIC. RICEVUTE BIANCHE ALTRO | G43: =impostazioni!G43 -> € | H43: =impostazioni!H43 -> N° RIC. RICEVUTE BIANCHE ALTRO | K43: =impostazioni!K43 -> €
A62: =impostazioni!A62 -> SUB-TOTALE | C62: =SUM(C44:C61) -> 0 | D62: =impostazioni!D62 -> SUB-TOTALE | G62: =SUM(G44:G61) -> 0 | H62: =impostazioni!H62 -> SUB-TOTALE | K62: =SUM(K44:K61) -> 0 | L62: USCITA | N62: TOTALE | O62: =SUM(C62,G62,K62-M62) -> 0
A64: GIUDITTA - EXTRA >> SEZIONE C <<
A66: =impostazioni!A66 -> DISTINTA RICEVUTE AZZURRE + BIANCHE | F66: =impostazioni!F66 -> NOTE GENERICHE
A67: =impostazioni!A67 -> TOTALE CONTANTI RIC. AZZURRE | B67: =B36 -> 0
A68: =impostazioni!A68 -> TOTALE CONTANTI RIC. BIANCHE | B68: =SUM(C62,G62,K62) -> 0
A69: =impostazioni!A69 -> USCITA CONTANTE | B69: =SUM(B38+M62) -> 0
A70: =impostazioni!A70 -> TOTALE CASSA | B70: =B67+B68-B69 -> 0 | F70: =IF(B70=B77,"OK","ERRORE") -> OK
A72: GIUDITTA - EXTRA >> SEZIONE D <<
A74: =impostazioni!A74 -> PEZZI
A75: =impostazioni!A75 -> TAGLIO | B75: 500 | C75: 200 | D75: 100 | E75: 50 | F75: 20 | G75: 10 | H75: 5 | I75: 2 | J75: 1 | K75: 0.5 | L75: 0.2 | M75: 0.1 | N75: 0.05 | O75: 0.02 | P75: 0.01
A76: =impostazioni!A76 -> TOT | B76: =B74*B75 -> 0 | C76: =C74*C75 -> 0 | D76: =D74*D75 -> 0 | E76: =E74*E75 -> 0 | F76: =F74*F75 -> 0 | G76: =G74*G75 -> 0 | H76: =H74*H75 -> 0 | I76: =I74*I75 -> 0 | ... P76: =P74*P75 -> 0
A77: =impostazioni!A77 -> TOTALE CASSA | B77: =SUM(B76:P76) -> 0
A79: =impostazioni!A79 -> ULTIMO ACCESSO: | B79: =impostazioni!B79 -> 46071.676 | E79: =impostazioni!E79 -> CONTROLLO FATTO DA: | G79: GIUDITTA | H79: FALSE | J79: ELISA Controllo | L79: OK | M79: FALSE | N79: REGIST. | O79: FALSE

Sheet Estefany
A1: ESTEFANY >> SEZIONE A <<
A2: ESTEFANY | B2: =impostazioni!B2 -> CONTANTE | D2: =impostazioni!D2 -> POS POSTA Recep | F2: =impostazioni!F2 -> CARTA POSTA Recep | H2: =impostazioni!H2 -> POS POSTA 2°P | J2: =impostazioni!J2 -> CARTA POSTA 2°P | L2: =impostazioni!L2 -> POS BPM 1°P | N2: =impostazioni!N2 -> CARTA BPM 1°P | P2: =impostazioni!P2 -> B/B | R2: =impostazioni!R2 -> SEDE SCALAPAY | T2: =impostazioni!T2 -> SEDE SATISPAY | V2: =impostazioni!V2 -> ONLINE TESSERATO | X2: =impostazioni!X2 -> ONLINE NON TESSERATO
A3: =impostazioni!A3 -> N° RICEVUTA | B3: =impostazioni!B3 -> CORSI | C3: =impostazioni!C3 -> QUOTA TESS. | D3: =impostazioni!D3 -> CORSI | E3: =impostazioni!E3 -> QUOTA TESS. | F3: =impostazioni!F3 -> CORSI | G3: =impostazioni!G3 -> QUOTA TESS. | H3: =impostazioni!H3 -> CORSI | ... Y3: =impostazioni!Y3 -> QUOTA TESS.
A35: =impostazioni!A35 -> SUB-TOTALE CORSI DIVISO | B35: =SUM(B4:B34) -> 0 | C35: =SUM(C4:C34) -> 0 | D35: =SUM(D4:D34) -> 0 | E35: =SUM(E4:E34) -> 0 | F35: =SUM(F4:F34) -> 0 | G35: =SUM(G4:G34) -> 0 | H35: =SUM(H4:H34) -> 0 | I35: =SUM(I4:I34) -> 0 | ... Y35: =SUM(Y4:Y34) -> 0
A36: =impostazioni!A36 -> TOTALE CORSI UNITO | B36: =SUM(B35:C35) -> 0 | D36: =SUM(D35:E35) -> 0 | F36: =SUM(F35:G35) -> 0 | H36: =SUM(H35:I35) -> 0 | J36: =SUM(J35:K35) -> 0 | L36: =SUM(L35:M35) -> 0 | N36: =SUM(N35:O35) -> 0 | P36: =SUM(P35:Q35) -> 0 | R36: =SUM(R35:S35) -> 0 | T36: =SUM(T35:U35) -> 0 | V36: =SUM(V35:W35) -> 0 | X36: =SUM(X35:Y35) -> 0
A37: =impostazioni!A37 -> SHOP FATTURE (pagato con Pos)
A38: =impostazioni!A38 -> USCITA CONTANTE | D38: =impostazioni!D38 -> NOTE PER USCITA:
A39: =impostazioni!A39 -> TOTALE CASSA CONTANTE ENTRATE-USCITE | B39: =SUM(B36:Y36-B38) -> 0
A41: ESTEFANY >> SEZIONE B <<
A43: =impostazioni!A43 -> N° RIC. BIANCHE VISITE MEDICHE | C43: =impostazioni!C43 -> € | D43: =impostazioni!D43 -> N° RIC. RICEVUTE BIANCHE ALTRO | G43: =impostazioni!G43 -> € | H43: =impostazioni!H43 -> N° RIC. RICEVUTE BIANCHE ALTRO | K43: =impostazioni!K43 -> €
A62: =impostazioni!A62 -> SUB-TOTALE | C62: =SUM(C44:C61) -> 0 | D62: =impostazioni!D62 -> SUB-TOTALE | G62: =SUM(G44:G61) -> 0 | H62: =impostazioni!H62 -> SUB-TOTALE | K62: =SUM(K44:K61) -> 0 | L62: USCITA | N62: TOTALE | O62: =SUM(C62,G62,K62-M62) -> 0
A64: ESTEFANY >> SEZIONE C <<
A66: =impostazioni!A66 -> DISTINTA RICEVUTE AZZURRE + BIANCHE | F66: =impostazioni!F66 -> NOTE GENERICHE
A67: =impostazioni!A67 -> TOTALE CONTANTI RIC. AZZURRE | B67: =B36 -> 0 | F67: -20€ LAVAAGGIO TESSUTI
A68: =impostazioni!A68 -> TOTALE CONTANTI RIC. BIANCHE | B68: =SUM(C62,G62,K62) -> 0
A69: =impostazioni!A69 -> USCITA CONTANTE | B69: =SUM(B38+M62) -> 0
A70: =impostazioni!A70 -> TOTALE CASSA | B70: =B67+B68-B69 -> 0 | F70: =IF(B70=B77,"OK","ERRORE") -> OK
A72: ESTEFANY >> SEZIONE D <<
A74: =impostazioni!A74 -> PEZZI
A75: =impostazioni!A75 -> TAGLIO | B75: 500 | C75: 200 | D75: 100 | E75: 50 | F75: 20 | G75: 10 | H75: 5 | I75: 2 | J75: 1 | K75: 0.5 | L75: 0.2 | M75: 0.1 | N75: 0.05 | O75: 0.02 | P75: 0.01
A76: =impostazioni!A76 -> TOT | B76: =B74*B75 -> 0 | C76: =C74*C75 -> 0 | D76: =D74*D75 -> 0 | E76: =E74*E75 -> 0 | F76: =F74*F75 -> 0 | G76: =G74*G75 -> 0 | H76: =H74*H75 -> 0 | I76: =I74*I75 -> 0 | ... P76: =P74*P75 -> 0
A77: =impostazioni!A77 -> TOTALE CASSA | B77: =SUM(B76:P76) -> 0
A79: =impostazioni!A79 -> ULTIMO ACCESSO: | B79: =impostazioni!B79 -> 46071.676 | E79: =impostazioni!E79 -> CONTROLLO FATTO DA: | G79: ESTEFANY | H79: FALSE | J79: ELISA Controllo | L79: OK | M79: FALSE | N79: REGIST. | O79: FALSE

Sheet Estefany-EX
A1: ESTEFANY - EXTRA >> SEZIONE A <<
A2: ESTEFANY EXTRA | B2: =impostazioni!B2 -> CONTANTE | D2: =impostazioni!D2 -> POS POSTA Recep | F2: =impostazioni!F2 -> CARTA POSTA Recep | H2: =impostazioni!H2 -> POS POSTA 2°P | J2: =impostazioni!J2 -> CARTA POSTA 2°P | L2: =impostazioni!L2 -> POS BPM 1°P | N2: =impostazioni!N2 -> CARTA BPM 1°P | P2: =impostazioni!P2 -> B/B | R2: =impostazioni!R2 -> SEDE SCALAPAY | T2: =impostazioni!T2 -> SEDE SATISPAY | V2: =impostazioni!V2 -> ONLINE TESSERATO | X2: =impostazioni!X2 -> ONLINE NON TESSERATO
A3: =impostazioni!A3 -> N° RICEVUTA | B3: =impostazioni!B3 -> CORSI | C3: =impostazioni!C3 -> QUOTA TESS. | D3: =impostazioni!D3 -> CORSI | E3: =impostazioni!E3 -> QUOTA TESS. | F3: =impostazioni!F3 -> CORSI | G3: =impostazioni!G3 -> QUOTA TESS. | H3: =impostazioni!H3 -> CORSI | ... Y3: =impostazioni!Y3 -> QUOTA TESS.
A35: =impostazioni!A35 -> SUB-TOTALE CORSI DIVISO | B35: =SUM(B4:B34) -> 0 | C35: =SUM(C4:C34) -> 0 | D35: =SUM(D4:D34) -> 0 | E35: =SUM(E4:E34) -> 0 | F35: =SUM(F4:F34) -> 0 | G35: =SUM(G4:G34) -> 0 | H35: =SUM(H4:H34) -> 0 | I35: =SUM(I4:I34) -> 0 | ... Y35: =SUM(Y4:Y34) -> 0
A36: =impostazioni!A36 -> TOTALE CORSI UNITO | B36: =SUM(B35:C35) -> 0 | D36: =SUM(D35:E35) -> 0 | F36: =SUM(F35:G35) -> 0 | H36: =SUM(H35:I35) -> 0 | J36: =SUM(J35:K35) -> 0 | L36: =SUM(L35:M35) -> 0 | N36: =SUM(N35:O35) -> 0 | P36: =SUM(P35:Q35) -> 0 | R36: =SUM(R35:S35) -> 0 | T36: =SUM(T35:U35) -> 0 | V36: =SUM(V35:W35) -> 0 | X36: =SUM(X35:Y35) -> 0
A37: =impostazioni!A37 -> SHOP FATTURE (pagato con Pos)
A38: =impostazioni!A38 -> USCITA CONTANTE | D38: =impostazioni!D38 -> NOTE PER USCITA:
A39: =impostazioni!A39 -> TOTALE CASSA CONTANTE ENTRATE-USCITE | B39: =SUM(B36:Y36-B38) -> 0
A41: ESTEFANY - EXTRA >> SEZIONE B <<
A43: =impostazioni!A43 -> N° RIC. BIANCHE VISITE MEDICHE | C43: =impostazioni!C43 -> € | D43: =impostazioni!D43 -> N° RIC. RICEVUTE BIANCHE ALTRO | G43: =impostazioni!G43 -> € | H43: =impostazioni!H43 -> N° RIC. RICEVUTE BIANCHE ALTRO | K43: =impostazioni!K43 -> €
A62: =impostazioni!A62 -> SUB-TOTALE | C62: =SUM(C44:C61) -> 0 | D62: =impostazioni!D62 -> SUB-TOTALE | G62: =SUM(G44:G61) -> 0 | H62: =impostazioni!H62 -> SUB-TOTALE | K62: =SUM(K44:K61) -> 0 | L62: USCITA | N62: TOTALE | O62: =SUM(C62,G62,K62-M62) -> 0
A64: ESTEFANY - EXTRA >> SEZIONE C <<
A66: =impostazioni!A66 -> DISTINTA RICEVUTE AZZURRE + BIANCHE | F66: =impostazioni!F66 -> NOTE GENERICHE
A67: =impostazioni!A67 -> TOTALE CONTANTI RIC. AZZURRE | B67: =B36 -> 0
A68: =impostazioni!A68 -> TOTALE CONTANTI RIC. BIANCHE | B68: =SUM(C62,G62,K62) -> 0
A69: =impostazioni!A69 -> USCITA CONTANTE | B69: =SUM(B38+M62) -> 0
A70: =impostazioni!A70 -> TOTALE CASSA | B70: =B67+B68-B69 -> 0 | F70: =IF(B70=B77,"OK","ERRORE") -> OK
A72: ESTEFANY - EXTRA >> SEZIONE D <<
A74: =impostazioni!A74 -> PEZZI
A75: =impostazioni!A75 -> TAGLIO | B75: 500 | C75: 200 | D75: 100 | E75: 50 | F75: 20 | G75: 10 | H75: 5 | I75: 2 | J75: 1 | K75: 0.5 | L75: 0.2 | M75: 0.1 | N75: 0.05 | O75: 0.02 | P75: 0.01
A76: =impostazioni!A76 -> TOT | B76: =B74*B75 -> 0 | C76: =C74*C75 -> 0 | D76: =D74*D75 -> 0 | E76: =E74*E75 -> 0 | F76: =F74*F75 -> 0 | G76: =G74*G75 -> 0 | H76: =H74*H75 -> 0 | I76: =I74*I75 -> 0 | ... P76: =P74*P75 -> 0
A77: =impostazioni!A77 -> TOTALE CASSA | B77: =SUM(B76:P76) -> 0
A79: =impostazioni!A79 -> ULTIMO ACCESSO: | B79: =impostazioni!B79 -> 46071.676 | E79: =impostazioni!E79 -> CONTROLLO FATTO DA: | G79: ESTEFANY | H79: FALSE | J79: ELISA Controllo | L79: OK | M79: FALSE | N79: REGIST. | O79: FALSE

Sheet TEAM
A1: TEAM >> SEZIONE A <<
A2: TEAM | B2: =impostazioni!B2 -> CONTANTE | D2: =impostazioni!D2 -> POS POSTA Recep | F2: =impostazioni!F2 -> CARTA POSTA Recep | H2: =impostazioni!H2 -> POS POSTA 2°P | J2: =impostazioni!J2 -> CARTA POSTA 2°P | L2: =impostazioni!L2 -> POS BPM 1°P | N2: =impostazioni!N2 -> CARTA BPM 1°P | P2: =impostazioni!P2 -> B/B | R2: =impostazioni!R2 -> SEDE SCALAPAY | T2: =impostazioni!T2 -> SEDE SATISPAY | V2: =impostazioni!V2 -> ONLINE TESSERATO | X2: =impostazioni!X2 -> ONLINE NON TESSERATO
A3: =impostazioni!A3 -> N° RICEVUTA | B3: =impostazioni!B3 -> CORSI | C3: =impostazioni!C3 -> QUOTA TESS. | D3: =impostazioni!D3 -> CORSI | E3: =impostazioni!E3 -> QUOTA TESS. | F3: =impostazioni!F3 -> CORSI | G3: =impostazioni!G3 -> QUOTA TESS. | H3: =impostazioni!H3 -> CORSI | ... Y3: =impostazioni!Y3 -> QUOTA TESS.
A35: =impostazioni!A35 -> SUB-TOTALE CORSI DIVISO | B35: =SUM(B4:B34) -> 0 | C35: =SUM(C4:C34) -> 0 | D35: =SUM(D4:D34) -> 0 | E35: =SUM(E4:E34) -> 0 | F35: =SUM(F4:F34) -> 0 | G35: =SUM(G4:G34) -> 0 | H35: =SUM(H4:H34) -> 0 | I35: =SUM(I4:I34) -> 0 | ... Y35: =SUM(Y4:Y34) -> 0
A36: =impostazioni!A36 -> TOTALE CORSI UNITO | B36: =SUM(B35:C35) -> 0 | D36: =SUM(D35:E35) -> 0 | F36: =SUM(F35:G35) -> 0 | H36: =SUM(H35:I35) -> 0 | J36: =SUM(J35:K35) -> 0 | L36: =SUM(L35:M35) -> 0 | N36: =SUM(N35:O35) -> 0 | P36: =SUM(P35:Q35) -> 0 | R36: =SUM(R35:S35) -> 0 | T36: =SUM(T35:U35) -> 0 | V36: =SUM(V35:W35) -> 0 | X36: =SUM(X35:Y35) -> 0
A37: =impostazioni!A37 -> SHOP FATTURE (pagato con Pos)
A38: =impostazioni!A38 -> USCITA CONTANTE | D38: =impostazioni!D38 -> NOTE PER USCITA:
A39: =impostazioni!A39 -> TOTALE CASSA CONTANTE ENTRATE-USCITE | B39: =SUM(B36:Y36-B38) -> 0
A41: TEAM >> SEZIONE B <<
A43: =impostazioni!A43 -> N° RIC. BIANCHE VISITE MEDICHE | C43: =impostazioni!C43 -> € | D43: =impostazioni!D43 -> N° RIC. RICEVUTE BIANCHE ALTRO | G43: =impostazioni!G43 -> € | H43: =impostazioni!H43 -> N° RIC. RICEVUTE BIANCHE ALTRO | K43: =impostazioni!K43 -> €
A62: =impostazioni!A62 -> SUB-TOTALE | C62: =SUM(C44:C61) -> 0 | D62: =impostazioni!D62 -> SUB-TOTALE | G62: =SUM(G44:G61) -> 0 | H62: =impostazioni!H62 -> SUB-TOTALE | K62: =SUM(K44:K61) -> 0 | L62: USCITA | N62: TOTALE | O62: =SUM(C62,G62,K62-M62) -> 0
A64: TEAM >> SEZIONE C <<
A66: =impostazioni!A66 -> DISTINTA RICEVUTE AZZURRE + BIANCHE | F66: =impostazioni!F66 -> NOTE GENERICHE
A67: =impostazioni!A67 -> TOTALE CONTANTI RIC. AZZURRE | B67: =B36 -> 0
A68: =impostazioni!A68 -> TOTALE CONTANTI RIC. BIANCHE | B68: =SUM(C62,G62,K62) -> 0
A69: =impostazioni!A69 -> USCITA CONTANTE | B69: =SUM(B38+M62) -> 0
A70: =impostazioni!A70 -> TOTALE CASSA | B70: =B67+B68-B69 -> 0 | F70: =IF(B70=B77,"OK","ERRORE") -> OK
A72: TEAM >> SEZIONE D <<
A74: =impostazioni!A74 -> PEZZI
A75: =impostazioni!A75 -> TAGLIO | B75: 500 | C75: 200 | D75: 100 | E75: 50 | F75: 20 | G75: 10 | H75: 5 | I75: 2 | J75: 1 | K75: 0.5 | L75: 0.2 | M75: 0.1 | N75: 0.05 | O75: 0.02 | P75: 0.01
A76: =impostazioni!A76 -> TOT | B76: =B74*B75 -> 0 | C76: =C74*C75 -> 0 | D76: =D74*D75 -> 0 | E76: =E74*E75 -> 0 | F76: =F74*F75 -> 0 | G76: =G74*G75 -> 0 | H76: =H74*H75 -> 0 | I76: =I74*I75 -> 0 | ... P76: =P74*P75 -> 0
A77: =impostazioni!A77 -> TOTALE CASSA | B77: =SUM(B76:P76) -> 0
A79: =impostazioni!A79 -> ULTIMO ACCESSO: | B79: =impostazioni!B79 -> 46071.676 | E79: =impostazioni!E79 -> CONTROLLO FATTO DA: | G79: TEAM | H79: FALSE | J79: ELISA Controllo | L79: OK | M79: FALSE | N79: REGIST. | O79: FALSE

Sheet TEAM-EX
A1: TEAM - EXTRA >> SEZIONE A <<
A2: TEAM EXTRA | B2: =impostazioni!B2 -> CONTANTE | D2: =impostazioni!D2 -> POS POSTA Recep | F2: =impostazioni!F2 -> CARTA POSTA Recep | H2: =impostazioni!H2 -> POS POSTA 2°P | J2: =impostazioni!J2 -> CARTA POSTA 2°P | L2: =impostazioni!L2 -> POS BPM 1°P | N2: =impostazioni!N2 -> CARTA BPM 1°P | P2: =impostazioni!P2 -> B/B | R2: =impostazioni!R2 -> SEDE SCALAPAY | T2: =impostazioni!T2 -> SEDE SATISPAY | V2: =impostazioni!V2 -> ONLINE TESSERATO | X2: =impostazioni!X2 -> ONLINE NON TESSERATO
A3: =impostazioni!A3 -> N° RICEVUTA | B3: =impostazioni!B3 -> CORSI | C3: =impostazioni!C3 -> QUOTA TESS. | D3: =impostazioni!D3 -> CORSI | E3: =impostazioni!E3 -> QUOTA TESS. | F3: =impostazioni!F3 -> CORSI | G3: =impostazioni!G3 -> QUOTA TESS. | H3: =impostazioni!H3 -> CORSI | ... Y3: =impostazioni!Y3 -> QUOTA TESS.
A35: =impostazioni!A35 -> SUB-TOTALE CORSI DIVISO | B35: =SUM(B4:B34) -> 0 | C35: =SUM(C4:C34) -> 0 | D35: =SUM(D4:D34) -> 0 | E35: =SUM(E4:E34) -> 0 | F35: =SUM(F4:F34) -> 0 | G35: =SUM(G4:G34) -> 0 | H35: =SUM(H4:H34) -> 0 | I35: =SUM(I4:I34) -> 0 | ... Y35: =SUM(Y4:Y34) -> 0
A36: =impostazioni!A36 -> TOTALE CORSI UNITO | B36: =SUM(B35:C35) -> 0 | D36: =SUM(D35:E35) -> 0 | F36: =SUM(F35:G35) -> 0 | H36: =SUM(H35:I35) -> 0 | J36: =SUM(J35:K35) -> 0 | L36: =SUM(L35:M35) -> 0 | N36: =SUM(N35:O35) -> 0 | P36: =SUM(P35:Q35) -> 0 | R36: =SUM(R35:S35) -> 0 | T36: =SUM(T35:U35) -> 0 | V36: =SUM(V35:W35) -> 0 | X36: =SUM(X35:Y35) -> 0
A37: =impostazioni!A37 -> SHOP FATTURE (pagato con Pos)
A38: =impostazioni!A38 -> USCITA CONTANTE | D38: =impostazioni!D38 -> NOTE PER USCITA:
A39: =impostazioni!A39 -> TOTALE CASSA CONTANTE ENTRATE-USCITE | B39: =SUM(B36:Y36-B38) -> 0
A41: TEAM - EXTRA >> SEZIONE B <<
A43: =impostazioni!A43 -> N° RIC. BIANCHE VISITE MEDICHE | C43: =impostazioni!C43 -> € | D43: =impostazioni!D43 -> N° RIC. RICEVUTE BIANCHE ALTRO | G43: =impostazioni!G43 -> € | H43: =impostazioni!H43 -> N° RIC. RICEVUTE BIANCHE ALTRO | K43: =impostazioni!K43 -> €
A62: =impostazioni!A62 -> SUB-TOTALE | C62: =SUM(C44:C61) -> 0 | D62: =impostazioni!D62 -> SUB-TOTALE | G62: =SUM(G44:G61) -> 0 | H62: =impostazioni!H62 -> SUB-TOTALE | K62: =SUM(K44:K61) -> 0 | L62: USCITA | N62: TOTALE | O62: =SUM(C62,G62,K62-M62) -> 0
A64: TEAM - EXTRA >> SEZIONE C <<
A66: =impostazioni!A66 -> DISTINTA RICEVUTE AZZURRE + BIANCHE | F66: =impostazioni!F66 -> NOTE GENERICHE
A67: =impostazioni!A67 -> TOTALE CONTANTI RIC. AZZURRE | B67: =B36 -> 0
A68: =impostazioni!A68 -> TOTALE CONTANTI RIC. BIANCHE | B68: =SUM(C62,G62,K62) -> 0
A69: =impostazioni!A69 -> USCITA CONTANTE | B69: =SUM(B38+M62) -> 0
A70: =impostazioni!A70 -> TOTALE CASSA | B70: =B67+B68-B69 -> 0 | F70: =IF(B70=B77,"OK","ERRORE") -> OK
A72: TEAM - EXTRA >> SEZIONE D <<
A74: =impostazioni!A74 -> PEZZI
A75: =impostazioni!A75 -> TAGLIO | B75: 500 | C75: 200 | D75: 100 | E75: 50 | F75: 20 | G75: 10 | H75: 5 | I75: 2 | J75: 1 | K75: 0.5 | L75: 0.2 | M75: 0.1 | N75: 0.05 | O75: 0.02 | P75: 0.01
A76: =impostazioni!A76 -> TOT | B76: =B74*B75 -> 0 | C76: =C74*C75 -> 0 | D76: =D74*D75 -> 0 | E76: =E74*E75 -> 0 | F76: =F74*F75 -> 0 | G76: =G74*G75 -> 0 | H76: =H74*H75 -> 0 | I76: =I74*I75 -> 0 | ... P76: =P74*P75 -> 0
A77: =impostazioni!A77 -> TOTALE CASSA | B77: =SUM(B76:P76) -> 0
A79: =impostazioni!A79 -> ULTIMO ACCESSO: | B79: =impostazioni!B79 -> 46071.676 | E79: =impostazioni!E79 -> CONTROLLO FATTO DA: | G79: TEAM | H79: FALSE | J79: ELISA Controllo | L79: OK | M79: FALSE | N79: REGIST. | O79: FALSE

Sheet Joel
A1: JOEL >> SEZIONE A <<
A2: JOEL | B2: =impostazioni!B2 -> CONTANTE | D2: =impostazioni!D2 -> POS POSTA Recep | F2: =impostazioni!F2 -> CARTA POSTA Recep | H2: =impostazioni!H2 -> POS POSTA 2°P | J2: =impostazioni!J2 -> CARTA POSTA 2°P | L2: =impostazioni!L2 -> POS BPM 1°P | N2: =impostazioni!N2 -> CARTA BPM 1°P | P2: =impostazioni!P2 -> B/B | R2: =impostazioni!R2 -> SEDE SCALAPAY | T2: =impostazioni!T2 -> SEDE SATISPAY | V2: =impostazioni!V2 -> ONLINE TESSERATO | X2: =impostazioni!X2 -> ONLINE NON TESSERATO
A3: =impostazioni!A3 -> N° RICEVUTA | B3: =impostazioni!B3 -> CORSI | C3: =impostazioni!C3 -> QUOTA TESS. | D3: =impostazioni!D3 -> CORSI | E3: =impostazioni!E3 -> QUOTA TESS. | F3: =impostazioni!F3 -> CORSI | G3: =impostazioni!G3 -> QUOTA TESS. | H3: =impostazioni!H3 -> CORSI | ... Y3: =impostazioni!Y3 -> QUOTA TESS.
A35: =impostazioni!A35 -> SUB-TOTALE CORSI DIVISO | B35: =SUM(B4:B34) -> 0 | C35: =SUM(C4:C34) -> 0 | D35: =SUM(D4:D34) -> 0 | E35: =SUM(E4:E34) -> 0 | F35: =SUM(F4:F34) -> 0 | G35: =SUM(G4:G34) -> 0 | H35: =SUM(H4:H34) -> 0 | I35: =SUM(I4:I34) -> 0 | ... Y35: =SUM(Y4:Y34) -> 0
A36: =impostazioni!A36 -> TOTALE CORSI UNITO | B36: =SUM(B35:C35) -> 0 | D36: =SUM(D35:E35) -> 0 | F36: =SUM(F35:G35) -> 0 | H36: =SUM(H35:I35) -> 0 | J36: =SUM(J35:K35) -> 0 | L36: =SUM(L35:M35) -> 0 | N36: =SUM(N35:O35) -> 0 | P36: =SUM(P35:Q35) -> 0 | R36: =SUM(R35:S35) -> 0 | T36: =SUM(T35:U35) -> 0 | V36: =SUM(V35:W35) -> 0 | X36: =SUM(X35:Y35) -> 0
A37: =impostazioni!A37 -> SHOP FATTURE (pagato con Pos)
A38: =impostazioni!A38 -> USCITA CONTANTE | D38: =impostazioni!D38 -> NOTE PER USCITA:
A39: =impostazioni!A39 -> TOTALE CASSA CONTANTE ENTRATE-USCITE | B39: =SUM(B36:Y36-B38) -> 0
A41: JOEL >> SEZIONE B <<
A43: =impostazioni!A43 -> N° RIC. BIANCHE VISITE MEDICHE | C43: =impostazioni!C43 -> € | D43: =impostazioni!D43 -> N° RIC. RICEVUTE BIANCHE ALTRO | G43: =impostazioni!G43 -> € | H43: =impostazioni!H43 -> N° RIC. RICEVUTE BIANCHE ALTRO | K43: =impostazioni!K43 -> €
A62: =impostazioni!A62 -> SUB-TOTALE | C62: =SUM(C44:C61) -> 0 | D62: =impostazioni!D62 -> SUB-TOTALE | G62: =SUM(G44:G61) -> 0 | H62: =impostazioni!H62 -> SUB-TOTALE | K62: =SUM(K44:K61) -> 0 | L62: USCITA | N62: TOTALE | O62: =SUM(C62,G62,K62-M62) -> 0
A64: JOEL >> SEZIONE C <<
A66: =impostazioni!A66 -> DISTINTA RICEVUTE AZZURRE + BIANCHE | F66: =impostazioni!F66 -> NOTE GENERICHE
A67: =impostazioni!A67 -> TOTALE CONTANTI RIC. AZZURRE | B67: =B36 -> 0
A68: =impostazioni!A68 -> TOTALE CONTANTI RIC. BIANCHE | B68: =SUM(C62,G62,K62) -> 0
A69: =impostazioni!A69 -> USCITA CONTANTE | B69: =SUM(B38+M62) -> 0
A70: =impostazioni!A70 -> TOTALE CASSA | B70: =B67+B68-B69 -> 0 | F70: =IF(B70=B77,"OK","ERRORE") -> OK
A72: JOEL >> SEZIONE D <<
A74: =impostazioni!A74 -> PEZZI
A75: =impostazioni!A75 -> TAGLIO | B75: 500 | C75: 200 | D75: 100 | E75: 50 | F75: 20 | G75: 10 | H75: 5 | I75: 2 | J75: 1 | K75: 0.5 | L75: 0.2 | M75: 0.1 | N75: 0.05 | O75: 0.02 | P75: 0.01
A76: =impostazioni!A76 -> TOT | B76: =B74*B75 -> 0 | C76: =C74*C75 -> 0 | D76: =D74*D75 -> 0 | E76: =E74*E75 -> 0 | F76: =F74*F75 -> 0 | G76: =G74*G75 -> 0 | H76: =H74*H75 -> 0 | I76: =I74*I75 -> 0 | ... P76: =P74*P75 -> 0
A77: =impostazioni!A77 -> TOTALE CASSA | B77: =SUM(B76:P76) -> 0
A79: =impostazioni!A79 -> ULTIMO ACCESSO: | B79: =impostazioni!B79 -> 46071.676 | E79: =impostazioni!E79 -> CONTROLLO FATTO DA: | G79: JOEL | H79: FALSE | J79: ELISA Controllo | L79: OK | M79: FALSE | N79: REGIST. | O79: FALSE

Sheet Joel-EX
A1: JOEL - EXTRA >> SEZIONE A <<
A2: JOEL EXTRA | B2: =impostazioni!B2 -> CONTANTE | D2: =impostazioni!D2 -> POS POSTA Recep | F2: =impostazioni!F2 -> CARTA POSTA Recep | H2: =impostazioni!H2 -> POS POSTA 2°P | J2: =impostazioni!J2 -> CARTA POSTA 2°P | L2: =impostazioni!L2 -> POS BPM 1°P | N2: =impostazioni!N2 -> CARTA BPM 1°P | P2: =impostazioni!P2 -> B/B | R2: =impostazioni!R2 -> SEDE SCALAPAY | T2: =impostazioni!T2 -> SEDE SATISPAY | V2: =impostazioni!V2 -> ONLINE TESSERATO | X2: =impostazioni!X2 -> ONLINE NON TESSERATO
A3: =impostazioni!A3 -> N° RICEVUTA | B3: =impostazioni!B3 -> CORSI | C3: =impostazioni!C3 -> QUOTA TESS. | D3: =impostazioni!D3 -> CORSI | E3: =impostazioni!E3 -> QUOTA TESS. | F3: =impostazioni!F3 -> CORSI | G3: =impostazioni!G3 -> QUOTA TESS. | H3: =impostazioni!H3 -> CORSI | ... Y3: =impostazioni!Y3 -> QUOTA TESS.
A35: =impostazioni!A35 -> SUB-TOTALE CORSI DIVISO | B35: =SUM(B4:B34) -> 0 | C35: =SUM(C4:C34) -> 0 | D35: =SUM(D4:D34) -> 0 | E35: =SUM(E4:E34) -> 0 | F35: =SUM(F4:F34) -> 0 | G35: =SUM(G4:G34) -> 0 | H35: =SUM(H4:H34) -> 0 | I35: =SUM(I4:I34) -> 0 | ... Y35: =SUM(Y4:Y34) -> 0
A36: =impostazioni!A36 -> TOTALE CORSI UNITO | B36: =SUM(B35:C35) -> 0 | D36: =SUM(D35:E35) -> 0 | F36: =SUM(F35:G35) -> 0 | H36: =SUM(H35:I35) -> 0 | J36: =SUM(J35:K35) -> 0 | L36: =SUM(L35:M35) -> 0 | N36: =SUM(N35:O35) -> 0 | P36: =SUM(P35:Q35) -> 0 | R36: =SUM(R35:S35) -> 0 | T36: =SUM(T35:U35) -> 0 | V36: =SUM(V35:W35) -> 0 | X36: =SUM(X35:Y35) -> 0
A37: =impostazioni!A37 -> SHOP FATTURE (pagato con Pos)
A38: =impostazioni!A38 -> USCITA CONTANTE | D38: =impostazioni!D38 -> NOTE PER USCITA:
A39: =impostazioni!A39 -> TOTALE CASSA CONTANTE ENTRATE-USCITE | B39: =SUM(B36:Y36-B38) -> 0
A41: JOEL - EXTRA >> SEZIONE B <<
A43: =impostazioni!A43 -> N° RIC. BIANCHE VISITE MEDICHE | C43: =impostazioni!C43 -> € | D43: =impostazioni!D43 -> N° RIC. RICEVUTE BIANCHE ALTRO | G43: =impostazioni!G43 -> € | H43: =impostazioni!H43 -> N° RIC. RICEVUTE BIANCHE ALTRO | K43: =impostazioni!K43 -> €
A62: =impostazioni!A62 -> SUB-TOTALE | C62: =SUM(C44:C61) -> 0 | D62: =impostazioni!D62 -> SUB-TOTALE | G62: =SUM(G44:G61) -> 0 | H62: =impostazioni!H62 -> SUB-TOTALE | K62: =SUM(K44:K61) -> 0 | L62: USCITA | N62: TOTALE | O62: =SUM(C62,G62,K62-M62) -> 0
A64: JOEL - EXTRA >> SEZIONE C <<
A66: =impostazioni!A66 -> DISTINTA RICEVUTE AZZURRE + BIANCHE | F66: =impostazioni!F66 -> NOTE GENERICHE
A67: =impostazioni!A67 -> TOTALE CONTANTI RIC. AZZURRE | B67: =B36 -> 0
A68: =impostazioni!A68 -> TOTALE CONTANTI RIC. BIANCHE | B68: =SUM(C62,G62,K62) -> 0
A69: =impostazioni!A69 -> USCITA CONTANTE | B69: =SUM(B38+M62) -> 0
A70: =impostazioni!A70 -> TOTALE CASSA | B70: =B67+B68-B69 -> 0 | F70: =IF(B70=B77,"OK","ERRORE") -> OK
A72: JOEL - EXTRA >> SEZIONE D <<
A74: =impostazioni!A74 -> PEZZI
A75: =impostazioni!A75 -> TAGLIO | B75: 500 | C75: 200 | D75: 100 | E75: 50 | F75: 20 | G75: 10 | H75: 5 | I75: 2 | J75: 1 | K75: 0.5 | L75: 0.2 | M75: 0.1 | N75: 0.05 | O75: 0.02 | P75: 0.01
A76: =impostazioni!A76 -> TOT | B76: =B74*B75 -> 0 | C76: =C74*C75 -> 0 | D76: =D74*D75 -> 0 | E76: =E74*E75 -> 0 | F76: =F74*F75 -> 0 | G76: =G74*G75 -> 0 | H76: =H74*H75 -> 0 | I76: =I74*I75 -> 0 | ... P76: =P74*P75 -> 0
A77: =impostazioni!A77 -> TOTALE CASSA | B77: =SUM(B76:P76) -> 0
A79: =impostazioni!A79 -> ULTIMO ACCESSO: | B79: =impostazioni!B79 -> 46071.676 | E79: =impostazioni!E79 -> CONTROLLO FATTO DA: | G79: JOEL | H79: FALSE | J79: ELISA Controllo | L79: OK | M79: FALSE | N79: REGIST. | O79: FALSE

Sheet TEAM1
A1: TEAM1 >> SEZIONE A <<
A2: TEAM1 | B2: =impostazioni!B2 -> CONTANTE | D2: =impostazioni!D2 -> POS POSTA Recep | F2: =impostazioni!F2 -> CARTA POSTA Recep | H2: =impostazioni!H2 -> POS POSTA 2°P | J2: =impostazioni!J2 -> CARTA POSTA 2°P | L2: =impostazioni!L2 -> POS BPM 1°P | N2: =impostazioni!N2 -> CARTA BPM 1°P | P2: =impostazioni!P2 -> B/B | R2: =impostazioni!R2 -> SEDE SCALAPAY | T2: =impostazioni!T2 -> SEDE SATISPAY | V2: =impostazioni!V2 -> ONLINE TESSERATO | X2: =impostazioni!X2 -> ONLINE NON TESSERATO
A3: =impostazioni!A3 -> N° RICEVUTA | B3: =impostazioni!B3 -> CORSI | C3: =impostazioni!C3 -> QUOTA TESS. | D3: =impostazioni!D3 -> CORSI | E3: =impostazioni!E3 -> QUOTA TESS. | F3: =impostazioni!F3 -> CORSI | G3: =impostazioni!G3 -> QUOTA TESS. | H3: =impostazioni!H3 -> CORSI | ... Y3: =impostazioni!Y3 -> QUOTA TESS.
A35: =impostazioni!A35 -> SUB-TOTALE CORSI DIVISO | B35: =SUM(B4:B34) -> 0 | C35: =SUM(C4:C34) -> 0 | D35: =SUM(D4:D34) -> 0 | E35: =SUM(E4:E34) -> 0 | F35: =SUM(F4:F34) -> 0 | G35: =SUM(G4:G34) -> 0 | H35: =SUM(H4:H34) -> 0 | I35: =SUM(I4:I34) -> 0 | ... Y35: =SUM(Y4:Y34) -> 0
A36: =impostazioni!A36 -> TOTALE CORSI UNITO | B36: =SUM(B35:C35) -> 0 | D36: =SUM(D35:E35) -> 0 | F36: =SUM(F35:G35) -> 0 | H36: =SUM(H35:I35) -> 0 | J36: =SUM(J35:K35) -> 0 | L36: =SUM(L35:M35) -> 0 | N36: =SUM(N35:O35) -> 0 | P36: =SUM(P35:Q35) -> 0 | R36: =SUM(R35:S35) -> 0 | T36: =SUM(T35:U35) -> 0 | V36: =SUM(V35:W35) -> 0 | X36: =SUM(X35:Y35) -> 0
A37: =impostazioni!A37 -> SHOP FATTURE (pagato con Pos)
A38: =impostazioni!A38 -> USCITA CONTANTE | D38: =impostazioni!D38 -> NOTE PER USCITA:
A39: =impostazioni!A39 -> TOTALE CASSA CONTANTE ENTRATE-USCITE | B39: =SUM(B36:Y36-B38) -> 0
A41: TEAM1 >> SEZIONE B <<
A43: =impostazioni!A43 -> N° RIC. BIANCHE VISITE MEDICHE | C43: =impostazioni!C43 -> € | D43: =impostazioni!D43 -> N° RIC. RICEVUTE BIANCHE ALTRO | G43: =impostazioni!G43 -> € | H43: =impostazioni!H43 -> N° RIC. RICEVUTE BIANCHE ALTRO | K43: =impostazioni!K43 -> €
A62: =impostazioni!A62 -> SUB-TOTALE | C62: =SUM(C44:C61) -> 0 | D62: =impostazioni!D62 -> SUB-TOTALE | G62: =SUM(G44:G61) -> 0 | H62: =impostazioni!H62 -> SUB-TOTALE | K62: =SUM(K44:K61) -> 0 | L62: USCITA | N62: TOTALE | O62: =SUM(C62,G62,K62-M62) -> 0
A64: TEAM1 >> SEZIONE C <<
A66: =impostazioni!A66 -> DISTINTA RICEVUTE AZZURRE + BIANCHE | F66: =impostazioni!F66 -> NOTE GENERICHE
A67: =impostazioni!A67 -> TOTALE CONTANTI RIC. AZZURRE | B67: =B36 -> 0
A68: =impostazioni!A68 -> TOTALE CONTANTI RIC. BIANCHE | B68: =SUM(C62,G62,K62) -> 0
A69: =impostazioni!A69 -> USCITA CONTANTE | B69: =SUM(B38+M62) -> 0
A70: =impostazioni!A70 -> TOTALE CASSA | B70: =B67+B68-B69 -> 0 | F70: =IF(B70=B77,"OK","ERRORE") -> OK
A72: TEAM1 >> SEZIONE D <<
A74: =impostazioni!A74 -> PEZZI
A75: =impostazioni!A75 -> TAGLIO | B75: 500 | C75: 200 | D75: 100 | E75: 50 | F75: 20 | G75: 10 | H75: 5 | I75: 2 | J75: 1 | K75: 0.5 | L75: 0.2 | M75: 0.1 | N75: 0.05 | O75: 0.02 | P75: 0.01
A76: =impostazioni!A76 -> TOT | B76: =B74*B75 -> 0 | C76: =C74*C75 -> 0 | D76: =D74*D75 -> 0 | E76: =E74*E75 -> 0 | F76: =F74*F75 -> 0 | G76: =G74*G75 -> 0 | H76: =H74*H75 -> 0 | I76: =I74*I75 -> 0 | ... P76: =P74*P75 -> 0
A77: =impostazioni!A77 -> TOTALE CASSA | B77: =SUM(B76:P76) -> 0
A79: =impostazioni!A79 -> ULTIMO ACCESSO: | B79: =impostazioni!B79 -> 46071.676 | E79: =impostazioni!E79 -> CONTROLLO FATTO DA: | G79: TEAM1 | H79: FALSE | J79: ELISA Controllo | L79: OK | M79: FALSE | N79: REGIST. | O79: FALSE

Sheet TEAM1-EX
A1: TEAM1 - EXTRA >> SEZIONE A <<
A2: TEAM1 EXTRA | B2: =impostazioni!B2 -> CONTANTE | D2: =impostazioni!D2 -> POS POSTA Recep | F2: =impostazioni!F2 -> CARTA POSTA Recep | H2: =impostazioni!H2 -> POS POSTA 2°P | J2: =impostazioni!J2 -> CARTA POSTA 2°P | L2: =impostazioni!L2 -> POS BPM 1°P | N2: =impostazioni!N2 -> CARTA BPM 1°P | P2: =impostazioni!P2 -> B/B | R2: =impostazioni!R2 -> SEDE SCALAPAY | T2: =impostazioni!T2 -> SEDE SATISPAY | V2: =impostazioni!V2 -> ONLINE TESSERATO | X2: =impostazioni!X2 -> ONLINE NON TESSERATO
A3: =impostazioni!A3 -> N° RICEVUTA | B3: =impostazioni!B3 -> CORSI | C3: =impostazioni!C3 -> QUOTA TESS. | D3: =impostazioni!D3 -> CORSI | E3: =impostazioni!E3 -> QUOTA TESS. | F3: =impostazioni!F3 -> CORSI | G3: =impostazioni!G3 -> QUOTA TESS. | H3: =impostazioni!H3 -> CORSI | ... Y3: =impostazioni!Y3 -> QUOTA TESS.
A35: =impostazioni!A35 -> SUB-TOTALE CORSI DIVISO | B35: =SUM(B4:B34) -> 0 | C35: =SUM(C4:C34) -> 0 | D35: =SUM(D4:D34) -> 0 | E35: =SUM(E4:E34) -> 0 | F35: =SUM(F4:F34) -> 0 | G35: =SUM(G4:G34) -> 0 | H35: =SUM(H4:H34) -> 0 | I35: =SUM(I4:I34) -> 0 | ... Y35: =SUM(Y4:Y34) -> 0
A36: =impostazioni!A36 -> TOTALE CORSI UNITO | B36: =SUM(B35:C35) -> 0 | D36: =SUM(D35:E35) -> 0 | F36: =SUM(F35:G35) -> 0 | H36: =SUM(H35:I35) -> 0 | J36: =SUM(J35:K35) -> 0 | L36: =SUM(L35:M35) -> 0 | N36: =SUM(N35:O35) -> 0 | P36: =SUM(P35:Q35) -> 0 | R36: =SUM(R35:S35) -> 0 | T36: =SUM(T35:U35) -> 0 | V36: =SUM(V35:W35) -> 0 | X36: =SUM(X35:Y35) -> 0
A37: =impostazioni!A37 -> SHOP FATTURE (pagato con Pos)
A38: =impostazioni!A38 -> USCITA CONTANTE | D38: =impostazioni!D38 -> NOTE PER USCITA:
A39: =impostazioni!A39 -> TOTALE CASSA CONTANTE ENTRATE-USCITE | B39: =SUM(B36:Y36-B38) -> 0
A41: TEAM1 - EXTRA >> SEZIONE B <<
A43: =impostazioni!A43 -> N° RIC. BIANCHE VISITE MEDICHE | C43: =impostazioni!C43 -> € | D43: =impostazioni!D43 -> N° RIC. RICEVUTE BIANCHE ALTRO | G43: =impostazioni!G43 -> € | H43: =impostazioni!H43 -> N° RIC. RICEVUTE BIANCHE ALTRO | K43: =impostazioni!K43 -> €
A62: =impostazioni!A62 -> SUB-TOTALE | C62: =SUM(C44:C61) -> 0 | D62: =impostazioni!D62 -> SUB-TOTALE | G62: =SUM(G44:G61) -> 0 | H62: =impostazioni!H62 -> SUB-TOTALE | K62: =SUM(K44:K61) -> 0 | L62: USCITA | N62: TOTALE | O62: =SUM(C62,G62,K62-M62) -> 0
A64: TEAM1 - EXTRA >> SEZIONE C <<
A66: =impostazioni!A66 -> DISTINTA RICEVUTE AZZURRE + BIANCHE | F66: =impostazioni!F66 -> NOTE GENERICHE
A67: =impostazioni!A67 -> TOTALE CONTANTI RIC. AZZURRE | B67: =B36 -> 0
A68: =impostazioni!A68 -> TOTALE CONTANTI RIC. BIANCHE | B68: =SUM(C62,G62,K62) -> 0
A69: =impostazioni!A69 -> USCITA CONTANTE | B69: =SUM(B38+M62) -> 0
A70: =impostazioni!A70 -> TOTALE CASSA | B70: =B67+B68-B69 -> 0 | F70: =IF(B70=B77,"OK","ERRORE") -> OK
A72: TEAM1 - EXTRA >> SEZIONE D <<
A74: =impostazioni!A74 -> PEZZI
A75: =impostazioni!A75 -> TAGLIO | B75: 500 | C75: 200 | D75: 100 | E75: 50 | F75: 20 | G75: 10 | H75: 5 | I75: 2 | J75: 1 | K75: 0.5 | L75: 0.2 | M75: 0.1 | N75: 0.05 | O75: 0.02 | P75: 0.01
A76: =impostazioni!A76 -> TOT | B76: =B74*B75 -> 0 | C76: =C74*C75 -> 0 | D76: =D74*D75 -> 0 | E76: =E74*E75 -> 0 | F76: =F74*F75 -> 0 | G76: =G74*G75 -> 0 | H76: =H74*H75 -> 0 | I76: =I74*I75 -> 0 | ... P76: =P74*P75 -> 0
A77: =impostazioni!A77 -> TOTALE CASSA | B77: =SUM(B76:P76) -> 0
A79: =impostazioni!A79 -> ULTIMO ACCESSO: | B79: =impostazioni!B79 -> 46071.676 | E79: =impostazioni!E79 -> CONTROLLO FATTO DA: | G79: TEAM1 | H79: FALSE | J79: ELISA Controllo | L79: OK | M79: FALSE | N79: REGIST. | O79: FALSE

Sheet TEAM2
A1: TEAM2 >> SEZIONE A <<
A2: TEAM2 | B2: =impostazioni!B2 -> CONTANTE | D2: =impostazioni!D2 -> POS POSTA Recep | F2: =impostazioni!F2 -> CARTA POSTA Recep | H2: =impostazioni!H2 -> POS POSTA 2°P | J2: =impostazioni!J2 -> CARTA POSTA 2°P | L2: =impostazioni!L2 -> POS BPM 1°P | N2: =impostazioni!N2 -> CARTA BPM 1°P | P2: =impostazioni!P2 -> B/B | R2: =impostazioni!R2 -> SEDE SCALAPAY | T2: =impostazioni!T2 -> SEDE SATISPAY | V2: =impostazioni!V2 -> ONLINE TESSERATO | X2: =impostazioni!X2 -> ONLINE NON TESSERATO
A3: =impostazioni!A3 -> N° RICEVUTA | B3: =impostazioni!B3 -> CORSI | C3: =impostazioni!C3 -> QUOTA TESS. | D3: =impostazioni!D3 -> CORSI | E3: =impostazioni!E3 -> QUOTA TESS. | F3: =impostazioni!F3 -> CORSI | G3: =impostazioni!G3 -> QUOTA TESS. | H3: =impostazioni!H3 -> CORSI | ... Y3: =impostazioni!Y3 -> QUOTA TESS.
A35: =impostazioni!A35 -> SUB-TOTALE CORSI DIVISO | B35: =SUM(B4:B34) -> 0 | C35: =SUM(C4:C34) -> 0 | D35: =SUM(D4:D34) -> 0 | E35: =SUM(E4:E34) -> 0 | F35: =SUM(F4:F34) -> 0 | G35: =SUM(G4:G34) -> 0 | H35: =SUM(H4:H34) -> 0 | I35: =SUM(I4:I34) -> 0 | ... Y35: =SUM(Y4:Y34) -> 0
A36: =impostazioni!A36 -> TOTALE CORSI UNITO | B36: =SUM(B35:C35) -> 0 | D36: =SUM(D35:E35) -> 0 | F36: =SUM(F35:G35) -> 0 | H36: =SUM(H35:I35) -> 0 | J36: =SUM(J35:K35) -> 0 | L36: =SUM(L35:M35) -> 0 | N36: =SUM(N35:O35) -> 0 | P36: =SUM(P35:Q35) -> 0 | R36: =SUM(R35:S35) -> 0 | T36: =SUM(T35:U35) -> 0 | V36: =SUM(V35:W35) -> 0 | X36: =SUM(X35:Y35) -> 0
A37: =impostazioni!A37 -> SHOP FATTURE (pagato con Pos)
A38: =impostazioni!A38 -> USCITA CONTANTE | D38: =impostazioni!D38 -> NOTE PER USCITA:
A39: =impostazioni!A39 -> TOTALE CASSA CONTANTE ENTRATE-USCITE | B39: =SUM(B36:Y36-B38) -> 0
A41: TEAM2 >> SEZIONE B <<
A43: =impostazioni!A43 -> N° RIC. BIANCHE VISITE MEDICHE | C43: =impostazioni!C43 -> € | D43: =impostazioni!D43 -> N° RIC. RICEVUTE BIANCHE ALTRO | G43: =impostazioni!G43 -> € | H43: =impostazioni!H43 -> N° RIC. RICEVUTE BIANCHE ALTRO | K43: =impostazioni!K43 -> €
A62: =impostazioni!A62 -> SUB-TOTALE | C62: =SUM(C44:C61) -> 0 | D62: =impostazioni!D62 -> SUB-TOTALE | G62: =SUM(G44:G61) -> 0 | H62: =impostazioni!H62 -> SUB-TOTALE | K62: =SUM(K44:K61) -> 0 | L62: USCITA | N62: TOTALE | O62: =SUM(C62,G62,K62-M62) -> 0
A64: TEAM2 >> SEZIONE C <<
A66: =impostazioni!A66 -> DISTINTA RICEVUTE AZZURRE + BIANCHE | F66: =impostazioni!F66 -> NOTE GENERICHE
A67: =impostazioni!A67 -> TOTALE CONTANTI RIC. AZZURRE | B67: =B36 -> 0
A68: =impostazioni!A68 -> TOTALE CONTANTI RIC. BIANCHE | B68: =SUM(C62,G62,K62) -> 0
A69: =impostazioni!A69 -> USCITA CONTANTE | B69: =SUM(B38+M62) -> 0
A70: =impostazioni!A70 -> TOTALE CASSA | B70: =B67+B68-B69 -> 0 | F70: =IF(B70=B77,"OK","ERRORE") -> OK
A72: TEAM2 >> SEZIONE D <<
A74: =impostazioni!A74 -> PEZZI
A75: =impostazioni!A75 -> TAGLIO | B75: 500 | C75: 200 | D75: 100 | E75: 50 | F75: 20 | G75: 10 | H75: 5 | I75: 2 | J75: 1 | K75: 0.5 | L75: 0.2 | M75: 0.1 | N75: 0.05 | O75: 0.02 | P75: 0.01
A76: =impostazioni!A76 -> TOT | B76: =B74*B75 -> 0 | C76: =C74*C75 -> 0 | D76: =D74*D75 -> 0 | E76: =E74*E75 -> 0 | F76: =F74*F75 -> 0 | G76: =G74*G75 -> 0 | H76: =H74*H75 -> 0 | I76: =I74*I75 -> 0 | ... P76: =P74*P75 -> 0
A77: =impostazioni!A77 -> TOTALE CASSA | B77: =SUM(B76:P76) -> 0
A79: =impostazioni!A79 -> ULTIMO ACCESSO: | B79: =impostazioni!B79 -> 46071.676 | E79: =impostazioni!E79 -> CONTROLLO FATTO DA: | G79: TEAM2 | H79: FALSE | J79: ELISA Controllo | L79: OK | M79: FALSE | N79: REGIST. | O79: FALSE

Sheet TEAM2-EX
A1: TEAM2 - EXTRA >> SEZIONE A <<
A2: TEAM2 EXTRA | B2: =impostazioni!B2 -> CONTANTE | D2: =impostazioni!D2 -> POS POSTA Recep | F2: =impostazioni!F2 -> CARTA POSTA Recep | H2: =impostazioni!H2 -> POS POSTA 2°P | J2: =impostazioni!J2 -> CARTA POSTA 2°P | L2: =impostazioni!L2 -> POS BPM 1°P | N2: =impostazioni!N2 -> CARTA BPM 1°P | P2: =impostazioni!P2 -> B/B | R2: =impostazioni!R2 -> SEDE SCALAPAY | T2: =impostazioni!T2 -> SEDE SATISPAY | V2: =impostazioni!V2 -> ONLINE TESSERATO | X2: =impostazioni!X2 -> ONLINE NON TESSERATO
A3: =impostazioni!A3 -> N° RICEVUTA | B3: =impostazioni!B3 -> CORSI | C3: =impostazioni!C3 -> QUOTA TESS. | D3: =impostazioni!D3 -> CORSI | E3: =impostazioni!E3 -> QUOTA TESS. | F3: =impostazioni!F3 -> CORSI | G3: =impostazioni!G3 -> QUOTA TESS. | H3: =impostazioni!H3 -> CORSI | ... Y3: =impostazioni!Y3 -> QUOTA TESS.
A35: =impostazioni!A35 -> SUB-TOTALE CORSI DIVISO | B35: =SUM(B4:B34) -> 0 | C35: =SUM(C4:C34) -> 0 | D35: =SUM(D4:D34) -> 0 | E35: =SUM(E4:E34) -> 0 | F35: =SUM(F4:F34) -> 0 | G35: =SUM(G4:G34) -> 0 | H35: =SUM(H4:H34) -> 0 | I35: =SUM(I4:I34) -> 0 | ... Y35: =SUM(Y4:Y34) -> 0
A36: =impostazioni!A36 -> TOTALE CORSI UNITO | B36: =SUM(B35:C35) -> 0 | D36: =SUM(D35:E35) -> 0 | F36: =SUM(F35:G35) -> 0 | H36: =SUM(H35:I35) -> 0 | J36: =SUM(J35:K35) -> 0 | L36: =SUM(L35:M35) -> 0 | N36: =SUM(N35:O35) -> 0 | P36: =SUM(P35:Q35) -> 0 | R36: =SUM(R35:S35) -> 0 | T36: =SUM(T35:U35) -> 0 | V36: =SUM(V35:W35) -> 0 | X36: =SUM(X35:Y35) -> 0
A37: =impostazioni!A37 -> SHOP FATTURE (pagato con Pos)
A38: =impostazioni!A38 -> USCITA CONTANTE | D38: =impostazioni!D38 -> NOTE PER USCITA:
A39: =impostazioni!A39 -> TOTALE CASSA CONTANTE ENTRATE-USCITE | B39: =SUM(B36:Y36-B38) -> 0
A41: TEAM2 - EXTRA >> SEZIONE B <<
A43: =impostazioni!A43 -> N° RIC. BIANCHE VISITE MEDICHE | C43: =impostazioni!C43 -> € | D43: =impostazioni!D43 -> N° RIC. RICEVUTE BIANCHE ALTRO | G43: =impostazioni!G43 -> € | H43: =impostazioni!H43 -> N° RIC. RICEVUTE BIANCHE ALTRO | K43: =impostazioni!K43 -> €
A62: =impostazioni!A62 -> SUB-TOTALE | C62: =SUM(C44:C61) -> 0 | D62: =impostazioni!D62 -> SUB-TOTALE | G62: =SUM(G44:G61) -> 0 | H62: =impostazioni!H62 -> SUB-TOTALE | K62: =SUM(K44:K61) -> 0 | L62: USCITA | N62: TOTALE | O62: =SUM(C62,G62,K62-M62) -> 0
A64: TEAM2 - EXTRA >> SEZIONE C <<
A66: =impostazioni!A66 -> DISTINTA RICEVUTE AZZURRE + BIANCHE | F66: =impostazioni!F66 -> NOTE GENERICHE
A67: =impostazioni!A67 -> TOTALE CONTANTI RIC. AZZURRE | B67: =B36 -> 0
A68: =impostazioni!A68 -> TOTALE CONTANTI RIC. BIANCHE | B68: =SUM(C62,G62,K62) -> 0
A69: =impostazioni!A69 -> USCITA CONTANTE | B69: =SUM(B38+M62) -> 0
A70: =impostazioni!A70 -> TOTALE CASSA | B70: =B67+B68-B69 -> 0 | F70: =IF(B70=B77,"OK","ERRORE") -> OK
A72: TEAM2 - EXTRA >> SEZIONE D <<
A74: =impostazioni!A74 -> PEZZI
A75: =impostazioni!A75 -> TAGLIO | B75: 500 | C75: 200 | D75: 100 | E75: 50 | F75: 20 | G75: 10 | H75: 5 | I75: 2 | J75: 1 | K75: 0.5 | L75: 0.2 | M75: 0.1 | N75: 0.05 | O75: 0.02 | P75: 0.01
A76: =impostazioni!A76 -> TOT | B76: =B74*B75 -> 0 | C76: =C74*C75 -> 0 | D76: =D74*D75 -> 0 | E76: =E74*E75 -> 0 | F76: =F74*F75 -> 0 | G76: =G74*G75 -> 0 | H76: =H74*H75 -> 0 | I76: =I74*I75 -> 0 | ... P76: =P74*P75 -> 0
A77: =impostazioni!A77 -> TOTALE CASSA | B77: =SUM(B76:P76) -> 0
A79: =impostazioni!A79 -> ULTIMO ACCESSO: | B79: =impostazioni!B79 -> 46071.676 | E79: =impostazioni!E79 -> CONTROLLO FATTO DA: | G79: TEAM2 | H79: FALSE | J79: ELISA Controllo | L79: OK | M79: FALSE | N79: REGIST. | O79: FALSE

Sheet GENERALE
A1: CHIUSURA GENERALE | C1: =impostazioni!B2 -> CONTANTE | E1: =impostazioni!D2 -> POS POSTA Recep | G1: =impostazioni!F2 -> CARTA POSTA Recep | I1: =impostazioni!H2 -> POS POSTA 2°P | K1: =impostazioni!J2 -> CARTA POSTA 2°P | M1: =impostazioni!L2 -> POS BPM 1°P | O1: =impostazioni!N2 -> CARTA BPM 1°P | Q1: =impostazioni!P2 -> B/B | S1: =impostazioni!R2 -> SEDE SCALAPAY | U1: =impostazioni!T2 -> SEDE SATISPAY | W1: =impostazioni!V2 -> ONLINE TESSERATO | Y1: =impostazioni!X2 -> ONLINE NON TESSERATO
C2: =impostazioni!B3 -> CORSI | D2: =impostazioni!C3 -> QUOTA TESS. | E2: =impostazioni!D3 -> CORSI | F2: =impostazioni!E3 -> QUOTA TESS. | G2: =impostazioni!F3 -> CORSI | H2: =impostazioni!G3 -> QUOTA TESS. | I2: =impostazioni!H3 -> CORSI | J2: =impostazioni!I3 -> QUOTA TESS. | ... Z2: =impostazioni!Y3 -> QUOTA TESS. | AA2: TOTALI SHOP FATTURE (pagato con POS)
A3: Alexanndra | C3: =Alexandra!B35 -> 0 | D3: =Alexandra!C35 -> 0 | E3: =Alexandra!D35 -> 0 | F3: =Alexandra!E35 -> 0 | G3: =Alexandra!F35 -> 0 | H3: =Alexandra!G35 -> 0 | I3: =Alexandra!H35 -> 0 | J3: =Alexandra!I35 -> 0 | ... Z3: =Alexandra!Y35 -> 0 | AA3: =SUM(Alexandra!D37:N37) -> 0
A4: Alexandra-EXTRA | C4: ='Alexandra-EX'!B35 -> 0 | D4: ='Alexandra-EX'!C35 -> 0 | E4: ='Alexandra-EX'!D35 -> 0 | F4: ='Alexandra-EX'!E35 -> 0 | G4: ='Alexandra-EX'!F35 -> 0 | H4: ='Alexandra-EX'!G35 -> 0 | I4: ='Alexandra-EX'!H35 -> 0 | J4: ='Alexandra-EX'!I35 -> 0 | ... Z4: ='Alexandra-EX'!Y35 -> 0 | AA4: =SUM('Alexandra-EX'!D37:N37) -> 0
A5: Nura | C5: =Nura!B35 -> 0 | D5: =Nura!C35 -> 0 | E5: =Nura!D35 -> 0 | F5: =Nura!E35 -> 0 | G5: =Nura!F35 -> 0 | H5: =Nura!G35 -> 0 | I5: =Nura!H35 -> 0 | J5: =Nura!I35 -> 0 | ... Z5: =Nura!Y35 -> 0 | AA5: =SUM(Nura!D37:N37) -> 0
A6: Nura-EXTRA | C6: ='Nura-EX'!B35 -> 0 | D6: ='Nura-EX'!C35 -> 0 | E6: ='Nura-EX'!D35 -> 0 | F6: ='Nura-EX'!E35 -> 0 | G6: ='Nura-EX'!F35 -> 0 | H6: ='Nura-EX'!G35 -> 0 | I6: ='Nura-EX'!H35 -> 0 | J6: ='Nura-EX'!I35 -> 0 | ... Z6: ='Nura-EX'!Y35 -> 0 | AA6: =SUM('Nura-EX'!D37:N37) -> 0
A7: Giuditta | C7: =Giuditta!B35 -> 0 | D7: =Giuditta!C35 -> 0 | E7: =Giuditta!D35 -> 0 | F7: =Giuditta!E35 -> 0 | G7: =Giuditta!F35 -> 0 | H7: =Giuditta!G35 -> 0 | I7: =Giuditta!H35 -> 0 | J7: =Giuditta!I35 -> 0 | ... Z7: =Giuditta!Y35 -> 0 | AA7: =SUM(Giuditta!D37:N37) -> 0
A8: Giuditta-EXTRA | C8: ='Giuditta-EX'!B35 -> 0 | D8: ='Giuditta-EX'!C35 -> 0 | E8: ='Giuditta-EX'!D35 -> 0 | F8: ='Giuditta-EX'!E35 -> 0 | G8: ='Giuditta-EX'!F35 -> 0 | H8: ='Giuditta-EX'!G35 -> 0 | I8: ='Giuditta-EX'!H35 -> 0 | J8: ='Giuditta-EX'!I35 -> 0 | ... Z8: ='Giuditta-EX'!Y35 -> 0 | AA8: =SUM('Giuditta-EX'!D37:N37) -> 0
A9: Estefany | C9: =Estefany!B35 -> 0 | D9: =Estefany!C35 -> 0 | E9: =Estefany!D35 -> 0 | F9: =Estefany!E35 -> 0 | G9: =Estefany!F35 -> 0 | H9: =Estefany!G35 -> 0 | I9: =Estefany!H35 -> 0 | J9: =Estefany!I35 -> 0 | ... Z9: =Estefany!Y35 -> 0 | AA9: =SUM(Estefany!D37:N37) -> 0
A10: Estefany-EXTRA | C10: ='Estefany-EX'!B35 -> 0 | D10: ='Estefany-EX'!C35 -> 0 | E10: ='Estefany-EX'!D35 -> 0 | F10: ='Estefany-EX'!E35 -> 0 | G10: ='Estefany-EX'!F35 -> 0 | H10: ='Estefany-EX'!G35 -> 0 | I10: ='Estefany-EX'!H35 -> 0 | J10: ='Estefany-EX'!I35 -> 0 | ... Z10: ='Estefany-EX'!Y35 -> 0 | AA10: =SUM('Estefany-EX'!D37:N37) -> 0
A11: TEAM | C11: =TEAM!B35 -> 0 | D11: =TEAM!C35 -> 0 | E11: =TEAM!D35 -> 0 | F11: =TEAM!E35 -> 0 | G11: =TEAM!F35 -> 0 | H11: =TEAM!G35 -> 0 | I11: =TEAM!H35 -> 0 | J11: =TEAM!I35 -> 0 | ... Z11: =TEAM!Y35 -> 0 | AA11: =SUM(TEAM!D37:N37) -> 0
