Workbook

Sheet ALEXANDRA
B1: =elenchi!B2 -> ALEXANDRA | F1: =elenchi!D2 ->  SETTIMANA - B | H1:  DA: | J1: =elenchi!E2 -> LUNEDI 11 A SABATO 16 NOVEMBRE 2024
B2: LUNEDÌ | E2: =IF(AND( OR(COUNT(E4:E9) = 0, SUM(E4:E9) = 60), OR(COUNT(E10:E15) = 0, SUM(E10:E15) = 60), OR(COUNT(E16:E21) = 0, SUM(E16:E21) = 60), OR(COUNT(E22:E27) = 0, SUM(E22:E27) = 60), OR(COUNT(E28:E33) = 0, SUM(E28:E33) = 60), OR(COUNT(E40:E45) = 0, SUM(E40:E45) = 60), OR(COUNT(E46:E51) = 0, SUM(E46:E51) = 60), OR(COUNT(E52:E57) = 0, SUM(E52:E57) = 60), OR(COUNT(E58:E63) = 0, SUM(E58:E63) = 60), OR(COUNT(E64:E69) = 0, SUM(E64:E69) = 60), OR(COUNT(E70:E75) = 0, SUM(E70:E75) = 60), OR(COUNT(E76:E81) = 0, SUM(E76:E81) = 60), OR(COUNT(E82:E87) = 0, SUM(E82:E87) = 60), OR(COUNT(E88:E93) = 0, SUM(E88:E93) = 60), OR(COUNT(E94:E99) = 0, SUM(E94:E99) = 60) ), "OK", "Errore") -> OK | F2: MARTEDÌ | I2: =IF(AND( OR(COUNT(I4:I9) = 0, SUM(I4:I9) = 60), OR(COUNT(I10:I15) = 0, SUM(I10:I15) = 60), OR(COUNT(I16:I21) = 0, SUM(I16:I21) = 60), OR(COUNT(I22:I27) = 0, SUM(I22:I27) = 60), OR(COUNT(I28:I33) = 0, SUM(I28:I33) = 60), OR(COUNT(I40:I45) = 0, SUM(I40:I45) = 60), OR(COUNT(I46:I51) = 0, SUM(I46:I51) = 60), OR(COUNT(I52:I57) = 0, SUM(I52:I57) = 60), OR(COUNT(I58:I63) = 0, SUM(I58:I63) = 60), OR(COUNT(I64:I69) = 0, SUM(I64:I69) = 60), OR(COUNT(I70:I75) = 0, SUM(I70:I75) = 60), OR(COUNT(I76:I81) = 0, SUM(I76:I81) = 60), OR(COUNT(I82:I87) = 0, SUM(I82:I87) = 60), OR(COUNT(I88:I93) = 0, SUM(I88:I93) = 60), OR(COUNT(I94:I99) = 0, SUM(I94:I99) = 60) ), "OK", "Errore") -> OK | J2: MERCOLEDÌ | M2: =IF(AND( OR(COUNT(M4:M9) = 0, SUM(M4:M9) = 60), OR(COUNT(M10:M15) = 0, SUM(M10:M15) = 60), OR(COUNT(M16:M21) = 0, SUM(M16:M21) = 60), OR(COUNT(M22:M27) = 0, SUM(M22:M27) = 60), OR(COUNT(M28:M33) = 0, SUM(M28:M33) = 60), OR(COUNT(M40:M45) = 0, SUM(M40:M45) = 60), OR(COUNT(M46:M51) = 0, SUM(M46:M51) = 60), OR(COUNT(M52:M57) = 0, SUM(M52:M57) = 60), OR(COUNT(M58:M63) = 0, SUM(M58:M63) = 60), OR(COUNT(M64:M69) = 0, SUM(M64:M69) = 60), OR(COUNT(M70:M75) = 0, SUM(M70:M75) = 60), OR(COUNT(M76:M81) = 0, SUM(M76:M81) = 60), OR(COUNT(M82:M87) = 0, SUM(M82:M87) = 60), OR(COUNT(M88:M93) = 0, SUM(M88:M93) = 60), OR(COUNT(M94:M99) = 0, SUM(M94:M99) = 60) ), "OK", "Errore") -> OK | N2: GIOVEDÌ | Q2: =IF(AND( OR(COUNT(Q4:Q9) = 0, SUM(Q4:Q9) = 60), OR(COUNT(Q10:Q15) = 0, SUM(Q10:Q15) = 60), OR(COUNT(Q16:Q21) = 0, SUM(Q16:Q21) = 60), OR(COUNT(Q22:Q27) = 0, SUM(Q22:Q27) = 60), OR(COUNT(Q28:Q33) = 0, SUM(Q28:Q33) = 60), OR(COUNT(Q40:Q45) = 0, SUM(Q40:Q45) = 60), OR(COUNT(Q46:Q51) = 0, SUM(Q46:Q51) = 60), OR(COUNT(Q52:Q57) = 0, SUM(Q52:Q57) = 60), OR(COUNT(Q58:Q63) = 0, SUM(Q58:Q63) = 60), OR(COUNT(Q64:Q69) = 0, SUM(Q64:Q69) = 60), OR(COUNT(Q70:Q75) = 0, SUM(Q70:Q75) = 60), OR(COUNT(Q76:Q81) = 0, SUM(Q76:Q81) = 60), OR(COUNT(Q82:Q87) = 0, SUM(Q82:Q87) = 60), OR(COUNT(Q88:Q93) = 0, SUM(Q88:Q93) = 60), OR(COUNT(Q94:Q99) = 0, SUM(Q94:Q99) = 60) ), "OK", "Errore") -> OK | R2: VENERDÌ | U2: =IF(AND( OR(COUNT(U4:U9) = 0, SUM(U4:U9) = 60), OR(COUNT(U10:U15) = 0, SUM(U10:U15) = 60), OR(COUNT(U16:U21) = 0, SUM(U16:U21) = 60), OR(COUNT(U22:U27) = 0, SUM(U22:U27) = 60), OR(COUNT(U28:U33) = 0, SUM(U28:U33) = 60), OR(COUNT(U40:U45) = 0, SUM(U40:U45) = 60), OR(COUNT(U46:U51) = 0, SUM(U46:U51) = 60), OR(COUNT(U52:U57) = 0, SUM(U52:U57) = 60), OR(COUNT(U58:U63) = 0, SUM(U58:U63) = 60), OR(COUNT(U64:U69) = 0, SUM(U64:U69) = 60), OR(COUNT(U70:U75) = 0, SUM(U70:U75) = 60), OR(COUNT(U76:U81) = 0, SUM(U76:U81) = 60), OR(COUNT(U82:U87) = 0, SUM(U82:U87) = 60), OR(COUNT(U88:U93) = 0, SUM(U88:U93) = 60), OR(COUNT(U94:U99) = 0, SUM(U94:U99) = 60) ), "OK", "Errore") -> OK | V2: SABATO | Y2: =IF(AND( OR(COUNT(Y4:Y9) = 0, SUM(Y4:Y9) = 60), OR(COUNT(Y10:Y15) = 0, SUM(Y10:Y15) = 60), OR(COUNT(Y16:Y21) = 0, SUM(Y16:Y21) = 60), OR(COUNT(Y22:Y27) = 0, SUM(Y22:Y27) = 60), OR(COUNT(Y28:Y33) = 0, SUM(Y28:Y33) = 60), OR(COUNT(Y40:Y45) = 0, SUM(Y40:Y45) = 60), OR(COUNT(Y46:Y51) = 0, SUM(Y46:Y51) = 60), OR(COUNT(Y52:Y57) = 0, SUM(Y52:Y57) = 60), OR(COUNT(Y58:Y63) = 0, SUM(Y58:Y63) = 60), OR(COUNT(Y64:Y69) = 0, SUM(Y64:Y69) = 60), OR(COUNT(Y70:Y75) = 0, SUM(Y70:Y75) = 60), OR(COUNT(Y76:Y81) = 0, SUM(Y76:Y81) = 60), OR(COUNT(Y82:Y87) = 0, SUM(Y82:Y87) = 60), OR(COUNT(Y88:Y93) = 0, SUM(Y88:Y93) = 60), OR(COUNT(Y94:Y99) = 0, SUM(Y94:Y99) = 60) ), "OK", "Errore") -> OK | Z2: DOMENICA | AC2: =IF(AND( OR(COUNT(AC4:AC9) = 0, SUM(AC4:AC9) = 60), OR(COUNT(AC10:AC15) = 0, SUM(AC10:AC15) = 60), OR(COUNT(AC16:AC21) = 0, SUM(AC16:AC21) = 60), OR(COUNT(AC22:AC27) = 0, SUM(AC22:AC27) = 60), OR(COUNT(AC28:AC33) = 0, SUM(AC28:AC33) = 60), OR(COUNT(AC40:AC45) = 0, SUM(AC40:AC45) = 60), OR(COUNT(AC46:AC51) = 0, SUM(AC46:AC51) = 60), OR(COUNT(AC52:AC57) = 0, SUM(AC52:AC57) = 60), OR(COUNT(AC58:AC63) = 0, SUM(AC58:AC63) = 60), OR(COUNT(AC64:AC69) = 0, SUM(AC64:AC69) = 60), OR(COUNT(AC70:AC75) = 0, SUM(AC70:AC75) = 60), OR(COUNT(AC76:AC81) = 0, SUM(AC76:AC81) = 60), OR(COUNT(AC82:AC87) = 0, SUM(AC82:AC87) = 60), OR(COUNT(AC88:AC93) = 0, SUM(AC88:AC93) = 60), OR(COUNT(AC94:AC99) = 0, SUM(AC94:AC99) = 60) ), "OK", "Errore") -> OK
A3: ORA | B3: postazione | C3: attività | D3: quantità | E3: minuti | F3: postazione | G3: attività | H3: quantità | I3: minuti | J3: postazione | K3: attività | L3: quantità | M3: minuti | N3: postazione | O3: attività | P3: quantità | Q3: minuti | R3: postazione | S3: attività | T3: quantità | U3: minuti | V3: postazione | W3: attività | X3: quantità | Y3: minuti | Z3: postazione | AA3: attività | AB3: quantità | AC3: minuti
A4: 07:30 08:30
A10: 08:30 09:30 | J10: PRIMO | K10: controllo fondi cassa per cambi | M10: 10
J11: RECEPTION | K11: estrapolato e inviato Sms per assenza di carlos | M11: 20
J12: RECEPTION | K12: risposto WA staff | M12: 10 | S12: entro alle 9 | U12: 30 | W12: entro alle 9 | Y12: 30
J13: RECEPTION | K13: risposto al Telefono | L13: 4 | M13: 10 | S13: corso safeguarding | U13: 30 | V13: RECEPTION | W13: compilato le schede corsi | Y13: 20
J14: RECEPTION | K14: pagamento affitto | L14: 1 | M14: 10 | W14: preso le presenze | X14: 5 | Y14: 10
J15: RECEPTION
A16: 09:30 10:30 | J16: RECEPTION | K16: risposto WA staff | L16: 1 | M16: 3 | V16: PRIMO | W16: inserito nel db Athena partecipazione | Y16: 20
J17: RECEPTION | K17: informazioni in sede | L17: 3 | M17: 15 | V17: PRIMO | W17: altro..... spiegazione quale certificato serve | X17: 1 | Y17: 5
J18: RECEPTION | K18: risposto al Telefono | L18: 2 | M18: 5 | V18: PRIMO | W18: informazioni in sede | X18: 1 | Y18: 5
J19: RECEPTION | K19: letto, spunta e risposto su Trello | M19: 5 | S19: corso safeguarding | U19: 60 | V19: PRIMO | W19: letto, spunta e risposto su Trello | Y19: 10
J20: RECEPTION | K20: inserito nel db Athena partecipazione | M20: 12 | V20: PRIMO | W20: altro..... seguito il workshop di giulia marino | Y20: 10
J21: RECEPTION | K21: altro..... parlato con tesserata che non gli arrivano i sms | L21: 3 | M21: 20 | V21: PRIMO | W21: preso le presenze | X21: 5 | Y21: 10
A22: 10:30 11:30 | J22: RECEPTION | K22: inserito nel db Athena partecipazione | M22: 60
V23: PRIMO | W23: inserito nel db Athena partecipazione | Y23: 45
S24: corso safeguarding | U24: 60 | V24: PRIMO | W24: preso le presenze | X24: 4 | Y24: 15
A28: 11:30 12:30
J29: RECEPTION | K29: risposto al Telefono | L29: 1 | M29: 5 | V29: PRIMO | W29: preso le presenze | X29: 4 | Y29: 10
J30: RECEPTION | K30: inserito nel db Athena partecipazione | M30: 40 | S30: altro.....corso safeguarding | U30: 60 | V30: PRIMO | W30: risposto al Telefono | X30: 2 | Y30: 10
J31: RECEPTION | K31: chiamato tesserati | M31: 15 | V31: PRIMO | W31: preso le presenze | X31: 4 | Y31: 20
V32: PRIMO | W32: altro..... spiegazione a un tesserato QUALE CERTIFICATO CI SERVE (MACASSO) | X32: 1 | Y32: 20
V33: PRIMO
A34: 12:30 13:30 | J34: RECEPTION | K34: risposto al Telefono | L34: 2 | M34: 15
J35: RECEPTION | K35: altro.....parlato con tesserata che non aveva letto i sms pper l'asenza di carlos | L35: 3 | M35: 20
J36: RECEPTION | K36: inserito nel db Athena partecipazione | M36: 25
G38: entro alle 13 | I38: 30
F39: RECEPTION | G39: letto, spunta e risposto su Trello, | I39: 30
A40: 13:30 14:30 | F40: RECEPTION | G40: prenotato e compilato elenco visite mediche | H40: 3 | I40: 10 | K40: pausa | M40: 30 | N40: RECEPTION | O40: inserito la prenotazione su Bookly | Q40: 5 | V40: PRIMO | W40: prenotato e compilato elenco visite mediche | Y40: 15
F41: RECEPTION | G41: risposto al Telefono | H41: 10 | I41: 25 | J41: RECEPTION | K41: informazioni in sede | M41: 10 | N41: RECEPTION | O41: telefonato per le prove | P41: 4 | Q41: 15 | V41: PRIMO | W41: informazioni in sede | Y41: 10
F42: RECEPTION | G42: info corsi | H42: 2 | I42: 5 | J42: RECEPTION | K42: sistemato corsi mentre inserivo le partecipacioni | M42: 20 | N42: RECEPTION | O42: inserito nel db Athena partecipazione | Q42: 20 | S42: altro.....corso safeguarding | U42: 60 | V42: PRIMO | W42: risposto al Telefono | Y42: 5
F43: RECEPTION | G43: prenotazioni sale | H43: 6 | I43: 10 | N43: RECEPTION | O43: pagamenti certificato medico | P43: 1 | Q43: 20 | V43: PAUSA | Y43: 30
F44: RECEPTION | G44: inserito nel db Athena partecipazione | I44: 10
F45: RECEPTION
A46: 14:30 15:30 | F46: RECEPTION | G46: inserito nel db Athena partecipazione | I46: 10 | J46: RECEPTION | K46: inserito nel db Athena partecipazione | M46: 60 | V46: RECEPTION | W46: altro..... SPIEGAZIONE DELLE ASSENZE DELLE VARIE INSEGNANTI | Y46: 20
F47: RECEPTION | G47: altro..... organizzato e prenotato una lezione individuale | I47: 10 | N47: RECEPTION | O47: altro..... tesseramento | P47: 20 | Q47: 60 | V47: RECEPTION | W47: prenotato e compilato elenco visite mediche | Y47: 10
F48: RECEPTION | G48: pulito e riordinato la postazione | I48: 10 | S48: altro.....corso safeguarding | U48: 60 | V48: RECEPTION | W48: informazioni in sede, iscrizione al corso e preso pagamento | Y48: 20
F49: RECEPTION | G49: stampare domende di tesseramento + allegarle | I49: 10 | V49: RECEPTION | W49: risposto WA staff | Y49: 10
...

Sheet GIUDITTA
B1: =elenchi!B3 -> GIUDITTA | F1: =elenchi!D2 ->  SETTIMANA - B | H1:  DA: | J1: =elenchi!E2 -> LUNEDI 11 A SABATO 16 NOVEMBRE 2024
B2: LUNEDÌ | E2: =IF(AND( OR(COUNT(E4:E9) = 0, SUM(E4:E9) = 60), OR(COUNT(E10:E15) = 0, SUM(E10:E15) = 60), OR(COUNT(E16:E21) = 0, SUM(E16:E21) = 60), OR(COUNT(E22:E27) = 0, SUM(E22:E27) = 60), OR(COUNT(E28:E33) = 0, SUM(E28:E33) = 60), OR(COUNT(E40:E45) = 0, SUM(E40:E45) = 60), OR(COUNT(E46:E51) = 0, SUM(E46:E51) = 60), OR(COUNT(E52:E57) = 0, SUM(E52:E57) = 60), OR(COUNT(E58:E63) = 0, SUM(E58:E63) = 60), OR(COUNT(E64:E69) = 0, SUM(E64:E69) = 60), OR(COUNT(E70:E75) = 0, SUM(E70:E75) = 60), OR(COUNT(E76:E81) = 0, SUM(E76:E81) = 60), OR(COUNT(E82:E87) = 0, SUM(E82:E87) = 60), OR(COUNT(E88:E93) = 0, SUM(E88:E93) = 60), OR(COUNT(E94:E99) = 0, SUM(E94:E99) = 60) ), "OK", "Errore") -> OK | F2: MARTEDÌ | I2: =IF(AND( OR(COUNT(I4:I9) = 0, SUM(I4:I9) = 60), OR(COUNT(I10:I15) = 0, SUM(I10:I15) = 60), OR(COUNT(I16:I21) = 0, SUM(I16:I21) = 60), OR(COUNT(I22:I27) = 0, SUM(I22:I27) = 60), OR(COUNT(I28:I33) = 0, SUM(I28:I33) = 60), OR(COUNT(I40:I45) = 0, SUM(I40:I45) = 60), OR(COUNT(I46:I51) = 0, SUM(I46:I51) = 60), OR(COUNT(I52:I57) = 0, SUM(I52:I57) = 60), OR(COUNT(I58:I63) = 0, SUM(I58:I63) = 60), OR(COUNT(I64:I69) = 0, SUM(I64:I69) = 60), OR(COUNT(I70:I75) = 0, SUM(I70:I75) = 60), OR(COUNT(I76:I81) = 0, SUM(I76:I81) = 60), OR(COUNT(I82:I87) = 0, SUM(I82:I87) = 60), OR(COUNT(I88:I93) = 0, SUM(I88:I93) = 60), OR(COUNT(I94:I99) = 0, SUM(I94:I99) = 60) ), "OK", "Errore") -> OK | J2: MERCOLEDÌ | M2: =IF(AND( OR(COUNT(M4:M9) = 0, SUM(M4:M9) = 60), OR(COUNT(M10:M15) = 0, SUM(M10:M15) = 60), OR(COUNT(M16:M21) = 0, SUM(M16:M21) = 60), OR(COUNT(M22:M27) = 0, SUM(M22:M27) = 60), OR(COUNT(M28:M33) = 0, SUM(M28:M33) = 60), OR(COUNT(M40:M45) = 0, SUM(M40:M45) = 60), OR(COUNT(M46:M51) = 0, SUM(M46:M51) = 60), OR(COUNT(M52:M57) = 0, SUM(M52:M57) = 60), OR(COUNT(M58:M63) = 0, SUM(M58:M63) = 60), OR(COUNT(M64:M69) = 0, SUM(M64:M69) = 60), OR(COUNT(M70:M75) = 0, SUM(M70:M75) = 60), OR(COUNT(M76:M81) = 0, SUM(M76:M81) = 60), OR(COUNT(M82:M87) = 0, SUM(M82:M87) = 60), OR(COUNT(M88:M93) = 0, SUM(M88:M93) = 60), OR(COUNT(M94:M99) = 0, SUM(M94:M99) = 60) ), "OK", "Errore") -> OK | N2: GIOVEDÌ | Q2: =IF(AND( OR(COUNT(Q4:Q9) = 0, SUM(Q4:Q9) = 60), OR(COUNT(Q10:Q15) = 0, SUM(Q10:Q15) = 60), OR(COUNT(Q16:Q21) = 0, SUM(Q16:Q21) = 60), OR(COUNT(Q22:Q27) = 0, SUM(Q22:Q27) = 60), OR(COUNT(Q28:Q33) = 0, SUM(Q28:Q33) = 60), OR(COUNT(Q40:Q45) = 0, SUM(Q40:Q45) = 60), OR(COUNT(Q46:Q51) = 0, SUM(Q46:Q51) = 60), OR(COUNT(Q52:Q57) = 0, SUM(Q52:Q57) = 60), OR(COUNT(Q58:Q63) = 0, SUM(Q58:Q63) = 60), OR(COUNT(Q64:Q69) = 0, SUM(Q64:Q69) = 60), OR(COUNT(Q70:Q75) = 0, SUM(Q70:Q75) = 60), OR(COUNT(Q76:Q81) = 0, SUM(Q76:Q81) = 60), OR(COUNT(Q82:Q87) = 0, SUM(Q82:Q87) = 60), OR(COUNT(Q88:Q93) = 0, SUM(Q88:Q93) = 60), OR(COUNT(Q94:Q99) = 0, SUM(Q94:Q99) = 60) ), "OK", "Errore") -> OK | R2: VENERDÌ | U2: =IF(AND( OR(COUNT(U4:U9) = 0, SUM(U4:U9) = 60), OR(COUNT(U10:U15) = 0, SUM(U10:U15) = 60), OR(COUNT(U16:U21) = 0, SUM(U16:U21) = 60), OR(COUNT(U22:U27) = 0, SUM(U22:U27) = 60), OR(COUNT(U28:U33) = 0, SUM(U28:U33) = 60), OR(COUNT(U40:U45) = 0, SUM(U40:U45) = 60), OR(COUNT(U46:U51) = 0, SUM(U46:U51) = 60), OR(COUNT(U52:U57) = 0, SUM(U52:U57) = 60), OR(COUNT(U58:U63) = 0, SUM(U58:U63) = 60), OR(COUNT(U64:U69) = 0, SUM(U64:U69) = 60), OR(COUNT(U70:U75) = 0, SUM(U70:U75) = 60), OR(COUNT(U76:U81) = 0, SUM(U76:U81) = 60), OR(COUNT(U82:U87) = 0, SUM(U82:U87) = 60), OR(COUNT(U88:U93) = 0, SUM(U88:U93) = 60), OR(COUNT(U94:U99) = 0, SUM(U94:U99) = 60) ), "OK", "Errore") -> OK | V2: SABATO | Y2: =IF(AND( OR(COUNT(Y4:Y9) = 0, SUM(Y4:Y9) = 60), OR(COUNT(Y10:Y15) = 0, SUM(Y10:Y15) = 60), OR(COUNT(Y16:Y21) = 0, SUM(Y16:Y21) = 60), OR(COUNT(Y22:Y27) = 0, SUM(Y22:Y27) = 60), OR(COUNT(Y28:Y33) = 0, SUM(Y28:Y33) = 60), OR(COUNT(Y40:Y45) = 0, SUM(Y40:Y45) = 60), OR(COUNT(Y46:Y51) = 0, SUM(Y46:Y51) = 60), OR(COUNT(Y52:Y57) = 0, SUM(Y52:Y57) = 60), OR(COUNT(Y58:Y63) = 0, SUM(Y58:Y63) = 60), OR(COUNT(Y64:Y69) = 0, SUM(Y64:Y69) = 60), OR(COUNT(Y70:Y75) = 0, SUM(Y70:Y75) = 60), OR(COUNT(Y76:Y81) = 0, SUM(Y76:Y81) = 60), OR(COUNT(Y82:Y87) = 0, SUM(Y82:Y87) = 60), OR(COUNT(Y88:Y93) = 0, SUM(Y88:Y93) = 60), OR(COUNT(Y94:Y99) = 0, SUM(Y94:Y99) = 60) ), "OK", "Errore") -> OK | Z2: DOMENICA | AC2: =IF(AND( OR(COUNT(AC4:AC9) = 0, SUM(AC4:AC9) = 60), OR(COUNT(AC10:AC15) = 0, SUM(AC10:AC15) = 60), OR(COUNT(AC16:AC21) = 0, SUM(AC16:AC21) = 60), OR(COUNT(AC22:AC27) = 0, SUM(AC22:AC27) = 60), OR(COUNT(AC28:AC33) = 0, SUM(AC28:AC33) = 60), OR(COUNT(AC40:AC45) = 0, SUM(AC40:AC45) = 60), OR(COUNT(AC46:AC51) = 0, SUM(AC46:AC51) = 60), OR(COUNT(AC52:AC57) = 0, SUM(AC52:AC57) = 60), OR(COUNT(AC58:AC63) = 0, SUM(AC58:AC63) = 60), OR(COUNT(AC64:AC69) = 0, SUM(AC64:AC69) = 60), OR(COUNT(AC70:AC75) = 0, SUM(AC70:AC75) = 60), OR(COUNT(AC76:AC81) = 0, SUM(AC76:AC81) = 60), OR(COUNT(AC82:AC87) = 0, SUM(AC82:AC87) = 60), OR(COUNT(AC88:AC93) = 0, SUM(AC88:AC93) = 60), OR(COUNT(AC94:AC99) = 0, SUM(AC94:AC99) = 60) ), "OK", "Errore") -> OK
A3: ORA | B3: postazione | C3: attività | D3: quantità | E3: minuti | F3: postazione | G3: attività | H3: quantità | I3: minuti | J3: postazione | K3: attività | L3: quantità | M3: minuti | N3: postazione | O3: attività | P3: quantità | Q3: minuti | R3: postazione | S3: attività | T3: quantità | U3: minuti | V3: postazione | W3: attività | X3: quantità | Y3: minuti | Z3: postazione | AA3: attività | AB3: quantità | AC3: minuti
A4: 07:30 08:30
A10: 08:30 09:30
A16: 09:30 10:30
A22: 10:30 11:30
A28: 11:30 12:30
A34: 12:30 13:30
A40: 13:30 14:30 | R40: PRIMO | S40: letto, spunta e risposto su Trello | U40: 5
R41: PRIMO | S41: informazioni in sede | T41: 1 | U41: 5
R42: PRIMO | S42: estrapolato e inviato Email | T42: 5539 | U42: 40
R43: PRIMO | S43: altro.....preparato email Misha | U43: 10
A46: 14:30 15:30 | B46: SECONDO | C46: altro..... riunione | E46: 30 | F46: PRIMO | G46: risposto alle Email | H46: 6 | I46: 15 | J46: PRIMO | K46: controllato bonifico sbagliato | L46: 1 | M46: 5 | N46: PRIMO | O46: inserito nel db Athena partecipazione | P46: 24 | Q46: 45 | R46: PRIMO | S46: altro.....preparato email Misha | U46: 10
F47: PRIMO | G47: altro.....ricerca certificati medici in archivio | H47: 3 | I47: 15 | J47: PRIMO | K47: altro.....inviata mail per bonifico di reso | L47: 1 | M47: 5 | N47: PRIMO | O47: compilato le schede corsi | P47: 10 | Q47: 15 | R47: PRIMO | S47: altro.....pulizia mail doppie per invio | U47: 10
B48: PRIMO | C48: estrapolato e inviato Email | D48: 444 | E48: 30 | F48: PRIMO | G48: inserito nel db Athena partecipazione | H48: 10 | I48: 30 | J48: PRIMO | K48: altro.....inserito il nominativo della persona nel corso richiesto | L48: 1 | M48: 5 | R48: PRIMO | S48: altro.....ricerca di un certificato medico | U48: 30
J49: PRIMO | K49: altro.....fatta ricevuta bonifico workshop | L49: 1 | M49: 5 | R49: SECONDO | S49: inserito nel db Athena partecipazione | T49: 4 | U49: 10
J50: PRIMO | K50: letto, spunta e risposto su Trello | L50: 1 | M50: 5
J51: PRIMO | K51: altro.....ricevute bonifici e inserimento nei corsi | L51: 4 | M51: 35
A52: 15:30 16:30 | B52: PRIMO | C52: estrapolato e inviato Email | E52: 30 | F52: PERMESSO | I52: 30 | J52: PRIMO | K52: inserito nel db Ahena anagrafica | L52: 4 | M52: 15 | N52: PRIMO | O52: inserito nel db Athena partecipazione | P52: 16 | Q52: 20 | R52: SECONDO | S52: altro.....ricerca di un pagamento nelle ricevute di giugno | U52: 15
F53: PRIMO | G53: inserito nel db Athena partecipazione | H53: 7 | I53: 15 | J53: PRIMO | K53: inserito nel db Athena partecipazione | L53: 4 | M53: 15 | N53: PRIMO | O53: inserito nel db Athena partecipazione | P53: 5 | Q53: 15 | R53: SECONDO | S53: letto, spunta e risposto su Trello | U53: 5
F54: PRIMO | G54: preso le presenze | I54: 15 | J54: PRIMO | K54: preso le presenze | L54: 1 | M54: 15 | N54: PRIMO | O54: altro.....risoluzione problema con una mamma | Q54: 25 | R54: SECONDO | S54: inserito nel db Athena partecipazione | T54: 2 | U54: 5
B55: PRIMO | C55: estrapolato e inviato Sms | D55: 445 | E55: 30 | J55: PRIMO | K55: risposto alle Email | L55: 5 | M55: 15 | R55: SECONDO | S55: letto, spunta e risposto su Trello | U55: 10
B56: PRIMO | C56: preso le presenze | D56: 2 | R56: SECONDO | S56: inserito nel db Athena partecipazione | T56: 10 | U56: 25
A58: 16:30 17:30 | B58: PRIMO | C58: inserito nel db Athena partecipazione | D58: 3 | E58: 15 | F58: PRIMO | G58: inserito nel db Athena partecipazione | H58: 13 | I58: 45 | J58: PRIMO | K58: risposto alle Email | M58: 20 | N58: PRIMO | O58: inserito nel db Athena partecipazione | Q58: 30 | R58: SECONDO | S58: inserito la prenotazione su Bookly | T58: 1 | U58: 5
B59: PRIMO | C59: altro.....ricerca di un certificato medico | D59: 1 | E59: 15 | F59: PRIMO | G59: preso le presenze | H59: 4 | I59: 15 | J59: PRIMO | K59: preso le presenze | L59: 4 | M59: 15 | N59: PRIMO | O59: preso le presenze | Q59: 30 | R59: SECONDO | S59: preso le presenze | T59: 15 | U59: 20
B60: PRIMO | C60: preso le presenze | D60: 4 | E60: 30 | J60: PRIMO | K60: compilato le schede corsi | L60: 3 | M60: 15 | R60: SECONDO | S60: estrapolato e inviato Email | T60: 300 | U60: 25
J61: PRIMO | K61: letto, spunta e risposto su Trello | L61: 1 | M61: 1 | R61: SECONDO | S61: compilato le schede corsi | T61: 5 | U61: 10
J62: PRIMO | K62: altro.....inseriti bonifici nelle chiusure | L62: 4 | M62: 4
J63: PRIMO | K63: letto, spunta e risposto su Trello | M63: 5
A64: 17:30 18:30 | B64: RECEPTION | C64: informazioni in sede, iscrizione ws/eventi e preso pagamento | D64: 1 | E64: 10 | F64: PRIMO | G64: compilato le schede corsi | H64: 2 | I64: 5 | J64: PRIMO | K64: informazioni in sede, iscrizione a lezioni private e preso pagamento | L64: 1 | M64: 15 | N64: PRIMO | O64: altro.....organizzazione lezione privata | P64: 1 | Q64: 15 | R64: SECONDO | S64: estrapolato e inviato Email | T64: 300 | U64: 30
C65: informazioni in sede, iscrizione ws/eventi e preso pagamento | D65: 1 | E65: 10 | F65: PRIMO | G65: inserito nel db Ahena anagrafica | H65: 1 | I65: 5 | J65: PRIMO | K65: preso le presenze | L65: 10 | M65: 5 | N65: PRIMO | O65: preso le presenze | Q65: 15 | R65: PAUSA | U65: 30
B66: RECEPTION | C66: inserito la prenotazione su Bookly | D66: 2 | E66: 5 | F66: PRIMO | G66: inserito nel db Athena partecipazione | H66: 5 | I66: 10 | J66: PRIMO | K66: letto, spunta e risposto su Trello | L66: 2 | M66: 5 | N66: RECEPTION | O66: informazioni in sede | P66: 1 | Q66: 15
B67: RECEPTION | C67: inserito nel db Athena partecipazione | D67: 2 | E67: 5 | F67: PRIMO | G67: preso le presenze | H67: 4 | I67: 15 | J67: RECEPTION | K67: prenotato e compilato elenco visite mediche | L67: 2 | M67: 15 | N67: RECEPTION | O67: inserito nel db Athena partecipazione | P67: 2 | Q67: 10
B68: PAUSA | E68: 30 | F68: PRIMO | G68: inserito nel db Athena partecipazione | H68: 5 | I68: 10 | J68: RECEPTION | K68: informazioni in sede | L68: 2 | M68: 20 | N68: RECEPTION | O68: inserito la prenotazione su Bookly | P68: 1 | Q68: 5
F69: PRIMO | G69: prenotato e compilato elenco visite mediche | H69: 3 | I69: 15
A70: 18:30 19:30 | B70: PRIMO | C70: prenotato e compilato elenco visite mediche | D70: 3 | E70: 15 | F70: PRIMO | G70: informazioni in sede, iscrizione al corso e preso pagamento | H70: 3 | I70: 30 | J70: PAUSA | M70: 30 | N70: PAUSA | Q70: 30 | R70: PRIMO | S70: preso le presenze | T70: 23 | U70: 15
C71: preso le presenze | D71: 4 | E71: 15 | J71: PRIMO | K71: preso le presenze | M71: 30 | N71: RECEPTION | O71: inserito nel db Athena partecipazione | P71: 2 | Q71: 10 | R71: PRIMO | S71: informazioni in sede | T71: 2 | U71: 10
B72: SECONDO | C72: preso le presenze | D72: 5 | E72: 15 | F72: PAUSA | I72: 30 | N72: RECEPTION | O72: informazioni in sede, iscrizione al corso e preso pagamento | P72: 3 | Q72: 20 | R72: PRIMO | S72: preso le presenze | T72: 40 | U72: 25
B73: SECONDO | C73: inserito nel db Athena partecipazione | D73: 2 | E73: 5 | R73: PRIMO | S73: risposto alle Email
...

Sheet ESTEFANY
B1: =elenchi!B4 -> ESTEFANY | F1: =elenchi!D2 ->  SETTIMANA - B | H1:  DA: | J1: =elenchi!E2 -> LUNEDI 11 A SABATO 16 NOVEMBRE 2024
B2: LUNEDÌ | E2: =IF(AND( OR(COUNT(E4:E9) = 0, SUM(E4:E9) = 60), OR(COUNT(E10:E15) = 0, SUM(E10:E15) = 60), OR(COUNT(E16:E21) = 0, SUM(E16:E21) = 60), OR(COUNT(E22:E27) = 0, SUM(E22:E27) = 60), OR(COUNT(E28:E33) = 0, SUM(E28:E33) = 60), OR(COUNT(E40:E45) = 0, SUM(E40:E45) = 60), OR(COUNT(E46:E51) = 0, SUM(E46:E51) = 60), OR(COUNT(E52:E57) = 0, SUM(E52:E57) = 60), OR(COUNT(E58:E63) = 0, SUM(E58:E63) = 60), OR(COUNT(E64:E69) = 0, SUM(E64:E69) = 60), OR(COUNT(E70:E75) = 0, SUM(E70:E75) = 60), OR(COUNT(E76:E81) = 0, SUM(E76:E81) = 60), OR(COUNT(E82:E87) = 0, SUM(E82:E87) = 60), OR(COUNT(E88:E93) = 0, SUM(E88:E93) = 60), OR(COUNT(E94:E99) = 0, SUM(E94:E99) = 60) ), "OK", "Errore") -> OK | F2: MARTEDÌ | I2: =IF(AND( OR(COUNT(I4:I9) = 0, SUM(I4:I9) = 60), OR(COUNT(I10:I15) = 0, SUM(I10:I15) = 60), OR(COUNT(I16:I21) = 0, SUM(I16:I21) = 60), OR(COUNT(I22:I27) = 0, SUM(I22:I27) = 60), OR(COUNT(I28:I33) = 0, SUM(I28:I33) = 60), OR(COUNT(I40:I45) = 0, SUM(I40:I45) = 60), OR(COUNT(I46:I51) = 0, SUM(I46:I51) = 60), OR(COUNT(I52:I57) = 0, SUM(I52:I57) = 60), OR(COUNT(I58:I63) = 0, SUM(I58:I63) = 60), OR(COUNT(I64:I69) = 0, SUM(I64:I69) = 60), OR(COUNT(I70:I75) = 0, SUM(I70:I75) = 60), OR(COUNT(I76:I81) = 0, SUM(I76:I81) = 60), OR(COUNT(I82:I87) = 0, SUM(I82:I87) = 60), OR(COUNT(I88:I93) = 0, SUM(I88:I93) = 60), OR(COUNT(I94:I99) = 0, SUM(I94:I99) = 60) ), "OK", "Errore") -> OK | J2: MERCOLEDÌ | M2: =IF(AND( OR(COUNT(M4:M9) = 0, SUM(M4:M9) = 60), OR(COUNT(M10:M15) = 0, SUM(M10:M15) = 60), OR(COUNT(M16:M21) = 0, SUM(M16:M21) = 60), OR(COUNT(M22:M27) = 0, SUM(M22:M27) = 60), OR(COUNT(M28:M33) = 0, SUM(M28:M33) = 60), OR(COUNT(M40:M45) = 0, SUM(M40:M45) = 60), OR(COUNT(M46:M51) = 0, SUM(M46:M51) = 60), OR(COUNT(M52:M57) = 0, SUM(M52:M57) = 60), OR(COUNT(M58:M63) = 0, SUM(M58:M63) = 60), OR(COUNT(M64:M69) = 0, SUM(M64:M69) = 60), OR(COUNT(M70:M75) = 0, SUM(M70:M75) = 60), OR(COUNT(M76:M81) = 0, SUM(M76:M81) = 60), OR(COUNT(M82:M87) = 0, SUM(M82:M87) = 60), OR(COUNT(M88:M93) = 0, SUM(M88:M93) = 60), OR(COUNT(M94:M99) = 0, SUM(M94:M99) = 60) ), "OK", "Errore") -> OK | N2: GIOVEDÌ | Q2: =IF(AND( OR(COUNT(Q4:Q9) = 0, SUM(Q4:Q9) = 60), OR(COUNT(Q10:Q15) = 0, SUM(Q10:Q15) = 60), OR(COUNT(Q16:Q21) = 0, SUM(Q16:Q21) = 60), OR(COUNT(Q22:Q27) = 0, SUM(Q22:Q27) = 60), OR(COUNT(Q28:Q33) = 0, SUM(Q28:Q33) = 60), OR(COUNT(Q40:Q45) = 0, SUM(Q40:Q45) = 60), OR(COUNT(Q46:Q51) = 0, SUM(Q46:Q51) = 60), OR(COUNT(Q52:Q57) = 0, SUM(Q52:Q57) = 60), OR(COUNT(Q58:Q63) = 0, SUM(Q58:Q63) = 60), OR(COUNT(Q64:Q69) = 0, SUM(Q64:Q69) = 60), OR(COUNT(Q70:Q75) = 0, SUM(Q70:Q75) = 60), OR(COUNT(Q76:Q81) = 0, SUM(Q76:Q81) = 60), OR(COUNT(Q82:Q87) = 0, SUM(Q82:Q87) = 60), OR(COUNT(Q88:Q93) = 0, SUM(Q88:Q93) = 60), OR(COUNT(Q94:Q99) = 0, SUM(Q94:Q99) = 60) ), "OK", "Errore") -> OK | R2: VENERDÌ | U2: =IF(AND( OR(COUNT(U4:U9) = 0, SUM(U4:U9) = 60), OR(COUNT(U10:U15) = 0, SUM(U10:U15) = 60), OR(COUNT(U16:U21) = 0, SUM(U16:U21) = 60), OR(COUNT(U22:U27) = 0, SUM(U22:U27) = 60), OR(COUNT(U28:U33) = 0, SUM(U28:U33) = 60), OR(COUNT(U40:U45) = 0, SUM(U40:U45) = 60), OR(COUNT(U46:U51) = 0, SUM(U46:U51) = 60), OR(COUNT(U52:U57) = 0, SUM(U52:U57) = 60), OR(COUNT(U58:U63) = 0, SUM(U58:U63) = 60), OR(COUNT(U64:U69) = 0, SUM(U64:U69) = 60), OR(COUNT(U70:U75) = 0, SUM(U70:U75) = 60), OR(COUNT(U76:U81) = 0, SUM(U76:U81) = 60), OR(COUNT(U82:U87) = 0, SUM(U82:U87) = 60), OR(COUNT(U88:U93) = 0, SUM(U88:U93) = 60), OR(COUNT(U94:U99) = 0, SUM(U94:U99) = 60) ), "OK", "Errore") -> OK | V2: SABATO | Y2: =IF(AND( OR(COUNT(Y4:Y9) = 0, SUM(Y4:Y9) = 60), OR(COUNT(Y10:Y15) = 0, SUM(Y10:Y15) = 60), OR(COUNT(Y16:Y21) = 0, SUM(Y16:Y21) = 60), OR(COUNT(Y22:Y27) = 0, SUM(Y22:Y27) = 60), OR(COUNT(Y28:Y33) = 0, SUM(Y28:Y33) = 60), OR(COUNT(Y40:Y45) = 0, SUM(Y40:Y45) = 60), OR(COUNT(Y46:Y51) = 0, SUM(Y46:Y51) = 60), OR(COUNT(Y52:Y57) = 0, SUM(Y52:Y57) = 60), OR(COUNT(Y58:Y63) = 0, SUM(Y58:Y63) = 60), OR(COUNT(Y64:Y69) = 0, SUM(Y64:Y69) = 60), OR(COUNT(Y70:Y75) = 0, SUM(Y70:Y75) = 60), OR(COUNT(Y76:Y81) = 0, SUM(Y76:Y81) = 60), OR(COUNT(Y82:Y87) = 0, SUM(Y82:Y87) = 60), OR(COUNT(Y88:Y93) = 0, SUM(Y88:Y93) = 60), OR(COUNT(Y94:Y99) = 0, SUM(Y94:Y99) = 60) ), "OK", "Errore") -> OK | Z2: DOMENICA | AC2: =IF(AND( OR(COUNT(AC4:AC9) = 0, SUM(AC4:AC9) = 60), OR(COUNT(AC10:AC15) = 0, SUM(AC10:AC15) = 60), OR(COUNT(AC16:AC21) = 0, SUM(AC16:AC21) = 60), OR(COUNT(AC22:AC27) = 0, SUM(AC22:AC27) = 60), OR(COUNT(AC28:AC33) = 0, SUM(AC28:AC33) = 60), OR(COUNT(AC40:AC45) = 0, SUM(AC40:AC45) = 60), OR(COUNT(AC46:AC51) = 0, SUM(AC46:AC51) = 60), OR(COUNT(AC52:AC57) = 0, SUM(AC52:AC57) = 60), OR(COUNT(AC58:AC63) = 0, SUM(AC58:AC63) = 60), OR(COUNT(AC64:AC69) = 0, SUM(AC64:AC69) = 60), OR(COUNT(AC70:AC75) = 0, SUM(AC70:AC75) = 60), OR(COUNT(AC76:AC81) = 0, SUM(AC76:AC81) = 60), OR(COUNT(AC82:AC87) = 0, SUM(AC82:AC87) = 60), OR(COUNT(AC88:AC93) = 0, SUM(AC88:AC93) = 60), OR(COUNT(AC94:AC99) = 0, SUM(AC94:AC99) = 60) ), "OK", "Errore") -> OK
A3: ORA | B3: postazione | C3: attività | D3: quantità | E3: minuti | F3: postazione | G3: attività | H3: quantità | I3: minuti | J3: postazione | K3: attività | L3: quantità | M3: minuti | N3: postazione | O3: attività | P3: quantità | Q3: minuti | R3: postazione | S3: attività | T3: quantità | U3: minuti | V3: postazione | W3: attività | X3: quantità | Y3: minuti | Z3: postazione | AA3: attività | AB3: quantità | AC3: minuti
A4: 07:30 08:30
A10: 08:30 09:30 | B10: RECEPTION | C10: altro..... | E10: 30 | N10: PRIMO | O10: altro..... preparazione postazione | Q10: 5
B11: PRIMO | C11: risposto alle Email | D11: 2 | E11: 30 | N11: PRIMO | O11: risposto alle Email | P11: 4 | Q11: 15
N12: PRIMO | O12: preso le presenze | P12: 1 | Q12: 10
N13: PRIMO | O13: risposto al Telefono | P13: 3 | Q13: 15
N14: PRIMO | O14: altro.....assistenza Giada | Q14: 5
N15: PRIMO | O15: preso le presenze | P15: 1 | Q15: 10
A16: 09:30 10:30 | B16: PRIMO | C16: risposto al Telefono | D16: 2 | E16: 15 | N16: PRIMO | O16: estrapolato e inviato Sms | Q16: 8
B17: PRIMO | C17: risposto alle Email | D17: 3 | E17: 15 | N17: PRIMO | O17: risposto alle Email | P17: 4 | Q17: 10
B18: PRIMO | C18: altro.....Assistenga giada | D18: 2 | E18: 10 | O18: inserito la prenotazione su Bookly | P18: 4 | Q18: 14
B19: PRIMO | C19: altro.....controllo workshop brasil. | D19: 2 | E19: 15 | N19: PRIMO | O19: risposto al Telefono | P19: 2 | Q19: 8
B20: PRIMO | C20: letto, spunta e risposto su Trello | D20: 3 | E20: 5 | N20: PRIMO | O20: altro.....assistenza Giada | Q20: 10
N21: PRIMO | O21: compilato le schede corsi | P21: 3 | Q21: 10
A22: 10:30 11:30 | B22: PRIMO | C22: risposto al Telefono | D22: 2 | E22: 15 | N22: PRIMO | O22: risposto alle Email | P22: 6 | Q22: 30
B23: PRIMO | C23: preso le presenze | D23: 1 | E23: 15 | N23: PRIMO | O23: altro.....assistenza Giada | P23: 2 | Q23: 5
B24: PRIMO | C24: altro.....Assistenga giada | D24: 3 | E24: 10 | N24: PRIMO | O24: risposto al Telefono | P24: 3 | Q24: 20
B25: PRIMO | C25: risposto alle Email | D25: 4 | E25: 20 | N25: PAUSA | Q25: 5
A28: 11:30 12:30 | B28: PRIMO | C28: risposto al Telefono | D28: 2 | E28: 10 | N28: PRIMO | O28: risposto alle Email | P28: 3 | Q28: 20
B29: PRIMO | C29: preso le presenze | D29: 1 | E29: 15 | N29: PRIMO | O29: informazioni in sede | P29: 2 | Q29: 10
B30: PRIMO | C30: preso le presenze | D30: 3 | E30: 10 | N30: PRIMO | O30: letto, spunta e risposto su Trello | P30: 7 schede | Q30: 15
B31: PRIMO | C31: risposto alle Email | D31: 3 | E31: 15 | N31: PRIMO | O31: altro.....assistenza Giada | P31: 4 errori | Q31: 15
B32: PRIMO | C32: altro..... | E32: 10
A34: 12:30 13:30 | B34: PRIMO | C34: altro.....assistenza giada | E34: 20 | N34: PRIMO | O34: altro..... archivio | P34: 20 fogli | Q34: 60
B35: PRIMO | C35: risposto al Telefono | D35: 5 | E35: 20
B36: PRIMO | C36: altro.....assistenza corsi | D36: 2 | E36: 20
A40: 13:30 14:30 | B40: RECEPTION | C40: risposto al Telefono | D40: 3 | E40: 10 | F40: PRIMO | G40: pulito e riordinato la postazione | H40: 1 | I40: 3 | J40: RECEPTION | K40: altro..... entrata alle 13 | M40: 5 | N40: PRIMO | O40: preso le presenze | P40: 2 | Q40: 15 | R40: RECEPTION | S40: pulito e riordinato la postazione | U40: 10
B41: RECEPTION | C41: risposto WA staff | D41: 3 | E41: 8 | F41: PRIMO | G41: letto, spunta e risposto su Trello | H41: 8 | I41: 5 | J41: RECEPTION | K41: letto, spunta e risposto su Trello | L41: 5 schede | M41: 10 | N41: PAUSA | Q41: 30 | R41: RECEPTION | S41: inserito nel db Athena partecipazione | T41: 5 schede | U41: 15
B42: RECEPTION | C42: inserito la prenotazione su Bookly | D42: 3 | E42: 8 | F42: PRIMO | G42: risposto al Telefono | H42: 1 | I42: 2 | J42: RECEPTION | K42: risposto al Telefono | L42: 7 | M42: 20 | N42: PRIMO | O42: altro.....sistemazione e spostamento | Q42: 15 | R42: RECEPTION | S42: risposto WA staff | T42: 3 | U42: 10
B43: RECEPTION | C43: altro.....ricevute prove | D43: 10 | E43: 10 | F43: PRIMO | G43: altro.....ARCHIVIO | I43: 50 | J43: RECEPTION | K43: altro..... ricevuta+athena+inserimento workshop | L43: 6 | M43: 25 | R43: RECEPTION | S43: informazioni in sede | T43: 2 | U43: 15
B44: RECEPTION | C44: informazioni in sede | D44: 3 | E44: 10 | R44: RECEPTION | S44: telefonato per le prove | T44: 4 | U44: 10
E45: 14
A46: 14:30 15:30 | B46: RIUNIONE | C46: altro..... | E46: 30 | F46: PRIMO | G46: altro.....ARCHIVIO | I46: 60 | J46: RECEPTION | K46: inserito la prenotazione su Bookly | L46: 3 | M46: 8 | N46: RECEPTION | O46: altro.....file prove provvisiorio | P46: 26 righe | Q46: 30 | R46: RECEPTION | S46: estrapolato e inviato Sms | T46: misha | U46: 20
B47: RECEPTION | C47: altro..... file prove provvisorio | D47: 10 righe | E47: 30 | J47: RECEPTION | K47: risposto al Telefono | L47: 2 | M47: 15 | N47: RECEPTION | O47: informazioni in sede | P47: 3 | Q47: 15 | R47: RECEPTION | S47: estrapolato e inviato Sms | T47: meta natale | U47: 10
J48: RECEPTION | K48: altro.....assistenza cliente (errori,spostamenti) | L48: 3 | M48: 19 | N48: RECEPTION | O48: altro..... sistemazione info richieste della sera prima | P48: 2 persone | Q48: 15 | R48: RECEPTION | S48: risposto WA staff | T48: 2 | U48: 3
J49: RECEPTION | K49: risposto WA staff | L49: 2 | M49: 10 | S49: inserito la prenotazione su Bookly | T49: 2 | U49: 3
J50: RECEPTION | K50: informazioni in sede | L50: 2 | M50: 8 | R50: RECEPTION | S50: altro.....controllo sms | T50: 24 | U50: 14
R51: RECEPTION | S51: informazioni in sede | T51: 2 | U51: 10
...

Sheet NURA
B1: =elenchi!B5 -> NURA | F1: =elenchi!D2 ->  SETTIMANA - B | H1:  DA: | J1: =elenchi!E2 -> LUNEDI 11 A SABATO 16 NOVEMBRE 2024
B2: LUNEDÌ | E2: =IF(AND( OR(COUNT(E4:E9) = 0, SUM(E4:E9) = 60), OR(COUNT(E10:E15) = 0, SUM(E10:E15) = 60), OR(COUNT(E16:E21) = 0, SUM(E16:E21) = 60), OR(COUNT(E22:E27) = 0, SUM(E22:E27) = 60), OR(COUNT(E28:E33) = 0, SUM(E28:E33) = 60), OR(COUNT(E40:E45) = 0, SUM(E40:E45) = 60), OR(COUNT(E46:E51) = 0, SUM(E46:E51) = 60), OR(COUNT(E52:E57) = 0, SUM(E52:E57) = 60), OR(COUNT(E58:E63) = 0, SUM(E58:E63) = 60), OR(COUNT(E64:E69) = 0, SUM(E64:E69) = 60), OR(COUNT(E70:E75) = 0, SUM(E70:E75) = 60), OR(COUNT(E76:E81) = 0, SUM(E76:E81) = 60), OR(COUNT(E82:E87) = 0, SUM(E82:E87) = 60), OR(COUNT(E88:E93) = 0, SUM(E88:E93) = 60), OR(COUNT(E94:E99) = 0, SUM(E94:E99) = 60) ), "OK", "Errore") -> OK | F2: MARTEDÌ | I2: =IF(AND( OR(COUNT(I4:I9) = 0, SUM(I4:I9) = 60), OR(COUNT(I10:I15) = 0, SUM(I10:I15) = 60), OR(COUNT(I16:I21) = 0, SUM(I16:I21) = 60), OR(COUNT(I22:I27) = 0, SUM(I22:I27) = 60), OR(COUNT(I28:I33) = 0, SUM(I28:I33) = 60), OR(COUNT(I40:I45) = 0, SUM(I40:I45) = 60), OR(COUNT(I46:I51) = 0, SUM(I46:I51) = 60), OR(COUNT(I52:I57) = 0, SUM(I52:I57) = 60), OR(COUNT(I58:I63) = 0, SUM(I58:I63) = 60), OR(COUNT(I64:I69) = 0, SUM(I64:I69) = 60), OR(COUNT(I70:I75) = 0, SUM(I70:I75) = 60), OR(COUNT(I76:I81) = 0, SUM(I76:I81) = 60), OR(COUNT(I82:I87) = 0, SUM(I82:I87) = 60), OR(COUNT(I88:I93) = 0, SUM(I88:I93) = 60), OR(COUNT(I94:I99) = 0, SUM(I94:I99) = 60) ), "OK", "Errore") -> OK | J2: MERCOLEDÌ | M2: =IF(AND( OR(COUNT(M4:M9) = 0, SUM(M4:M9) = 60), OR(COUNT(M10:M15) = 0, SUM(M10:M15) = 60), OR(COUNT(M16:M21) = 0, SUM(M16:M21) = 60), OR(COUNT(M22:M27) = 0, SUM(M22:M27) = 60), OR(COUNT(M28:M33) = 0, SUM(M28:M33) = 60), OR(COUNT(M40:M45) = 0, SUM(M40:M45) = 60), OR(COUNT(M46:M51) = 0, SUM(M46:M51) = 60), OR(COUNT(M52:M57) = 0, SUM(M52:M57) = 60), OR(COUNT(M58:M63) = 0, SUM(M58:M63) = 60), OR(COUNT(M64:M69) = 0, SUM(M64:M69) = 60), OR(COUNT(M70:M75) = 0, SUM(M70:M75) = 60), OR(COUNT(M76:M81) = 0, SUM(M76:M81) = 60), OR(COUNT(M82:M87) = 0, SUM(M82:M87) = 60), OR(COUNT(M88:M93) = 0, SUM(M88:M93) = 60), OR(COUNT(M94:M99) = 0, SUM(M94:M99) = 60) ), "OK", "Errore") -> OK | N2: GIOVEDÌ | Q2: =IF(AND( OR(COUNT(Q4:Q9) = 0, SUM(Q4:Q9) = 60), OR(COUNT(Q10:Q15) = 0, SUM(Q10:Q15) = 60), OR(COUNT(Q16:Q21) = 0, SUM(Q16:Q21) = 60), OR(COUNT(Q22:Q27) = 0, SUM(Q22:Q27) = 60), OR(COUNT(Q28:Q33) = 0, SUM(Q28:Q33) = 60), OR(COUNT(Q40:Q45) = 0, SUM(Q40:Q45) = 60), OR(COUNT(Q46:Q51) = 0, SUM(Q46:Q51) = 60), OR(COUNT(Q52:Q57) = 0, SUM(Q52:Q57) = 60), OR(COUNT(Q58:Q63) = 0, SUM(Q58:Q63) = 60), OR(COUNT(Q64:Q69) = 0, SUM(Q64:Q69) = 60), OR(COUNT(Q70:Q75) = 0, SUM(Q70:Q75) = 60), OR(COUNT(Q76:Q81) = 0, SUM(Q76:Q81) = 60), OR(COUNT(Q82:Q87) = 0, SUM(Q82:Q87) = 60), OR(COUNT(Q88:Q93) = 0, SUM(Q88:Q93) = 60), OR(COUNT(Q94:Q99) = 0, SUM(Q94:Q99) = 60) ), "OK", "Errore") -> OK | R2: VENERDÌ | U2: =IF(AND( OR(COUNT(U4:U9) = 0, SUM(U4:U9) = 60), OR(COUNT(U10:U15) = 0, SUM(U10:U15) = 60), OR(COUNT(U16:U21) = 0, SUM(U16:U21) = 60), OR(COUNT(U22:U27) = 0, SUM(U22:U27) = 60), OR(COUNT(U28:U33) = 0, SUM(U28:U33) = 60), OR(COUNT(U40:U45) = 0, SUM(U40:U45) = 60), OR(COUNT(U46:U51) = 0, SUM(U46:U51) = 60), OR(COUNT(U52:U57) = 0, SUM(U52:U57) = 60), OR(COUNT(U58:U63) = 0, SUM(U58:U63) = 60), OR(COUNT(U64:U69) = 0, SUM(U64:U69) = 60), OR(COUNT(U70:U75) = 0, SUM(U70:U75) = 60), OR(COUNT(U76:U81) = 0, SUM(U76:U81) = 60), OR(COUNT(U82:U87) = 0, SUM(U82:U87) = 60), OR(COUNT(U88:U93) = 0, SUM(U88:U93) = 60), OR(COUNT(U94:U99) = 0, SUM(U94:U99) = 60) ), "OK", "Errore") -> OK | V2: SABATO | Y2: =IF(AND( OR(COUNT(Y4:Y9) = 0, SUM(Y4:Y9) = 60), OR(COUNT(Y10:Y15) = 0, SUM(Y10:Y15) = 60), OR(COUNT(Y16:Y21) = 0, SUM(Y16:Y21) = 60), OR(COUNT(Y22:Y27) = 0, SUM(Y22:Y27) = 60), OR(COUNT(Y28:Y33) = 0, SUM(Y28:Y33) = 60), OR(COUNT(Y40:Y45) = 0, SUM(Y40:Y45) = 60), OR(COUNT(Y46:Y51) = 0, SUM(Y46:Y51) = 60), OR(COUNT(Y52:Y57) = 0, SUM(Y52:Y57) = 60), OR(COUNT(Y58:Y63) = 0, SUM(Y58:Y63) = 60), OR(COUNT(Y64:Y69) = 0, SUM(Y64:Y69) = 60), OR(COUNT(Y70:Y75) = 0, SUM(Y70:Y75) = 60), OR(COUNT(Y76:Y81) = 0, SUM(Y76:Y81) = 60), OR(COUNT(Y82:Y87) = 0, SUM(Y82:Y87) = 60), OR(COUNT(Y88:Y93) = 0, SUM(Y88:Y93) = 60), OR(COUNT(Y94:Y99) = 0, SUM(Y94:Y99) = 60) ), "OK", "Errore") -> Errore | Z2: DOMENICA | AC2: =IF(AND( OR(COUNT(AC4:AC9) = 0, SUM(AC4:AC9) = 60), OR(COUNT(AC10:AC15) = 0, SUM(AC10:AC15) = 60), OR(COUNT(AC16:AC21) = 0, SUM(AC16:AC21) = 60), OR(COUNT(AC22:AC27) = 0, SUM(AC22:AC27) = 60), OR(COUNT(AC28:AC33) = 0, SUM(AC28:AC33) = 60), OR(COUNT(AC40:AC45) = 0, SUM(AC40:AC45) = 60), OR(COUNT(AC46:AC51) = 0, SUM(AC46:AC51) = 60), OR(COUNT(AC52:AC57) = 0, SUM(AC52:AC57) = 60), OR(COUNT(AC58:AC63) = 0, SUM(AC58:AC63) = 60), OR(COUNT(AC64:AC69) = 0, SUM(AC64:AC69) = 60), OR(COUNT(AC70:AC75) = 0, SUM(AC70:AC75) = 60), OR(COUNT(AC76:AC81) = 0, SUM(AC76:AC81) = 60), OR(COUNT(AC82:AC87) = 0, SUM(AC82:AC87) = 60), OR(COUNT(AC88:AC93) = 0, SUM(AC88:AC93) = 60), OR(COUNT(AC94:AC99) = 0, SUM(AC94:AC99) = 60) ), "OK", "Errore") -> OK
A3: ORA | B3: postazione | C3: attività | D3: quantità | E3: minuti | F3: postazione | G3: attività | H3: quantità | I3: minuti | J3: postazione | K3: attività | L3: quantità | M3: minuti | N3: postazione | O3: attività | P3: quantità | Q3: minuti | R3: postazione | S3: attività | T3: quantità | U3: minuti | V3: postazione | W3: attività | X3: quantità | Y3: minuti | Z3: postazione | AA3: attività | AB3: quantità | AC3: minuti
A4: 07:30 08:30
A10: 08:30 09:30 | F10: RECEPTION | G10: letto, spunta e risposto su Trello | I10: 5 | N10: RECEPTION | O10: letto, spunta e risposto su Trello | Q10: 5 | V10: RECEPTION | W10: letto, spunta e risposto su Trello | Y10: 1
F11: RECEPTION | G11: inserito nel db Athena partecipazione | I11: 25 | N11: RECEPTION | O11: risposto al Telefono | P11: 5 | Q11: 15 | V11: RECEPTION | W11: inserito nel db Athena partecipazione | Y11: 29
F12: RECEPTION | G12: inserito nel db Ahena anagrafica | H12: 6 | I12: 25 | N12: RECEPTION | O12: inserito nel db Ahena anagrafica | P12: 4 | Q12: 30
F13: RECEPTION | G13: risposto al Telefono | H13: 2 | I13: 5 | N13: RECEPTION | O13: risposto WA staff | Q13: 5
N14: RECEPTION | O14: inserito la prenotazione su Bookly | Q14: 5
A16: 09:30 10:30 | F16: RECEPTION | G16: inserito nel db Ahena anagrafica | H16: 7 | I16: 30 | N16: RECEPTION | O16: compilato le schede corsi | Q16: 30 | V16: RECEPTION | W16: altro.. mandato sms assenza insegnante | Y16: 30
F17: RECEPTION | G17: risposto al Telefono | H17: 5 | I17: 15 | N17: RECEPTION | O17: risposto WA staff | Q17: 15 | V17: RECEPTION | W17: informazioni in sede | Y17: 15
F18: RECEPTION | G18: compilato le schede corsi | I18: 15 | N18: RECEPTION | O18: risposto al Telefono | P18: 3 | Q18: 15 | V18: RECEPTION | W18: risposto al Telefono | X18: 2 | Y18: 15
A22: 10:30 11:30 | F22: RECEPTION | G22: risposto al Telefono | H22: 9 | I22: 15 | N22: RECEPTION | O22: inserito nel db Ahena anagrafica | Q22: 30 | V22: RECEPTION | W22: altro. mandato sms assenza insegante | Y22: 15
F23: RECEPTION | G23: inserito nel db Ahena anagrafica | I23: 30 | N23: RECEPTION | O23: compilato le schede corsi | Q23: 30 | V23: RECEPTION | W23: risposto al Telefono | X23: 6 | Y23: 15
F24: RECEPTION | G24: inserito la prenotazione su Bookly | I24: 15 | V24: RECEPTION | W24: inserito nel db Ahena anagrafica | Y24: 30
A28: 11:30 12:30 | F28: RECEPTION | G28: inserito nel db Ahena anagrafica | I28: 45 | N28: RECEPTION | O28: risposto al Telefono | P28: 5 | Q28: 30 | V28: RECEPTION | W28: altro..pagamento prove e inserimento su athena | X28: 6 | Y28: 30
F29: RECEPTION | G29: risposto al Telefono | H29: 4 | I29: 15 | N29: RECEPTION | O29: inserito nel db Ahena anagrafica | Q29: 30 | V29: RECEPTION | W29: inserito nel db Ahena anagrafica | Y29: 30
A34: 12:30 13:30
A40: 13:30 14:30 | B40: PRIMO | C40: letto, spunta e risposto su Trello | E40: 10 | F40: PAUSA | I40: 30 | N40: PAUSA | Q40: 30 | R40: PRIMO | S40: letto, spunta e risposto su Trello | U40: 5 | V40: RECEPTION | W40: informazioni in sede, iscrizione al corso e preso pagamento | Y40: 30
B41: PRIMO | C41: informazioni in sede, iscrizione al corso e preso pagamento | D41: 1 | E41: 10 | F41: PRIMO | G41: risposto alle Email | H41: 7 | I41: 30 | N41: PRIMO | O41: risposto alle Email | P41: 9 | Q41: 30 | R41: PRIMO | S41: risposto alle Email | T41: 10 | U41: 55 | V41: PAUSA | Y41: 30
B42: PRIMO | C42: risposto al Telefono | D42: 45385 | E42: 10
B43: PRIMO | C43: Ricevuta per detrazione | D43: 1 | E43: 10
B44: PRIMO | C44: inserimento ricevute generiche | E44: 10
B45: PRIMO | C45: inserimento ricevute generiche | E45: 10
A46: 14:30 15:30 | B46: RIUNIONE | E46: 30 | F46: PRIMO | G46: altro : risposto email feedback negativo | H46: 1 | I46: 20 | J46: PRIMO | K46: letto, spunta e risposto su Trello | M46: 5 | N46: PRIMO | O46: risposto alle Email | P46: 5 | Q46: 30 | R46: PRIMO | S46: estrapolato e inviato Sms | U46: 20 | V46: PRIMO | W46: preso le presenze | Y46: 30
B47: PRIMO | C47: risposto alle Email | D47: 6 | E47: 30 | F47: PRIMO | G47: risposto alle Email | H47: 3 | I47: 20 | J47: PRIMO | K47: risposto alle Email | L47: 8 | M47: 55 | N47: PRIMO | O47: altro... inserimento cceritficati medici stampati | P47: 4 | Q47: 30 | R47: PRIMO | S47: risposto alle Email | U47: 40 | V47: PRIMO | W47: informazioni in sede, iscrizione ws/eventi e preso pagamento | Y47: 30
F48: PRIMO | G48: compilato le schede corsi | I48: 20
A52: 15:30 16:30 | B52: PRIMO | C52: risposto alle Email | D52: 5 | E52: 45 | F52: SECONDO | G52: risposto alle Email | H52: 10 | I52: 45 | J52: RECEPTION | K52: inserito la prenotazione su Bookly | L52: 6 | M52: 45 | N52: PRIMO | O52: risposto alle Email | P52: 4 | Q52: 30 | R52: PRIMO | S52: altro. esposoto volantini festa natale desk1-desk2 | U52: 5 | V52: PRIMO | W52: preso le presenze | Y52: 15
B53: PRIMO | C53: preso le presenze | D53: 2 | E53: 5 | F53: SECONDO | G53: preso le presenze | H53: 1 | I53: 5 | J53: RECEPTION | K53: informazioni in sede | M53: 15 | N53: PRIMO | O53: altro..organizzazione lez privata | Q53: 15 | R53: PRIMO | S53: risposto alle Email | U53: 25 | V53: PRIMO | W53: inserito nel db Ahena anagrafica | Y53: 15
B54: PRIMO | C54: altro.....pagamento quota tes | D54: 1 | E54: 10 | F54: SECONDO | G54: Chiusura giornaliera e pulito desk | I54: 10 | N54: PRIMO | O54: altro. chiusura contabile | Q54: 15 | R54: PRIMO | S54: inserito nel db Ahena anagrafica | U54: 30 | V54: PRIMO | W54: inserito nel db Athena partecipazione | Y54: 30
A58: 16:30 17:30 | B58: PRIMO | C58: risposto alle Email | D58: 7 | E58: 30 | J58: RECEPTION | K58: inserito la prenotazione su Bookly | M58: 30 | R58: PRIMO | S58: risposto alle Email | U58: 45 | V58: PRIMO | W58: compilato le schede corsi | Y58: 30
B59: RECEPTION | C59: informazioni in sede, iscrizione al corso e preso pagamento | E59: 15 | J59: RECEPTION | K59: risposto WA staff | M59: 30 | R59: PRIMO | S59: preso le presenze | U59: 15 | V59: PRIMO | W59: altro..infomazioni festa natale | Y59: 15
B60: RECEPTION | C60: prenotato e compilato elenco visite mediche | E60: 15 | V60: PRIMO | W60: altro.. chiusura e pulizia desk | Y60: 15
A64: 17:30 18:30 | B64: PAUSA | E64: 30 | R64: PRIMO | S64: risposto alle Email | U64: 20
B65: RECEPTION | C65: informazioni in sede, iscrizione al corso e preso pagamento | E65: 30 | J65: RECEPTION | K65: compilato le schede corsi | M65: 30 | R65: PRIMO | S65: inserito nel db Ahena anagrafica | U65: 40
J66: RECEPTION | K66: informazioni in sede | M66: 30
A70: 18:30 19:30 | B70: RECEPTION | C70: informazioni in sede, iscrizione al corso e preso pagamento | E70: 30 | J70: RECEPTION | K70: informazioni in sede, iscrizione al corso e preso pagamento | M70: 30 | R70: PAUSA | U70: 30
B71: RECEPTION | C71: inserito nel db Athena partecipazione | E71: 15 | J71: PAUSA | M71: 30 | R71: RECEPTION | S71: informazioni in sede | U71: 15
B72: RECEPTION | C72: informazioni in sede, iscrizione al corso e preso pagamento | E72: 15 | R72: RECEPTION | S72: informazioni in sede, iscrizione al corso e preso pagamento | U72: 15
A76: 19:30 20:30 | B76: RECEPTION | C76: informazioni in sede, iscrizione al corso e preso pagamento | E76: 60 | J76: RECEPTION | K76: informazioni in sede, iscrizione al corso e preso pagamento | M76: 30 | R76: RECEPTION | S76: informazioni in sede, iscrizione al corso e preso pagamento | U76: 60
...

Sheet VITTORIO
B1: =elenchi!B6 -> VITTORIO | F1: =elenchi!D2 ->  SETTIMANA - B | H1:  DA: | J1: =elenchi!E2 -> LUNEDI 11 A SABATO 16 NOVEMBRE 2024
B2: LUNEDÌ | E2: =IF(AND( OR(COUNT(E4:E9) = 0, SUM(E4:E9) = 60), OR(COUNT(E10:E15) = 0, SUM(E10:E15) = 60), OR(COUNT(E16:E21) = 0, SUM(E16:E21) = 60), OR(COUNT(E22:E27) = 0, SUM(E22:E27) = 60), OR(COUNT(E28:E33) = 0, SUM(E28:E33) = 60), OR(COUNT(E40:E45) = 0, SUM(E40:E45) = 60), OR(COUNT(E46:E51) = 0, SUM(E46:E51) = 60), OR(COUNT(E52:E57) = 0, SUM(E52:E57) = 60), OR(COUNT(E58:E63) = 0, SUM(E58:E63) = 60), OR(COUNT(E64:E69) = 0, SUM(E64:E69) = 60), OR(COUNT(E70:E75) = 0, SUM(E70:E75) = 60), OR(COUNT(E76:E81) = 0, SUM(E76:E81) = 60), OR(COUNT(E82:E87) = 0, SUM(E82:E87) = 60), OR(COUNT(E88:E93) = 0, SUM(E88:E93) = 60), OR(COUNT(E94:E99) = 0, SUM(E94:E99) = 60) ), "OK", "Errore") -> OK | F2: MARTEDÌ | I2: =IF(AND( OR(COUNT(I4:I9) = 0, SUM(I4:I9) = 60), OR(COUNT(I10:I15) = 0, SUM(I10:I15) = 60), OR(COUNT(I16:I21) = 0, SUM(I16:I21) = 60), OR(COUNT(I22:I27) = 0, SUM(I22:I27) = 60), OR(COUNT(I28:I33) = 0, SUM(I28:I33) = 60), OR(COUNT(I40:I45) = 0, SUM(I40:I45) = 60), OR(COUNT(I46:I51) = 0, SUM(I46:I51) = 60), OR(COUNT(I52:I57) = 0, SUM(I52:I57) = 60), OR(COUNT(I58:I63) = 0, SUM(I58:I63) = 60), OR(COUNT(I64:I69) = 0, SUM(I64:I69) = 60), OR(COUNT(I70:I75) = 0, SUM(I70:I75) = 60), OR(COUNT(I76:I81) = 0, SUM(I76:I81) = 60), OR(COUNT(I82:I87) = 0, SUM(I82:I87) = 60), OR(COUNT(I88:I93) = 0, SUM(I88:I93) = 60), OR(COUNT(I94:I99) = 0, SUM(I94:I99) = 60) ), "OK", "Errore") -> OK | J2: MERCOLEDÌ | M2: =IF(AND( OR(COUNT(M4:M9) = 0, SUM(M4:M9) = 60), OR(COUNT(M10:M15) = 0, SUM(M10:M15) = 60), OR(COUNT(M16:M21) = 0, SUM(M16:M21) = 60), OR(COUNT(M22:M27) = 0, SUM(M22:M27) = 60), OR(COUNT(M28:M33) = 0, SUM(M28:M33) = 60), OR(COUNT(M40:M45) = 0, SUM(M40:M45) = 60), OR(COUNT(M46:M51) = 0, SUM(M46:M51) = 60), OR(COUNT(M52:M57) = 0, SUM(M52:M57) = 60), OR(COUNT(M58:M63) = 0, SUM(M58:M63) = 60), OR(COUNT(M64:M69) = 0, SUM(M64:M69) = 60), OR(COUNT(M70:M75) = 0, SUM(M70:M75) = 60), OR(COUNT(M76:M81) = 0, SUM(M76:M81) = 60), OR(COUNT(M82:M87) = 0, SUM(M82:M87) = 60), OR(COUNT(M88:M93) = 0, SUM(M88:M93) = 60), OR(COUNT(M94:M99) = 0, SUM(M94:M99) = 60) ), "OK", "Errore") -> OK | N2: GIOVEDÌ | Q2: =IF(AND( OR(COUNT(Q4:Q9) = 0, SUM(Q4:Q9) = 60), OR(COUNT(Q10:Q15) = 0, SUM(Q10:Q15) = 60), OR(COUNT(Q16:Q21) = 0, SUM(Q16:Q21) = 60), OR(COUNT(Q22:Q27) = 0, SUM(Q22:Q27) = 60), OR(COUNT(Q28:Q33) = 0, SUM(Q28:Q33) = 60), OR(COUNT(Q40:Q45) = 0, SUM(Q40:Q45) = 60), OR(COUNT(Q46:Q51) = 0, SUM(Q46:Q51) = 60), OR(COUNT(Q52:Q57) = 0, SUM(Q52:Q57) = 60), OR(COUNT(Q58:Q63) = 0, SUM(Q58:Q63) = 60), OR(COUNT(Q64:Q69) = 0, SUM(Q64:Q69) = 60), OR(COUNT(Q70:Q75) = 0, SUM(Q70:Q75) = 60), OR(COUNT(Q76:Q81) = 0, SUM(Q76:Q81) = 60), OR(COUNT(Q82:Q87) = 0, SUM(Q82:Q87) = 60), OR(COUNT(Q88:Q93) = 0, SUM(Q88:Q93) = 60), OR(COUNT(Q94:Q99) = 0, SUM(Q94:Q99) = 60) ), "OK", "Errore") -> OK | R2: VENERDÌ | U2: =IF(AND( OR(COUNT(U4:U9) = 0, SUM(U4:U9) = 60), OR(COUNT(U10:U15) = 0, SUM(U10:U15) = 60), OR(COUNT(U16:U21) = 0, SUM(U16:U21) = 60), OR(COUNT(U22:U27) = 0, SUM(U22:U27) = 60), OR(COUNT(U28:U33) = 0, SUM(U28:U33) = 60), OR(COUNT(U40:U45) = 0, SUM(U40:U45) = 60), OR(COUNT(U46:U51) = 0, SUM(U46:U51) = 60), OR(COUNT(U52:U57) = 0, SUM(U52:U57) = 60), OR(COUNT(U58:U63) = 0, SUM(U58:U63) = 60), OR(COUNT(U64:U69) = 0, SUM(U64:U69) = 60), OR(COUNT(U70:U75) = 0, SUM(U70:U75) = 60), OR(COUNT(U76:U81) = 0, SUM(U76:U81) = 60), OR(COUNT(U82:U87) = 0, SUM(U82:U87) = 60), OR(COUNT(U88:U93) = 0, SUM(U88:U93) = 60), OR(COUNT(U94:U99) = 0, SUM(U94:U99) = 60) ), "OK", "Errore") -> OK | V2: SABATO | Y2: =IF(AND( OR(COUNT(Y4:Y9) = 0, SUM(Y4:Y9) = 60), OR(COUNT(Y10:Y15) = 0, SUM(Y10:Y15) = 60), OR(COUNT(Y16:Y21) = 0, SUM(Y16:Y21) = 60), OR(COUNT(Y22:Y27) = 0, SUM(Y22:Y27) = 60), OR(COUNT(Y28:Y33) = 0, SUM(Y28:Y33) = 60), OR(COUNT(Y40:Y45) = 0, SUM(Y40:Y45) = 60), OR(COUNT(Y46:Y51) = 0, SUM(Y46:Y51) = 60), OR(COUNT(Y52:Y57) = 0, SUM(Y52:Y57) = 60), OR(COUNT(Y58:Y63) = 0, SUM(Y58:Y63) = 60), OR(COUNT(Y64:Y69) = 0, SUM(Y64:Y69) = 60), OR(COUNT(Y70:Y75) = 0, SUM(Y70:Y75) = 60), OR(COUNT(Y76:Y81) = 0, SUM(Y76:Y81) = 60), OR(COUNT(Y82:Y87) = 0, SUM(Y82:Y87) = 60), OR(COUNT(Y88:Y93) = 0, SUM(Y88:Y93) = 60), OR(COUNT(Y94:Y99) = 0, SUM(Y94:Y99) = 60) ), "OK", "Errore") -> OK | Z2: DOMENICA | AC2: =IF(AND( OR(COUNT(AC4:AC9) = 0, SUM(AC4:AC9) = 60), OR(COUNT(AC10:AC15) = 0, SUM(AC10:AC15) = 60), OR(COUNT(AC16:AC21) = 0, SUM(AC16:AC21) = 60), OR(COUNT(AC22:AC27) = 0, SUM(AC22:AC27) = 60), OR(COUNT(AC28:AC33) = 0, SUM(AC28:AC33) = 60), OR(COUNT(AC40:AC45) = 0, SUM(AC40:AC45) = 60), OR(COUNT(AC46:AC51) = 0, SUM(AC46:AC51) = 60), OR(COUNT(AC52:AC57) = 0, SUM(AC52:AC57) = 60), OR(COUNT(AC58:AC63) = 0, SUM(AC58:AC63) = 60), OR(COUNT(AC64:AC69) = 0, SUM(AC64:AC69) = 60), OR(COUNT(AC70:AC75) = 0, SUM(AC70:AC75) = 60), OR(COUNT(AC76:AC81) = 0, SUM(AC76:AC81) = 60), OR(COUNT(AC82:AC87) = 0, SUM(AC82:AC87) = 60), OR(COUNT(AC88:AC93) = 0, SUM(AC88:AC93) = 60), OR(COUNT(AC94:AC99) = 0, SUM(AC94:AC99) = 60) ), "OK", "Errore") -> OK
A3: ORA | B3: postazione | C3: attività | D3: quantità | E3: minuti | F3: postazione | G3: attività | H3: quantità | I3: minuti | J3: postazione | K3: attività | L3: quantità | M3: minuti | N3: postazione | O3: attività | P3: quantità | Q3: minuti | R3: postazione | S3: attività | T3: quantità | U3: minuti | V3: postazione | W3: attività | X3: quantità | Y3: minuti | Z3: postazione | AA3: attività | AB3: quantità | AC3: minuti
A4: 07:30 08:30 | F4: STUDIO 1 | G4: letto, spunta e risposto su Trello | I4: 10 | R4: RECEPTION | S4: informazioni in sede | U4: 60
F5: STUDIO 1 | G5: risposto alle Email | I5: 50
A10: 08:30 09:30 | F10: STUDIO 1 | G10: preso le presenze | I10: 30 | R10: RECEPTION | S10: informazioni in sede | U10: 60
F11: STUDIO 1 | G11: risposto alle Email | I11: 30
A16: 09:30 10:30 | F16: STUDIO 1 | G16: risposto alle Email | I16: 60 | R16: RECEPTION | S16: informazioni in sede | U16: 60
A22: 10:30 11:30 | F22: STUDIO 1 | G22: risposto alle Email | I22: 60 | R22: RECEPTION | S22: informazioni in sede | U22: 60
A28: 11:30 12:30 | F28: STUDIO 1 | G28: risposto alle Email | I28: 60 | R28: RECEPTION | S28: informazioni in sede | U28: 60
A34: 12:30 13:30
A40: 13:30 14:30 | F40: STUDIO 1 | G40: risposto alle Email | I40: 60 | R40: RECEPTION | S40: informazioni in sede | U40: 60
A46: 14:30 15:30 | B46: STUDIO 1 | C46: letto, spunta e risposto su Trello | D46: 2 | E46: 5 | F46: STUDIO 1 | G46: risposto alle Email | I46: 30 | J46: STUDIO 1 | K46: letto, spunta e risposto su Trello | M46: 10 | N46: STUDIO 1 | O46: letto, spunta e risposto su Trello | Q46: 10 | R46: STUDIO 1 | S46: estrapolato e inviato Email 1200 | U46: 60
B47: STUDIO 1 | C47: inserito nel db Athena partecipazione | E47: 10 | F47: STUDIO 1 | G47: informazioni in sede, iscrizione ws/eventi e preso pagamento | I47: 30 | J47: STUDIO 1 | K47: risposto alle Email | M47: 50 | N47: STUDIO 1 | O47: informazioni in sede, iscrizione ws/eventi e preso pagamento | Q47: 50
B48: STUDIO 1 | C48: inserito nel db Athena partecipazione | E48: 10
B49: STUDIO 1 | C49: inserito nel db Athena partecipazione | E49: 10
B50: STUDIO 1 | C50: inserito nel db Athena partecipazione | E50: 10
B51: STUDIO 1 | C51: inserito nel db Athena partecipazione | E51: 15
A52: 15:30 16:30 | B52: STUDIO 1 | C52: inserito nel db Athena partecipazione | E52: 10 | F52: STUDIO 1 | G52: informazioni in sede, iscrizione ws/eventi e preso pagamento | I52: 30 | J52: STUDIO 1 | K52: risposto alle Email | M52: 60 | N52: STUDIO 1 | O52: informazioni in sede, iscrizione ws/eventi e preso pagamento | Q52: 60 | R52: STUDIO 1 | S52: estrapolato e inviato Email 1200 | U52: 60
B53: STUDIO 1 | C53: inserito nel db Athena partecipazione | E53: 10 | F53: STUDIO 1 | G53: informazioni in sede, iscrizione ws/eventi e preso pagamento | I53: 30
B54: STUDIO 1 | C54: inserito nel db Athena partecipazione | E54: 10
B55: STUDIO 1 | C55: inserito nel db Athena partecipazione | E55: 10
B56: STUDIO 1 | C56: inserito nel db Athena partecipazione | E56: 10
B57: STUDIO 1 | C57: inserito nel db Athena partecipazione | E57: 10
A58: 16:30 17:30 | B58: STUDIO 1 | C58: inserito nel db Athena partecipazione | E58: 10 | F58: STUDIO 1 | G58: informazioni in sede, iscrizione ws/eventi e preso pagamento | I58: 60 | J58: STUDIO 1 | K58: preso le presenze | M58: 30 | N58: STUDIO 1 | O58: preso le presenze | Q58: 30 | R58: STUDIO 1 | S58: estrapolato e inviato Email 1200 | U58: 60
B59: STUDIO 1 | C59: inserito nel db Athena partecipazione | E59: 10 | J59: STUDIO 1 | K59: inserito nel db Ahena anagrafica | M59: 30 | N59: STUDIO 1 | O59: inserito nel db Ahena anagrafica | Q59: 30
B60: STUDIO 1 | C60: inserito nel db Athena partecipazione | E60: 10
B61: STUDIO 1 | C61: inserito nel db Athena partecipazione | E61: 10
B62: STUDIO 1 | C62: inserito nel db Athena partecipazione | E62: 10
B63: STUDIO 1 | C63: inserito nel db Athena partecipazione | E63: 10
A64: 17:30 18:30 | B64: STUDIO 1 | C64: altro.....attivita' di reception varie (iscrizioni presenze info ecc) | E64: 60 | J64: STUDIO 1 | K64: informazioni in sede, iscrizione ws/eventi e preso pagamento | M64: 60 | N64: STUDIO 1 | O64: informazioni in sede, iscrizione ws/eventi e preso pagamento | Q64: 60
A70: 18:30 19:30 | B70: STUDIO 1 | C70: altro.....attivita' di reception varie (iscrizioni presenze info ecc) | E70: 60 | J70: STUDIO 1 | K70: altro.....informazioni in sede, iscrizione ws/eventi e preso pagamento | M70: 60 | N70: STUDIO 1 | O70: altro.....informazioni in sede, iscrizione ws/eventi e preso pagamento | Q70: 60
A76: 19:30 20:30 | B76: STUDIO 1 | C76: altro.....attivita' di reception varie (iscrizioni presenze info ecc) | E76: 60 | J76: STUDIO 1 | K76: altro.....informazioni in sede, iscrizione ws/eventi e preso pagamento | M76: 60 | N76: STUDIO 1 | O76: altro.....informazioni in sede, iscrizione ws/eventi e preso pagamento | Q76: 60
A82: 20:30 21:30 | B82: STUDIO 1 | C82: altro.....attivita' di reception varie (iscrizioni presenze info ecc) | E82: 60 | J82: STUDIO 1 | K82: altro.....informazioni in sede, iscrizione ws/eventi e preso pagamento | M82: 60 | N82: STUDIO 1 | O82: altro.....informazioni in sede, iscrizione ws/eventi e preso pagamento | Q82: 60
A88: 21:30 22:30 | B88: STUDIO 1 | C88: altro.....attivita' di reception varie (iscrizioni presenze info ecc) | E88: 60 | J88: STUDIO 1 | K88: altro.....informazioni in sede, iscrizione ws/eventi e preso pagamento | M88: 60 | N88: STUDIO 1 | O88: altro.....informazioni in sede, iscrizione ws/eventi e preso pagamento | Q88: 60
A94: 22:30 23:30 | B94: STUDIO 1 | C94: altro.....attivita' di reception varie (iscrizioni presenze info ecc) | E94: 60 | J94: STUDIO 1 | K94: informazioni, prove, chiusura | M94: 60 | N94: STUDIO 1 | O94: informazioni, prove, chiusura | Q94: 60

Sheet JOEL
B1: =elenchi!B7 -> JOEL | F1: =elenchi!D2 ->  SETTIMANA - B | H1:  DA: | J1: =elenchi!E2 -> LUNEDI 11 A SABATO 16 NOVEMBRE 2024
