Workbook

Sheet LUNEDÌ A
B1: LUNEDÌ | D1: =elenchi!C1 ->  SETTIMANA - A | F1:  DA: | G1: =elenchi!D1 -> LUNEDI 20 A DOMENICA 26 APRILE 2026
A3: ORA | B3: =elenchi!B1 -> ALEXANDRA | C3: =elenchi!B2 -> GIUDITTA | D3: =elenchi!B3 -> ESTEFANY | E3: =elenchi!B4 -> NURA | F3: =elenchi!B5 | G3: =elenchi!B6 -> JOEL | H3: =elenchi!B7 -> KEVIN | I3: =elenchi!B8 -> JASIR | J3: =elenchi!B9 -> DIEGO | K3: =elenchi!B10 -> SARA | L3: =elenchi!B11 -> SANTO | M3: =elenchi!B12 -> MASSI | N3: =elenchi!B13
A4: 07:00
A5: 07:30
A6: 08:00
A7: 40475.354 | B7: RECEPTION | H7: PRIMO | K7: UFFICIO | L7: AMM.ZIONE
A8: 40475.375 | B8: RECEPTION | H8: PRIMO | K8: UFFICIO | L8: AMM.ZIONE
A9: 40475.396 | B9: RECEPTION | H9: PRIMO | K9: UFFICIO | L9: AMM.ZIONE
A10: 40475.417 | B10: RECEPTION | H10: PRIMO | K10: UFFICIO | L10: AMM.ZIONE | M10: UFFICIO
A11: 40475.438 | B11: RECEPTION | E11: PRIMO | H11: PRIMO | K11: UFFICIO | L11: AMM.ZIONE | M11: UFFICIO
A12: 40475.458 | B12: RECEPTION | E12: PRIMO | H12: PRIMO | K12: UFFICIO | L12: AMM.ZIONE | M12: UFFICIO
A13: 40475.479 | B13: RECEPTION | E13: PRIMO | H13: PRIMO | K13: UFFICIO | L13: AMM.ZIONE | M13: UFFICIO
A14: 40475.5 | B14: RECEPTION | E14: PRIMO | H14: PRIMO | K14: PAUSA | L14: AMM.ZIONE | M14: UFFICIO
A15: 40475.521 | B15: PAUSA | E15: PRIMO | H15: PRIMO | K15: UFFICIO | L15: AMM.ZIONE | M15: UFFICIO
A16: 40475.542 | B16: PRIMO | E16: RECEPTION | H16: PRIMO | K16: UFFICIO | L16: PAUSA | M16: PAUSA
A17: 40475.562 | B17: PRIMO | E17: RECEPTION | H17: PAUSA | K17: UFFICIO | L17: AMM.ZIONE | M17: UFFICIO
A18: 40475.583 | B18: PRIMO | E18: RECEPTION | H18: PRIMO | K18: UFFICIO | L18: AMM.ZIONE | M18: UFFICIO
A19: 40475.604 | B19: PRIMO | C19: PRIMO | D19: SECONDO | E19: PAUSA | F19: SECONDO | G19: RECEPTION | H19: PRIMO | I19: SECONDO | K19: UFFICIO | L19: AMM.ZIONE | M19: UFFICIO | N19: PRIMO
A20: 40475.625 | B20: PRIMO | C20: PRIMO | D20: SECONDO | E20: SECONDO | F20: SECONDO | G20: RECEPTION | H20: PRIMO | I20: SECONDO | K20: UFFICIO | L20: AMM.ZIONE | M20: UFFICIO | N20: PRIMO
A21: 40475.646 | B21: PRIMO | C21: PRIMO | D21: SECONDO | E21: SECONDO | F21: SECONDO | G21: RECEPTION | H21: PRIMO | I21: SECONDO | K21: UFFICIO | L21: AMM.ZIONE | M21: UFFICIO | N21: PRIMO
A22: 40475.667 | B22: PRIMO | C22: PRIMO | D22: SECONDO | E22: SECONDO | F22: SECONDO | G22: RECEPTION | H22: PRIMO | I22: SECONDO | K22: UFFICIO | L22: AMM.ZIONE | M22: UFFICIO | N22: PRIMO
A23: 40475.688 | B23: PRIMO | C23: PRIMO | D23: SECONDO | E23: SECONDO | F23: SECONDO | G23: RECEPTION | H23: PRIMO | I23: SECONDO | K23: UFFICIO | L23: AMM.ZIONE | M23: UFFICIO | N23: PRIMO
A24: 40475.708 | C24: PRIMO | D24: SECONDO | E24: SECONDO | F24: SECONDO | G24: RECEPTION | I24: SECONDO | M24: UFFICIO | N24: PRIMO
A25: 40475.729 | C25: PRIMO | D25: SECONDO | E25: SECONDO | F25: SECONDO | G25: RECEPTION | I25: SECONDO | M25: UFFICIO | N25: PRIMO
A26: 40475.75 | C26: PRIMO | D26: PAUSA | E26: SECONDO | F26: PAUSA | G26: RECEPTION | I26: SECONDO | M26: UFFICIO | N26: PAUSA
A27: 40475.771 | C27: PRIMO | D27: RECEPTION | E27: SECONDO | F27: RECEPTION | G27: PAUSA | I27: PAUSA | N27: PRIMO
A28: 40475.792 | C28: PAUSA | D28: RECEPTION | F28: RECEPTION | G28: PRIMO | I28: PRIMO | N28: PRIMO
A29: 40475.812 | C29: SECONDO | D29: RECEPTION | F29: RECEPTION | G29: PRIMO | I29: PRIMO | N29: PRIMO
A30: 40475.833 | C30: SECONDO | D30: RECEPTION | F30: RECEPTION | G30: PRIMO | I30: PRIMO | N30: PRIMO
A31: 40475.854 | C31: SECONDO | D31: RECEPTION | F31: RECEPTION | G31: PRIMO | I31: PRIMO | N31: PRIMO
A32: 40475.875 | C32: SECONDO | D32: RECEPTION | F32: RECEPTION | G32: PRIMO | I32: PRIMO | N32: PRIMO
A33: 40475.896 | C33: SECONDO | D33: RECEPTION | F33: RECEPTION | G33: PRIMO | I33: PRIMO | N33: PRIMO
A34: 40475.917 | C34: SECONDO | D34: RECEPTION | F34: RECEPTION | G34: PRIMO | I34: PRIMO | N34: PRIMO
A35: 40475.938 | C35: SECONDO | D35: RECEPTION | F35: RECEPTION | G35: PRIMO | I35: PRIMO | N35: PRIMO
A36: 40475.958
A37: 40475.979
A38: 24:00
A39: TOT | B39: =CONCATENATE(COUNTIF(B4:B38,"MAGAZZINI")+COUNTIF(B4:B38,"PRIMO")+COUNTIF(B4:B38,"RECEPTION")+COUNTIF(B4:B38,"SAGGI")+COUNTIF(B4:B38,"SECONDO")+COUNTIF(B4:B38,"SMART W")+COUNTIF(B4:B38,"STUDIO 1 e 2")+COUNTIF(B4:B38,"MANUTENZ.")+COUNTIF(B4:B38,"UFFICIO")+COUNTIF(B4:B38,"CAMPUS")+COUNTIF(B4:B38,"TEATRO")+COUNTIF(B4:B38,"AMM.ZIONE")+COUNTIF(B4:B38,"FORMAZ-1p")+COUNTIF(B4:B38,"FORMAZ-2p")+COUNTIF(B4:B38,"FORMAZ-rec")+COUNTIF(B4:B38,"WORKSHOP")+COUNTIF(B4:B38,"EVENTO EST."))/2 -> 8 | C39: =CONCATENATE(COUNTIF(C4:C38,"MAGAZZINI")+COUNTIF(C4:C38,"PRIMO")+COUNTIF(C4:C38,"RECEPTION")+COUNTIF(C4:C38,"SAGGI")+COUNTIF(C4:C38,"SECONDO")+COUNTIF(C4:C38,"SMART W")+COUNTIF(C4:C38,"STUDIO 1 e 2")+COUNTIF(C4:C38,"MANUTENZ.")+COUNTIF(C4:C38,"UFFICIO")+COUNTIF(C4:C38,"CAMPUS")+COUNTIF(C4:C38,"TEATRO")+COUNTIF(C4:C38,"AMM.ZIONE")+COUNTIF(C4:C38,"FORMAZ-1p")+COUNTIF(C4:C38,"FORMAZ-2p")+COUNTIF(C4:C38,"FORMAZ-rec")+COUNTIF(C4:C38,"WORKSHOP")+COUNTIF(C4:C38,"EVENTO EST."))/2 -> 8 | D39: =CONCATENATE(COUNTIF(D4:D38,"MAGAZZINI")+COUNTIF(D4:D38,"PRIMO")+COUNTIF(D4:D38,"RECEPTION")+COUNTIF(D4:D38,"SAGGI")+COUNTIF(D4:D38,"SECONDO")+COUNTIF(D4:D38,"SMART W")+COUNTIF(D4:D38,"STUDIO 1 e 2")+COUNTIF(D4:D38,"MANUTENZ.")+COUNTIF(D4:D38,"UFFICIO")+COUNTIF(D4:D38,"CAMPUS")+COUNTIF(D4:D38,"TEATRO")+COUNTIF(D4:D38,"AMM.ZIONE")+COUNTIF(D4:D38,"FORMAZ-1p")+COUNTIF(D4:D38,"FORMAZ-2p")+COUNTIF(D4:D38,"FORMAZ-rec")+COUNTIF(D4:D38,"WORKSHOP")+COUNTIF(D4:D38,"EVENTO EST."))/2 -> 8 | E39: =CONCATENATE(COUNTIF(E4:E38,"MAGAZZINI")+COUNTIF(E4:E38,"PRIMO")+COUNTIF(E4:E38,"RECEPTION")+COUNTIF(E4:E38,"SAGGI")+COUNTIF(E4:E38,"SECONDO")+COUNTIF(E4:E38,"SMART W")+COUNTIF(E4:E38,"STUDIO 1 e 2")+COUNTIF(E4:E38,"MANUTENZ.")+COUNTIF(E4:E38,"UFFICIO")+COUNTIF(E4:E38,"CAMPUS")+COUNTIF(E4:E38,"TEATRO")+COUNTIF(E4:E38,"AMM.ZIONE")+COUNTIF(E4:E38,"FORMAZ-1p")+COUNTIF(E4:E38,"FORMAZ-2p")+COUNTIF(E4:E38,"FORMAZ-rec")+COUNTIF(E4:E38,"WORKSHOP")+COUNTIF(E4:E38,"EVENTO EST."))/2 -> 8 | F39: =CONCATENATE(COUNTIF(F4:F38,"MAGAZZINI")+COUNTIF(F4:F38,"PRIMO")+COUNTIF(F4:F38,"RECEPTION")+COUNTIF(F4:F38,"SAGGI")+COUNTIF(F4:F38,"SECONDO")+COUNTIF(F4:F38,"SMART W")+COUNTIF(F4:F38,"STUDIO 1 e 2")+COUNTIF(F4:F38,"MANUTENZ.")+COUNTIF(F4:F38,"UFFICIO")+COUNTIF(F4:F38,"CAMPUS")+COUNTIF(F4:F38,"TEATRO")+COUNTIF(F4:F38,"AMM.ZIONE")+COUNTIF(F4:F38,"FORMAZ-1p")+COUNTIF(F4:F38,"FORMAZ-2p")+COUNTIF(F4:F38,"FORMAZ-rec")+COUNTIF(F4:F38,"WORKSHOP")+COUNTIF(F4:F38,"EVENTO EST."))/2 -> 8 | G39: =CONCATENATE(COUNTIF(G4:G38,"MAGAZZINI")+COUNTIF(G4:G38,"PRIMO")+COUNTIF(G4:G38,"RECEPTION")+COUNTIF(G4:G38,"SAGGI")+COUNTIF(G4:G38,"SECONDO")+COUNTIF(G4:G38,"SMART W")+COUNTIF(G4:G38,"STUDIO 1 e 2")+COUNTIF(G4:G38,"MANUTENZ.")+COUNTIF(G4:G38,"UFFICIO")+COUNTIF(G4:G38,"CAMPUS")+COUNTIF(G4:G38,"TEATRO")+COUNTIF(G4:G38,"AMM.ZIONE")+COUNTIF(G4:G38,"FORMAZ-1p")+COUNTIF(G4:G38,"FORMAZ-2p")+COUNTIF(G4:G38,"FORMAZ-rec")+COUNTIF(G4:G38,"WORKSHOP")+COUNTIF(G4:G38,"EVENTO EST."))/2 -> 8 | H39: =CONCATENATE(COUNTIF(H4:H38,"MAGAZZINI")+COUNTIF(H4:H38,"PRIMO")+COUNTIF(H4:H38,"RECEPTION")+COUNTIF(H4:H38,"SAGGI")+COUNTIF(H4:H38,"SECONDO")+COUNTIF(H4:H38,"SMART W")+COUNTIF(H4:H38,"STUDIO 1 e 2")+COUNTIF(H4:H38,"MANUTENZ.")+COUNTIF(H4:H38,"UFFICIO")+COUNTIF(H4:H38,"CAMPUS")+COUNTIF(H4:H38,"TEATRO")+COUNTIF(H4:H38,"AMM.ZIONE")+COUNTIF(H4:H38,"FORMAZ-1p")+COUNTIF(H4:H38,"FORMAZ-2p")+COUNTIF(H4:H38,"FORMAZ-rec")+COUNTIF(H4:H38,"WORKSHOP")+COUNTIF(H4:H38,"EVENTO EST."))/2 -> 8 | I39: =CONCATENATE(COUNTIF(I4:I38,"MAGAZZINI")+COUNTIF(I4:I38,"PRIMO")+COUNTIF(I4:I38,"RECEPTION")+COUNTIF(I4:I38,"SAGGI")+COUNTIF(I4:I38,"SECONDO")+COUNTIF(I4:I38,"SMART W")+COUNTIF(I4:I38,"STUDIO 1 e 2")+COUNTIF(I4:I38,"MANUTENZ.")+COUNTIF(I4:I38,"UFFICIO")+COUNTIF(I4:I38,"CAMPUS")+COUNTIF(I4:I38,"TEATRO")+COUNTIF(I4:I38,"AMM.ZIONE")+COUNTIF(I4:I38,"FORMAZ-1p")+COUNTIF(I4:I38,"FORMAZ-2p")+COUNTIF(I4:I38,"FORMAZ-rec")+COUNTIF(I4:I38,"WORKSHOP")+COUNTIF(I4:I38,"EVENTO EST."))/2 -> 8 | ... N39: =CONCATENATE(COUNTIF(N4:N38,"MAGAZZINI")+COUNTIF(N4:N38,"PRIMO")+COUNTIF(N4:N38,"RECEPTION")+COUNTIF(N4:N38,"SAGGI")+COUNTIF(N4:N38,"SECONDO")+COUNTIF(N4:N38,"SMART W")+COUNTIF(N4:N38,"STUDIO 1 e 2")+COUNTIF(N4:N38,"MANUTENZ.")+COUNTIF(N4:N38,"UFFICIO")+COUNTIF(N4:N38,"CAMPUS")+COUNTIF(N4:N38,"TEATRO")+COUNTIF(N4:N38,"AMM.ZIONE")+COUNTIF(N4:N38,"FORMAZ-1p")+COUNTIF(N4:N38,"FORMAZ-2p")+COUNTIF(N4:N38,"FORMAZ-rec")+COUNTIF(N4:N38,"WORKSHOP")+COUNTIF(N4:N38,"EVENTO EST."))/2 -> 8

Sheet MARTEDÌ A
B1: MARTEDÌ | D1: =elenchi!C1 ->  SETTIMANA - A | F1:  DA: | G1: =elenchi!D1 -> LUNEDI 20 A DOMENICA 26 APRILE 2026
A3: ORA | B3: =elenchi!B1 -> ALEXANDRA | C3: =elenchi!B2 -> GIUDITTA | D3: =elenchi!B3 -> ESTEFANY | E3: =elenchi!B4 -> NURA | F3: =elenchi!B5 | G3: =elenchi!B6 -> JOEL | H3: =elenchi!B7 -> KEVIN | I3: =elenchi!B8 -> JASIR | J3: =elenchi!B9 -> DIEGO | K3: =elenchi!B10 -> SARA | L3: =elenchi!B11 -> SANTO | M3: =elenchi!B12 -> MASSI | N3: =elenchi!B13
A4: 07:00
A5: 07:30
A6: 08:00
A7: 40475.354 | D7: RECEPTION | H7: SECONDO | K7: UFFICIO | L7: AMM.ZIONE
A8: 40475.375 | D8: RECEPTION | H8: SECONDO | K8: UFFICIO | L8: AMM.ZIONE
A9: 40475.396 | D9: RECEPTION | H9: SECONDO | K9: UFFICIO | L9: AMM.ZIONE
A10: 40475.417 | D10: RECEPTION | H10: SECONDO | K10: UFFICIO | L10: AMM.ZIONE | M10: UFFICIO
A11: 40475.438 | D11: RECEPTION | G11: PRIMO | H11: SECONDO | K11: UFFICIO | L11: AMM.ZIONE | M11: UFFICIO
A12: 40475.458 | D12: RECEPTION | G12: PRIMO | H12: SECONDO | K12: UFFICIO | L12: AMM.ZIONE | M12: UFFICIO
A13: 40475.479 | D13: RECEPTION | G13: PRIMO | H13: SECONDO | K13: UFFICIO | L13: AMM.ZIONE | M13: UFFICIO
A14: 40475.5 | D14: RECEPTION | G14: PRIMO | H14: SECONDO | K14: PAUSA | L14: AMM.ZIONE | M14: UFFICIO
A15: 40475.521 | D15: PAUSA | G15: RECEPTION | H15: SECONDO | K15: UFFICIO | L15: AMM.ZIONE | M15: UFFICIO | N15: PRIMO
A16: 40475.542 | D16: RECEPTION | G16: RECEPTION | K16: UFFICIO | L16: PAUSA | M16: PAUSA | N16: PRIMO
A17: 40475.562 | D17: RECEPTION | G17: RECEPTION | K17: UFFICIO | L17: AMM.ZIONE | M17: UFFICIO | N17: PRIMO
A18: 40475.583 | D18: RECEPTION | G18: RECEPTION | K18: UFFICIO | L18: AMM.ZIONE | M18: UFFICIO | N18: PRIMO
A19: 40475.604 | B19: PRIMO | C19: PRIMO | D19: RECEPTION | E19: SECONDO | F19: RECEPTION | G19: PAUSA | I19: PRIMO | K19: UFFICIO | L19: AMM.ZIONE | M19: UFFICIO | N19: PRIMO
A20: 40475.625 | B20: PRIMO | C20: PRIMO | D20: RECEPTION | E20: SECONDO | F20: RECEPTION | G20: PRIMO | I20: PRIMO | K20: UFFICIO | L20: AMM.ZIONE | M20: UFFICIO | N20: PRIMO
A21: 40475.646 | B21: PRIMO | C21: PRIMO | D21: RECEPTION | E21: SECONDO | F21: RECEPTION | G21: PRIMO | I21: PRIMO | K21: UFFICIO | L21: AMM.ZIONE | M21: UFFICIO | N21: PRIMO
A22: 40475.667 | B22: PRIMO | C22: PRIMO | D22: RECEPTION | E22: SECONDO | F22: RECEPTION | G22: PRIMO | I22: PRIMO | K22: UFFICIO | L22: AMM.ZIONE | M22: UFFICIO | N22: PRIMO
A23: 40475.688 | B23: PRIMO | C23: PRIMO | D23: RECEPTION | E23: SECONDO | F23: RECEPTION | G23: PRIMO | I23: PRIMO | K23: UFFICIO | L23: AMM.ZIONE | M23: UFFICIO | N23: PAUSA
A24: 40475.708 | B24: PRIMO | C24: PRIMO | E24: SECONDO | F24: RECEPTION | G24: PRIMO | I24: PRIMO | M24: UFFICIO | N24: PRIMO
A25: 40475.729 | B25: PRIMO | C25: PAUSA | E25: SECONDO | F25: RECEPTION | G25: PRIMO | I25: PRIMO | M25: UFFICIO | N25: PRIMO
A26: 40475.75 | B26: PAUSA | C26: RECEPTION | E26: SECONDO | F26: RECEPTION | G26: PRIMO | I26: PRIMO | M26: UFFICIO | N26: PRIMO
A27: 40475.771 | B27: SECONDO | C27: RECEPTION | E27: PAUSA | F27: RECEPTION | G27: PRIMO | I27: PAUSA | N27: PRIMO
A28: 40475.792 | B28: SECONDO | C28: RECEPTION | E28: PRIMO | F28: PAUSA | I28: PRIMO | N28: PRIMO
A29: 40475.812 | B29: SECONDO | C29: RECEPTION | E29: PRIMO | F29: RECEPTION | I29: PRIMO | N29: PRIMO
A30: 40475.833 | B30: SECONDO | C30: RECEPTION | E30: PRIMO | F30: RECEPTION | I30: PRIMO | N30: PRIMO
A31: 40475.854 | B31: SECONDO | C31: RECEPTION | E31: PRIMO | F31: RECEPTION | I31: PRIMO | N31: PRIMO
A32: 40475.875 | B32: SECONDO | C32: RECEPTION | E32: PRIMO | F32: RECEPTION | I32: PRIMO
A33: 40475.896 | B33: SECONDO | C33: RECEPTION | E33: PRIMO | F33: RECEPTION | I33: PRIMO
A34: 40475.917 | B34: SECONDO | C34: RECEPTION | E34: PRIMO | F34: RECEPTION | I34: PRIMO
A35: 40475.938 | B35: SECONDO | C35: RECEPTION | E35: PRIMO | F35: RECEPTION | I35: PRIMO
A36: 40475.958
A37: 40475.979
A38: 24:00
A39: TOT | B39: =CONCATENATE(COUNTIF(B4:B38,"MAGAZZINI")+COUNTIF(B4:B38,"PRIMO")+COUNTIF(B4:B38,"RECEPTION")+COUNTIF(B4:B38,"SAGGI")+COUNTIF(B4:B38,"SECONDO")+COUNTIF(B4:B38,"SMART W")+COUNTIF(B4:B38,"STUDIO 1 e 2")+COUNTIF(B4:B38,"MANUTENZ.")+COUNTIF(B4:B38,"UFFICIO")+COUNTIF(B4:B38,"CAMPUS")+COUNTIF(B4:B38,"TEATRO")+COUNTIF(B4:B38,"AMM.ZIONE")+COUNTIF(B4:B38,"FORMAZ-1p")+COUNTIF(B4:B38,"FORMAZ-2p")+COUNTIF(B4:B38,"FORMAZ-rec")+COUNTIF(B4:B38,"WORKSHOP")+COUNTIF(B4:B38,"EVENTO EST."))/2 -> 8 | C39: =CONCATENATE(COUNTIF(C4:C38,"MAGAZZINI")+COUNTIF(C4:C38,"PRIMO")+COUNTIF(C4:C38,"RECEPTION")+COUNTIF(C4:C38,"SAGGI")+COUNTIF(C4:C38,"SECONDO")+COUNTIF(C4:C38,"SMART W")+COUNTIF(C4:C38,"STUDIO 1 e 2")+COUNTIF(C4:C38,"MANUTENZ.")+COUNTIF(C4:C38,"UFFICIO")+COUNTIF(C4:C38,"CAMPUS")+COUNTIF(C4:C38,"TEATRO")+COUNTIF(C4:C38,"AMM.ZIONE")+COUNTIF(C4:C38,"FORMAZ-1p")+COUNTIF(C4:C38,"FORMAZ-2p")+COUNTIF(C4:C38,"FORMAZ-rec")+COUNTIF(C4:C38,"WORKSHOP")+COUNTIF(C4:C38,"EVENTO EST."))/2 -> 8 | D39: =CONCATENATE(COUNTIF(D4:D38,"MAGAZZINI")+COUNTIF(D4:D38,"PRIMO")+COUNTIF(D4:D38,"RECEPTION")+COUNTIF(D4:D38,"SAGGI")+COUNTIF(D4:D38,"SECONDO")+COUNTIF(D4:D38,"SMART W")+COUNTIF(D4:D38,"STUDIO 1 e 2")+COUNTIF(D4:D38,"MANUTENZ.")+COUNTIF(D4:D38,"UFFICIO")+COUNTIF(D4:D38,"CAMPUS")+COUNTIF(D4:D38,"TEATRO")+COUNTIF(D4:D38,"AMM.ZIONE")+COUNTIF(D4:D38,"FORMAZ-1p")+COUNTIF(D4:D38,"FORMAZ-2p")+COUNTIF(D4:D38,"FORMAZ-rec")+COUNTIF(D4:D38,"WORKSHOP")+COUNTIF(D4:D38,"EVENTO EST."))/2 -> 8 | E39: =CONCATENATE(COUNTIF(E4:E38,"MAGAZZINI")+COUNTIF(E4:E38,"PRIMO")+COUNTIF(E4:E38,"RECEPTION")+COUNTIF(E4:E38,"SAGGI")+COUNTIF(E4:E38,"SECONDO")+COUNTIF(E4:E38,"SMART W")+COUNTIF(E4:E38,"STUDIO 1 e 2")+COUNTIF(E4:E38,"MANUTENZ.")+COUNTIF(E4:E38,"UFFICIO")+COUNTIF(E4:E38,"CAMPUS")+COUNTIF(E4:E38,"TEATRO")+COUNTIF(E4:E38,"AMM.ZIONE")+COUNTIF(E4:E38,"FORMAZ-1p")+COUNTIF(E4:E38,"FORMAZ-2p")+COUNTIF(E4:E38,"FORMAZ-rec")+COUNTIF(E4:E38,"WORKSHOP")+COUNTIF(E4:E38,"EVENTO EST."))/2 -> 8 | F39: =CONCATENATE(COUNTIF(F4:F38,"MAGAZZINI")+COUNTIF(F4:F38,"PRIMO")+COUNTIF(F4:F38,"RECEPTION")+COUNTIF(F4:F38,"SAGGI")+COUNTIF(F4:F38,"SECONDO")+COUNTIF(F4:F38,"SMART W")+COUNTIF(F4:F38,"STUDIO 1 e 2")+COUNTIF(F4:F38,"MANUTENZ.")+COUNTIF(F4:F38,"UFFICIO")+COUNTIF(F4:F38,"CAMPUS")+COUNTIF(F4:F38,"TEATRO")+COUNTIF(F4:F38,"AMM.ZIONE")+COUNTIF(F4:F38,"FORMAZ-1p")+COUNTIF(F4:F38,"FORMAZ-2p")+COUNTIF(F4:F38,"FORMAZ-rec")+COUNTIF(F4:F38,"WORKSHOP")+COUNTIF(F4:F38,"EVENTO EST."))/2 -> 8 | G39: =CONCATENATE(COUNTIF(G4:G38,"MAGAZZINI")+COUNTIF(G4:G38,"PRIMO")+COUNTIF(G4:G38,"RECEPTION")+COUNTIF(G4:G38,"SAGGI")+COUNTIF(G4:G38,"SECONDO")+COUNTIF(G4:G38,"SMART W")+COUNTIF(G4:G38,"STUDIO 1 e 2")+COUNTIF(G4:G38,"MANUTENZ.")+COUNTIF(G4:G38,"UFFICIO")+COUNTIF(G4:G38,"CAMPUS")+COUNTIF(G4:G38,"TEATRO")+COUNTIF(G4:G38,"AMM.ZIONE")+COUNTIF(G4:G38,"FORMAZ-1p")+COUNTIF(G4:G38,"FORMAZ-2p")+COUNTIF(G4:G38,"FORMAZ-rec")+COUNTIF(G4:G38,"WORKSHOP")+COUNTIF(G4:G38,"EVENTO EST."))/2 -> 8 | H39: =CONCATENATE(COUNTIF(H4:H38,"MAGAZZINI")+COUNTIF(H4:H38,"PRIMO")+COUNTIF(H4:H38,"RECEPTION")+COUNTIF(H4:H38,"SAGGI")+COUNTIF(H4:H38,"SECONDO")+COUNTIF(H4:H38,"SMART W")+COUNTIF(H4:H38,"STUDIO 1 e 2")+COUNTIF(H4:H38,"MANUTENZ.")+COUNTIF(H4:H38,"UFFICIO")+COUNTIF(H4:H38,"CAMPUS")+COUNTIF(H4:H38,"TEATRO")+COUNTIF(H4:H38,"AMM.ZIONE")+COUNTIF(H4:H38,"FORMAZ-1p")+COUNTIF(H4:H38,"FORMAZ-2p")+COUNTIF(H4:H38,"FORMAZ-rec")+COUNTIF(H4:H38,"WORKSHOP")+COUNTIF(H4:H38,"EVENTO EST."))/2 -> 4.5 | I39: =CONCATENATE(COUNTIF(I4:I38,"MAGAZZINI")+COUNTIF(I4:I38,"PRIMO")+COUNTIF(I4:I38,"RECEPTION")+COUNTIF(I4:I38,"SAGGI")+COUNTIF(I4:I38,"SECONDO")+COUNTIF(I4:I38,"SMART W")+COUNTIF(I4:I38,"STUDIO 1 e 2")+COUNTIF(I4:I38,"MANUTENZ.")+COUNTIF(I4:I38,"UFFICIO")+COUNTIF(I4:I38,"CAMPUS")+COUNTIF(I4:I38,"TEATRO")+COUNTIF(I4:I38,"AMM.ZIONE")+COUNTIF(I4:I38,"FORMAZ-1p")+COUNTIF(I4:I38,"FORMAZ-2p")+COUNTIF(I4:I38,"FORMAZ-rec")+COUNTIF(I4:I38,"WORKSHOP")+COUNTIF(I4:I38,"EVENTO EST."))/2 -> 8 | ... N39: =CONCATENATE(COUNTIF(N4:N38,"MAGAZZINI")+COUNTIF(N4:N38,"PRIMO")+COUNTIF(N4:N38,"RECEPTION")+COUNTIF(N4:N38,"SAGGI")+COUNTIF(N4:N38,"SECONDO")+COUNTIF(N4:N38,"SMART W")+COUNTIF(N4:N38,"STUDIO 1 e 2")+COUNTIF(N4:N38,"MANUTENZ.")+COUNTIF(N4:N38,"UFFICIO")+COUNTIF(N4:N38,"CAMPUS")+COUNTIF(N4:N38,"TEATRO")+COUNTIF(N4:N38,"AMM.ZIONE")+COUNTIF(N4:N38,"FORMAZ-1p")+COUNTIF(N4:N38,"FORMAZ-2p")+COUNTIF(N4:N38,"FORMAZ-rec")+COUNTIF(N4:N38,"WORKSHOP")+COUNTIF(N4:N38,"EVENTO EST."))/2 -> 8

Sheet MERCOLEDÌ A
B1: MERCOLEDÌ | D1: =elenchi!C1 ->  SETTIMANA - A | F1:  DA: | G1: =elenchi!D1 -> LUNEDI 20 A DOMENICA 26 APRILE 2026
A3: ORA | B3: =elenchi!B1 -> ALEXANDRA | C3: =elenchi!B2 -> GIUDITTA | D3: =elenchi!B3 -> ESTEFANY | E3: =elenchi!B4 -> NURA | F3: =elenchi!B5 | G3: =elenchi!B6 -> JOEL | H3: =elenchi!B7 -> KEVIN | I3: =elenchi!B8 -> JASIR | J3: =elenchi!B9 -> DIEGO | K3: =elenchi!B10 -> SARA | L3: =elenchi!B11 -> SANTO | M3: =elenchi!B12 -> MASSI | N3: =elenchi!B13
A4: 07:00
A5: 07:30
A6: 08:00
A7: 40475.354 | G7: RECEPTION | H7: PRIMO | K7: UFFICIO | L7: AMM.ZIONE
A8: 40475.375 | G8: RECEPTION | H8: PRIMO | K8: UFFICIO | L8: AMM.ZIONE | M8: UFFICIO
A9: 40475.396 | G9: RECEPTION | H9: PRIMO | K9: UFFICIO | L9: AMM.ZIONE | M9: UFFICIO
A10: 40475.417 | G10: RECEPTION | H10: PRIMO | K10: UFFICIO | L10: AMM.ZIONE | M10: UFFICIO
A11: 40475.438 | B11: PRIMO | G11: RECEPTION | H11: PRIMO | K11: UFFICIO | L11: AMM.ZIONE | M11: UFFICIO
A12: 40475.458 | B12: PRIMO | G12: RECEPTION | H12: PRIMO | K12: UFFICIO | L12: AMM.ZIONE | M12: UFFICIO
A13: 40475.479 | B13: PRIMO | G13: RECEPTION | H13: PRIMO | K13: UFFICIO | L13: AMM.ZIONE | M13: UFFICIO
A14: 40475.5 | B14: PRIMO | G14: RECEPTION | H14: PRIMO | K14: PAUSA | L14: AMM.ZIONE | M14: UFFICIO
A15: 40475.521 | B15: RECEPTION | G15: PAUSA | H15: PRIMO | K15: UFFICIO | L15: AMM.ZIONE | M15: UFFICIO
A16: 40475.542 | B16: RECEPTION | G16: PRIMO | H16: PRIMO | K16: UFFICIO | L16: PAUSA | M16: PAUSA
A17: 40475.562 | B17: RECEPTION | G17: PRIMO | H17: PAUSA | K17: UFFICIO | L17: AMM.ZIONE | M17: UFFICIO
A18: 40475.583 | B18: RECEPTION | G18: PRIMO | H18: PRIMO | K18: UFFICIO | L18: AMM.ZIONE | M18: UFFICIO
A19: 40475.604 | B19: PAUSA | C19: PRIMO | D19: RECEPTION | E19: SECONDO | F19: RECEPTION | G19: PRIMO | H19: PRIMO | I19: PRIMO | K19: UFFICIO | L19: AMM.ZIONE | M19: UFFICIO | N19: PRIMO
A20: 40475.625 | B20: PRIMO | C20: PRIMO | D20: RECEPTION | E20: SECONDO | F20: RECEPTION | G20: PRIMO | H20: PRIMO | I20: PRIMO | K20: UFFICIO | L20: AMM.ZIONE | M20: UFFICIO | N20: PRIMO
A21: 40475.646 | B21: PRIMO | C21: PRIMO | D21: RECEPTION | E21: SECONDO | F21: RECEPTION | G21: PRIMO | H21: PRIMO | I21: PRIMO | K21: UFFICIO | L21: AMM.ZIONE | M21: UFFICIO | N21: PRIMO
A22: 40475.667 | B22: PRIMO | C22: PRIMO | D22: RECEPTION | E22: SECONDO | F22: RECEPTION | G22: PRIMO | H22: PRIMO | I22: PRIMO | K22: UFFICIO | L22: AMM.ZIONE | M22: UFFICIO | N22: PRIMO
A23: 40475.688 | B23: PRIMO | C23: PRIMO | D23: RECEPTION | E23: SECONDO | F23: RECEPTION | G23: PRIMO | H23: PRIMO | I23: PRIMO | K23: UFFICIO | L23: AMM.ZIONE | M23: UFFICIO | N23: PRIMO
A24: 40475.708 | B24: PRIMO | C24: PRIMO | D24: RECEPTION | E24: SECONDO | F24: RECEPTION | I24: PRIMO | M24: UFFICIO | N24: PRIMO
A25: 40475.729 | B25: PRIMO | C25: PAUSA | D25: RECEPTION | E25: SECONDO | F25: RECEPTION | I25: PRIMO | M25: UFFICIO | N25: PRIMO
A26: 40475.75 | B26: PRIMO | C26: SECONDO | D26: PAUSA | E26: SECONDO | F26: RECEPTION | I26: PRIMO | M26: UFFICIO | N26: PRIMO
A27: 40475.771 | B27: PRIMO | C27: SECONDO | D27: PRIMO | E27: PAUSA | F27: RECEPTION | I27: PAUSA | N27: PAUSA
A28: 40475.792 | C28: SECONDO | D28: PRIMO | E28: RECEPTION | F28: PAUSA | I28: PRIMO | N28: PRIMO
A29: 40475.812 | C29: SECONDO | D29: PRIMO | E29: RECEPTION | F29: PRIMO | I29: PRIMO | N29: PRIMO
A30: 40475.833 | C30: SECONDO | D30: PRIMO | E30: RECEPTION | F30: PRIMO | I30: PRIMO | N30: PRIMO
A31: 40475.854 | C31: SECONDO | D31: PRIMO | E31: RECEPTION | F31: PRIMO | I31: PRIMO | N31: PRIMO
A32: 40475.875 | C32: SECONDO | D32: PRIMO | E32: RECEPTION | F32: PRIMO | I32: PRIMO | N32: PRIMO
A33: 40475.896 | C33: SECONDO | D33: PRIMO | E33: RECEPTION | F33: PRIMO | I33: PRIMO | N33: PRIMO
A34: 40475.917 | C34: SECONDO | D34: PRIMO | E34: RECEPTION | F34: PRIMO | I34: PRIMO | N34: PRIMO
A35: 40475.938 | C35: SECONDO | D35: PRIMO | E35: RECEPTION | F35: PRIMO | I35: PRIMO | N35: PRIMO
A36: 40475.958
A37: 40475.979
A38: 24:00
A39: TOT | B39: =CONCATENATE(COUNTIF(B4:B38,"MAGAZZINI")+COUNTIF(B4:B38,"PRIMO")+COUNTIF(B4:B38,"RECEPTION")+COUNTIF(B4:B38,"SAGGI")+COUNTIF(B4:B38,"SECONDO")+COUNTIF(B4:B38,"SMART W")+COUNTIF(B4:B38,"STUDIO 1 e 2")+COUNTIF(B4:B38,"MANUTENZ.")+COUNTIF(B4:B38,"UFFICIO")+COUNTIF(B4:B38,"CAMPUS")+COUNTIF(B4:B38,"TEATRO")+COUNTIF(B4:B38,"AMM.ZIONE")+COUNTIF(B4:B38,"FORMAZ-1p")+COUNTIF(B4:B38,"FORMAZ-2p")+COUNTIF(B4:B38,"FORMAZ-rec")+COUNTIF(B4:B38,"WORKSHOP")+COUNTIF(B4:B38,"EVENTO EST."))/2 -> 8 | C39: =CONCATENATE(COUNTIF(C4:C38,"MAGAZZINI")+COUNTIF(C4:C38,"PRIMO")+COUNTIF(C4:C38,"RECEPTION")+COUNTIF(C4:C38,"SAGGI")+COUNTIF(C4:C38,"SECONDO")+COUNTIF(C4:C38,"SMART W")+COUNTIF(C4:C38,"STUDIO 1 e 2")+COUNTIF(C4:C38,"MANUTENZ.")+COUNTIF(C4:C38,"UFFICIO")+COUNTIF(C4:C38,"CAMPUS")+COUNTIF(C4:C38,"TEATRO")+COUNTIF(C4:C38,"AMM.ZIONE")+COUNTIF(C4:C38,"FORMAZ-1p")+COUNTIF(C4:C38,"FORMAZ-2p")+COUNTIF(C4:C38,"FORMAZ-rec")+COUNTIF(C4:C38,"WORKSHOP")+COUNTIF(C4:C38,"EVENTO EST."))/2 -> 8 | D39: =CONCATENATE(COUNTIF(D4:D38,"MAGAZZINI")+COUNTIF(D4:D38,"PRIMO")+COUNTIF(D4:D38,"RECEPTION")+COUNTIF(D4:D38,"SAGGI")+COUNTIF(D4:D38,"SECONDO")+COUNTIF(D4:D38,"SMART W")+COUNTIF(D4:D38,"STUDIO 1 e 2")+COUNTIF(D4:D38,"MANUTENZ.")+COUNTIF(D4:D38,"UFFICIO")+COUNTIF(D4:D38,"CAMPUS")+COUNTIF(D4:D38,"TEATRO")+COUNTIF(D4:D38,"AMM.ZIONE")+COUNTIF(D4:D38,"FORMAZ-1p")+COUNTIF(D4:D38,"FORMAZ-2p")+COUNTIF(D4:D38,"FORMAZ-rec")+COUNTIF(D4:D38,"WORKSHOP")+COUNTIF(D4:D38,"EVENTO EST."))/2 -> 8 | E39: =CONCATENATE(COUNTIF(E4:E38,"MAGAZZINI")+COUNTIF(E4:E38,"PRIMO")+COUNTIF(E4:E38,"RECEPTION")+COUNTIF(E4:E38,"SAGGI")+COUNTIF(E4:E38,"SECONDO")+COUNTIF(E4:E38,"SMART W")+COUNTIF(E4:E38,"STUDIO 1 e 2")+COUNTIF(E4:E38,"MANUTENZ.")+COUNTIF(E4:E38,"UFFICIO")+COUNTIF(E4:E38,"CAMPUS")+COUNTIF(E4:E38,"TEATRO")+COUNTIF(E4:E38,"AMM.ZIONE")+COUNTIF(E4:E38,"FORMAZ-1p")+COUNTIF(E4:E38,"FORMAZ-2p")+COUNTIF(E4:E38,"FORMAZ-rec")+COUNTIF(E4:E38,"WORKSHOP")+COUNTIF(E4:E38,"EVENTO EST."))/2 -> 8 | F39: =CONCATENATE(COUNTIF(F4:F38,"MAGAZZINI")+COUNTIF(F4:F38,"PRIMO")+COUNTIF(F4:F38,"RECEPTION")+COUNTIF(F4:F38,"SAGGI")+COUNTIF(F4:F38,"SECONDO")+COUNTIF(F4:F38,"SMART W")+COUNTIF(F4:F38,"STUDIO 1 e 2")+COUNTIF(F4:F38,"MANUTENZ.")+COUNTIF(F4:F38,"UFFICIO")+COUNTIF(F4:F38,"CAMPUS")+COUNTIF(F4:F38,"TEATRO")+COUNTIF(F4:F38,"AMM.ZIONE")+COUNTIF(F4:F38,"FORMAZ-1p")+COUNTIF(F4:F38,"FORMAZ-2p")+COUNTIF(F4:F38,"FORMAZ-rec")+COUNTIF(F4:F38,"WORKSHOP")+COUNTIF(F4:F38,"EVENTO EST."))/2 -> 8 | G39: =CONCATENATE(COUNTIF(G4:G38,"MAGAZZINI")+COUNTIF(G4:G38,"PRIMO")+COUNTIF(G4:G38,"RECEPTION")+COUNTIF(G4:G38,"SAGGI")+COUNTIF(G4:G38,"SECONDO")+COUNTIF(G4:G38,"SMART W")+COUNTIF(G4:G38,"STUDIO 1 e 2")+COUNTIF(G4:G38,"MANUTENZ.")+COUNTIF(G4:G38,"UFFICIO")+COUNTIF(G4:G38,"CAMPUS")+COUNTIF(G4:G38,"TEATRO")+COUNTIF(G4:G38,"AMM.ZIONE")+COUNTIF(G4:G38,"FORMAZ-1p")+COUNTIF(G4:G38,"FORMAZ-2p")+COUNTIF(G4:G38,"FORMAZ-rec")+COUNTIF(G4:G38,"WORKSHOP")+COUNTIF(G4:G38,"EVENTO EST."))/2 -> 8 | H39: =CONCATENATE(COUNTIF(H4:H38,"MAGAZZINI")+COUNTIF(H4:H38,"PRIMO")+COUNTIF(H4:H38,"RECEPTION")+COUNTIF(H4:H38,"SAGGI")+COUNTIF(H4:H38,"SECONDO")+COUNTIF(H4:H38,"SMART W")+COUNTIF(H4:H38,"STUDIO 1 e 2")+COUNTIF(H4:H38,"MANUTENZ.")+COUNTIF(H4:H38,"UFFICIO")+COUNTIF(H4:H38,"CAMPUS")+COUNTIF(H4:H38,"TEATRO")+COUNTIF(H4:H38,"AMM.ZIONE")+COUNTIF(H4:H38,"FORMAZ-1p")+COUNTIF(H4:H38,"FORMAZ-2p")+COUNTIF(H4:H38,"FORMAZ-rec")+COUNTIF(H4:H38,"WORKSHOP")+COUNTIF(H4:H38,"EVENTO EST."))/2 -> 8 | I39: =CONCATENATE(COUNTIF(I4:I38,"MAGAZZINI")+COUNTIF(I4:I38,"PRIMO")+COUNTIF(I4:I38,"RECEPTION")+COUNTIF(I4:I38,"SAGGI")+COUNTIF(I4:I38,"SECONDO")+COUNTIF(I4:I38,"SMART W")+COUNTIF(I4:I38,"STUDIO 1 e 2")+COUNTIF(I4:I38,"MANUTENZ.")+COUNTIF(I4:I38,"UFFICIO")+COUNTIF(I4:I38,"CAMPUS")+COUNTIF(I4:I38,"TEATRO")+COUNTIF(I4:I38,"AMM.ZIONE")+COUNTIF(I4:I38,"FORMAZ-1p")+COUNTIF(I4:I38,"FORMAZ-2p")+COUNTIF(I4:I38,"FORMAZ-rec")+COUNTIF(I4:I38,"WORKSHOP")+COUNTIF(I4:I38,"EVENTO EST."))/2 -> 8 | ... N39: =CONCATENATE(COUNTIF(N4:N38,"MAGAZZINI")+COUNTIF(N4:N38,"PRIMO")+COUNTIF(N4:N38,"RECEPTION")+COUNTIF(N4:N38,"SAGGI")+COUNTIF(N4:N38,"SECONDO")+COUNTIF(N4:N38,"SMART W")+COUNTIF(N4:N38,"STUDIO 1 e 2")+COUNTIF(N4:N38,"MANUTENZ.")+COUNTIF(N4:N38,"UFFICIO")+COUNTIF(N4:N38,"CAMPUS")+COUNTIF(N4:N38,"TEATRO")+COUNTIF(N4:N38,"AMM.ZIONE")+COUNTIF(N4:N38,"FORMAZ-1p")+COUNTIF(N4:N38,"FORMAZ-2p")+COUNTIF(N4:N38,"FORMAZ-rec")+COUNTIF(N4:N38,"WORKSHOP")+COUNTIF(N4:N38,"EVENTO EST."))/2 -> 8

Sheet GIOVEDÌ A
B1: GIOVEDÌ | D1: =elenchi!C1 ->  SETTIMANA - A | F1:  DA: | G1: =elenchi!D1 -> LUNEDI 20 A DOMENICA 26 APRILE 2026
A3: ORA | B3: =elenchi!B1 -> ALEXANDRA | C3: =elenchi!B2 -> GIUDITTA | D3: =elenchi!B3 -> ESTEFANY | E3: =elenchi!B4 -> NURA | F3: =elenchi!B5 | G3: =elenchi!B6 -> JOEL | H3: =elenchi!B7 -> KEVIN | I3: =elenchi!B8 -> JASIR | J3: =elenchi!B9 -> DIEGO | K3: =elenchi!B10 -> SARA | L3: =elenchi!B11 -> SANTO | M3: =elenchi!B12 -> MASSI | N3: =elenchi!B13
A4: 07:00
A5: 07:30
A6: 08:00
A7: 40475.354 | E7: RECEPTION | I7: PRIMO | K7: UFFICIO | L7: AMM.ZIONE
A8: 40475.375 | E8: RECEPTION | I8: PRIMO | K8: UFFICIO | L8: AMM.ZIONE
A9: 40475.396 | E9: RECEPTION | I9: PRIMO | K9: UFFICIO | L9: AMM.ZIONE
A10: 40475.417 | E10: RECEPTION | I10: PRIMO | K10: UFFICIO | L10: AMM.ZIONE | M10: UFFICIO
A11: 40475.438 | D11: PRIMO | E11: RECEPTION | I11: PRIMO | K11: UFFICIO | L11: AMM.ZIONE | M11: UFFICIO
A12: 40475.458 | D12: PRIMO | E12: RECEPTION | I12: PRIMO | K12: UFFICIO | L12: AMM.ZIONE | M12: UFFICIO
A13: 40475.479 | D13: PRIMO | E13: RECEPTION | I13: PRIMO | K13: UFFICIO | L13: AMM.ZIONE | M13: UFFICIO
A14: 40475.5 | D14: PRIMO | E14: RECEPTION | I14: PRIMO | K14: PAUSA | L14: AMM.ZIONE | M14: UFFICIO
A15: 40475.521 | D15: RECEPTION | E15: PAUSA | I15: PRIMO | K15: UFFICIO | L15: AMM.ZIONE | M15: UFFICIO
A16: 40475.542 | D16: RECEPTION | E16: PRIMO | I16: PRIMO | K16: UFFICIO | L16: PAUSA | M16: PAUSA
A17: 40475.562 | D17: RECEPTION | E17: PRIMO | I17: PRIMO | K17: UFFICIO | L17: AMM.ZIONE | M17: UFFICIO
A18: 40475.583 | D18: RECEPTION | E18: PRIMO | I18: PRIMO | K18: UFFICIO | L18: AMM.ZIONE | M18: UFFICIO
A19: 40475.604 | B19: PRIMO | C19: RECEPTION | D19: PAUSA | E19: PRIMO | F19: RECEPTION | G19: SECONDO | H19: PRIMO | I19: PAUSA | K19: UFFICIO | L19: AMM.ZIONE | M19: UFFICIO | N19: PRIMO
A20: 40475.625 | B20: PRIMO | C20: RECEPTION | D20: PRIMO | E20: PRIMO | F20: RECEPTION | G20: SECONDO | H20: PRIMO | I20: PRIMO | K20: UFFICIO | L20: AMM.ZIONE | M20: UFFICIO | N20: PRIMO
A21: 40475.646 | B21: PRIMO | C21: RECEPTION | D21: PRIMO | E21: PRIMO | F21: RECEPTION | G21: SECONDO | H21: PRIMO | I21: PRIMO | K21: UFFICIO | L21: AMM.ZIONE | M21: UFFICIO | N21: PRIMO
A22: 40475.667 | B22: PRIMO | C22: RECEPTION | D22: PRIMO | E22: PRIMO | F22: RECEPTION | G22: SECONDO | H22: PRIMO | I22: PRIMO | K22: UFFICIO | L22: AMM.ZIONE | M22: UFFICIO | N22: PRIMO
A23: 40475.688 | B23: PRIMO | C23: RECEPTION | D23: PRIMO | E23: PRIMO | F23: RECEPTION | G23: SECONDO | H23: PRIMO | I23: PRIMO | K23: UFFICIO | L23: AMM.ZIONE | M23: UFFICIO | N23: PRIMO
A24: 40475.708 | B24: PRIMO | C24: RECEPTION | D24: PRIMO | F24: RECEPTION | G24: SECONDO | H24: PRIMO | M24: UFFICIO | N24: PRIMO
A25: 40475.729 | B25: PRIMO | C25: PAUSA | D25: PRIMO | F25: RECEPTION | G25: SECONDO | H25: PRIMO | M25: UFFICIO | N25: PRIMO
A26: 40475.75 | B26: PAUSA | C26: PRIMO | D26: PRIMO | F26: RECEPTION | G26: SECONDO | H26: PRIMO | M26: UFFICIO | N26: PRIMO
A27: 40475.771 | B27: SECONDO | C27: PRIMO | D27: PRIMO | F27: RECEPTION | G27: PAUSA | H27: PRIMO | N27: PRIMO
A28: 40475.792 | B28: SECONDO | C28: PRIMO | F28: PAUSA | G28: RECEPTION | H28: PAUSA | N28: PAUSA
A29: 40475.812 | B29: SECONDO | C29: PRIMO | F29: PRIMO | G29: RECEPTION | H29: SECONDO | N29: SECONDO
A30: 40475.833 | B30: SECONDO | C30: PRIMO | F30: PRIMO | G30: RECEPTION | H30: SECONDO | N30: SECONDO
A31: 40475.854 | B31: SECONDO | C31: PRIMO | F31: PRIMO | G31: RECEPTION | H31: SECONDO | N31: SECONDO
A32: 40475.875 | B32: SECONDO | C32: PRIMO | F32: PRIMO | G32: RECEPTION | H32: SECONDO | N32: SECONDO
A33: 40475.896 | B33: SECONDO | C33: PRIMO | F33: PRIMO | G33: RECEPTION | H33: SECONDO | N33: SECONDO
A34: 40475.917 | B34: SECONDO | C34: PRIMO | F34: PRIMO | G34: RECEPTION | H34: SECONDO | N34: SECONDO
A35: 40475.938 | B35: SECONDO | C35: PRIMO | F35: PRIMO | G35: RECEPTION | H35: SECONDO | N35: SECONDO
A36: 40475.958
A37: 40475.979
A38: 24:00
A39: TOT | B39: =CONCATENATE(COUNTIF(B4:B38,"MAGAZZINI")+COUNTIF(B4:B38,"PRIMO")+COUNTIF(B4:B38,"RECEPTION")+COUNTIF(B4:B38,"SAGGI")+COUNTIF(B4:B38,"SECONDO")+COUNTIF(B4:B38,"SMART W")+COUNTIF(B4:B38,"STUDIO 1 e 2")+COUNTIF(B4:B38,"MANUTENZ.")+COUNTIF(B4:B38,"UFFICIO")+COUNTIF(B4:B38,"CAMPUS")+COUNTIF(B4:B38,"TEATRO")+COUNTIF(B4:B38,"AMM.ZIONE")+COUNTIF(B4:B38,"FORMAZ-1p")+COUNTIF(B4:B38,"FORMAZ-2p")+COUNTIF(B4:B38,"FORMAZ-rec")+COUNTIF(B4:B38,"WORKSHOP")+COUNTIF(B4:B38,"EVENTO EST."))/2 -> 8 | C39: =CONCATENATE(COUNTIF(C4:C38,"MAGAZZINI")+COUNTIF(C4:C38,"PRIMO")+COUNTIF(C4:C38,"RECEPTION")+COUNTIF(C4:C38,"SAGGI")+COUNTIF(C4:C38,"SECONDO")+COUNTIF(C4:C38,"SMART W")+COUNTIF(C4:C38,"STUDIO 1 e 2")+COUNTIF(C4:C38,"MANUTENZ.")+COUNTIF(C4:C38,"UFFICIO")+COUNTIF(C4:C38,"CAMPUS")+COUNTIF(C4:C38,"TEATRO")+COUNTIF(C4:C38,"AMM.ZIONE")+COUNTIF(C4:C38,"FORMAZ-1p")+COUNTIF(C4:C38,"FORMAZ-2p")+COUNTIF(C4:C38,"FORMAZ-rec")+COUNTIF(C4:C38,"WORKSHOP")+COUNTIF(C4:C38,"EVENTO EST."))/2 -> 8 | D39: =CONCATENATE(COUNTIF(D4:D38,"MAGAZZINI")+COUNTIF(D4:D38,"PRIMO")+COUNTIF(D4:D38,"RECEPTION")+COUNTIF(D4:D38,"SAGGI")+COUNTIF(D4:D38,"SECONDO")+COUNTIF(D4:D38,"SMART W")+COUNTIF(D4:D38,"STUDIO 1 e 2")+COUNTIF(D4:D38,"MANUTENZ.")+COUNTIF(D4:D38,"UFFICIO")+COUNTIF(D4:D38,"CAMPUS")+COUNTIF(D4:D38,"TEATRO")+COUNTIF(D4:D38,"AMM.ZIONE")+COUNTIF(D4:D38,"FORMAZ-1p")+COUNTIF(D4:D38,"FORMAZ-2p")+COUNTIF(D4:D38,"FORMAZ-rec")+COUNTIF(D4:D38,"WORKSHOP")+COUNTIF(D4:D38,"EVENTO EST."))/2 -> 8 | E39: =CONCATENATE(COUNTIF(E4:E38,"MAGAZZINI")+COUNTIF(E4:E38,"PRIMO")+COUNTIF(E4:E38,"RECEPTION")+COUNTIF(E4:E38,"SAGGI")+COUNTIF(E4:E38,"SECONDO")+COUNTIF(E4:E38,"SMART W")+COUNTIF(E4:E38,"STUDIO 1 e 2")+COUNTIF(E4:E38,"MANUTENZ.")+COUNTIF(E4:E38,"UFFICIO")+COUNTIF(E4:E38,"CAMPUS")+COUNTIF(E4:E38,"TEATRO")+COUNTIF(E4:E38,"AMM.ZIONE")+COUNTIF(E4:E38,"FORMAZ-1p")+COUNTIF(E4:E38,"FORMAZ-2p")+COUNTIF(E4:E38,"FORMAZ-rec")+COUNTIF(E4:E38,"WORKSHOP")+COUNTIF(E4:E38,"EVENTO EST."))/2 -> 8 | F39: =CONCATENATE(COUNTIF(F4:F38,"MAGAZZINI")+COUNTIF(F4:F38,"PRIMO")+COUNTIF(F4:F38,"RECEPTION")+COUNTIF(F4:F38,"SAGGI")+COUNTIF(F4:F38,"SECONDO")+COUNTIF(F4:F38,"SMART W")+COUNTIF(F4:F38,"STUDIO 1 e 2")+COUNTIF(F4:F38,"MANUTENZ.")+COUNTIF(F4:F38,"UFFICIO")+COUNTIF(F4:F38,"CAMPUS")+COUNTIF(F4:F38,"TEATRO")+COUNTIF(F4:F38,"AMM.ZIONE")+COUNTIF(F4:F38,"FORMAZ-1p")+COUNTIF(F4:F38,"FORMAZ-2p")+COUNTIF(F4:F38,"FORMAZ-rec")+COUNTIF(F4:F38,"WORKSHOP")+COUNTIF(F4:F38,"EVENTO EST."))/2 -> 8 | G39: =CONCATENATE(COUNTIF(G4:G38,"MAGAZZINI")+COUNTIF(G4:G38,"PRIMO")+COUNTIF(G4:G38,"RECEPTION")+COUNTIF(G4:G38,"SAGGI")+COUNTIF(G4:G38,"SECONDO")+COUNTIF(G4:G38,"SMART W")+COUNTIF(G4:G38,"STUDIO 1 e 2")+COUNTIF(G4:G38,"MANUTENZ.")+COUNTIF(G4:G38,"UFFICIO")+COUNTIF(G4:G38,"CAMPUS")+COUNTIF(G4:G38,"TEATRO")+COUNTIF(G4:G38,"AMM.ZIONE")+COUNTIF(G4:G38,"FORMAZ-1p")+COUNTIF(G4:G38,"FORMAZ-2p")+COUNTIF(G4:G38,"FORMAZ-rec")+COUNTIF(G4:G38,"WORKSHOP")+COUNTIF(G4:G38,"EVENTO EST."))/2 -> 8 | H39: =CONCATENATE(COUNTIF(H4:H38,"MAGAZZINI")+COUNTIF(H4:H38,"PRIMO")+COUNTIF(H4:H38,"RECEPTION")+COUNTIF(H4:H38,"SAGGI")+COUNTIF(H4:H38,"SECONDO")+COUNTIF(H4:H38,"SMART W")+COUNTIF(H4:H38,"STUDIO 1 e 2")+COUNTIF(H4:H38,"MANUTENZ.")+COUNTIF(H4:H38,"UFFICIO")+COUNTIF(H4:H38,"CAMPUS")+COUNTIF(H4:H38,"TEATRO")+COUNTIF(H4:H38,"AMM.ZIONE")+COUNTIF(H4:H38,"FORMAZ-1p")+COUNTIF(H4:H38,"FORMAZ-2p")+COUNTIF(H4:H38,"FORMAZ-rec")+COUNTIF(H4:H38,"WORKSHOP")+COUNTIF(H4:H38,"EVENTO EST."))/2 -> 8 | I39: =CONCATENATE(COUNTIF(I4:I38,"MAGAZZINI")+COUNTIF(I4:I38,"PRIMO")+COUNTIF(I4:I38,"RECEPTION")+COUNTIF(I4:I38,"SAGGI")+COUNTIF(I4:I38,"SECONDO")+COUNTIF(I4:I38,"SMART W")+COUNTIF(I4:I38,"STUDIO 1 e 2")+COUNTIF(I4:I38,"MANUTENZ.")+COUNTIF(I4:I38,"UFFICIO")+COUNTIF(I4:I38,"CAMPUS")+COUNTIF(I4:I38,"TEATRO")+COUNTIF(I4:I38,"AMM.ZIONE")+COUNTIF(I4:I38,"FORMAZ-1p")+COUNTIF(I4:I38,"FORMAZ-2p")+COUNTIF(I4:I38,"FORMAZ-rec")+COUNTIF(I4:I38,"WORKSHOP")+COUNTIF(I4:I38,"EVENTO EST."))/2 -> 8 | ... N39: =CONCATENATE(COUNTIF(N4:N38,"MAGAZZINI")+COUNTIF(N4:N38,"PRIMO")+COUNTIF(N4:N38,"RECEPTION")+COUNTIF(N4:N38,"SAGGI")+COUNTIF(N4:N38,"SECONDO")+COUNTIF(N4:N38,"SMART W")+COUNTIF(N4:N38,"STUDIO 1 e 2")+COUNTIF(N4:N38,"MANUTENZ.")+COUNTIF(N4:N38,"UFFICIO")+COUNTIF(N4:N38,"CAMPUS")+COUNTIF(N4:N38,"TEATRO")+COUNTIF(N4:N38,"AMM.ZIONE")+COUNTIF(N4:N38,"FORMAZ-1p")+COUNTIF(N4:N38,"FORMAZ-2p")+COUNTIF(N4:N38,"FORMAZ-rec")+COUNTIF(N4:N38,"WORKSHOP")+COUNTIF(N4:N38,"EVENTO EST."))/2 -> 8

Sheet VENERDÌ A
B1: VENERDÌ | D1: =elenchi!C1 ->  SETTIMANA - A | F1:  DA: | G1: =elenchi!D1 -> LUNEDI 20 A DOMENICA 26 APRILE 2026
A3: ORA | B3: =elenchi!B1 -> ALEXANDRA | C3: =elenchi!B2 -> GIUDITTA | D3: =elenchi!B3 -> ESTEFANY | E3: =elenchi!B4 -> NURA | F3: =elenchi!B5 | G3: =elenchi!B6 -> JOEL | H3: =elenchi!B7 -> KEVIN | I3: =elenchi!B8 -> JASIR | J3: =elenchi!B9 -> DIEGO | K3: =elenchi!B10 -> SARA | L3: =elenchi!B11 -> SANTO | M3: =elenchi!B12 -> MASSI | N3: =elenchi!B13
A4: 07:00
A5: 07:30
A6: 08:00
A7: 40475.354 | D7: RECEPTION | I7: PRIMO | K7: UFFICIO | L7: AMM.ZIONE
A8: 40475.375 | D8: RECEPTION | I8: PRIMO | K8: UFFICIO | L8: AMM.ZIONE | M8: UFFICIO
A9: 40475.396 | D9: RECEPTION | I9: PRIMO | K9: UFFICIO | L9: AMM.ZIONE | M9: UFFICIO
A10: 40475.417 | D10: RECEPTION | I10: PRIMO | K10: UFFICIO | L10: AMM.ZIONE | M10: UFFICIO
A11: 40475.438 | D11: RECEPTION | E11: PRIMO | I11: PRIMO | K11: UFFICIO | L11: AMM.ZIONE | M11: UFFICIO
A12: 40475.458 | D12: RECEPTION | E12: PRIMO | I12: PRIMO | K12: UFFICIO | L12: AMM.ZIONE | M12: UFFICIO
A13: 40475.479 | D13: RECEPTION | E13: PRIMO | I13: PRIMO | K13: UFFICIO | L13: AMM.ZIONE | M13: UFFICIO
A14: 40475.5 | D14: RECEPTION | E14: PRIMO | I14: PRIMO | K14: PAUSA | L14: AMM.ZIONE | M14: UFFICIO
A15: 40475.521 | D15: RECEPTION | E15: PRIMO | I15: PRIMO | K15: UFFICIO | L15: AMM.ZIONE | M15: UFFICIO
A16: 40475.542 | D16: RECEPTION | E16: PRIMO | I16: PRIMO | K16: UFFICIO | L16: PAUSA | M16: PAUSA
A17: 40475.562 | B17: PRIMO | C17: RECEPTION | D17: PAUSA | E17: PAUSA | G17: SECONDO | H17: PRIMO | I17: PAUSA | K17: UFFICIO | L17: AMM.ZIONE | M17: UFFICIO | N17: PRIMO
A18: 40475.583 | B18: PRIMO | C18: RECEPTION | D18: PRIMO | E18: PRIMO | G18: SECONDO | H18: PRIMO | I18: PRIMO | K18: UFFICIO | L18: AMM.ZIONE | M18: UFFICIO | N18: PRIMO
A19: 40475.604 | B19: PRIMO | C19: RECEPTION | D19: PRIMO | E19: PRIMO | G19: SECONDO | H19: PRIMO | I19: PRIMO | K19: UFFICIO | L19: AMM.ZIONE | M19: UFFICIO | N19: PRIMO
A20: 40475.625 | B20: PRIMO | C20: RECEPTION | D20: PRIMO | E20: PRIMO | G20: SECONDO | H20: PRIMO | I20: PRIMO | K20: UFFICIO | L20: AMM.ZIONE | M20: UFFICIO | N20: PRIMO
A21: 40475.646 | B21: PRIMO | C21: RECEPTION | D21: PRIMO | E21: PRIMO | G21: SECONDO | H21: PRIMO | I21: PRIMO | K21: UFFICIO | L21: AMM.ZIONE | M21: UFFICIO | N21: PRIMO
A22: 40475.667 | B22: PRIMO | C22: RECEPTION | D22: PRIMO | E22: PRIMO | G22: SECONDO | H22: PRIMO | I22: PRIMO | K22: UFFICIO | L22: AMM.ZIONE | M22: UFFICIO | N22: PRIMO
A23: 40475.688 | B23: PRIMO | C23: RECEPTION | D23: PRIMO | E23: PRIMO | G23: SECONDO | H23: PRIMO | I23: PRIMO | K23: UFFICIO | L23: AMM.ZIONE | M23: UFFICIO | N23: PRIMO
A24: 40475.708 | B24: PRIMO | C24: RECEPTION | E24: PRIMO | G24: SECONDO | H24: PRIMO | M24: UFFICIO | N24: PRIMO
A25: 40475.729 | B25: PAUSA | C25: PAUSA | E25: PRIMO | G25: SECONDO | H25: PRIMO | M25: UFFICIO | N25: PRIMO
A26: 40475.75 | B26: SECONDO | C26: PRIMO | E26: PRIMO | G26: PAUSA | H26: PAUSA | M26: UFFICIO | N26: PAUSA
A27: 40475.771 | B27: SECONDO | C27: PRIMO | E27: PRIMO | G27: RECEPTION | H27: SECONDO | N27: SECONDO
A28: 40475.792 | B28: SECONDO | C28: PRIMO | G28: RECEPTION | H28: SECONDO | N28: SECONDO
A29: 40475.812 | B29: SECONDO | C29: PRIMO | G29: RECEPTION | H29: SECONDO | N29: SECONDO
A30: 40475.833 | B30: SECONDO | C30: PRIMO | G30: RECEPTION | H30: SECONDO | N30: SECONDO
A31: 40475.854 | B31: SECONDO | C31: PRIMO | G31: RECEPTION | H31: SECONDO | N31: SECONDO
A32: 40475.875 | B32: SECONDO | C32: PRIMO | G32: RECEPTION | H32: SECONDO | N32: SECONDO
A33: 40475.896 | B33: SECONDO | C33: PRIMO | G33: RECEPTION | H33: SECONDO | N33: SECONDO
A34: 40475.917
A35: 40475.938
A36: 40475.958
A37: 40475.979
A38: 24:00
A39: TOT | B39: =CONCATENATE(COUNTIF(B4:B38,"MAGAZZINI")+COUNTIF(B4:B38,"PRIMO")+COUNTIF(B4:B38,"RECEPTION")+COUNTIF(B4:B38,"SAGGI")+COUNTIF(B4:B38,"SECONDO")+COUNTIF(B4:B38,"SMART W")+COUNTIF(B4:B38,"STUDIO 1 e 2")+COUNTIF(B4:B38,"MANUTENZ.")+COUNTIF(B4:B38,"UFFICIO")+COUNTIF(B4:B38,"CAMPUS")+COUNTIF(B4:B38,"TEATRO")+COUNTIF(B4:B38,"AMM.ZIONE")+COUNTIF(B4:B38,"FORMAZ-1p")+COUNTIF(B4:B38,"FORMAZ-2p")+COUNTIF(B4:B38,"FORMAZ-rec")+COUNTIF(B4:B38,"WORKSHOP")+COUNTIF(B4:B38,"EVENTO EST."))/2 -> 8 | C39: =CONCATENATE(COUNTIF(C4:C38,"MAGAZZINI")+COUNTIF(C4:C38,"PRIMO")+COUNTIF(C4:C38,"RECEPTION")+COUNTIF(C4:C38,"SAGGI")+COUNTIF(C4:C38,"SECONDO")+COUNTIF(C4:C38,"SMART W")+COUNTIF(C4:C38,"STUDIO 1 e 2")+COUNTIF(C4:C38,"MANUTENZ.")+COUNTIF(C4:C38,"UFFICIO")+COUNTIF(C4:C38,"CAMPUS")+COUNTIF(C4:C38,"TEATRO")+COUNTIF(C4:C38,"AMM.ZIONE")+COUNTIF(C4:C38,"FORMAZ-1p")+COUNTIF(C4:C38,"FORMAZ-2p")+COUNTIF(C4:C38,"FORMAZ-rec")+COUNTIF(C4:C38,"WORKSHOP")+COUNTIF(C4:C38,"EVENTO EST."))/2 -> 8 | D39: =CONCATENATE(COUNTIF(D4:D38,"MAGAZZINI")+COUNTIF(D4:D38,"PRIMO")+COUNTIF(D4:D38,"RECEPTION")+COUNTIF(D4:D38,"SAGGI")+COUNTIF(D4:D38,"SECONDO")+COUNTIF(D4:D38,"SMART W")+COUNTIF(D4:D38,"STUDIO 1 e 2")+COUNTIF(D4:D38,"MANUTENZ.")+COUNTIF(D4:D38,"UFFICIO")+COUNTIF(D4:D38,"CAMPUS")+COUNTIF(D4:D38,"TEATRO")+COUNTIF(D4:D38,"AMM.ZIONE")+COUNTIF(D4:D38,"FORMAZ-1p")+COUNTIF(D4:D38,"FORMAZ-2p")+COUNTIF(D4:D38,"FORMAZ-rec")+COUNTIF(D4:D38,"WORKSHOP")+COUNTIF(D4:D38,"EVENTO EST."))/2 -> 8 | E39: =CONCATENATE(COUNTIF(E4:E38,"MAGAZZINI")+COUNTIF(E4:E38,"PRIMO")+COUNTIF(E4:E38,"RECEPTION")+COUNTIF(E4:E38,"SAGGI")+COUNTIF(E4:E38,"SECONDO")+COUNTIF(E4:E38,"SMART W")+COUNTIF(E4:E38,"STUDIO 1 e 2")+COUNTIF(E4:E38,"MANUTENZ.")+COUNTIF(E4:E38,"UFFICIO")+COUNTIF(E4:E38,"CAMPUS")+COUNTIF(E4:E38,"TEATRO")+COUNTIF(E4:E38,"AMM.ZIONE")+COUNTIF(E4:E38,"FORMAZ-1p")+COUNTIF(E4:E38,"FORMAZ-2p")+COUNTIF(E4:E38,"FORMAZ-rec")+COUNTIF(E4:E38,"WORKSHOP")+COUNTIF(E4:E38,"EVENTO EST."))/2 -> 8 | F39: =CONCATENATE(COUNTIF(F4:F38,"MAGAZZINI")+COUNTIF(F4:F38,"PRIMO")+COUNTIF(F4:F38,"RECEPTION")+COUNTIF(F4:F38,"SAGGI")+COUNTIF(F4:F38,"SECONDO")+COUNTIF(F4:F38,"SMART W")+COUNTIF(F4:F38,"STUDIO 1 e 2")+COUNTIF(F4:F38,"MANUTENZ.")+COUNTIF(F4:F38,"UFFICIO")+COUNTIF(F4:F38,"CAMPUS")+COUNTIF(F4:F38,"TEATRO")+COUNTIF(F4:F38,"AMM.ZIONE")+COUNTIF(F4:F38,"FORMAZ-1p")+COUNTIF(F4:F38,"FORMAZ-2p")+COUNTIF(F4:F38,"FORMAZ-rec")+COUNTIF(F4:F38,"WORKSHOP")+COUNTIF(F4:F38,"EVENTO EST."))/2 -> 0 | G39: =CONCATENATE(COUNTIF(G4:G38,"MAGAZZINI")+COUNTIF(G4:G38,"PRIMO")+COUNTIF(G4:G38,"RECEPTION")+COUNTIF(G4:G38,"SAGGI")+COUNTIF(G4:G38,"SECONDO")+COUNTIF(G4:G38,"SMART W")+COUNTIF(G4:G38,"STUDIO 1 e 2")+COUNTIF(G4:G38,"MANUTENZ.")+COUNTIF(G4:G38,"UFFICIO")+COUNTIF(G4:G38,"CAMPUS")+COUNTIF(G4:G38,"TEATRO")+COUNTIF(G4:G38,"AMM.ZIONE")+COUNTIF(G4:G38,"FORMAZ-1p")+COUNTIF(G4:G38,"FORMAZ-2p")+COUNTIF(G4:G38,"FORMAZ-rec")+COUNTIF(G4:G38,"WORKSHOP")+COUNTIF(G4:G38,"EVENTO EST."))/2 -> 8 | H39: =CONCATENATE(COUNTIF(H4:H38,"MAGAZZINI")+COUNTIF(H4:H38,"PRIMO")+COUNTIF(H4:H38,"RECEPTION")+COUNTIF(H4:H38,"SAGGI")+COUNTIF(H4:H38,"SECONDO")+COUNTIF(H4:H38,"SMART W")+COUNTIF(H4:H38,"STUDIO 1 e 2")+COUNTIF(H4:H38,"MANUTENZ.")+COUNTIF(H4:H38,"UFFICIO")+COUNTIF(H4:H38,"CAMPUS")+COUNTIF(H4:H38,"TEATRO")+COUNTIF(H4:H38,"AMM.ZIONE")+COUNTIF(H4:H38,"FORMAZ-1p")+COUNTIF(H4:H38,"FORMAZ-2p")+COUNTIF(H4:H38,"FORMAZ-rec")+COUNTIF(H4:H38,"WORKSHOP")+COUNTIF(H4:H38,"EVENTO EST."))/2 -> 8 | I39: =CONCATENATE(COUNTIF(I4:I38,"MAGAZZINI")+COUNTIF(I4:I38,"PRIMO")+COUNTIF(I4:I38,"RECEPTION")+COUNTIF(I4:I38,"SAGGI")+COUNTIF(I4:I38,"SECONDO")+COUNTIF(I4:I38,"SMART W")+COUNTIF(I4:I38,"STUDIO 1 e 2")+COUNTIF(I4:I38,"MANUTENZ.")+COUNTIF(I4:I38,"UFFICIO")+COUNTIF(I4:I38,"CAMPUS")+COUNTIF(I4:I38,"TEATRO")+COUNTIF(I4:I38,"AMM.ZIONE")+COUNTIF(I4:I38,"FORMAZ-1p")+COUNTIF(I4:I38,"FORMAZ-2p")+COUNTIF(I4:I38,"FORMAZ-rec")+COUNTIF(I4:I38,"WORKSHOP")+COUNTIF(I4:I38,"EVENTO EST."))/2 -> 8 | ... N39: =CONCATENATE(COUNTIF(N4:N38,"MAGAZZINI")+COUNTIF(N4:N38,"PRIMO")+COUNTIF(N4:N38,"RECEPTION")+COUNTIF(N4:N38,"SAGGI")+COUNTIF(N4:N38,"SECONDO")+COUNTIF(N4:N38,"SMART W")+COUNTIF(N4:N38,"STUDIO 1 e 2")+COUNTIF(N4:N38,"MANUTENZ.")+COUNTIF(N4:N38,"UFFICIO")+COUNTIF(N4:N38,"CAMPUS")+COUNTIF(N4:N38,"TEATRO")+COUNTIF(N4:N38,"AMM.ZIONE")+COUNTIF(N4:N38,"FORMAZ-1p")+COUNTIF(N4:N38,"FORMAZ-2p")+COUNTIF(N4:N38,"FORMAZ-rec")+COUNTIF(N4:N38,"WORKSHOP")+COUNTIF(N4:N38,"EVENTO EST."))/2 -> 8

Sheet SABATO A
B1: SABATO | D1: =elenchi!C1 ->  SETTIMANA - A | F1:  DA: | G1: =elenchi!D1 -> LUNEDI 20 A DOMENICA 26 APRILE 2026
A3: ORA | B3: =elenchi!B1 -> ALEXANDRA | C3: =elenchi!B2 -> GIUDITTA | D3: =elenchi!B3 -> ESTEFANY | E3: =elenchi!B4 -> NURA | F3: =elenchi!B5 | G3: =elenchi!B6 -> JOEL | H3: =elenchi!B7 -> KEVIN | I3: =elenchi!B8 -> JASIR | J3: =elenchi!B9 -> DIEGO | K3: =elenchi!B10 -> SARA | L3: =elenchi!B11 -> SANTO | M3: =elenchi!B12 -> MASSI | N3: =elenchi!B13
A4: 07:00
A5: 07:30
A6: 08:00
A7: 40475.354
A8: 40475.375
A9: 40475.396
A10: 40475.417
A11: 40475.438
A12: 40475.458
A13: 40475.479
A14: 40475.5
A15: 40475.521
A16: 40475.542
A17: 40475.562
A18: 40475.583
... A37: 40475.979
A38: 24:00
A39: TOT | B39: =CONCATENATE(COUNTIF(B4:B38,"MAGAZZINI")+COUNTIF(B4:B38,"PRIMO")+COUNTIF(B4:B38,"RECEPTION")+COUNTIF(B4:B38,"SAGGI")+COUNTIF(B4:B38,"SECONDO")+COUNTIF(B4:B38,"SMART W")+COUNTIF(B4:B38,"STUDIO 1 e 2")+COUNTIF(B4:B38,"MANUTENZ.")+COUNTIF(B4:B38,"UFFICIO")+COUNTIF(B4:B38,"CAMPUS")+COUNTIF(B4:B38,"TEATRO")+COUNTIF(B4:B38,"AMM.ZIONE")+COUNTIF(B4:B38,"FORMAZ-1p")+COUNTIF(B4:B38,"FORMAZ-2p")+COUNTIF(B4:B38,"FORMAZ-rec")+COUNTIF(B4:B38,"WORKSHOP")+COUNTIF(B4:B38,"EVENTO EST."))/2 -> 0 | C39: =CONCATENATE(COUNTIF(C4:C38,"MAGAZZINI")+COUNTIF(C4:C38,"PRIMO")+COUNTIF(C4:C38,"RECEPTION")+COUNTIF(C4:C38,"SAGGI")+COUNTIF(C4:C38,"SECONDO")+COUNTIF(C4:C38,"SMART W")+COUNTIF(C4:C38,"STUDIO 1 e 2")+COUNTIF(C4:C38,"MANUTENZ.")+COUNTIF(C4:C38,"UFFICIO")+COUNTIF(C4:C38,"CAMPUS")+COUNTIF(C4:C38,"TEATRO")+COUNTIF(C4:C38,"AMM.ZIONE")+COUNTIF(C4:C38,"FORMAZ-1p")+COUNTIF(C4:C38,"FORMAZ-2p")+COUNTIF(C4:C38,"FORMAZ-rec")+COUNTIF(C4:C38,"WORKSHOP")+COUNTIF(C4:C38,"EVENTO EST."))/2 -> 0 | D39: =CONCATENATE(COUNTIF(D4:D38,"MAGAZZINI")+COUNTIF(D4:D38,"PRIMO")+COUNTIF(D4:D38,"RECEPTION")+COUNTIF(D4:D38,"SAGGI")+COUNTIF(D4:D38,"SECONDO")+COUNTIF(D4:D38,"SMART W")+COUNTIF(D4:D38,"STUDIO 1 e 2")+COUNTIF(D4:D38,"MANUTENZ.")+COUNTIF(D4:D38,"UFFICIO")+COUNTIF(D4:D38,"CAMPUS")+COUNTIF(D4:D38,"TEATRO")+COUNTIF(D4:D38,"AMM.ZIONE")+COUNTIF(D4:D38,"FORMAZ-1p")+COUNTIF(D4:D38,"FORMAZ-2p")+COUNTIF(D4:D38,"FORMAZ-rec")+COUNTIF(D4:D38,"WORKSHOP")+COUNTIF(D4:D38,"EVENTO EST."))/2 -> 0 | E39: =CONCATENATE(COUNTIF(E4:E38,"MAGAZZINI")+COUNTIF(E4:E38,"PRIMO")+COUNTIF(E4:E38,"RECEPTION")+COUNTIF(E4:E38,"SAGGI")+COUNTIF(E4:E38,"SECONDO")+COUNTIF(E4:E38,"SMART W")+COUNTIF(E4:E38,"STUDIO 1 e 2")+COUNTIF(E4:E38,"MANUTENZ.")+COUNTIF(E4:E38,"UFFICIO")+COUNTIF(E4:E38,"CAMPUS")+COUNTIF(E4:E38,"TEATRO")+COUNTIF(E4:E38,"AMM.ZIONE")+COUNTIF(E4:E38,"FORMAZ-1p")+COUNTIF(E4:E38,"FORMAZ-2p")+COUNTIF(E4:E38,"FORMAZ-rec")+COUNTIF(E4:E38,"WORKSHOP")+COUNTIF(E4:E38,"EVENTO EST."))/2 -> 0 | F39: =CONCATENATE(COUNTIF(F4:F38,"MAGAZZINI")+COUNTIF(F4:F38,"PRIMO")+COUNTIF(F4:F38,"RECEPTION")+COUNTIF(F4:F38,"SAGGI")+COUNTIF(F4:F38,"SECONDO")+COUNTIF(F4:F38,"SMART W")+COUNTIF(F4:F38,"STUDIO 1 e 2")+COUNTIF(F4:F38,"MANUTENZ.")+COUNTIF(F4:F38,"UFFICIO")+COUNTIF(F4:F38,"CAMPUS")+COUNTIF(F4:F38,"TEATRO")+COUNTIF(F4:F38,"AMM.ZIONE")+COUNTIF(F4:F38,"FORMAZ-1p")+COUNTIF(F4:F38,"FORMAZ-2p")+COUNTIF(F4:F38,"FORMAZ-rec")+COUNTIF(F4:F38,"WORKSHOP")+COUNTIF(F4:F38,"EVENTO EST."))/2 -> 0 | G39: =CONCATENATE(COUNTIF(G4:G38,"MAGAZZINI")+COUNTIF(G4:G38,"PRIMO")+COUNTIF(G4:G38,"RECEPTION")+COUNTIF(G4:G38,"SAGGI")+COUNTIF(G4:G38,"SECONDO")+COUNTIF(G4:G38,"SMART W")+COUNTIF(G4:G38,"STUDIO 1 e 2")+COUNTIF(G4:G38,"MANUTENZ.")+COUNTIF(G4:G38,"UFFICIO")+COUNTIF(G4:G38,"CAMPUS")+COUNTIF(G4:G38,"TEATRO")+COUNTIF(G4:G38,"AMM.ZIONE")+COUNTIF(G4:G38,"FORMAZ-1p")+COUNTIF(G4:G38,"FORMAZ-2p")+COUNTIF(G4:G38,"FORMAZ-rec")+COUNTIF(G4:G38,"WORKSHOP")+COUNTIF(G4:G38,"EVENTO EST."))/2 -> 0 | H39: =CONCATENATE(COUNTIF(H4:H38,"MAGAZZINI")+COUNTIF(H4:H38,"PRIMO")+COUNTIF(H4:H38,"RECEPTION")+COUNTIF(H4:H38,"SAGGI")+COUNTIF(H4:H38,"SECONDO")+COUNTIF(H4:H38,"SMART W")+COUNTIF(H4:H38,"STUDIO 1 e 2")+COUNTIF(H4:H38,"MANUTENZ.")+COUNTIF(H4:H38,"UFFICIO")+COUNTIF(H4:H38,"CAMPUS")+COUNTIF(H4:H38,"TEATRO")+COUNTIF(H4:H38,"AMM.ZIONE")+COUNTIF(H4:H38,"FORMAZ-1p")+COUNTIF(H4:H38,"FORMAZ-2p")+COUNTIF(H4:H38,"FORMAZ-rec")+COUNTIF(H4:H38,"WORKSHOP")+COUNTIF(H4:H38,"EVENTO EST."))/2 -> 0 | I39: =CONCATENATE(COUNTIF(I4:I38,"MAGAZZINI")+COUNTIF(I4:I38,"PRIMO")+COUNTIF(I4:I38,"RECEPTION")+COUNTIF(I4:I38,"SAGGI")+COUNTIF(I4:I38,"SECONDO")+COUNTIF(I4:I38,"SMART W")+COUNTIF(I4:I38,"STUDIO 1 e 2")+COUNTIF(I4:I38,"MANUTENZ.")+COUNTIF(I4:I38,"UFFICIO")+COUNTIF(I4:I38,"CAMPUS")+COUNTIF(I4:I38,"TEATRO")+COUNTIF(I4:I38,"AMM.ZIONE")+COUNTIF(I4:I38,"FORMAZ-1p")+COUNTIF(I4:I38,"FORMAZ-2p")+COUNTIF(I4:I38,"FORMAZ-rec")+COUNTIF(I4:I38,"WORKSHOP")+COUNTIF(I4:I38,"EVENTO EST."))/2 -> 0 | ... N39: =CONCATENATE(COUNTIF(N4:N38,"MAGAZZINI")+COUNTIF(N4:N38,"PRIMO")+COUNTIF(N4:N38,"RECEPTION")+COUNTIF(N4:N38,"SAGGI")+COUNTIF(N4:N38,"SECONDO")+COUNTIF(N4:N38,"SMART W")+COUNTIF(N4:N38,"STUDIO 1 e 2")+COUNTIF(N4:N38,"MANUTENZ.")+COUNTIF(N4:N38,"UFFICIO")+COUNTIF(N4:N38,"CAMPUS")+COUNTIF(N4:N38,"TEATRO")+COUNTIF(N4:N38,"AMM.ZIONE")+COUNTIF(N4:N38,"FORMAZ-1p")+COUNTIF(N4:N38,"FORMAZ-2p")+COUNTIF(N4:N38,"FORMAZ-rec")+COUNTIF(N4:N38,"WORKSHOP")+COUNTIF(N4:N38,"EVENTO EST."))/2 -> 0

Sheet DOMENICA A
B1: DOMENICA | D1: =elenchi!C1 ->  SETTIMANA - A | F1:  DA: | G1: =elenchi!D1 -> LUNEDI 20 A DOMENICA 26 APRILE 2026
A3: ORA | B3: =elenchi!B1 -> ALEXANDRA | C3: =elenchi!B2 -> GIUDITTA | D3: =elenchi!B3 -> ESTEFANY | E3: =elenchi!B4 -> NURA | F3: =elenchi!B5 | G3: =elenchi!B6 -> JOEL | H3: =elenchi!B7 -> KEVIN | I3: =elenchi!B8 -> JASIR | J3: =elenchi!B9 -> DIEGO | K3: =elenchi!B10 -> SARA | L3: =elenchi!B11 -> SANTO | M3: =elenchi!B12 -> MASSI | N3: =elenchi!B13
A4: 07:00
A5: 07:30
A6: 08:00
A7: 40475.354
A8: 40475.375
A9: 40475.396
A10: 40475.417
A11: 40475.438
A12: 40475.458
A13: 40475.479
A14: 40475.5
A15: 40475.521
A16: 40475.542
A17: 40475.562
A18: 40475.583
... A37: 40475.979
A38: 24:00
A39: TOT | B39: =CONCATENATE(COUNTIF(B4:B38,"MAGAZZINI")+COUNTIF(B4:B38,"PRIMO")+COUNTIF(B4:B38,"RECEPTION")+COUNTIF(B4:B38,"SAGGI")+COUNTIF(B4:B38,"SECONDO")+COUNTIF(B4:B38,"SMART W")+COUNTIF(B4:B38,"STUDIO 1 e 2")+COUNTIF(B4:B38,"MANUTENZ.")+COUNTIF(B4:B38,"UFFICIO")+COUNTIF(B4:B38,"CAMPUS")+COUNTIF(B4:B38,"TEATRO")+COUNTIF(B4:B38,"AMM.ZIONE")+COUNTIF(B4:B38,"FORMAZ-1p")+COUNTIF(B4:B38,"FORMAZ-2p")+COUNTIF(B4:B38,"FORMAZ-rec")+COUNTIF(B4:B38,"WORKSHOP")+COUNTIF(B4:B38,"EVENTO EST."))/2 -> 0 | C39: =CONCATENATE(COUNTIF(C4:C38,"MAGAZZINI")+COUNTIF(C4:C38,"PRIMO")+COUNTIF(C4:C38,"RECEPTION")+COUNTIF(C4:C38,"SAGGI")+COUNTIF(C4:C38,"SECONDO")+COUNTIF(C4:C38,"SMART W")+COUNTIF(C4:C38,"STUDIO 1 e 2")+COUNTIF(C4:C38,"MANUTENZ.")+COUNTIF(C4:C38,"UFFICIO")+COUNTIF(C4:C38,"CAMPUS")+COUNTIF(C4:C38,"TEATRO")+COUNTIF(C4:C38,"AMM.ZIONE")+COUNTIF(C4:C38,"FORMAZ-1p")+COUNTIF(C4:C38,"FORMAZ-2p")+COUNTIF(C4:C38,"FORMAZ-rec")+COUNTIF(C4:C38,"WORKSHOP")+COUNTIF(C4:C38,"EVENTO EST."))/2 -> 0 | D39: =CONCATENATE(COUNTIF(D4:D38,"MAGAZZINI")+COUNTIF(D4:D38,"PRIMO")+COUNTIF(D4:D38,"RECEPTION")+COUNTIF(D4:D38,"SAGGI")+COUNTIF(D4:D38,"SECONDO")+COUNTIF(D4:D38,"SMART W")+COUNTIF(D4:D38,"STUDIO 1 e 2")+COUNTIF(D4:D38,"MANUTENZ.")+COUNTIF(D4:D38,"UFFICIO")+COUNTIF(D4:D38,"CAMPUS")+COUNTIF(D4:D38,"TEATRO")+COUNTIF(D4:D38,"AMM.ZIONE")+COUNTIF(D4:D38,"FORMAZ-1p")+COUNTIF(D4:D38,"FORMAZ-2p")+COUNTIF(D4:D38,"FORMAZ-rec")+COUNTIF(D4:D38,"WORKSHOP")+COUNTIF(D4:D38,"EVENTO EST."))/2 -> 0 | E39: =CONCATENATE(COUNTIF(E4:E38,"MAGAZZINI")+COUNTIF(E4:E38,"PRIMO")+COUNTIF(E4:E38,"RECEPTION")+COUNTIF(E4:E38,"SAGGI")+COUNTIF(E4:E38,"SECONDO")+COUNTIF(E4:E38,"SMART W")+COUNTIF(E4:E38,"STUDIO 1 e 2")+COUNTIF(E4:E38,"MANUTENZ.")+COUNTIF(E4:E38,"UFFICIO")+COUNTIF(E4:E38,"CAMPUS")+COUNTIF(E4:E38,"TEATRO")+COUNTIF(E4:E38,"AMM.ZIONE")+COUNTIF(E4:E38,"FORMAZ-1p")+COUNTIF(E4:E38,"FORMAZ-2p")+COUNTIF(E4:E38,"FORMAZ-rec")+COUNTIF(E4:E38,"WORKSHOP")+COUNTIF(E4:E38,"EVENTO EST."))/2 -> 0 | F39: =CONCATENATE(COUNTIF(F4:F38,"MAGAZZINI")+COUNTIF(F4:F38,"PRIMO")+COUNTIF(F4:F38,"RECEPTION")+COUNTIF(F4:F38,"SAGGI")+COUNTIF(F4:F38,"SECONDO")+COUNTIF(F4:F38,"SMART W")+COUNTIF(F4:F38,"STUDIO 1 e 2")+COUNTIF(F4:F38,"MANUTENZ.")+COUNTIF(F4:F38,"UFFICIO")+COUNTIF(F4:F38,"CAMPUS")+COUNTIF(F4:F38,"TEATRO")+COUNTIF(F4:F38,"AMM.ZIONE")+COUNTIF(F4:F38,"FORMAZ-1p")+COUNTIF(F4:F38,"FORMAZ-2p")+COUNTIF(F4:F38,"FORMAZ-rec")+COUNTIF(F4:F38,"WORKSHOP")+COUNTIF(F4:F38,"EVENTO EST."))/2 -> 0 | G39: =CONCATENATE(COUNTIF(G4:G38,"MAGAZZINI")+COUNTIF(G4:G38,"PRIMO")+COUNTIF(G4:G38,"RECEPTION")+COUNTIF(G4:G38,"SAGGI")+COUNTIF(G4:G38,"SECONDO")+COUNTIF(G4:G38,"SMART W")+COUNTIF(G4:G38,"STUDIO 1 e 2")+COUNTIF(G4:G38,"MANUTENZ.")+COUNTIF(G4:G38,"UFFICIO")+COUNTIF(G4:G38,"CAMPUS")+COUNTIF(G4:G38,"TEATRO")+COUNTIF(G4:G38,"AMM.ZIONE")+COUNTIF(G4:G38,"FORMAZ-1p")+COUNTIF(G4:G38,"FORMAZ-2p")+COUNTIF(G4:G38,"FORMAZ-rec")+COUNTIF(G4:G38,"WORKSHOP")+COUNTIF(G4:G38,"EVENTO EST."))/2 -> 0 | H39: =CONCATENATE(COUNTIF(H4:H38,"MAGAZZINI")+COUNTIF(H4:H38,"PRIMO")+COUNTIF(H4:H38,"RECEPTION")+COUNTIF(H4:H38,"SAGGI")+COUNTIF(H4:H38,"SECONDO")+COUNTIF(H4:H38,"SMART W")+COUNTIF(H4:H38,"STUDIO 1 e 2")+COUNTIF(H4:H38,"MANUTENZ.")+COUNTIF(H4:H38,"UFFICIO")+COUNTIF(H4:H38,"CAMPUS")+COUNTIF(H4:H38,"TEATRO")+COUNTIF(H4:H38,"AMM.ZIONE")+COUNTIF(H4:H38,"FORMAZ-1p")+COUNTIF(H4:H38,"FORMAZ-2p")+COUNTIF(H4:H38,"FORMAZ-rec")+COUNTIF(H4:H38,"WORKSHOP")+COUNTIF(H4:H38,"EVENTO EST."))/2 -> 0 | I39: =CONCATENATE(COUNTIF(I4:I38,"MAGAZZINI")+COUNTIF(I4:I38,"PRIMO")+COUNTIF(I4:I38,"RECEPTION")+COUNTIF(I4:I38,"SAGGI")+COUNTIF(I4:I38,"SECONDO")+COUNTIF(I4:I38,"SMART W")+COUNTIF(I4:I38,"STUDIO 1 e 2")+COUNTIF(I4:I38,"MANUTENZ.")+COUNTIF(I4:I38,"UFFICIO")+COUNTIF(I4:I38,"CAMPUS")+COUNTIF(I4:I38,"TEATRO")+COUNTIF(I4:I38,"AMM.ZIONE")+COUNTIF(I4:I38,"FORMAZ-1p")+COUNTIF(I4:I38,"FORMAZ-2p")+COUNTIF(I4:I38,"FORMAZ-rec")+COUNTIF(I4:I38,"WORKSHOP")+COUNTIF(I4:I38,"EVENTO EST."))/2 -> 0 | ... N39: =CONCATENATE(COUNTIF(N4:N38,"MAGAZZINI")+COUNTIF(N4:N38,"PRIMO")+COUNTIF(N4:N38,"RECEPTION")+COUNTIF(N4:N38,"SAGGI")+COUNTIF(N4:N38,"SECONDO")+COUNTIF(N4:N38,"SMART W")+COUNTIF(N4:N38,"STUDIO 1 e 2")+COUNTIF(N4:N38,"MANUTENZ.")+COUNTIF(N4:N38,"UFFICIO")+COUNTIF(N4:N38,"CAMPUS")+COUNTIF(N4:N38,"TEATRO")+COUNTIF(N4:N38,"AMM.ZIONE")+COUNTIF(N4:N38,"FORMAZ-1p")+COUNTIF(N4:N38,"FORMAZ-2p")+COUNTIF(N4:N38,"FORMAZ-rec")+COUNTIF(N4:N38,"WORKSHOP")+COUNTIF(N4:N38,"EVENTO EST."))/2 -> 0

Sheet LUNEDÌ B
B1: LUNEDÌ | D1: =elenchi!C2 ->  SETTIMANA - B | F1:  DA: | G1: =elenchi!D2 -> LUNEDI 23 A DOMENICA 29 MARZO 2026
A3: ORA | B3: =elenchi!B1 -> ALEXANDRA | C3: =elenchi!B2 -> GIUDITTA | D3: =elenchi!B3 -> ESTEFANY | E3: =elenchi!B4 -> NURA | F3: =elenchi!B5 | G3: =elenchi!B6 -> JOEL | H3: =elenchi!B7 -> KEVIN | I3: =elenchi!B8 -> JASIR | J3: =elenchi!B9 -> DIEGO | K3: =elenchi!B10 -> SARA | L3: =elenchi!B11 -> SANTO | M3: =elenchi!B12 -> MASSI | N3: =elenchi!B13
A4: 07:00
A5: 07:30
A6: 08:00
A7: 40475.354 | B7: RECEPTION | H7: PRIMO | K7: UFFICIO | L7: AMM.ZIONE
A8: 40475.375 | B8: RECEPTION | H8: PRIMO | K8: UFFICIO | L8: AMM.ZIONE
A9: 40475.396 | B9: RECEPTION | H9: PRIMO | K9: UFFICIO | L9: AMM.ZIONE
A10: 40475.417 | B10: RECEPTION | H10: PRIMO | K10: UFFICIO | L10: AMM.ZIONE | M10: UFFICIO
A11: 40475.438 | B11: RECEPTION | E11: PRIMO | H11: PRIMO | K11: UFFICIO | L11: AMM.ZIONE | M11: UFFICIO
A12: 40475.458 | B12: RECEPTION | E12: PRIMO | H12: PRIMO | K12: UFFICIO | L12: AMM.ZIONE | M12: UFFICIO
A13: 40475.479 | B13: RECEPTION | E13: PRIMO | H13: PRIMO | K13: UFFICIO | L13: AMM.ZIONE | M13: UFFICIO
A14: 40475.5 | B14: RECEPTION | E14: PRIMO | H14: PRIMO | K14: PAUSA | L14: AMM.ZIONE | M14: UFFICIO
A15: 40475.521 | B15: PAUSA | E15: PRIMO | H15: PRIMO | K15: UFFICIO | L15: AMM.ZIONE | M15: UFFICIO
A16: 40475.542 | B16: PRIMO | E16: RECEPTION | H16: PRIMO | K16: UFFICIO | L16: PAUSA | M16: PAUSA
A17: 40475.562 | B17: PRIMO | E17: RECEPTION | H17: PAUSA | K17: UFFICIO | L17: AMM.ZIONE | M17: UFFICIO
A18: 40475.583 | B18: PRIMO | E18: RECEPTION | H18: PRIMO | K18: UFFICIO | L18: AMM.ZIONE | M18: UFFICIO
A19: 40475.604 | B19: PRIMO | C19: PRIMO | D19: SECONDO | E19: PAUSA | G19: RECEPTION | H19: PRIMO | I19: SECONDO | J19: PRIMO | K19: UFFICIO | L19: AMM.ZIONE | M19: UFFICIO
A20: 40475.625 | B20: PRIMO | C20: PRIMO | D20: SECONDO | E20: SECONDO | G20: RECEPTION | H20: PRIMO | I20: SECONDO | J20: PRIMO | K20: UFFICIO | L20: AMM.ZIONE | M20: UFFICIO
A21: 40475.646 | B21: PRIMO | C21: PRIMO | D21: SECONDO | E21: SECONDO | G21: RECEPTION | H21: PRIMO | I21: SECONDO | J21: PRIMO | K21: UFFICIO | L21: AMM.ZIONE | M21: UFFICIO
A22: 40475.667 | B22: PRIMO | C22: PRIMO | D22: SECONDO | E22: SECONDO | G22: RECEPTION | H22: PRIMO | I22: SECONDO | J22: PRIMO | K22: UFFICIO | L22: AMM.ZIONE | M22: UFFICIO
A23: 40475.688 | B23: PRIMO | C23: PRIMO | D23: SECONDO | E23: SECONDO | G23: RECEPTION | H23: PRIMO | I23: SECONDO | J23: PRIMO | K23: UFFICIO | L23: AMM.ZIONE | M23: UFFICIO
A24: 40475.708 | C24: PRIMO | D24: SECONDO | E24: SECONDO | G24: RECEPTION | I24: SECONDO | J24: PRIMO | M24: UFFICIO
A25: 40475.729 | C25: PRIMO | D25: SECONDO | E25: SECONDO | G25: RECEPTION | I25: SECONDO | J25: PRIMO | M25: UFFICIO
A26: 40475.75 | C26: PRIMO | D26: PAUSA | E26: SECONDO | G26: RECEPTION | I26: SECONDO | J26: PAUSA | M26: UFFICIO
A27: 40475.771 | C27: PRIMO | D27: RECEPTION | E27: SECONDO | G27: PAUSA | I27: PAUSA | J27: PRIMO
A28: 40475.792 | C28: PAUSA | D28: RECEPTION | G28: PRIMO | I28: PRIMO | J28: PRIMO
A29: 40475.812 | C29: SECONDO | D29: RECEPTION | G29: PRIMO | I29: PRIMO | J29: PRIMO
A30: 40475.833 | C30: SECONDO | D30: RECEPTION | G30: PRIMO | I30: PRIMO | J30: PRIMO
A31: 40475.854 | C31: SECONDO | D31: RECEPTION | G31: PRIMO | I31: PRIMO | J31: PRIMO
A32: 40475.875 | C32: SECONDO | D32: RECEPTION | G32: PRIMO | I32: PRIMO | J32: PRIMO
A33: 40475.896 | C33: SECONDO | D33: RECEPTION | G33: PRIMO | I33: PRIMO | J33: PRIMO
A34: 40475.917 | C34: SECONDO | D34: RECEPTION | G34: PRIMO | I34: PRIMO | J34: PRIMO
A35: 40475.938 | C35: SECONDO | D35: RECEPTION | G35: PRIMO | I35: PRIMO | J35: PRIMO
A36: 40475.958
A37: 40475.979
A38: 24:00
A39: TOT | B39: =CONCATENATE(COUNTIF(B4:B38,"MAGAZZINI")+COUNTIF(B4:B38,"PRIMO")+COUNTIF(B4:B38,"RECEPTION")+COUNTIF(B4:B38,"SAGGI")+COUNTIF(B4:B38,"SECONDO")+COUNTIF(B4:B38,"SMART W")+COUNTIF(B4:B38,"STUDIO 1 e 2")+COUNTIF(B4:B38,"MANUTENZ.")+COUNTIF(B4:B38,"UFFICIO")+COUNTIF(B4:B38,"CAMPUS")+COUNTIF(B4:B38,"TEATRO")+COUNTIF(B4:B38,"AMM.ZIONE")+COUNTIF(B4:B38,"FORMAZ-1p")+COUNTIF(B4:B38,"FORMAZ-2p")+COUNTIF(B4:B38,"FORMAZ-rec")+COUNTIF(B4:B38,"WORKSHOP")+COUNTIF(B4:B38,"EVENTO EST."))/2 -> 8 | C39: =CONCATENATE(COUNTIF(C4:C38,"MAGAZZINI")+COUNTIF(C4:C38,"PRIMO")+COUNTIF(C4:C38,"RECEPTION")+COUNTIF(C4:C38,"SAGGI")+COUNTIF(C4:C38,"SECONDO")+COUNTIF(C4:C38,"SMART W")+COUNTIF(C4:C38,"STUDIO 1 e 2")+COUNTIF(C4:C38,"MANUTENZ.")+COUNTIF(C4:C38,"UFFICIO")+COUNTIF(C4:C38,"CAMPUS")+COUNTIF(C4:C38,"TEATRO")+COUNTIF(C4:C38,"AMM.ZIONE")+COUNTIF(C4:C38,"FORMAZ-1p")+COUNTIF(C4:C38,"FORMAZ-2p")+COUNTIF(C4:C38,"FORMAZ-rec")+COUNTIF(C4:C38,"WORKSHOP")+COUNTIF(C4:C38,"EVENTO EST."))/2 -> 8 | D39: =CONCATENATE(COUNTIF(D4:D38,"MAGAZZINI")+COUNTIF(D4:D38,"PRIMO")+COUNTIF(D4:D38,"RECEPTION")+COUNTIF(D4:D38,"SAGGI")+COUNTIF(D4:D38,"SECONDO")+COUNTIF(D4:D38,"SMART W")+COUNTIF(D4:D38,"STUDIO 1 e 2")+COUNTIF(D4:D38,"MANUTENZ.")+COUNTIF(D4:D38,"UFFICIO")+COUNTIF(D4:D38,"CAMPUS")+COUNTIF(D4:D38,"TEATRO")+COUNTIF(D4:D38,"AMM.ZIONE")+COUNTIF(D4:D38,"FORMAZ-1p")+COUNTIF(D4:D38,"FORMAZ-2p")+COUNTIF(D4:D38,"FORMAZ-rec")+COUNTIF(D4:D38,"WORKSHOP")+COUNTIF(D4:D38,"EVENTO EST."))/2 -> 8 | E39: =CONCATENATE(COUNTIF(E4:E38,"MAGAZZINI")+COUNTIF(E4:E38,"PRIMO")+COUNTIF(E4:E38,"RECEPTION")+COUNTIF(E4:E38,"SAGGI")+COUNTIF(E4:E38,"SECONDO")+COUNTIF(E4:E38,"SMART W")+COUNTIF(E4:E38,"STUDIO 1 e 2")+COUNTIF(E4:E38,"MANUTENZ.")+COUNTIF(E4:E38,"UFFICIO")+COUNTIF(E4:E38,"CAMPUS")+COUNTIF(E4:E38,"TEATRO")+COUNTIF(E4:E38,"AMM.ZIONE")+COUNTIF(E4:E38,"FORMAZ-1p")+COUNTIF(E4:E38,"FORMAZ-2p")+COUNTIF(E4:E38,"FORMAZ-rec")+COUNTIF(E4:E38,"WORKSHOP")+COUNTIF(E4:E38,"EVENTO EST."))/2 -> 8 | F39: =CONCATENATE(COUNTIF(F4:F38,"MAGAZZINI")+COUNTIF(F4:F38,"PRIMO")+COUNTIF(F4:F38,"RECEPTION")+COUNTIF(F4:F38,"SAGGI")+COUNTIF(F4:F38,"SECONDO")+COUNTIF(F4:F38,"SMART W")+COUNTIF(F4:F38,"STUDIO 1 e 2")+COUNTIF(F4:F38,"MANUTENZ.")+COUNTIF(F4:F38,"UFFICIO")+COUNTIF(F4:F38,"CAMPUS")+COUNTIF(F4:F38,"TEATRO")+COUNTIF(F4:F38,"AMM.ZIONE")+COUNTIF(F4:F38,"FORMAZ-1p")+COUNTIF(F4:F38,"FORMAZ-2p")+COUNTIF(F4:F38,"FORMAZ-rec")+COUNTIF(F4:F38,"WORKSHOP")+COUNTIF(F4:F38,"EVENTO EST."))/2 -> 0 | G39: =CONCATENATE(COUNTIF(G4:G38,"MAGAZZINI")+COUNTIF(G4:G38,"PRIMO")+COUNTIF(G4:G38,"RECEPTION")+COUNTIF(G4:G38,"SAGGI")+COUNTIF(G4:G38,"SECONDO")+COUNTIF(G4:G38,"SMART W")+COUNTIF(G4:G38,"STUDIO 1 e 2")+COUNTIF(G4:G38,"MANUTENZ.")+COUNTIF(G4:G38,"UFFICIO")+COUNTIF(G4:G38,"CAMPUS")+COUNTIF(G4:G38,"TEATRO")+COUNTIF(G4:G38,"AMM.ZIONE")+COUNTIF(G4:G38,"FORMAZ-1p")+COUNTIF(G4:G38,"FORMAZ-2p")+COUNTIF(G4:G38,"FORMAZ-rec")+COUNTIF(G4:G38,"WORKSHOP")+COUNTIF(G4:G38,"EVENTO EST."))/2 -> 8 | H39: =CONCATENATE(COUNTIF(H4:H38,"MAGAZZINI")+COUNTIF(H4:H38,"PRIMO")+COUNTIF(H4:H38,"RECEPTION")+COUNTIF(H4:H38,"SAGGI")+COUNTIF(H4:H38,"SECONDO")+COUNTIF(H4:H38,"SMART W")+COUNTIF(H4:H38,"STUDIO 1 e 2")+COUNTIF(H4:H38,"MANUTENZ.")+COUNTIF(H4:H38,"UFFICIO")+COUNTIF(H4:H38,"CAMPUS")+COUNTIF(H4:H38,"TEATRO")+COUNTIF(H4:H38,"AMM.ZIONE")+COUNTIF(H4:H38,"FORMAZ-1p")+COUNTIF(H4:H38,"FORMAZ-2p")+COUNTIF(H4:H38,"FORMAZ-rec")+COUNTIF(H4:H38,"WORKSHOP")+COUNTIF(H4:H38,"EVENTO EST."))/2 -> 8 | I39: =CONCATENATE(COUNTIF(I4:I38,"MAGAZZINI")+COUNTIF(I4:I38,"PRIMO")+COUNTIF(I4:I38,"RECEPTION")+COUNTIF(I4:I38,"SAGGI")+COUNTIF(I4:I38,"SECONDO")+COUNTIF(I4:I38,"SMART W")+COUNTIF(I4:I38,"STUDIO 1 e 2")+COUNTIF(I4:I38,"MANUTENZ.")+COUNTIF(I4:I38,"UFFICIO")+COUNTIF(I4:I38,"CAMPUS")+COUNTIF(I4:I38,"TEATRO")+COUNTIF(I4:I38,"AMM.ZIONE")+COUNTIF(I4:I38,"FORMAZ-1p")+COUNTIF(I4:I38,"FORMAZ-2p")+COUNTIF(I4:I38,"FORMAZ-rec")+COUNTIF(I4:I38,"WORKSHOP")+COUNTIF(I4:I38,"EVENTO EST."))/2 -> 8 | ... N39: =CONCATENATE(COUNTIF(N4:N38,"MAGAZZINI")+COUNTIF(N4:N38,"PRIMO")+COUNTIF(N4:N38,"RECEPTION")+COUNTIF(N4:N38,"SAGGI")+COUNTIF(N4:N38,"SECONDO")+COUNTIF(N4:N38,"SMART W")+COUNTIF(N4:N38,"STUDIO 1 e 2")+COUNTIF(N4:N38,"MANUTENZ.")+COUNTIF(N4:N38,"UFFICIO")+COUNTIF(N4:N38,"CAMPUS")+COUNTIF(N4:N38,"TEATRO")+COUNTIF(N4:N38,"AMM.ZIONE")+COUNTIF(N4:N38,"FORMAZ-1p")+COUNTIF(N4:N38,"FORMAZ-2p")+COUNTIF(N4:N38,"FORMAZ-rec")+COUNTIF(N4:N38,"WORKSHOP")+COUNTIF(N4:N38,"EVENTO EST."))/2 -> 0

Sheet MARTEDÌ B
