Workbook

Sheet Settembre25
A1: 45901 | B1: =elenchi!A1 -> ALEXANDRA | C1: =elenchi!A2 -> GIUDITTA | D1: =elenchi!A3 -> ESTEFANY | E1: =elenchi!A4 -> NURA | F1: =elenchi!A5 -> JOEL | G1: =elenchi!A6 -> KEVIN | H1: =elenchi!A7 -> ZOILA | I1: =elenchi!A8 -> JASIR | J1: =elenchi!A9 -> SARA | K1: =elenchi!A10 -> SANTO | L1: =elenchi!A11 -> MASSI | M1: =elenchi!A12 -> STEFANO | N1: =elenchi!A13 -> DIEGO | O1: =elenchi!A14 -> ELISA | P1: =elenchi!A15 -> GAETANO
A2: 45901 | B2: 8 | C2: 8 | D2: 8 | E2: 8 | F2: ML | G2: 8 | H2: 8 | I2: 7.5 | J2: 8 | K2: 8 | L2: 8 | O2: 8 | P2: 8
A3: 45902 | B3: 8 | C3: 8 | D3: 8 | E3: 8 | F3: ML | G3: 8 | H3: 8 | I3: 8 | J3: 8 | K3: 8 | L3: 8 | O3: 8 | P3: 8
A4: 45903 | B4: 8 | C4: 7.5 | D4: 6 | E4: 8 | F4: ML | G4: 8 | H4: 8 | I4: 8 | J4: 8 | K4: 8 | L4: 9 | O4: 8 | P4: 8
A5: 45904 | B5: 8 | C5: 8 | D5: 8 | E5: 8 | F5: ML | G5: PE | H5: 8 | I5: 8 | J5: 9 | K5: 8 | L5: 8 | O5: 8 | P5: 8
A6: 45905 | B6: 8 | C6: 8 | D6: 8 | E6: 8 | F6: ML | G6: PE | H6: 8 | I6: 8 | J6: 8 | K6: 8 | L6: 9 | O6: 8 | P6: 8
A7: 45906 | B7: 8 | E7: 8 | F7: ML | G7: 8 | H7: 8 | I7: 8 | J7: 2
A8: 45907 | J8: 10
A9: 45908 | B9: 9.5 | C9: 9.5 | D9: 9.5 | E9: 9.5 | F9: ML | G9: 8 | H9: 8 | I9: 8 | J9: 8 | K9: 9 | L9: 8 | O9: 8 | P9: 8
A10: 45909 | B10: 9.5 | C10: 9.5 | D10: 9.5 | E10: 9.5 | F10: ML | G10: 8 | H10: 8 | I10: 8 | J10: 8 | K10: 9 | L10: 8 | O10: 8 | P10: 8
A11: 45910 | B11: 10.5 | C11: 9.5 | D11: 9.5 | E11: 9.5 | F11: ML | G11: 8 | H11: 8 | I11: 8 | J11: 8 | K11: 9 | L11: 9 | O11: 8 | P11: 8
A12: 45911 | B12: 9.5 | C12: 9.5 | D12: 9.5 | E12: 9.5 | F12: ML | G12: 8 | H12: 8 | I12: 8 | J12: 11.5 | K12: 9 | L12: 8 | O12: 8 | P12: 8
A13: 45912 | B13: 9.5 | C13: 9.5 | D13: 9.5 | E13: 9.5 | F13: ML | G13: 8 | H13: 8 | I13: 8 | J13: 8 | K13: 9 | L13: 9 | O13: 8 | P13: 8
A14: 45913 | B14: 8 | D14: 8 | E14: 8 | F14: ML | G14: 8 | H14: 8 | I14: 8
A15: 45914
A16: 45915 | B16: 11.5 | C16: 9.5 | D16: 9.5 | E16: 9.5 | F16: 8 | G16: 8 | H16: 8 | I16: 8 | J16: 8 | K16: 8 | L16: 8 | M16: 8 | O16: 8 | P16: 8
A17: 45916 | B17: 9.5 | C17: 9.5 | D17: 9.5 | E17: 9.5 | F17: 8 | G17: 8 | H17: 8 | I17: 8 | J17: 11.5 | K17: 8 | L17: 8 | M17: 8 | O17: 8 | P17: 8
A18: 45917 | B18: 9.5 | C18: 9.5 | D18: 9.5 | E18: 9.5 | F18: 9 | G18: 8 | H18: 8 | I18: 8 | J18: 11.5 | K18: 8 | L18: 9 | M18: 8 | O18: 8 | P18: 8
A19: 45918 | B19: 9.5 | C19: 9.5 | D19: 9.5 | E19: 9.5 | F19: 9 | G19: 8 | H19: 8 | I19: 8 | J19: 11.5 | K19: 8 | L19: 8 | M19: 8 | O19: 8 | P19: 8
A20: 45919 | B20: 9.5 | C20: 9.5 | D20: 9.5 | E20: 9.5 | F20: 9 | G20: 8 | H20: 8 | I20: 8 | J20: 8 | K20: 8 | L20: 9 | M20: 8 | O20: 8 | P20: 8
A21: 45920 | B21: 8 | D21: 8 | F21: 8 | G21: 8 | I21: 8 | M21: 5
A22: 45921 | G22: 6.5
A23: 45922 | B23: 10 | C23: 9.5 | D23: 9.5 | E23: 9.5 | F23: 8 | G23: 8 | H23: 8 | I23: 8 | J23: 7 | K23: 8 | L23: 8 | M23: 8 | O23: 8 | P23: 8
A24: 45923 | B24: 9.5 | C24: 9.5 | D24: 9.5 | E24: 9.5 | F24: 8 | G24: 8 | H24: 8 | J24: 11.5 | K24: 8 | L24: 8 | M24: 8 | O24: 8 | P24: 8
A25: 45924 | B25: 9.5 | C25: 9.5 | D25: 9.5 | E25: 9.5 | F25: 8 | G25: 8 | H25: 8 | I25: 7.5 | J25: 11.5 | K25: 8 | L25: 9 | M25: 8 | O25: 8 | P25: 8
A26: 45925 | B26: 9.5 | C26: 9.5 | D26: 9.5 | E26: 9.5 | F26: 4 | G26: 4 | H26: 8 | I26: 7.5 | J26: 8 | K26: 8 | L26: 8 | M26: 8 | O26: 8 | P26: 8
A27: 45926 | B27: 9.5 | C27: 9.5 | D27: 9.5 | E27: 9.5 | F27: 8 | G27: 4 | H27: 8 | I27: 7.5 | J27: 8 | K27: 8 | L27: 9 | M27: 7 | O27: 8 | P27: 8
A28: 45927 | B28: 8 | D28: 8 | E28: 8 | F28: 8 | H28: 8 | I28: 8 | M28: 5
A29: 45928
A30: 45929 | B30: 9.5 | C30: 9.5 | D30: 9.5 | E30: 9.5 | F30: 8 | G30: 8 | H30: 8 | I30: 8 | J30: 8 | K30: 8 | L30: 8 | M30: 8 | O30: 8 | P30: 8
A31: 45930 | B31: 9.5 | C31: 9.5 | D31: 9.5 | E31: 9.5 | F31: 4.5 | G31: 10 | H31: 8 | I31: 8 | J31: 8 | K31: 8 | L31: 8 | M31: 8 | O31: 8 | P31: 8
A33: TOTALE ore mese | B33: =SUM(B2:B32) -> 237 | C33: =SUM(C2:C32) -> 201 | D33: =SUM(D2:D32) -> 223.5 | E33: =SUM(E2:E32) -> 225.5 | F33: =SUM(F2:F32) -> 107.5 | G33: =SUM(G2:G32) -> 184.5 | H33: =SUM(H2:H32) -> 200 | I33: =SUM(I2:I32) -> 198 | ... P33: =SUM(P2:P32) -> 176
A34: Totale ore BUSTA | B34: 176 | C34: 176 | D34: 176 | E34: 176 | F34: 176 | G34: 176 | H34: 176 | I34: 176 | J34: 176 | K34: 176 | L34: 176 | M34: 105 | O34: 176 | P34: 176
A35: Totale ora extra | B35: =B33-B34 -> 61 | C35: =C33-C34 -> 25 | D35: =D33-D34 -> 47.5 | E35: =E33-E34 -> 49.5 | F35: =F33-F34 -> -68.5 | G35: =G33-G34 -> 8.5 | H35: =H33-H34 -> 24 | I35: =I33-I34 -> 22 | ... P35: =P33-P34 -> 0
A36: importo in busta | B36: 1900 | C36: 1850 | D36: 1850 | E36: 1750 | G36: 1500 | H36: 1300 | I36: 1300 | J36: 1800 | K36: 2600 | M36: 680 | O36: 2000 | P36: 2000
A37: importo tiket edenred | B37: 104 | C37: 104 | D37: 104 | E37: 104 | F37: 104 | G37: 104 | H37: 104 | I37: 104 | J37: 104 | K37: 104 | O37: 104 | P37: 104
A38: costi orari | B38: =elenchi!B28 -> "Ale 9€/ora, Giad 10€/ora, Estefany 9€/ora, Nura 8€/ora, Joel 8€/ora Kevin 8€/ora, Jassir 7€/ora, Zoila 7€/ora, Sara 9€/ora, Massi 9€/ora, Santo fisso"
A39: note

Sheet Ottobre25
A1: 45931 | B1: =elenchi!A1 -> ALEXANDRA | C1: =elenchi!A2 -> GIUDITTA | D1: =elenchi!A3 -> ESTEFANY | E1: =elenchi!A4 -> NURA | F1: =elenchi!A5 -> JOEL | G1: =elenchi!A6 -> KEVIN | H1: =elenchi!A7 -> ZOILA | I1: =elenchi!A8 -> JASIR | J1: =elenchi!A9 -> SARA | K1: =elenchi!A10 -> SANTO | L1: =elenchi!A11 -> MASSI | M1: =elenchi!A12 -> STEFANO | N1: =elenchi!A13 -> DIEGO | O1: =elenchi!A14 -> ELISA | P1: =elenchi!A15 -> GAETANO
A2: 45931 | B2: 13.5 | C2: 9.5 | D2: 9.5 | E2: 9.5 | F2: Pe | G2: 8 | H2: 8 | I2: 8 | J2: 8 | K2: 8 | L2: 9 | M2: Pe | O2: 8 | P2: 8
A3: 45932 | B3: 9.5 | C3: 9.5 | D3: 9.5 | E3: 9.5 | F3: 8 | G3: 8 | H3: 8 | I3: 8 | J3: 8 | K3: 8 | L3: 8 | M3: 8 | O3: 8 | P3: 8
A4: 45933 | B4: 9.5 | C4: 9.5 | D4: 9.5 | E4: 8 | F4: 8 | G4: 8 | H4: Pe | I4: 8 | J4: 8 | K4: 8 | L4: 9 | M4: 8 | O4: 8 | P4: 8
A5: 45934 | B5: 8 | D5: 8 | F5: 8 | G5: 8 | H5: 8 | I5: 8 | M5: 5
A6: 45935
A7: 45936 | B7: 9 | C7: 8 | D7: 8 | E7: 8 | F7: 8 | G7: 8 | H7: 8 | I7: 8 | J7: Pe | K7: 8 | L7: 8 | M7: 8 | O7: 8 | P7: 8
A8: 45937 | B8: 9 | C8: 8 | D8: 7.5 | E8: 8 | F8: 8 | G8: 8 | H8: 8 | I8: 8 | J8: Pe | K8: 8 | L8: 8 | M8: 8 | O8: 8 | P8: 8
A9: 45938 | B9: 10 | C9: 8 | D9: 8 | E9: 8 | F9: 2 | G9: 8 | H9: 8 | I9: 8 | J9: Pe | K9: 8 | L9: 9 | M9: 8 | O9: 8 | P9: 8
A10: 45939 | B10: 9 | C10: 8 | D10: 8 | E10: 8 | F10: ML | G10: 8 | H10: 8 | I10: 8 | J10: 8 | K10: 8 | L10: 8 | M10: 8 | O10: 8 | P10: 8
A11: 45940 | B11: 8 | C11: 8.5 | D11: 8 | E11: 8 | F11: ML | G11: 8 | H11: 8 | I11: 8 | J11: 8 | K11: 8 | L11: 9 | M11: 8 | O11: 8 | P11: 8
A12: 45941 | B12: 8 | E12: 8 | F12: 8 | G12: Pe | H12: 7 | I12: 8 | M12: 5
A13: 45942
A14: 45943 | B14: 9 | C14: 9.5 | D14: 8 | E14: 8 | F14: 8 | G14: 8 | H14: 8 | I14: 8 | J14: 8 | K14: 8 | L14: 9 | M14: 8 | O14: 8 | P14: 8
A15: 45944 | B15: 9.5 | C15: 8 | D15: 8 | E15: 9.5 | F15: 8 | G15: 8 | H15: Pe | I15: 8 | J15: 8 | K15: 8 | L15: 8 | M15: 8 | O15: 8 | P15: 8
A16: 45945 | B16: 9 | C16: 9.5 | D16: 8 | E16: 8 | F16: 8 | G16: 8 | H16: 8 | I16: 8 | J16: 8 | K16: 8 | L16: 9 | M16: 8 | O16: 8 | P16: 8
A17: 45946 | B17: 9 | C17: 8 | D17: 9.5 | E17: 8 | F17: 8 | G17: 8 | H17: 5.5 | I17: 8 | J17: 8 | K17: 8 | L17: 8 | M17: 8 | O17: 8 | P17: 8
A18: 45947 | B18: 8 | C18: 8.5 | D18: 8 | E18: 8 | F18: ML | G18: 8 | H18: No | I18: 8 | J18: 8 | K18: 8 | L18: 9 | M18: 8 | O18: 8 | P18: 8
A19: 45948 | D19: 8 | E19: 8 | F19: 8 | G19: 9 | H19: No | I19: No | M19: 5
A20: 45949 | B20: 8 | G20: 8 | J20: 3.5
A21: 45950 | B21: 9 | C21: 9.5 | D21: 8 | E21: 8 | F21: 8 | G21: 8 | H21: 8 | I21: 8 | J21: 8 | K21: 8 | L21: 9 | M21: 8 | O21: 8 | P21: 8
A22: 45951 | B22: 9.5 | C22: 8 | D22: 8 | E22: 9.5 | F22: 8 | G22: 4.5 | H22: 8 | I22: 8 | J22: 8 | K22: 8 | L22: 8 | M22: 8 | O22: 8 | P22: 8
A23: 45952 | B23: 9 | C23: 9.5 | D23: 8 | E23: 8 | F23: 8 | G23: 8 | H23: 8 | I23: 8 | J23: 8 | K23: 8 | L23: 8 | M23: Pe | O23: 8 | P23: 8
A24: 45953 | B24: 9.5 | C24: 8 | D24: 9.5 | E24: 8 | F24: 8 | G24: 8 | H24: 8 | I24: 8 | J24: 8 | K24: 8 | L24: 8 | M24: 8 | O24: 8 | P24: 8
A25: 45954 | B25: 8 | C25: 8.5 | D25: 8 | E25: 8 | F25: 8 | G25: 8 | H25: 8 | I25: 8 | J25: 8 | K25: 8 | L25: 9 | M25: 8 | O25: 8 | P25: 8
A26: 45955 | D26: 8 | E26: 8 | F26: 8 | G26: 10 | H26: No | I26: 8
A27: 45956 | B27: 8.5 | H27: 8.5 | J27: 4
A28: 45957 | B28: 9 | C28: 9.5 | D28: 8 | E28: 8 | F28: 8 | G28: 8 | H28: 8 | I28: 8 | J28: ML | K28: 8 | L28: 9 | M28: ML | O28: 8 | P28: 8
A29: 45958 | B29: 9.5 | C29: 8 | D29: 8 | E29: 9.5 | F29: 8 | G29: 6 | H29: 8 | I29: 8 | J29: 8 | K29: 8 | L29: 8 | M29: ML | O29: 8 | P29: 8
A30: 45959 | B30: 9 | C30: 9.5 | D30: 8 | E30: 8 | F30: 8 | G30: 8 | H30: 8 | I30: 8 | J30: 8 | K30: 8 | L30: 8 | M30: ML | O30: 8 | P30: 8
A31: 45960 | B31: 9.5 | C31: 8 | D31: 9.5 | E31: 8 | F31: 8 | G31: 8 | H31: 8 | I31: 8 | J31: 8 | K31: 8 | L31: 8 | M31: ML | O31: 8 | P31: 8
A32: 45961 | B32: 8 | C32: 8.5 | D32: 8 | E32: 8 | F32: 8 | G32: Pe | H32: 8 | I32: 8 | J32: 8 | K32: 8 | L32: 9 | M32: ML | O32: 8 | P32: 8
A33: TOTALE ore mese | B33: =SUM(B2:B32) -> 244.5 | C33: =SUM(C2:C32) -> 199.5 | D33: =SUM(D2:D32) -> 216.5 | E33: =SUM(E2:E32) -> 215.5 | F33: =SUM(F2:F32) -> 178 | G33: =SUM(G2:G32) -> 205.5 | H33: =SUM(H2:H32) -> 181 | I33: =SUM(I2:I32) -> 208 | ... P33: =SUM(P2:P32) -> 184
A34: Totale ore BUSTA | B34: 184 | C34: 184 | D34: 184 | E34: 184 | F34: 184 | G34: 184 | H34: 184 | I34: 184 | J34: 184 | K34: 184 | L34: 184 | M34: 184 | O34: 184 | P34: 184
A35: Totale ora extra | B35: =B33-B34 -> 60.5 | C35: =C33-C34 -> 15.5 | D35: =D33-D34 -> 32.5 | E35: =E33-E34 -> 31.5 | F35: =F33-F34 -> -6 | G35: =G33-G34 -> 21.5 | H35: =H33-H34 -> -3 | I35: =I33-I34 -> 24 | ... P35: =P33-P34 -> 0
A36: importo in busta | B36: 1950 | C36: 1850 | D36: 1800 | E36: 1700 | F36: 1550 | G36: 1550 | H36: 1300 | I36: 1300 | J36: 1650 | K36: 2500 | L36: 1600 | M36: 950 | O36: 2000 | P36: 2000
A37: importo tiket edenred | B37: 104 | C37: 104 | D37: 104 | E37: 104 | F37: 104 | G37: 104 | H37: 104 | I37: 104 | J37: 104 | K37: 104 | O37: 208
A38: costi orari | B38: =elenchi!B28 -> "Ale 9€/ora, Giad 10€/ora, Estefany 9€/ora, Nura 8€/ora, Joel 8€/ora Kevin 8€/ora, Jassir 7€/ora, Zoila 7€/ora, Sara 9€/ora, Massi 9€/ora, Santo fisso"
A39: note

Sheet Novembre25
A1: 45962 | B1: =elenchi!A1 -> ALEXANDRA | C1: =elenchi!A2 -> GIUDITTA | D1: =elenchi!A3 -> ESTEFANY | E1: =elenchi!A4 -> NURA | F1: =elenchi!A5 -> JOEL | G1: =elenchi!A6 -> KEVIN | H1: =elenchi!A7 -> ZOILA | I1: =elenchi!A8 -> JASIR | J1: =elenchi!A9 -> SARA | K1: =elenchi!A10 -> SANTO | L1: =elenchi!A11 -> MASSI | M1: =elenchi!A12 -> STEFANO | N1: =elenchi!A13 -> DIEGO | O1: =elenchi!A14 -> ELISA | P1: =elenchi!A15 -> GAETANO
A2: 45962
A3: 45963
A4: 45964 | B4: 8 | C4: 8 | D4: 8 | E4: 8 | F4: 8 | G4: Pe | H4: 8 | I4: 8 | J4: 8 | K4: 8 | L4: 8 | M4: 8 | O4: 8 | P4: 8
A5: 45965 | B5: 8 | C5: 8 | D5: 8 | E5: 8 | F5: 8 | G5: Pe | H5: 8 | I5: 8 | J5: 8 | K5: 8 | L5: 8 | M5: 8 | O5: 8 | P5: 8
A6: 45966 | B6: 8 | C6: 8 | D6: 8 | E6: 8 | F6: 8 | G6: Pe | H6: 8 | I6: 8 | J6: 8 | K6: 8 | L6: 9 | M6: 8 | O6: 8 | P6: 8
A7: 45967 | B7: 8 | C7: 8 | D7: 8 | E7: 8 | F7: 8 | G7: 7 | H7: 7 | I7: 8 | J7: 8 | K7: 8 | L7: 8 | M7: 8 | O7: 8 | P7: 8
A8: 45968 | B8: 8 | C8: Pe | D8: 8 | E8: 8 | F8: 8 | G8: 8 | H8: Pe | I8: 8 | J8: 8 | K8: 8 | L8: 9 | M8: 8 | O8: 8 | P8: 8
A9: 45969 | B9: 8 | D9: 8 | F9: 8 | G9: Pe | H9: 9 | I9: 8 | M9: 5
A10: 45970 | B10: 7.5 | G10: 8 | J10: 3.5
A11: 45971 | B11: 8 | C11: 8 | D11: 8 | E11: Pe | F11: 8 | G11: 8 | H11: 8 | I11: 8 | J11: 8 | K11: 8 | L11: 8 | M11: 8 | O11: 8 | P11: 8
A12: 45972 | B12: 8 | C12: 8 | D12: 8 | E12: 8 | F12: 8 | G12: 6 | H12: 8 | I12: 8 | J12: 8 | K12: 8 | L12: 8 | M12: 8 | O12: 8 | P12: 8
A13: 45973 | B13: 8 | C13: 8 | D13: 8 | E13: 8 | F13: 8 | G13: 8 | H13: 8 | I13: 8 | J13: 8 | K13: 8 | L13: 9 | O13: 8 | P13: 8
A14: 45974 | B14: 8 | C14: 8 | D14: 8 | E14: 8 | F14: 8 | G14: Pe | H14: 8 | I14: 8 | J14: 8 | K14: 8 | L14: 8 | M14: 8 | O14: 8 | P14: 8
A15: 45975 | B15: 8 | C15: 8 | D15: 6 | E15: 8 | F15: 8 | G15: Pe | H15: 8 | I15: 8 | J15: 8 | K15: 8 | L15: 9 | M15: 8 | O15: 8 | P15: 8
A16: 45976 | B16: 8 | E16: 8 | G16: Pe | H16: 8 | I16: 6 | M16: 5
A17: 45977 | E17: 4 | F17: 4 | J17: 3
A18: 45978 | B18: 8 | C18: 8 | D18: ML | E18: ML | F18: 8 | G18: Pe | H18: 8 | I18: 8 | J18: 8 | K18: 8 | L18: 8 | M18: 8 | O18: 8 | P18: 8
A19: 45979 | B19: 8 | C19: 8 | D19: ML | E19: ML | F19: 8 | G19: Pe | H19: 8 | I19: 8 | J19: 8 | K19: 8 | L19: 8 | M19: 8 | O19: 8 | P19: 8
A20: 45980 | B20: 8 | C20: 8 | D20: ML | E20: ML | F20: 8 | G20: Pe | H20: 8 | I20: 8 | J20: 8 | K20: 8 | L20: 9 | M20: 8 | O20: 8 | P20: 8
A21: 45981 | B21: 8 | C21: Pe | D21: 8 | E21: ML | F21: 8 | G21: Pe | H21: 8 | I21: 8 | J21: 8 | K21: 8 | L21: 8 | O21: 8 | P21: 8
A22: 45982 | B22: 8 | C22: 8 | D22: 8 | E22: ML | F22: 8 | G22: Pe | H22: 8 | I22: 8 | J22: 8 | K22: 8 | L22: 9 | M22: 8 | O22: 8 | P22: 8
A23: 45983 | B23: 8 | E23: ML | F23: 8 | G23: Pe | H23: 7 | I23: 8
A24: 45984 | D24: 5.5 | G24: 5.5
A25: 45985 | B25: 8 | C25: 5 | D25: 8 | E25: 8 | F25: 8 | G25: 8 | H25: 8 | I25: 8 | J25: 8 | K25: 8 | L25: 8 | M25: 8 | O25: 8 | P25: 8
A26: 45986 | B26: 8 | C26: 8 | D26: 8 | E26: 8 | F26: 8 | G26: 6 | H26: 8 | I26: 8 | J26: 8 | K26: 8 | L26: 8 | O26: 8 | P26: 8
A27: 45987 | B27: 8 | C27: 8 | D27: 8 | E27: 8 | F27: 8 | G27: 8 | H27: 8 | I27: 8 | J27: 8 | K27: 8 | L27: 9 | O27: 8 | P27: 8
A28: 45988 | B28: 8 | C28: 8 | D28: 8 | E28: 8 | F28: 8 | G28: Pe | H28: 8 | I28: 8 | J28: 8 | K28: 8 | L28: 8 | O28: 8 | P28: 8
A29: 45989 | B29: 8 | C29: 8 | D29: 8 | E29: 8 | F29: 8 | G29: Pe | H29: 8 | I29: 8 | J29: 8 | K29: 8 | L29: 9 | O29: 8 | P29: 8
A30: 45990 | D30: 8 | E30: 8 | F30: 8 | G30: Pe | H30: 8 | I30: 8
A31: 45991
A33: TOTALE ore mese | B33: =SUM(B2:B32) -> 191.5 | C33: =SUM(C2:C32) -> 141 | D33: =SUM(D2:D32) -> 155.5 | E33: =SUM(E2:E32) -> 132 | F33: =SUM(F2:F32) -> 188 | G33: =SUM(G2:G32) -> 72.5 | H33: =SUM(H2:H32) -> 183 | I33: =SUM(I2:I32) -> 190 | ... P33: =SUM(P2:P32) -> 160
A34: Totale ore BUSTA | B34: 160 | C34: 160 | D34: 160 | E34: 160 | F34: 160 | G34: 160 | H34: 160 | I34: 160 | J34: 160 | K34: 160 | L34: 160 | M34: 160 | O34: 160 | P34: 160
A35: Totale ora extra | B35: =B33-B34 -> 31.5 | C35: =C33-C34 -> -19 | D35: =D33-D34 -> -4.5 | E35: =E33-E34 -> -28 | F35: =F33-F34 -> 28 | G35: =G33-G34 -> -87.5 | H35: =H33-H34 -> 23 | I35: =I33-I34 -> 30 | ... P35: =P33-P34 -> 0
A36: importo in busta | B36: 1800 | C36: 1800 | D36: 1700 | E36: 1650 | F36: 1700 | H36: 1300 | I36: 1300 | J36: 1700 | K36: 2500 | L36: 1600 | O36: 2000 | P36: 2000
A37: importo tiket edenred | B37: 104 | C37: 104 | D37: 104 | E37: 104 | F37: 104 | G37: 104 | H37: 104 | I37: 104 | J37: 104 | K37: 104 | M37: 900 | O37: 208
A38: costi orari | B38: =elenchi!B28 -> "Ale 9€/ora, Giad 10€/ora, Estefany 9€/ora, Nura 8€/ora, Joel 8€/ora Kevin 8€/ora, Jassir 7€/ora, Zoila 7€/ora, Sara 9€/ora, Massi 9€/ora, Santo fisso"
A39: note

Sheet Dicembre25
A1: 45992 | B1: =elenchi!A1 -> ALEXANDRA | C1: =elenchi!A2 -> GIUDITTA | D1: =elenchi!A3 -> ESTEFANY | E1: =elenchi!A4 -> NURA | F1: =elenchi!A5 -> JOEL | G1: =elenchi!A6 -> KEVIN | H1: =elenchi!A7 -> ZOILA | I1: =elenchi!A8 -> JASIR | J1: =elenchi!A9 -> SARA | K1: =elenchi!A10 -> SANTO | L1: =elenchi!A11 -> MASSI | M1: =elenchi!A12 -> STEFANO | N1: =elenchi!A13 -> DIEGO | O1: =elenchi!A14 -> ELISA | P1: =elenchi!A15 -> GAETANO
A2: 45992 | B2: 8 | C2: 8 | D2: 8 | E2: 8 | F2: 8 | G2: 8 | H2: 8 | I2: 8 | J2: 8 | K2: 8 | L2: 8 | O2: 8 | P2: 8
A3: 45993 | B3: Pe | C3: 8 | D3: 8 | E3: 8 | F3: 8 | G3: 6 | H3: 8 | I3: 8 | J3: 8 | K3: 8 | L3: 8 | O3: 8 | P3: 8
A4: 45994 | B4: Pe | C4: 8 | D4: 8 | E4: 8 | F4: 8 | G4: Pe | H4: 8 | I4: 8 | J4: 8 | K4: 8 | L4: 9 | O4: 8 | P4: 8
A5: 45995 | B5: 8 | C5: 8 | D5: 8 | E5: 8 | F5: 8 | G5: Pe | H5: 8 | I5: 8 | J5: 8 | K5: 8 | L5: 8 | O5: 8 | P5: 8
A6: 45996 | B6: 8 | C6: 8 | D6: 8 | E6: 8 | F6: ML | G6: Pe | H6: 8 | I6: 8 | J6: 8 | K6: 8 | L6: 9 | O6: 8 | P6: 8
A7: 45997 | D7: 8 | E7: 8 | F7: ML | G7: Pe | H7: Pe | I7: 9
A8: 45998
A9: 45999 | B9: F | C9: F | D9: F | E9: F | F9: F | G9: F | H9: F | I9: F | J9: F | K9: F | L9: F | O9: F | P9: F
A10: 46000 | B10: 8 | C10: 8 | D10: 8 | E10: 8 | F10: 8 | G10: 8 | H10: 8 | I10: Pe | J10: 8 | K10: 8 | L10: 8 | O10: 8 | P10: 8
A11: 46001 | B11: 8 | C11: 8 | D11: 8 | E11: 8 | F11: 8 | G11: 8 | H11: 8 | I11: 8 | J11: 8 | K11: 8 | L11: 9 | O11: 8 | P11: 8
A12: 46002 | B12: 8 | C12: 8 | D12: 8 | E12: 8 | F12: 8 | G12: Pe | H12: 8 | I12: 8 | J12: 8 | K12: 8 | L12: 8 | O12: 8 | P12: 8
A13: 46003 | B13: 8 | C13: 8 | D13: Pe | E13: 8 | F13: 8 | G13: Pe | H13: 8 | I13: 8 | J13: Pe | K13: 8 | L13: 9 | O13: 8 | P13: 8
A14: 46004 | B14: 8 | D14: Pe | E14: 8 | F14: 8 | G14: Pe | H14: 8 | I14: 5
A15: 46005 | D15: Pe
A16: 46006 | B16: 8 | C16: 8 | D16: Pe | E16: 8 | F16: 8 | G16: 8 | H16: 6 | I16: 8 | J16: 8 | K16: 8 | L16: 8 | O16: 8 | P16: 8
A17: 46007 | B17: 8 | C17: 8 | D17: Pe | E17: 8 | F17: 8 | G17: 6 | H17: 8 | I17: 8 | J17: 8 | K17: 8 | L17: 8 | O17: 8 | P17: 8
A18: 46008 | B18: 8 | C18: 8 | D18: Pe | E18: 8 | F18: 8 | G18: 7.5 | H18: 8 | I18: 8 | J18: 8 | K18: 8 | L18: 9 | O18: 8 | P18: 8
A19: 46009 | B19: 8 | C19: 8 | D19: Pe | E19: 8 | F19: 8 | G19: 8 | H19: 7.5 | I19: 8 | J19: 8 | K19: 8 | L19: 8 | O19: 8 | P19: 8
A20: 46010 | B20: 8 | C20: 8 | D20: Pe | E20: Pe | F20: 8 | G20: Pe | H20: 8 | I20: 8 | J20: 8 | K20: 8 | L20: 9 | O20: 8 | P20: 8
A21: 46011 | B21: 8 | D21: Pe | E21: 8 | F21: 8 | G21: Pe | H21: 4 | I21: 8
A22: 46012
A23: 46013 | B23: 8 | C23: 8 | D23: Pe | E23: 8 | F23: 8 | G23: 8 | H23: 8 | I23: 8 | J23: 8 | K23: 8 | L23: 8 | O23: 8 | P23: 8
A24: 46014 | B24: 8 | C24: 8 | D24: Pe | E24: 8 | F24: 8 | G24: 8 | H24: 8 | I24: 8 | J24: 8 | K24: 8 | L24: 8 | O24: 8 | P24: 8
A25: 46015 | B25: Fe | C25: Fe | D25: Fe | E25: Fe | F25: Fe | G25: Fe | H25: Fe | I25: Fe | J25: Fe | K25: Fe | L25: Fe | O25: 8 | P25: 8
A26: 46016 | B26: F | C26: F | D26: F | E26: F | F26: F | G26: F | H26: F | I26: F | J26: F | K26: F | L26: F | O26: F | P26: F
A27: 46017 | B27: F | C27: F | D27: F | E27: F | F27: F | G27: F | H27: F | I27: F | J27: F | K27: F | L27: F | O27: F | P27: F
A28: 46018
A29: 46019
A30: 46020 | B30: 8 | C30: 8 | D30: Pe | E30: 8 | F30: 8 | G30: 8 | H30: 8 | I30: 8 | J30: Pe | K30: 8 | L30: 8 | O30: 8 | P30: 8
A31: 46021 | B31: 8 | C31: 8 | D31: Pe | E31: 8 | F31: 8 | G31: 8 | H31: 8 | I31: 8 | J31: Pe | K31: 8 | L31: 8 | O31: 8 | P31: 8
A32: 46022
A33: TOTALE ore mese | B33: =SUM(B2:B32) -> 144 | C33: =SUM(C2:C32) -> 144 | D33: =SUM(D2:D32) -> 72 | E33: =SUM(E2:E32) -> 160 | F33: =SUM(F2:F32) -> 152 | G33: =SUM(G2:G32) -> 91.5 | H33: =SUM(H2:H32) -> 153.5 | I33: =SUM(I2:I32) -> 158 | ... P33: =SUM(P2:P32) -> 152
A34: Totale ore BUSTA | B34: 144 | C34: 144 | D34: 144 | E34: 144 | F34: 144 | G34: 144 | H34: 144 | I34: 144 | J34: 144 | K34: 144 | L34: 144 | O34: 144 | P34: 144
A35: Totale ora extra | B35: =B33-B34 -> 0 | C35: =C33-C34 -> 0 | D35: =D33-D34 -> -72 | E35: =E33-E34 -> 16 | F35: =F33-F34 -> 8 | G35: =G33-G34 -> -52.5 | H35: =H33-H34 -> 9.5 | I35: =I33-I34 -> 14 | ... P35: =P33-P34 -> 8
A36: importo in busta | B36: 1700 | C36: 1700 | D36: 781 | E36: 1650 | F36: 1700 | G36: 2000 | H36: 1200 | I36: 1200 | J36: 1600 | K36: 2500 | L36: 1600
A37: importo tiket edenred | B37: 104 | C37: 104 | D37: 104 | E37: 104 | F37: 104 | G37: 104 | H37: 104 | I37: 104 | J37: 104 | K37: 104 | O37: 104
A38: costi orari | B38: =elenchi!B28 -> "Ale 9€/ora, Giad 10€/ora, Estefany 9€/ora, Nura 8€/ora, Joel 8€/ora Kevin 8€/ora, Jassir 7€/ora, Zoila 7€/ora, Sara 9€/ora, Massi 9€/ora, Santo fisso"
A39: note

Sheet Gennaio26
A1: 46023 | B1: =elenchi!A1 -> ALEXANDRA | C1: =elenchi!A2 -> GIUDITTA | D1: =elenchi!A3 -> ESTEFANY | E1: =elenchi!A4 -> NURA | F1: =elenchi!A5 -> JOEL | G1: =elenchi!A6 -> KEVIN | H1: =elenchi!A7 -> ZOILA | I1: =elenchi!A8 -> JASIR | J1: =elenchi!A9 -> SARA | K1: =elenchi!A10 -> SANTO | L1: =elenchi!A11 -> MASSI | M1: =elenchi!A12 -> STEFANO | N1: =elenchi!A13 -> DIEGO | O1: =elenchi!A14 -> ELISA | P1: =elenchi!A15 -> GAETANO
A2: 46023 | B2: F | C2: F | D2: Pe | E2: F | F2: F | G2: F | H2: F | I2: F | J2: F | K2: F | L2: F | O2: F | P2: F
A3: 46024 | B3: FE | C3: FE | D3: Pe | E3: FE | F3: FE | G3: FE | H3: FE | I3: FE | J3: FE | K3: FE | L3: FE | O3: FE | P3: FE
A4: 46025 | D4: Pe
A5: 46026 | D5: Pe
A6: 46027 | B6: FE | C6: FE | D6: Pe | E6: FE | F6: FE | G6: FE | H6: FE | I6: FE | J6: FE | K6: FE | L6: FE | O6: FE | P6: FE
A7: 46028 | B7: F | C7: F | D7: Pe | E7: F | F7: F | G7: F | H7: F | I7: F | J7: F | K7: F | L7: F | O7: F | P7: F
A8: 46029 | B8: 8 | C8: 8 | D8: Pe | E8: 8 | F8: 8 | G8: 8 | H8: 8 | I8: 8 | J8: Pe | K8: 8 | L8: 9 | M8: 8 | O8: 8 | P8: 8
A9: 46030 | B9: 8 | C9: 6 | D9: Pe | E9: 8 | F9: 8 | G9: 8 | H9: 8 | I9: 8 | J9: 8 | K9: 8 | L9: 8 | M9: 8 | O9: 8 | P9: 8
A10: 46031 | B10: 8 | C10: 7 | D10: 8 | E10: 8 | F10: 8 | G10: 8 | H10: 8 | I10: 8 | J10: 5.5 | K10: 8 | L10: 9 | M10: 8 | O10: 8 | P10: 8
A11: 46032 | D11: 8 | E11: 8 | F11: 8 | G11: 8 | H11: 8 | M11: 4
A12: 46033
A13: 46034 | B13: 5 | C13: 8 | D13: 8 | E13: 8 | F13: 8 | G13: 8 | H13: 8 | I13: 8 | J13: 8 | K13: 8 | L13: 8 | M13: 8 | O13: 8 | P13: 8
A14: 46035 | B14: 8 | C14: 8 | D14: 8 | E14: 8 | F14: 8 | G14: 6 | H14: 8 | I14: 8 | J14: 8 | K14: 8 | L14: 8 | M14: 8 | O14: 8 | P14: 8
A15: 46036 | B15: 6.5 | C15: 8 | D15: 8 | E15: 8 | F15: 8 | G15: 8 | H15: 8 | I15: 8 | J15: 8 | K15: 8 | L15: 9 | M15: 8 | O15: 8 | P15: 8
A16: 46037 | B16: 8 | C16: 8 | D16: 8 | E16: 8 | F16: 8 | G16: 8 | H16: 8 | I16: 8 | J16: 8 | K16: 8 | L16: 8 | M16: 8 | O16: 8 | P16: 8
A17: 46038 | B17: 8 | C17: 8 | D17: 8 | E17: 8 | F17: 8 | G17: 8 | H17: 8 | I17: 8 | J17: 8 | K17: 8 | L17: 9 | M17: 8 | O17: 8 | P17: 8
A18: 46039 | B18: 8 | D18: 8 | F18: 8 | G18: 8 | I18: 8 | M18: 4
A19: 46040 | E19: 7.5 | G19: 8
A20: 46041 | B20: 8 | C20: 8 | D20: 8 | E20: 8 | F20: 8 | G20: 8 | H20: 8 | I20: 8 | J20: 8 | K20: 8 | L20: 8 | O20: 8 | P20: 8
A21: 46042 | B21: 8 | C21: 8 | D21: 8 | E21: Pe | F21: 8 | G21: 5 | H21: 8 | I21: 8 | J21: 8 | K21: 8 | L21: 8 | O21: 8 | P21: 8
A22: 46043 | B22: 8 | C22: 8 | D22: 8 | E22: 8 | F22: 8 | G22: 8 | H22: 7 | I22: 8 | J22: 8 | K22: 8 | L22: 9 | O22: 8 | P22: 8
A23: 46044 | B23: 8 | C23: 8 | D23: 8 | E23: 8 | F23: 8 | G23: 8 | H23: 8 | I23: 8 | J23: 8 | K23: 8 | L23: 8 | O23: 8 | P23: 8
A24: 46045 | B24: 8 | C24: 8 | D24: 8 | E24: 8 | F24: 8 | G24: 8 | H24: 8 | I24: 8 | J24: 8 | K24: 8 | L24: 9 | O24: 8 | P24: 8
A25: 46046 | B25: 8 | D25: 8 | E25: 8 | H25: 8 | I25: 8
A26: 46047 | H26: 4.5
A27: 46048 | B27: 8 | C27: 8 | D27: 8 | E27: 8 | F27: 7 | G27: 8 | H27: Pe | I27: 8 | J27: 8 | K27: 8 | L27: 8 | O27: 8 | P27: 8
A28: 46049 | B28: 8 | C28: 8 | D28: 8 | E28: 8 | F28: 8 | G28: 6 | H28: 8 | I28: 8 | J28: 8 | K28: 8 | L28: 8 | O28: 8 | P28: 8
A29: 46050 | B29: 8 | C29: 8 | D29: 8 | E29: 8 | F29: 8 | G29: 8 | H29: 7.5 | I29: 8 | J29: 8 | K29: 8 | L29: 9 | O29: 8 | P29: 8
A30: 46051 | B30: 8 | C30: Pe | D30: 8 | E30: 8 | F30: 8 | G30: 8 | H30: Pe | I30: 8 | J30: 8 | K30: 8 | L30: 8 | O30: 8 | P30: 8
A31: 46052 | B31: 8 | C31: Pe | D31: 8 | E31: 8 | F31: 8 | G31: 8 | H31: 8 | I31: 8 | J31: 8 | K31: 8 | L31: 9 | O31: 8 | P31: 8
A32: 46053 | B32: 8 | E32: 8 | F32: 8 | G32: 8 | H32: 8
A33: TOTALE ore mese | B33: =SUM(B2:B32) -> 163.5 | C33: =SUM(C2:C32) -> 125 | D33: =SUM(D2:D32) -> 152 | E33: =SUM(E2:E32) -> 167.5 | F33: =SUM(F2:F32) -> 167 | G33: =SUM(G2:G32) -> 169 | H33: =SUM(H2:H32) -> 155 | I33: =SUM(I2:I32) -> 160 | ... P33: =SUM(P2:P32) -> 144
A34: Totale ore BUSTA | B34: 144 | C34: 144 | D34: 144 | E34: 144 | F34: 144 | G34: 144 | H34: 144 | I34: 144 | J34: 144 | K34: 144 | L34: 144 | O34: 144 | P34: 144
A35: Totale ora extra | B35: =B33-B34 -> 19.5 | C35: =C33-C34 -> -19 | D35: =D33-D34 -> 8 | E35: =E33-E34 -> 23.5 | F35: =F33-F34 -> 23 | G35: =G33-G34 -> 25 | H35: =H33-H34 -> 11 | I35: =I33-I34 -> 16 | ... P35: =P33-P34 -> 0
A36: importo in busta | B36: 1700 | C36: 1700 | D36: 1600 | E36: 1700 | F36: 1700 | G36: 1600 | H36: 1250 | I36: 1250 | K36: 2500 | L36: 1600
A37: importo tiket edenred | B37: 104 | C37: 104 | D37: 104 | E37: 104 | F37: 104 | G37: 104 | H37: 104 | I37: 104 | J37: 104 | K37: 104 | O37: 130
A38: costi orari | B38: =elenchi!B28 -> "Ale 9€/ora, Giad 10€/ora, Estefany 9€/ora, Nura 8€/ora, Joel 8€/ora Kevin 8€/ora, Jassir 7€/ora, Zoila 7€/ora, Sara 9€/ora, Massi 9€/ora, Santo fisso"
A39: note

Sheet Febbraio26
A1: 46054 | B1: =elenchi!A1 -> ALEXANDRA | C1: =elenchi!A2 -> GIUDITTA | D1: =elenchi!A3 -> ESTEFANY | E1: =elenchi!A4 -> NURA | F1: =elenchi!A5 -> JOEL | G1: =elenchi!A6 -> KEVIN | H1: =elenchi!A7 -> ZOILA | I1: =elenchi!A8 -> JASIR | J1: =elenchi!A9 -> SARA | K1: =elenchi!A10 -> SANTO | L1: =elenchi!A11 -> MASSI | M1: =elenchi!A12 -> STEFANO | N1: =elenchi!A13 -> DIEGO | O1: =elenchi!A14 -> ELISA | P1: =elenchi!A15 -> GAETANO
A2: 46054 | D2: 3 | I2: 3
A3: 46055 | B3: 11.5 | C3: 8 | D3: 8 | E3: 8 | F3: 8 | G3: 8 | H3: 6 | I3: 0 | J3: 8 | K3: 8 | L3: 8 | O3: 8 | P3: 8
A4: 46056 | B4: 8 | C4: 8 | D4: 8 | E4: 8 | F4: 8 | G4: 5 | H4: 6 | I4: 8 | J4: 8 | K4: 8 | L4: 8 | O4: 8 | P4: 8
A5: 46057 | B5: 9 | C5: 8 | D5: 8 | E5: 8 | F5: 8 | G5: 8 | H5: 6 | I5: 8 | J5: 8 | K5: 8 | L5: 9 | O5: 8 | P5: 8
A6: 46058 | B6: 8 | C6: 8 | D6: 8 | E6: 8 | F6: 8 | G6: 8 | H6: 0 | I6: 8 | J6: 8 | K6: 8 | L6: 8 | O6: 8 | P6: 8
A7: 46059 | B7: 8 | C7: 8 | D7: 8 | E7: 4 | F7: 8 | G7: 8 | H7: 5.5 | I7: 8 | J7: 8 | K7: 8 | L7: 9 | O7: 8 | P7: 8
A8: 46060 | D8: 8 | E8: 8 | F8: 8 | G8: 8 | I8: 8
A9: 46061
A10: 46062 | B10: 8 | C10: 8 | D10: 8 | E10: 8 | F10: 8 | G10: 8 | H10: 6 | I10: 8 | J10: 8 | K10: 8 | L10: 8 | O10: 8 | P10: 8
A11: 46063 | B11: 8 | C11: 8 | D11: 8 | E11: 8 | F11: 8 | G11: 6 | H11: 6 | I11: 8 | J11: 8 | K11: 8 | L11: 8 | O11: 8 | P11: 8
A12: 46064 | B12: 8 | C12: 8 | D12: 8 | E12: 8 | F12: 8 | G12: 8 | H12: 6 | I12: 8 | J12: 8 | K12: 8 | L12: 9 | O12: 8 | P12: 8
A13: 46065 | B13: 8 | C13: 8 | D13: 8 | E13: 8 | F13: 8 | G13: 3 | H13: 6 | I13: 8 | J13: 8 | K13: 8 | L13: 8 | O13: 8 | P13: 8
A14: 46066 | B14: 8 | C14: 8 | D14: 8 | E14: 6 | F14: 8 | G14: 8 | H14: 0 | I14: 8 | J14: 8 | K14: 8 | L14: 9 | O14: 8 | P14: 8
A15: 46067 | B15: 8 | D15: 8 | F15: 8 | I15: 9
A16: 46068 | E16: 8 | G16: 8
A17: 46069 | B17: 8 | C17: 8 | D17: 8 | E17: 8 | F17: 8 | G17: 8 | H17: 6 | I17: 8 | J17: 8 | K17: 8 | L17: 8 | O17: 8 | P17: 8
A18: 46070 | B18: 8 | C18: 8 | D18: 8 | E18: 8 | F18: 8 | G18: 5.5 | H18: 6 | I18: 8 | J18: 8 | K18: 8 | L18: 8 | O18: 8 | P18: 8
A19: 46071 | B19: 8 | C19: 8 | D19: 8 | E19: 8 | F19: 7 | G19: 8 | H19: 6 | I19: 8 | J19: 8 | K19: 8 | L19: 9 | O19: 8 | P19: 8
A20: 46072 | B20: 8 | C20: 8 | D20: 8 | E20: ML | F20: 8 | G20: 8 | H20: 0 | I20: 8 | J20: 8 | K20: 8 | L20: 8 | O20: 8 | P20: 8
A21: 46073 | B21: 8 | C21: 8 | D21: 8 | E21: ML | F21: 8 | G21: 7.5 | H21: 5.5 | I21: 8 | J21: 8 | K21: 8 | L21: 9 | O21: 8 | P21: 8
A22: 46074 | B22: 0 | D22: 8 | E22: ML | F22: 8 | G22: 8 | I22: 4
A23: 46075 | B23: 8.5 | H23: 8.5 | J23: 5.5
A24: 46076 | B24: 8 | C24: 8 | D24: 8 | E24: 8 | F24: 8 | G24: 8 | I24: 8 | J24: ML | K24: 8 | L24: 8 | O24: 8 | P24: 8
A25: 46077 | B25: 8 | C25: 8 | D25: 8 | E25: 8 | F25: 8 | G25: 6 | H25: 6 | I25: 8 | J25: ML | K25: 8 | L25: 8 | O25: 8 | P25: 8
A26: 46078 | B26: 8 | C26: 8 | D26: 8 | E26: 8 | F26: 8 | G26: 8 | H26: 6 | I26: 8 | J26: ML | K26: 8 | L26: 9 | O26: 8 | P26: 8
A27: 46079 | B27: 8 | C27: 8 | D27: 8 | E27: 8 | F27: 8 | G27: 8 | H27: 6 | I27: 8 | J27: 8 | K27: 8 | L27: 8 | O27: 8 | P27: 8
A28: 46080 | B28: 8 | C28: 8 | D28: 8 | E28: 8 | F28: 8 | G28: 8 | I28: 8 | J28: 8 | K28: 8 | L28: 8 | O28: 8 | P28: 8
A29: 46081 | B29: 8 | D29: 8 | E29: 8 | G29: 9
A33: TOTALE ore mese | B33: =SUM(B2:B32) -> 189 | C33: =SUM(C2:C32) -> 160 | D33: =SUM(D2:D32) -> 195 | E33: =SUM(E2:E32) -> 162 | F33: =SUM(F2:F32) -> 183 | G33: =SUM(G2:G32) -> 178 | H33: =SUM(H2:H32) -> 97.5 | I33: =SUM(I2:I32) -> 176 | ... P33: =SUM(P2:P32) -> 160
A34: Totale ore BUSTA | B34: 160 | C34: 160 | D34: 160 | E34: 160 | F34: 160 | G34: 160 | H34: 160 | I34: 160 | J34: 160 | K34: 160 | L34: 160 | O34: 160 | P34: 160
A35: Totale ora extra | B35: =B33-B34 -> 29 | C35: =C33-C34 -> 0 | D35: =D33-D34 -> 35 | E35: =E33-E34 -> 2 | F35: =F33-F34 -> 23 | G35: =G33-G34 -> 18 | H35: =H33-H34 -> -62.5 | I35: =I33-I34 -> 16 | ... P35: =P33-P34 -> 0
A36: importo in busta | B36: 1750 | C36: 1700 | D36: 1800 | E36: 1700 | F36: 1700 | G36: 1650 | H36: 700 | I36: 1400 | J36: 1600 | K36: 2500 | L36: 1600 | O36: 2000 | P36: 2000
A37: importo tiket edenred | B37: 104 | C37: 104 | D37: 104 | E37: 104 | F37: 104 | G37: 104 | I37: 104 | J37: 104 | K37: 104 | O37: 130
A38: costi orari | B38: =elenchi!B28 -> "Ale 9€/ora, Giad 10€/ora, Estefany 9€/ora, Nura 8€/ora, Joel 8€/ora Kevin 8€/ora, Jassir 7€/ora, Zoila 7€/ora, Sara 9€/ora, Massi 9€/ora, Santo fisso"
A39: note

Sheet Marzo26
A1: 46082 | B1: =elenchi!A1 -> ALEXANDRA | C1: =elenchi!A2 -> GIUDITTA | D1: =elenchi!A3 -> ESTEFANY | E1: =elenchi!A4 -> NURA | F1: =elenchi!A5 -> JOEL | G1: =elenchi!A6 -> KEVIN | H1: =elenchi!A7 -> ZOILA | I1: =elenchi!A8 -> JASIR | J1: =elenchi!A9 -> SARA | K1: =elenchi!A10 -> SANTO | L1: =elenchi!A11 -> MASSI | M1: =elenchi!A12 -> STEFANO | N1: =elenchi!A13 -> DIEGO | O1: =elenchi!A14 -> ELISA | P1: =elenchi!A15 -> GAETANO
A2: 46082 | F2: 3 | G2: 3 | J2: 2.5
A3: 46083 | B3: 8 | C3: 8 | D3: 8 | E3: 8 | F3: 8 | G3: 8 | I3: 8 | J3: 8 | K3: 8 | L3: 8 | M3: 8 | N3: 8 | O3: 8 | P3: 8
A4: 46084 | B4: 8 | C4: 8 | D4: 8 | E4: 8 | F4: 8 | G4: 6 | I4: 8 | J4: 8 | K4: 8 | L4: 8 | M4: 8 | N4: 8 | O4: 8 | P4: 8
A5: 46085 | B5: 8 | C5: 8 | D5: 8 | E5: 8 | F5: 8 | G5: 8 | I5: 8 | J5: 8 | K5: 8 | L5: 9 | M5: 8 | N5: 8 | O5: 8 | P5: 8
A6: 46086 | B6: 8 | C6: 8 | D6: 8 | E6: 8 | F6: 8 | G6: 8 | I6: 8 | J6: 8 | K6: 8 | L6: 8 | N6: 8 | O6: 8 | P6: 8
A7: 46087 | B7: 8 | C7: 8 | D7: 8 | E7: 8 | F7: 8 | G7: 8 | I7: 8 | J7: 8 | K7: 8 | L7: 9 | M7: 8 | N7: 8 | O7: 8 | P7: 8
A8: 46088 | B8: 8 | E8: 8 | F8: 8 | G8: 8 | I8: 8 | M8: 4
A9: 46089
A10: 46090 | B10: 8 | C10: 8 | D10: 8 | E10: 8 | F10: 8 | G10: 8 | I10: 8 | J10: 8 | K10: 8 | L10: 8 | N10: 8 | O10: 8 | P10: 8
A11: 46091 | B11: 8 | C11: 8 | D11: 8 | E11: 8 | F11: 8 | G11: 6 | I11: 8 | J11: 8 | K11: 8 | L11: 8 | N11: 8 | O11: 8 | P11: 8
A12: 46092 | B12: 8 | C12: 8 | D12: 8 | E12: 8 | F12: 8 | G12: 8 | I12: 7 | J12: 8 | K12: 8 | L12: 9 | N12: 8 | O12: 8 | P12: 8
A13: 46093 | B13: 8 | C13: 8 | D13: 8 | E13: 8 | F13: 8 | G13: 8 | I13: 8 | J13: 8 | K13: 8 | L13: 8 | N13: 8 | O13: 8 | P13: 8
A14: 46094 | B14: 8 | C14: 8 | D14: 8 | E14: 8 | F14: 8 | G14: 8 | I14: 8 | J14: 8 | K14: 8 | L14: 9 | N14: 8 | O14: 8 | P14: 8
A15: 46095 | B15: 8 | D15: 8 | E15: 8 | G15: 6.5 | I15: 4
A16: 46096 | B16: 8 | G16: 8.5 | J16: 3 | N16: 8
A17: 46097 | B17: 8 | C17: 8 | D17: 8 | E17: 8 | F17: 8 | G17: 8 | I17: 8 | J17: 8 | K17: 8 | L17: 8 | N17: 8 | O17: 8 | P17: 8
A18: 46098 | B18: 8 | C18: 8 | D18: 8 | E18: 8 | F18: 8 | G18: 6 | I18: 8 | J18: 8 | K18: 8 | L18: 8 | N18: 8 | O18: 8 | P18: 8
A19: 46099 | B19: 8 | C19: 8 | D19: 8 | E19: 8 | F19: 8 | G19: 8 | I19: 7 | J19: 8 | K19: 8 | L19: 9 | N19: 8 | O19: 8 | P19: 8
A20: 46100 | B20: 8 | C20: 7 | D20: 8 | E20: 8 | F20: 8 | G20: 8 | I20: 8 | J20: 8 | K20: 8 | L20: 8 | N20: 8 | O20: 8 | P20: 8
A21: 46101 | B21: 8 | D21: 8 | E21: 8 | F21: 4.5 | G21: 8 | I21: 8 | J21: 8 | K21: 8 | L21: 9 | N21: 8 | O21: 8 | P21: 8
A22: 46102 | B22: 8 | D22: 8 | F22: 8 | I22: 8 | N22: 8
A23: 46103
A24: 46104 | B24: 8 | C24: 8 | D24: 8 | E24: 8 | F24: 8 | G24: 8 | I24: 8 | J24: 8 | K24: 8 | L24: 8 | N24: 8 | O24: 8 | P24: 8
A25: 46105 | B25: 8 | C25: 8 | D25: 8 | E25: 8 | F25: 5.5 | G25: 6 | I25: 8 | J25: 8 | K25: 8 | L25: 8 | N25: 8 | O25: 8 | P25: 8
A26: 46106 | B26: 8 | C26: 8 | D26: 8 | E26: 8 | F26: 8 | G26: 8 | I26: 8 | J26: 8 | K26: 8 | L26: 9 | N26: 8 | O26: 8 | P26: 8
A27: 46107 | B27: 8 | C27: 8 | D27: 8 | E27: 8 | F27: 8 | G27: 8 | I27: 8 | J27: 8 | K27: 8 | L27: 8 | N27: 8 | O27: 8 | P27: 8
A28: 46108 | B28: 8 | C28: 8 | D28: 8 | E28: 8 | F28: 8 | G28: 8 | I28: 8 | J28: 8 | K28: 8 | L28: 9 | N28: 8 | O28: 8 | P28: 8
A29: 46109 | D29: 8 | E29: 8 | F29: 8 | I29: 8 | N29: 8
A30: 46110
A31: 46111 | B31: 8 | C31: 8 | D31: 8 | E31: 7 | F31: 8 | G31: 8 | J31: 8 | K31: 8 | L31: 8 | N31: 8 | O31: 8 | P31: 8
A32: 46112 | B32: 8 | D32: 8 | E32: 8 | F32: 8 | G32: 6 | I32: 8 | J32: 8 | K32: 8 | L32: 8 | N32: 8 | O32: 8 | P32: 8
A33: TOTALE ore mese | B33: =SUM(B2:B32) -> 208 | C33: =SUM(C2:C32) -> 159 | D33: =SUM(D2:D32) -> 200 | E33: =SUM(E2:E32) -> 199 | F33: =SUM(F2:F32) -> 197 | G33: =SUM(G2:G32) -> 192 | H33: =SUM(H2:H32) -> 0 | I33: =SUM(I2:I32) -> 194 | ... P33: =SUM(P2:P32) -> 176
A34: Totale ore BUSTA | B34: 176 | C34: 176 | D34: 176 | E34: 176 | F34: 176 | G34: 176 | I34: 176 | J34: 176 | K34: 176 | L34: 176 | N34: 176 | O34: 176 | P34: 176
A35: Totale ora extra | B35: =B33-B34 -> 32 | C35: =C33-C34 -> -17 | D35: =D33-D34 -> 24 | E35: =E33-E34 -> 23 | F35: =F33-F34 -> 21 | G35: =G33-G34 -> 16 | H35: =H33-H34 -> 0 | I35: =I33-I34 -> 18 | ... P35: =P33-P34 -> 0
A36: importo in busta
A37: importo tiket edenred | B37: 104 | C37: 104 | D37: 104 | E37: 104 | F37: 104 | G37: 104 | I37: 104 | J37: 104 | K37: 104 | O37: 130
A38: costi orari | B38: =elenchi!B28 -> "Ale 9€/ora, Giad 10€/ora, Estefany 9€/ora, Nura 8€/ora, Joel 8€/ora Kevin 8€/ora, Jassir 7€/ora, Zoila 7€/ora, Sara 9€/ora, Massi 9€/ora, Santo fisso"
A39: note

Sheet Aprile26
A1: 46113 | B1: =elenchi!A1 -> ALEXANDRA | C1: =elenchi!A2 -> GIUDITTA | D1: =elenchi!A3 -> ESTEFANY | E1: =elenchi!A4 -> NURA | F1: =elenchi!A5 -> JOEL | G1: =elenchi!A6 -> KEVIN | H1: =elenchi!A7 -> ZOILA | I1: =elenchi!A8 -> JASIR | J1: =elenchi!A9 -> SARA | K1: =elenchi!A10 -> SANTO | L1: =elenchi!A11 -> MASSI | M1: =elenchi!A12 -> STEFANO | N1: =elenchi!A13 -> DIEGO | O1: =elenchi!A14 -> ELISA | P1: =elenchi!A15 -> GAETANO
A2: 46113
A3: 46114
A4: 46115
A5: 46116
A6: 46117
A7: 46118
A8: 46119
A9: 46120
A10: 46121
A11: 46122
A12: 46123
A13: 46124
... A31: 46142
A33: TOTALE ore mese | B33: =SUM(B2:B32) -> 0 | C33: =SUM(C2:C32) -> 0 | D33: =SUM(D2:D32) -> 0 | E33: =SUM(E2:E32) -> 0 | F33: =SUM(F2:F32) -> 0 | G33: =SUM(G2:G32) -> 0 | H33: =SUM(H2:H32) -> 0 | I33: =SUM(I2:I32) -> 0 | ... P33: =SUM(P2:P32) -> 0
A34: Totale ore BUSTA
A35: Totale ora extra | B35: =B33-B34 -> 0 | C35: =C33-C34 -> 0 | D35: =D33-D34 -> 0 | E35: =E33-E34 -> 0 | F35: =F33-F34 -> 0 | G35: =G33-G34 -> 0 | H35: =H33-H34 -> 0 | I35: =I33-I34 -> 0 | ... P35: =P33-P34 -> 0
A36: importo in busta
A37: importo tiket edenred
A38: costi orari | B38: =elenchi!B28 -> "Ale 9€/ora, Giad 10€/ora, Estefany 9€/ora, Nura 8€/ora, Joel 8€/ora Kevin 8€/ora, Jassir 7€/ora, Zoila 7€/ora, Sara 9€/ora, Massi 9€/ora, Santo fisso"
A39: note

Sheet Maggio26
A1: 46143 | B1: =elenchi!A1 -> ALEXANDRA | C1: =elenchi!A2 -> GIUDITTA | D1: =elenchi!A3 -> ESTEFANY | E1: =elenchi!A4 -> NURA | F1: =elenchi!A5 -> JOEL | G1: =elenchi!A6 -> KEVIN | H1: =elenchi!A7 -> ZOILA | I1: =elenchi!A8 -> JASIR | J1: =elenchi!A9 -> SARA | K1: =elenchi!A10 -> SANTO | L1: =elenchi!A11 -> MASSI | M1: =elenchi!A12 -> STEFANO | N1: =elenchi!A13 -> DIEGO | O1: =elenchi!A14 -> ELISA | P1: =elenchi!A15 -> GAETANO
A2: 46143
A3: 46144
A4: 46145
A5: 46146
A6: 46147
A7: 46148
A8: 46149
A9: 46150
A10: 46151
A11: 46152
A12: 46153
A13: 46154
... A32: 46173
A33: TOTALE ore mese | B33: =SUM(B2:B32) -> 0 | C33: =SUM(C2:C32) -> 0 | D33: =SUM(D2:D32) -> 0 | E33: =SUM(E2:E32) -> 0 | F33: =SUM(F2:F32) -> 0 | G33: =SUM(G2:G32) -> 0 | H33: =SUM(H2:H32) -> 0 | I33: =SUM(I2:I32) -> 0 | ... P33: =SUM(P2:P32) -> 0
A34: Totale ore BUSTA
A35: Totale ora extra | B35: =B33-B34 -> 0 | C35: =C33-C34 -> 0 | D35: =D33-D34 -> 0 | E35: =E33-E34 -> 0 | F35: =F33-F34 -> 0 | G35: =G33-G34 -> 0 | H35: =H33-H34 -> 0 | I35: =I33-I34 -> 0 | ... P35: =P33-P34 -> 0
A36: importo in busta
A37: importo tiket edenred
A38: costi orari | B38: =elenchi!B28 -> "Ale 9€/ora, Giad 10€/ora, Estefany 9€/ora, Nura 8€/ora, Joel 8€/ora Kevin 8€/ora, Jassir 7€/ora, Zoila 7€/ora, Sara 9€/ora, Massi 9€/ora, Santo fisso"
A39: note

Sheet Giugno26
A1: 46174 | B1: =elenchi!A1 -> ALEXANDRA | C1: =elenchi!A2 -> GIUDITTA | D1: =elenchi!A3 -> ESTEFANY | E1: =elenchi!A4 -> NURA | F1: =elenchi!A5 -> JOEL | G1: =elenchi!A6 -> KEVIN | H1: =elenchi!A7 -> ZOILA | I1: =elenchi!A8 -> JASIR | J1: =elenchi!A9 -> SARA | K1: =elenchi!A10 -> SANTO | L1: =elenchi!A11 -> MASSI | M1: =elenchi!A12 -> STEFANO | N1: =elenchi!A13 -> DIEGO | O1: =elenchi!A14 -> ELISA | P1: =elenchi!A15 -> GAETANO
A2: 46174
A3: 46175
A4: 46176
A5: 46177
A6: 46178
A7: 46179
A8: 46180
A9: 46181
A10: 46182
A11: 46183
A12: 46184
A13: 46185
... A31: 46203
A33: TOTALE ore mese | B33: =SUM(B2:B32) -> 0 | C33: =SUM(C2:C32) -> 0 | D33: =SUM(D2:D32) -> 0 | E33: =SUM(E2:E32) -> 0 | F33: =SUM(F2:F32) -> 0 | G33: =SUM(G2:G32) -> 0 | H33: =SUM(H2:H32) -> 0 | I33: =SUM(I2:I32) -> 0 | ... P33: =SUM(P2:P32) -> 0
A34: Totale ore BUSTA
A35: Totale ora extra | B35: =B33-B34 -> 0 | C35: =C33-C34 -> 0 | D35: =D33-D34 -> 0 | E35: =E33-E34 -> 0 | F35: =F33-F34 -> 0 | G35: =G33-G34 -> 0 | H35: =H33-H34 -> 0 | I35: =I33-I34 -> 0 | ... P35: =P33-P34 -> 0
A36: importo in busta
A37: importo tiket edenred
A38: costi orari | B38: =elenchi!B28 -> "Ale 9€/ora, Giad 10€/ora, Estefany 9€/ora, Nura 8€/ora, Joel 8€/ora Kevin 8€/ora, Jassir 7€/ora, Zoila 7€/ora, Sara 9€/ora, Massi 9€/ora, Santo fisso"
A39: note

Sheet Luglio26
A1: 46204 | B1: =elenchi!A1 -> ALEXANDRA | C1: =elenchi!A2 -> GIUDITTA | D1: =elenchi!A3 -> ESTEFANY | E1: =elenchi!A4 -> NURA | F1: =elenchi!A5 -> JOEL | G1: =elenchi!A6 -> KEVIN | H1: =elenchi!A7 -> ZOILA | I1: =elenchi!A8 -> JASIR | J1: =elenchi!A9 -> SARA | K1: =elenchi!A10 -> SANTO | L1: =elenchi!A11 -> MASSI | M1: =elenchi!A12 -> STEFANO | N1: =elenchi!A13 -> DIEGO | O1: =elenchi!A14 -> ELISA | P1: =elenchi!A15 -> GAETANO
A2: 46204
A3: 46205
A4: 46206
A5: 46207
A6: 46208
A7: 46209
A8: 46210
A9: 46211
A10: 46212
A11: 46213
A12: 46214
A13: 46215
... A32: 46234
A33: TOTALE ore mese | B33: =SUM(B2:B32) -> 0 | C33: =SUM(C2:C32) -> 0 | D33: =SUM(D2:D32) -> 0 | E33: =SUM(E2:E32) -> 0 | F33: =SUM(F2:F32) -> 0 | G33: =SUM(G2:G32) -> 0 | H33: =SUM(H2:H32) -> 0 | I33: =SUM(I2:I32) -> 0 | ... P33: =SUM(P2:P32) -> 0
A34: Totale ore BUSTA
A35: Totale ora extra | B35: =B33-B34 -> 0 | C35: =C33-C34 -> 0 | D35: =D33-D34 -> 0 | E35: =E33-E34 -> 0 | F35: =F33-F34 -> 0 | G35: =G33-G34 -> 0 | H35: =H33-H34 -> 0 | I35: =I33-I34 -> 0 | ... P35: =P33-P34 -> 0
A36: importo in busta
A37: importo tiket edenred
A38: costi orari | B38: =elenchi!B28 -> "Ale 9€/ora, Giad 10€/ora, Estefany 9€/ora, Nura 8€/ora, Joel 8€/ora Kevin 8€/ora, Jassir 7€/ora, Zoila 7€/ora, Sara 9€/ora, Massi 9€/ora, Santo fisso"
A39: note

Sheet Agosto26
A1: 46235 | B1: =elenchi!A1 -> ALEXANDRA | C1: =elenchi!A2 -> GIUDITTA | D1: =elenchi!A3 -> ESTEFANY | E1: =elenchi!A4 -> NURA | F1: =elenchi!A5 -> JOEL | G1: =elenchi!A6 -> KEVIN | H1: =elenchi!A7 -> ZOILA | I1: =elenchi!A8 -> JASIR | J1: =elenchi!A9 -> SARA | K1: =elenchi!A10 -> SANTO | L1: =elenchi!A11 -> MASSI | M1: =elenchi!A12 -> STEFANO | N1: =elenchi!A13 -> DIEGO | O1: =elenchi!A14 -> ELISA | P1: =elenchi!A15 -> GAETANO
A2: 46235
A3: 46236
A4: 46237
A5: 46238
A6: 46239
A7: 46240
A8: 46241
A9: 46242
A10: 46243
A11: 46244
A12: 46245
A13: 46246
... A32: 46265
A33: TOTALE ore mese | B33: =SUM(B2:B32) -> 0 | C33: =SUM(C2:C32) -> 0 | D33: =SUM(D2:D32) -> 0 | E33: =SUM(E2:E32) -> 0 | F33: =SUM(F2:F32) -> 0 | G33: =SUM(G2:G32) -> 0 | H33: =SUM(H2:H32) -> 0 | I33: =SUM(I2:I32) -> 0 | ... P33: =SUM(P2:P32) -> 0
A34: Totale ore BUSTA
A35: Totale ora extra | B35: =B33-B34 -> 0 | C35: =C33-C34 -> 0 | D35: =D33-D34 -> 0 | E35: =E33-E34 -> 0 | F35: =F33-F34 -> 0 | G35: =G33-G34 -> 0 | H35: =H33-H34 -> 0 | I35: =I33-I34 -> 0 | ... P35: =P33-P34 -> 0
A36: importo in busta
A37: importo tiket edenred
A38: costi orari | B38: =elenchi!B28 -> "Ale 9€/ora, Giad 10€/ora, Estefany 9€/ora, Nura 8€/ora, Joel 8€/ora Kevin 8€/ora, Jassir 7€/ora, Zoila 7€/ora, Sara 9€/ora, Massi 9€/ora, Santo fisso"
A39: note

Sheet report_ORE
A1: 2025 - 2026 | B1: SET. | C1: OTT. | D1: NOV. | E1: DIC. | F1: GEN. | G1: FEB. | H1: MAR. | I1: APR. | J1: MAG. | K1: GIU. | L1: LUG. | M1: AGO. | N1: NOTE
A2: =elenchi!A1 -> ALEXANDRA | B2: =Settembre25!$B33 -> 237 | C2: =Ottobre25!$B33 -> 244.5 | D2: =Novembre25!$B33 -> 191.5 | E2: =Dicembre25!$B33 -> 144 | F2: =Gennaio26!$B33 -> 163.5 | G2: =Febbraio26!$B33 -> 189 | H2: =Marzo26!$B33 -> 208 | I2: =Aprile26!$B33 -> 0 | J2: =Maggio26!$B33 -> 0 | K2: =Giugno26!$B33 -> 0 | L2: =Luglio26!$B33 -> 0 | M2: =Agosto26!$B33 -> 0 | O2: ORE
B3: =Settembre25!$B36 -> 1900 | C3: =Ottobre25!$B36 -> 1950 | D3: =Novembre25!$B36 -> 1800 | E3: =Dicembre25!$B36 -> 1700 | F3: =Gennaio26!$B36 -> 1700 | G3: =Febbraio26!$B36 -> 1750 | H3: =Marzo26!$B36 | I3: =Aprile26!$B36 | J3: =Maggio26!$B36 | K3: =Giugno26!$B36 | L3: =Luglio26!$B36 | M3: =Agosto26!$B36 | O3: IMPORTO
A4: =elenchi!A2 -> GIUDITTA | B4: =Settembre25!$C33 -> 201 | C4: =Ottobre25!$C33 -> 199.5 | D4: =Novembre25!$C33 -> 141 | E4: =Dicembre25!$C33 -> 144 | F4: =Gennaio26!$C33 -> 125 | G4: =Febbraio26!$C33 -> 160 | H4: =Marzo26!$C33 -> 159 | I4: =Aprile26!$C33 -> 0 | J4: =Maggio26!$C33 -> 0 | K4: =Giugno26!$C33 -> 0 | L4: =Luglio26!$C33 -> 0 | M4: =Agosto26!$C33 -> 0
B5: =Settembre25!$C36 -> 1850 | C5: =Ottobre25!$C36 -> 1850 | D5: =Novembre25!$C36 -> 1800 | E5: =Dicembre25!$C36 -> 1700 | F5: =Gennaio26!$C36 -> 1700 | G5: =Febbraio26!$C36 -> 1700 | H5: =Marzo26!$C36 | I5: =Aprile26!$C36 | J5: =Maggio26!$C36 | K5: =Giugno26!$C36 | L5: =Luglio26!$C36 | M5: =Agosto26!$C36
A6: =elenchi!A3 -> ESTEFANY | B6: =Settembre25!$D33 -> 223.5 | C6: =Ottobre25!$D33 -> 216.5 | D6: =Novembre25!$D33 -> 155.5 | E6: =Dicembre25!$D33 -> 72 | F6: =Gennaio26!$D33 -> 152 | G6: =Febbraio26!$D33 -> 195 | H6: =Marzo26!$D33 -> 200 | I6: =Aprile26!$D33 -> 0 | J6: =Maggio26!$D33 -> 0 | K6: =Giugno26!$D33 -> 0 | L6: =Luglio26!$D33 -> 0 | M6: =Agosto26!$D33 -> 0
B7: =Settembre25!$D36 -> 1850 | C7: =Ottobre25!$D36 -> 1800 | D7: =Novembre25!$D36 -> 1700 | E7: =Dicembre25!$D36 -> 781 | F7: =Gennaio26!$D36 -> 1600 | G7: =Febbraio26!$D36 -> 1800 | H7: =Marzo26!$D36 | I7: =Aprile26!$D36 | J7: =Maggio26!$D36 | K7: =Giugno26!$D36 | L7: =Luglio26!$D36 | M7: =Agosto26!$D36
A8: =elenchi!A4 -> NURA | B8: =Settembre25!$E33 -> 225.5 | C8: =Ottobre25!$E33 -> 215.5 | D8: =Novembre25!$E33 -> 132 | E8: =Dicembre25!$E33 -> 160 | F8: =Gennaio26!$E33 -> 167.5 | G8: =Febbraio26!$E33 -> 162 | H8: =Marzo26!$E33 -> 199 | I8: =Aprile26!$E33 -> 0 | J8: =Maggio26!$E33 -> 0 | K8: =Giugno26!$E33 -> 0 | L8: =Luglio26!$E33 -> 0 | M8: =Agosto26!$E33 -> 0
B9: =Settembre25!$E36 -> 1750 | C9: =Ottobre25!$E36 -> 1700 | D9: =Novembre25!$E36 -> 1650 | E9: =Dicembre25!$E36 -> 1650 | F9: =Gennaio26!$E36 -> 1700 | G9: =Febbraio26!$E36 -> 1700 | H9: =Marzo26!$E36 | I9: =Aprile26!$E36 | J9: =Maggio26!$E36 | K9: =Giugno26!$E36 | L9: =Luglio26!$E36 | M9: =Agosto26!$E36
A10: =elenchi!A5 -> JOEL | B10: =Settembre25!$F33 -> 107.5 | C10: =Ottobre25!$F33 -> 178 | D10: =Novembre25!$F33 -> 188 | E10: =Dicembre25!$F33 -> 152 | F10: =Gennaio26!$F33 -> 167 | G10: =Febbraio26!$F33 -> 183 | H10: =Marzo26!$F33 -> 197 | I10: =Aprile26!$F33 -> 0 | J10: =Maggio26!$F33 -> 0 | K10: =Giugno26!$F33 -> 0 | L10: =Luglio26!$F33 -> 0 | M10: =Agosto26!$F33 -> 0
B11: =Settembre25!$F36 | C11: =Ottobre25!$F36 -> 1550 | D11: =Novembre25!$F36 -> 1700 | E11: =Dicembre25!$F36 -> 1700 | F11: =Gennaio26!$F36 -> 1700 | G11: =Febbraio26!$F36 -> 1700 | H11: =Marzo26!$F36 | I11: =Aprile26!$F36 | J11: =Maggio26!$F36 | K11: =Giugno26!$F36 | L11: =Luglio26!$F36 | M11: =Agosto26!$F36
A12: =elenchi!A6 -> KEVIN | B12: =Settembre25!$G33 -> 184.5 | C12: =Ottobre25!$G33 -> 205.5 | D12: =Novembre25!$G33 -> 72.5 | E12: =Dicembre25!$G33 -> 91.5 | F12: =Gennaio26!$G33 -> 169 | G12: =Febbraio26!$G33 -> 178 | H12: =Marzo26!$G33 -> 192 | I12: =Aprile26!$G33 -> 0 | J12: =Maggio26!$G33 -> 0 | K12: =Giugno26!$G33 -> 0 | L12: =Luglio26!$G33 -> 0 | M12: =Agosto26!$G33 -> 0
B13: =Settembre25!$G36 -> 1500 | C13: =Ottobre25!$G36 -> 1550 | D13: =Novembre25!$G36 | E13: =Dicembre25!$G36 -> 2000 | F13: =Gennaio26!$G36 -> 1600 | G13: =Febbraio26!$G36 -> 1650 | H13: =Marzo26!$G36 | I13: =Aprile26!$G36 | J13: =Maggio26!$G36 | K13: =Giugno26!$G36 | L13: =Luglio26!$G36 | M13: =Agosto26!$G36
A14: =elenchi!A7 -> ZOILA | B14: =Settembre25!$H33 -> 200 | C14: =Ottobre25!$H33 -> 181 | D14: =Novembre25!$H33 -> 183 | E14: =Dicembre25!$H33 -> 153.5 | F14: =Gennaio26!$H33 -> 155 | G14: =Febbraio26!$H33 -> 97.5 | H14: =Marzo26!$H33 -> 0 | I14: =Aprile26!$H33 -> 0 | J14: =Maggio26!$H33 -> 0 | K14: =Giugno26!$H33 -> 0 | L14: =Luglio26!$H33 -> 0 | M14: =Agosto26!$H33 -> 0
B15: =Settembre25!$H36 -> 1300 | C15: =Ottobre25!$H36 -> 1300 | D15: =Novembre25!$H36 -> 1300 | E15: =Dicembre25!$H36 -> 1200 | F15: =Gennaio26!$H36 -> 1250 | G15: =Febbraio26!$H36 -> 700 | H15: =Marzo26!$H36 | I15: =Aprile26!$H36 | J15: =Maggio26!$H36 | K15: =Giugno26!$H36 | L15: =Luglio26!$H36 | M15: =Agosto26!$H36
A16: =elenchi!A8 -> JASIR | B16: =Settembre25!$I33 -> 198 | C16: =Ottobre25!$I33 -> 208 | D16: =Novembre25!$I33 -> 190 | E16: =Dicembre25!$I33 -> 158 | F16: =Gennaio26!$I33 -> 160 | G16: =Febbraio26!$I33 -> 176 | H16: =Marzo26!$I33 -> 194 | I16: =Aprile26!$I33 -> 0 | J16: =Maggio26!$I33 -> 0 | K16: =Giugno26!$I33 -> 0 | L16: =Luglio26!$I33 -> 0 | M16: =Agosto26!$I33 -> 0
B17: =Settembre25!$I36 -> 1300 | C17: =Ottobre25!$I36 -> 1300 | D17: =Novembre25!$I36 -> 1300 | E17: =Dicembre25!$I36 -> 1200 | F17: =Gennaio26!$I36 -> 1250 | G17: =Febbraio26!$I36 -> 1400 | H17: =Marzo26!$I36 | I17: =Aprile26!$I36 | J17: =Maggio26!$I36 | K17: =Giugno26!$I36 | L17: =Luglio26!$I36 | M17: =Agosto26!$I36
A18: =elenchi!A9 -> SARA | B18: =Settembre25!$J33 -> 209 | C18: =Ottobre25!$J33 -> 159.5 | D18: =Novembre25!$J33 -> 166.5 | E18: =Dicembre25!$J33 -> 120 | F18: =Gennaio26!$J33 -> 133.5 | G18: =Febbraio26!$J33 -> 141.5 | H18: =Marzo26!$J33 -> 181.5 | I18: =Aprile26!$J33 -> 0 | J18: =Maggio26!$J33 -> 0 | K18: =Giugno26!$J33 -> 0 | L18: =Luglio26!$J33 -> 0 | M18: =Agosto26!$J33 -> 0
B19: =Settembre25!$J36 -> 1800 | C19: =Ottobre25!$J36 -> 1650 | D19: =Novembre25!$J36 -> 1700 | E19: =Dicembre25!$J36 -> 1600 | F19: =Gennaio26!$J36 | G19: =Febbraio26!$J36 -> 1600 | H19: =Marzo26!$J36 | I19: =Aprile26!$J36 | J19: =Maggio26!$J36 | K19: =Giugno26!$J36 | L19: =Luglio26!$J36 | M19: =Agosto26!$J36
A20: =elenchi!A10 -> SANTO | B20: =Settembre25!$K33 -> 181 | C20: =Ottobre25!$K33 -> 184 | D20: =Novembre25!$K33 -> 160 | E20: =Dicembre25!$K33 -> 144 | F20: =Gennaio26!$K33 -> 144 | G20: =Febbraio26!$K33 -> 160 | H20: =Marzo26!$K33 -> 176 | I20: =Aprile26!$K33 -> 0 | J20: =Maggio26!$K33 -> 0 | K20: =Giugno26!$K33 -> 0 | L20: =Luglio26!$K33 -> 0 | M20: =Agosto26!$K33 -> 0
B21: =Settembre25!$K36 -> 2600 | C21: =Ottobre25!$K36 -> 2500 | D21: =Novembre25!$K36 -> 2500 | E21: =Dicembre25!$K36 -> 2500 | F21: =Gennaio26!$K36 -> 2500 | G21: =Febbraio26!$K36 -> 2500 | H21: =Marzo26!$K36 | I21: =Aprile26!$K36 | J21: =Maggio26!$K36 | K21: =Giugno26!$K36 | L21: =Luglio26!$K36 | M21: =Agosto26!$K36
A22: =elenchi!A11 -> MASSI | B22: =Settembre25!$L33 -> 184 | C22: =Ottobre25!$L33 -> 195 | D22: =Novembre25!$L33 -> 168 | E22: =Dicembre25!$L33 -> 150 | F22: =Gennaio26!$L33 -> 152 | G22: =Febbraio26!$L33 -> 167 | H22: =Marzo26!$L33 -> 184 | I22: =Aprile26!$L33 -> 0 | J22: =Maggio26!$L33 -> 0 | K22: =Giugno26!$L33 -> 0 | L22: =Luglio26!$L33 -> 0 | M22: =Agosto26!$L33 -> 0
B23: =Settembre25!$L36 | C23: =Ottobre25!$L36 -> 1600 | D23: =Novembre25!$L36 -> 1600 | E23: =Dicembre25!$L36 -> 1600 | F23: =Gennaio26!$L36 -> 1600 | G23: =Febbraio26!$L36 -> 1600 | H23: =Marzo26!$L36 | I23: =Aprile26!$L36 | J23: =Maggio26!$L36 | K23: =Giugno26!$L36 | L23: =Luglio26!$L36 | M23: =Agosto26!$L36
A24: =elenchi!A12 -> STEFANO | B24: =Settembre25!$M33 -> 105 | C24: =Ottobre25!$M33 -> 143 | D24: =Novembre25!$M33 -> 122 | E24: =Dicembre25!$M33 -> 0 | F24: =Gennaio26!$M33 -> 72 | G24: =Febbraio26!$M33 -> 0 | H24: =Marzo26!$M33 -> 36 | I24: =Aprile26!$M33 -> 0 | J24: =Maggio26!$M33 -> 0 | K24: =Giugno26!$M33 -> 0 | L24: =Luglio26!$M33 -> 0 | M24: =Agosto26!$M33 -> 0
B25: =Settembre25!$M36 -> 680 | C25: =Ottobre25!$M36 -> 950 | D25: =Novembre25!$M36 | E25: =Dicembre25!$M36 | F25: =Gennaio26!$M36 | G25: =Febbraio26!$M36 | H25: =Marzo26!$M36 | I25: =Aprile26!$M36 | J25: =Maggio26!$M36 | K25: =Giugno26!$M36 | L25: =Luglio26!$M36 | M25: =Agosto26!$M36

Sheet griglia_presenze_SET-AGO
A1: =elenchi!D1 -> SET - Nominativo Dipendente | D1: =elenchi!E1 -> PRESTAZIONI PER CIASCUNA GIORNATA DEL MESE DI: SETTEMBRE 2025 | AT1: =elenchi!D2 -> OTT - Nominativo Dipendente | AW1: =elenchi!E2 -> PRESTAZIONI PER CIASCUNA GIORNATA DEL MESE DI: OTTOBRE 2025 | CM1: =elenchi!D3 -> NOV - Nominativo Dipendente | CP1: =elenchi!E3 -> PRESTAZIONI PER CIASCUNA GIORNATA DEL MESE DI: NOVEMBRE 2025 | EF1: =elenchi!D4 -> DIC - Nominativo Dipendente | EI1: =elenchi!E4 -> PRESTAZIONI PER CIASCUNA GIORNATA DEL MESE DI: DICEMBRE 2025 | FY1: =elenchi!D5 -> GEN - Nominativo Dipendente | GB1: =elenchi!E5 -> PRESTAZIONI PER CIASCUNA GIORNATA DEL MESE DI: GENNAIO 2026 | HR1: =elenchi!D6 -> FEB - Nominativo Dipendente | HU1: =elenchi!E6 -> PRESTAZIONI PER CIASCUNA GIORNATA DEL MESE DI: FEBBRAIO 2026 | JK1: =elenchi!D7 -> MAR - Nominativo Dipendente | JN1: =elenchi!E7 -> PRESTAZIONI PER CIASCUNA GIORNATA DEL MESE DI: MARZO 2026 | LD1: =elenchi!D8 -> APR - Nominativo Dipendente | LG1: =elenchi!E8 -> PRESTAZIONI PER CIASCUNA GIORNATA DEL MESE DI: APRILE 2026 | MW1: =elenchi!D9 -> MAG - Nominativo Dipendente | MZ1: =elenchi!E9 -> PRESTAZIONI PER CIASCUNA GIORNATA DEL MESE DI: MAGGIO 2026 | OP1: =elenchi!D10 -> GIU - Nominativo Dipendente | OS1: =elenchi!E10 -> PRESTAZIONI PER CIASCUNA GIORNATA DEL MESE DI: GIUGNO 2026 | QI1: =elenchi!D11 -> LUG - Nominativo Dipendente | QL1: =elenchi!E11 -> PRESTAZIONI PER CIASCUNA GIORNATA DEL MESE DI: LUGLIO 2026 | SB1: =elenchi!D12 -> AGO - Nominativo Dipendente | SE1: =elenchi!E12 -> PRESTAZIONI PER CIASCUNA GIORNATA DEL MESE DI: AGOSTO 2026
A2: Giorni | D2: 45901 | E2: 45902 | F2: 45903 | G2: 45904 | H2: 45905 | I2: 45906 | J2: 45907 | K2: 45908 | L2: 45909 | M2: 45910 | N2: 45911 | O2: 45912 | P2: 45913 | Q2: 45914 | R2: 45915 | S2: 45916 | T2: 45917 | U2: 45918 | V2: 45919 | W2: 45920 | X2: 45921 | Y2: 45922 | Z2: 45923 | AA2: 45924 | AB2: 45925 | AC2: 45926 | AD2: 45927 | AE2: 45928 | AF2: 45929 | AG2: 45930 | AI2: GIORNI/ORE LAV. | AL2: Assenze | AW2: 45931 | AX2: 45932 | AY2: 45933 | AZ2: 45934 | BA2: 45935 | BB2: 45936 | BC2: 45937 | BD2: 45938 | BE2: 45939 | BF2: 45940 | BG2: 45941 | BH2: 45942 | BI2: 45943 | BJ2: 45944 | BK2: 45945 | BL2: 45946 | BM2: 45947 | BN2: 45948 | BO2: 45949 | BP2: 45950 | BQ2: 45951 | BR2: 45952 | BS2: 45953 | BT2: 45954 | BU2: 45955 | BV2: 45956 | BW2: 45957 | BX2: 45958 | BY2: 45959 | BZ2: 45960 | CA2: 45961 | CB2: GIORNI/ORE LAV. | CE2: Assenze | CP2: 45962 | CQ2: 45963 | CR2: 45964 | CS2: 45965 | CT2: 45966 | CU2: 45967 | CV2: 45968 | CW2: 45969 | CX2: 45970 | CY2: 45971 | CZ2: 45972 | DA2: 45973 | DB2: 45974 | DC2: 45975 | DD2: 45976 | DE2: 45977 | DF2: 45978 | DG2: 45979 | DH2: 45980 | DI2: 45981 | DJ2: 45982 | DK2: 45983 | DL2: 45984 | DM2: 45985 | DN2: 45986 | DO2: 45987 | DP2: 45988 | DQ2: 45989 | DR2: 45990 | DS2: 45991 | DU2: GIORNI/ORE LAV. | DX2: Assenze | EI2: 45992 | EJ2: 45993 | EK2: 45994 | EL2: 45995 | EM2: 45996 | EN2: 45997 | EO2: 45998 | EP2: 45999 | EQ2: 46000 | ER2: 46001 | ES2: 46002 | ET2: 46003 | EU2: 46004 | EV2: 46005 | EW2: 46006 | EX2: 46007 | EY2: 46008 | EZ2: 46009 | FA2: 46010 | FB2: 46011 | FC2: 46012 | FD2: 46013 | FE2: 46014 | FF2: 46015 | FG2: 46016 | FH2: 46017 | FI2: 46018 | FJ2: 46019 | FK2: 46020 | FL2: 46021 | FM2: 46022 | FN2: GIORNI/ORE LAV. | FQ2: Assenze | GB2: 46023 | GC2: 46024 | GD2: 46025 | GE2: 46026 | GF2: 46027 | GG2: 46028 | GH2: 46029 | GI2: 46030 | GJ2: 46031 | GK2: 46032 | GL2: 46033 | GM2: 46034 | GN2: 46035 | GO2: 46036 | GP2: 46037 | GQ2: 46038 | GR2: 46039 | GS2: 46040 | GT2: 46041 | GU2: 46042 | GV2: 46043 | GW2: 46044 | GX2: 46045 | GY2: 46046 | GZ2: 46047 | HA2: 46048 | HB2: 46049 | HC2: 46050 | HD2: 46051 | HE2: 46052 | HF2: 46053 | HG2: GIORNI/ORE LAV. | HJ2: Assenze | HU2: 46054 | HV2: 46055 | HW2: 46056 | HX2: 46057 | HY2: 46058 | HZ2: 46059 | IA2: 46060 | IB2: 46061 | IC2: 46062 | ID2: 46063 | IE2: 46064 | IF2: 46065 | IG2: 46066 | IH2: 46067 | II2: 46068 | IJ2: 46069 | IK2: 46070 | IL2: 46071 | IM2: 46072 | IN2: 46073 | IO2: 46074 | IP2: 46075 | IQ2: 46076 | IR2: 46077 | IS2: 46078 | IT2: 46079 | IU2: 46080 | IV2: 46081 | IZ2: GIORNI/ORE LAV. | JC2: Assenze | JN2: 46082 | JO2: 46083 | JP2: 46084 | JQ2: 46085 | JR2: 46086 | JS2: 46087 | JT2: 46088 | JU2: 46089 | JV2: 46090 | JW2: 46091 | JX2: 46092 | JY2: 46093 | JZ2: 46094 | KA2: 46095 | KB2: 46096 | KC2: 46097 | KD2: 46098 | KE2: 46099 | KF2: 46100 | KG2: 46101 | KH2: 46102 | KI2: 46103 | KJ2: 46104 | KK2: 46105 | KL2: 46106 | KM2: 46107 | KN2: 46108 | KO2: 46109 | KP2: 46110 | KQ2: 46111 | KR2: 46112 | KS2: GIORNI/ORE LAV. | KV2: Assenze | LG2: 46113 | LH2: 46114 | LI2: 46115 | LJ2: 46116 | LK2: 46117 | LL2: 46118 | LM2: 46119 | LN2: 46120 | LO2: 46121 | LP2: 46122 | LQ2: 46123 | LR2: 46124 | LS2: 46125 | LT2: 46126 | LU2: 46127 | LV2: 46128 | LW2: 46129 | LX2: 46130 | LY2: 46131 | LZ2: 46132 | MA2: 46133 | MB2: 46134 | MC2: 46135 | MD2: 46136 | ME2: 46137 | MF2: 46138 | MG2: 46139 | MH2: 46140 | MI2: 46141 | MJ2: 46142 | ML2: GIORNI/ORE LAV. | MO2: Assenze | MZ2: 46143 | NA2: 46144 | NB2: 46145 | NC2: 46146 | ND2: 46147 | NE2: 46148 | NF2: 46149 | NG2: 46150 | NH2: 46151 | NI2: 46152 | NJ2: 46153 | NK2: 46154 | NL2: 46155 | NM2: 46156 | NN2: 46157 | NO2: 46158 | NP2: 46159 | NQ2: 46160 | NR2: 46161 | NS2: 46162 | NT2: 46163 | NU2: 46164 | NV2: 46165 | NW2: 46166 | NX2: 46167 | NY2: 46168 | NZ2: 46169 | OA2: 46170 | OB2: 46171 | OC2: 46172 | OD2: 46173 | OE2: GIORNI/ORE LAV. | OH2: Assenze | OS2: 46174 | OT2: 46175 | OU2: 46176 | OV2: 46177 | OW2: 46178 | OX2: 46179 | OY2: 46180 | OZ2: 46181 | PA2: 46182 | PB2: 46183 | PC2: 46184 | PD2: 46185 | PE2: 46186 | PF2: 46187 | PG2: 46188 | PH2: 46189 | PI2: 46190 | PJ2: 46191 | PK2: 46192 | PL2: 46193 | PM2: 46194 | PN2: 46195 | PO2: 46196 | PP2: 46197 | PQ2: 46198 | PR2: 46199 | PS2: 46200 | PT2: 46201 | PU2: 46202 | PV2: 46203 | PX2: GIORNI/ORE LAV. | QA2: Assenze | QL2: 46204 | QM2: 46205 | QN2: 46206 | QO2: 46207 | QP2: 46208 | QQ2: 46209 | QR2: 46210 | QS2: 46211 | QT2: 46212 | QU2: 46213 | QV2: 46214 | QW2: 46215 | QX2: 46216 | QY2: 46217 | QZ2: 46218 | RA2: 46219 | RB2: 46220 | RC2: 46221 | RD2: 46222 | RE2: 46223 | RF2: 46224 | RG2: 46225 | RH2: 46226 | RI2: 46227 | RJ2: 46228 | RK2: 46229 | RL2: 46230 | RM2: 46231 | RN2: 46232 | RO2: 46233 | RP2: 46234 | RQ2: GIORNI/ORE LAV. | RT2: Assenze | SE2: 46235 | SF2: 46236 | SG2: 46237 | SH2: 46238 | SI2: 46239 | SJ2: 46240 | SK2: 46241 | SL2: 46242 | SM2: 46243 | SN2: 46244 | SO2: 46245 | SP2: 46246 | SQ2: 46247 | SR2: 46248 | SS2: 46249 | ST2: 46250 | SU2: 46251 | SV2: 46252 | SW2: 46253 | SX2: 46254 | SY2: 46255 | SZ2: 46256 | TA2: 46257 | TB2: 46258 | TC2: 46259 | TD2: 46260 | TE2: 46261 | TF2: 46262 | TG2: 46263 | TH2: 46264 | TI2: 46265 | TJ2: GIORNI/ORE LAV. | TM2: Assenze
A3: =elenchi!$C1 -> MALDONADO ALEXANDRA | D3: =D$2 -> 45901 | E3: =E$2 -> 45902 | F3: =F$2 -> 45903 | G3: =G$2 -> 45904 | H3: =H$2 -> 45905 | I3: =I$2 -> 45906 | J3: =J$2 -> 45907 | K3: =K$2 -> 45908 | ... AH3: =AH$2 | AI3: GG | AJ3: ORE | AK3: ST* | AL3: FE | AM3: PE | AN3: AI | AO3: AG | AP3: MT | AQ3: ML | AR3: IN | AS3: F | AT3: =elenchi!$C1 -> MALDONADO ALEXANDRA | AW3: =AW$2 -> 45931 | AX3: =AX$2 -> 45932 | AY3: =AY$2 -> 45933 | AZ3: =AZ$2 -> 45934 | BA3: =BA$2 -> 45935 | BB3: =BB$2 -> 45936 | BC3: =BC$2 -> 45937 | BD3: =BD$2 -> 45938 | ... CA3: =CA$2 -> 45961 | CB3: GG | CC3: ORE | CD3: ST* | CE3: FE | CF3: PE | CG3: AI | CH3: AG | CI3: MT | CJ3: ML | CK3: IN | CL3: F | CM3: =elenchi!$C1 -> MALDONADO ALEXANDRA | CP3: =CP$2 -> 45962 | CQ3: =CQ$2 -> 45963 | CR3: =CR$2 -> 45964 | CS3: =CS$2 -> 45965 | CT3: =CT$2 -> 45966 | CU3: =CU$2 -> 45967 | CV3: =CV$2 -> 45968 | CW3: =CW$2 -> 45969 | ... DT3: =DT$2 | DU3: GG | DV3: ORE | DW3: ST* | DX3: FE | DY3: PE | DZ3: AI | EA3: AG | EB3: MT | EC3: ML | ED3: IN | EE3: F | EF3: =elenchi!$C1 -> MALDONADO ALEXANDRA | EI3: =EI$2 -> 45992 | EJ3: =EJ$2 -> 45993 | EK3: =EK$2 -> 45994 | EL3: =EL$2 -> 45995 | EM3: =EM$2 -> 45996 | EN3: =EN$2 -> 45997 | EO3: =EO$2 -> 45998 | EP3: =EP$2 -> 45999 | ... FM3: =FM$2 -> 46022 | FN3: GG | FO3: ORE | FP3: ST* | FQ3: FE | FR3: PE | FS3: AI | FT3: AG | FU3: MT | FV3: ML | FW3: IN | FX3: F | FY3: =elenchi!$C1 -> MALDONADO ALEXANDRA | GB3: =GB$2 -> 46023 | GC3: =GC$2 -> 46024 | GD3: =GD$2 -> 46025 | GE3: =GE$2 -> 46026 | GF3: =GF$2 -> 46027 | GG3: =GG$2 -> 46028 | GH3: =GH$2 -> 46029 | GI3: =GI$2 -> 46030 | ... HF3: =HF$2 -> 46053 | HG3: GG | HH3: ORE | HI3: ST* | HJ3: FE | HK3: PE | HL3: AI | HM3: AG | HN3: MT | HO3: ML | HP3: IN | HQ3: F | HR3: =elenchi!$C1 -> MALDONADO ALEXANDRA | HU3: =HU$2 -> 46054 | HV3: =HV$2 -> 46055 | HW3: =HW$2 -> 46056 | HX3: =HX$2 -> 46057 | HY3: =HY$2 -> 46058 | HZ3: =HZ$2 -> 46059 | IA3: =IA$2 -> 46060 | IB3: =IB$2 -> 46061 | ... IY3: =IY$2 | IZ3: GG | JA3: ORE | JB3: ST* | JC3: FE | JD3: PE | JE3: AI | JF3: AG | JG3: MT | JH3: ML | JI3: IN | JJ3: F | JK3: =elenchi!$C1 -> MALDONADO ALEXANDRA | JN3: =JN$2 -> 46082 | JO3: =JO$2 -> 46083 | JP3: =JP$2 -> 46084 | JQ3: =JQ$2 -> 46085 | JR3: =JR$2 -> 46086 | JS3: =JS$2 -> 46087 | JT3: =JT$2 -> 46088 | JU3: =JU$2 -> 46089 | ... KR3: =KR$2 -> 46112 | KS3: GG | KT3: ORE | KU3: ST* | KV3: FE | KW3: PE | KX3: AI | KY3: AG | KZ3: MT | LA3: ML | LB3: IN | LC3: F | LD3: =elenchi!$C1 -> MALDONADO ALEXANDRA | LG3: =LG$2 -> 46113 | LH3: =LH$2 -> 46114 | LI3: =LI$2 -> 46115 | LJ3: =LJ$2 -> 46116 | LK3: =LK$2 -> 46117 | LL3: =LL$2 -> 46118 | LM3: =LM$2 -> 46119 | LN3: =LN$2 -> 46120 | ... MK3: =MK$2 | ML3: GG | MM3: ORE | MN3: ST* | MO3: FE | MP3: PE | MQ3: AI | MR3: AG | MS3: MT | MT3: ML | MU3: IN | MV3: F | MW3: =elenchi!$C1 -> MALDONADO ALEXANDRA | MZ3: =MZ$2 -> 46143 | NA3: =NA$2 -> 46144 | NB3: =NB$2 -> 46145 | NC3: =NC$2 -> 46146 | ND3: =ND$2 -> 46147 | NE3: =NE$2 -> 46148 | NF3: =NF$2 -> 46149 | NG3: =NG$2 -> 46150 | ... OD3: =OD$2 -> 46173 | OE3: GG | OF3: ORE | OG3: ST* | OH3: FE | OI3: PE | OJ3: AI | OK3: AG | OL3: MT | OM3: ML | ON3: IN | OO3: F | OP3: =elenchi!$C1 -> MALDONADO ALEXANDRA | OS3: =OS$2 -> 46174 | OT3: =OT$2 -> 46175 | OU3: =OU$2 -> 46176 | OV3: =OV$2 -> 46177 | OW3: =OW$2 -> 46178 | OX3: =OX$2 -> 46179 | OY3: =OY$2 -> 46180 | OZ3: =OZ$2 -> 46181 | ... PW3: =PW$2 | PX3: GG | PY3: ORE | PZ3: ST* | QA3: FE | QB3: PE | QC3: AI | QD3: AG | QE3: MT | QF3: ML | QG3: IN | QH3: F | QI3: =elenchi!$C1 -> MALDONADO ALEXANDRA | QL3: =QL$2 -> 46204 | QM3: =QM$2 -> 46205 | QN3: =QN$2 -> 46206 | QO3: =QO$2 -> 46207 | QP3: =QP$2 -> 46208 | QQ3: =QQ$2 -> 46209 | QR3: =QR$2 -> 46210 | QS3: =QS$2 -> 46211 | ... RP3: =RP$2 -> 46234 | RQ3: GG | RR3: ORE | RS3: ST* | RT3: FE | RU3: PE | RV3: AI | RW3: AG | RX3: MT | RY3: ML | RZ3: IN | SA3: F | SB3: =elenchi!$C1 -> MALDONADO ALEXANDRA | SE3: =SE$2 -> 46235 | SF3: =SF$2 -> 46236 | SG3: =SG$2 -> 46237 | SH3: =SH$2 -> 46238 | SI3: =SI$2 -> 46239 | SJ3: =SJ$2 -> 46240 | SK3: =SK$2 -> 46241 | SL3: =SL$2 -> 46242 | ... TI3: =TI$2 -> 46265 | TJ3: GG | TK3: ORE | TL3: ST* | TM3: FE | TN3: PE | TO3: AI | TP3: AG | TQ3: MT | TR3: ML | TS3: IN | TT3: F
