Workbook

Sheet CLAUDIA_LARUCCIA_26
A1: CLAUDIA LARUCCIA
B2: Descrizione | C2: Dettagli | D2: Q.t | E2: Importo | F2: Metodo di pagamento
A3: USCITE ARTISTA | B3: Fee artist | C3: WS da 1h 30 | D3: 1 | E3: -550 | F3: Bonifico
B4: Spese di viaggio | D4: - | E4: 0 | F4: Carta
B5: Taxi da aeroporto a Hotel | D5: - | E5: 0
B6: Taxi da Hotel a aeroporto | D6: - | E6: 0
B7: Hotel | D7: 0 | E7: 0
B8: Pranzi | D8: 0 | E8: 0
B9: Cene | D9: 0 | E9: 0
B10: Adidas | C10: Tshirt | D10: 1 | E10: -18 | F10: Rid Bancario
B11: TOTALE USCITE X ARTISTA | E11: =SUM(E3:E10) -> -568
A13: USCITE EXTRA | B13: Affitto spazio | C13: No (minimo €300) | D13: - | E13: 0
B14: Personale | C14: 3 | D14: - | E14: -100 | F14: Bonifico
B15: Video maker | D15: - | E15: -200 | F15: Affitto Yuri
B16: Volantini | E16: -10 | F16: Bonifico
B17: Manifesti | D17: - | E17: 0
B18: Fish singolo per vendita | D18: - | E18: -20 | F18: Contanti cassa Elisa
B19: Bonus team per vendita | D19: - | E19: -20 | F19: Contanti cassa Elisa
B20: Pranzo per team | D20: - | E20: 0
B21: Sponsorizzate | D21: - | E21: -200 | F21: Carta
B22: Resi | D22: - | E22: 0
B23: Commissioni Online | C23: Percentuale del 1,5% su una media di €36 | D23: 60 | E23: =D23*36*-1.5% -> -32.4 | F23: Commissioni
B24: TOTALE USCITE EXTRA | E24: =SUM(E13:E23) -> -582.4
B26: TOTALE USCITE | E26: =E11+E24 -> -1150.4
A28: STIMA CONTRIBUTI/INCASSI €32 entro il 28 gennaio compreso (con cod sconto €30) €37 entro il 28 marzo compreso (con cod sconto €35) €42 il giorno stesso (con cod sconto €40) | B28: Stima del MINIMO incassabile | C28: 30 | D28: 60 | E28: =C28*D28 -> 1800 | F28: =E26+E28 -> 649.6
B29: Stima del MASSIMO incassabile | C29: 42 | D29: 60 | E29: =C29*D29 -> 2520 | F29: =E26+E29 -> 1369.6
B30: Stima MEDIA incassabile | C30: 36 | D30: 60 | E30: =C30*D30 -> 2160 | F30: =E26+E30 -> 1009.6
A32: ENTRATE
B43: RICAVO/PERDITA | E43: =E40+E26 -> -1150.4

Sheet CARLOS_DIAZ_10MAG26
A1: CARLOS DIAZ
B2: Descrizione | C2: Dettagli | D2: Q.t | E2: Importo | F2: Metodo di pagamento
A3: USCITE ARTISTA | B3: Fee artist | C3: WS da 1h 30 | D3: 1 | E3: -1000
B4: Spese di viaggio | D4: - | E4: 0
B5: Taxi da aeroporto a Hotel | D5: - | E5: 0
B6: Taxi da Hotel a aeroporto | D6: - | E6: 0
B7: Hotel | D7: 0 | E7: 0
B8: Pranzi | D8: 0 | E8: 0
B9: Cene | D9: 0 | E9: 0
B10: Adidas | C10: Tshirt JE9024 tg XL | D10: 1 | E10: -18 | F10: Rid Bancario
B11: TOTALE USCITE X ARTISTA | E11: =SUM(E3:E10) -> -1018
A13: USCITE EXTRA | B13: Affitto spazio | C13: No (minimo €300) | D13: - | E13: 0
B14: Personale | C14: 3h30/4h | D14: - | E14: -100 | F14: Bonifico
B15: Video maker | D15: - | E15: -200 | F15: Affitto Yuri
B16: Volantini | E16: -10 | F16: Bonifico
B17: Video per sponsorizzate Meta | D17: - | E17: -30 | F17: Bonifico
B18: Fish singolo per vendita | D18: - | E18: -20 | F18: Contanti cassa Elisa
B19: Bonus team per vendita | D19: - | E19: -20 | F19: Contanti cassa Elisa
B20: Pranzo per team | D20: - | E20: 0
B21: Sponsorizzate | D21: - | E21: -200 | F21: Carta
B22: Resi | D22: - | E22: 0
B23: Commissioni Online | C23: Percentuale del 1,5% su una media di €36 | D23: 60 | E23: =D23*35*-1.5% -> -31.5 | F23: Commissioni
B24: TOTALE USCITE EXTRA | E24: =SUM(E13:E23) -> -611.5
B26: TOTALE USCITE | E26: =E11+E24 -> -1629.5
A28: STIMA CONTRIBUTI/INCASSI €37 entro il X compreso (con cod sconto €35) €42 entro il Y compreso (con cod sconto €40) €45 il giorno stesso (con cod sconto €43) | B28: Stima del MINIMO incassabile | C28: 35 | D28: 60 | E28: =C28*D28 -> 2100 | F28: =E26+E28 -> 470.5
B29: Stima del MASSIMO incassabile | C29: 37 | D29: 60 | E29: =C29*D29 -> 2220 | F29: =E26+E29 -> 590.5
B30: Stima MEDIA incassabile | C30: 36 | D30: 60 | E30: =C30*D30 -> 2160 | F30: =E26+E30 -> 530.5
A32: ENTRATE
B43: RICAVO/PERDITA | E43: =E40+E26 -> -1629.5

Sheet BRASILIAN_GEM_DAY_10MAG26
A1: BRASILIAN GEM DAY
B2: Descrizione | C2: Dettagli | D2: Q.t | E2: Importo | F2: Metodo di pagamento
A3: USCITE ARTISTA | B3: Fee artist | C3: WS da 1h 30 | D3: 1 | E3: -500 | F3: Bonifico
B4: Spese di viaggio | C4: A/R Londra-Mi | D4: - | E4: 0
B5: Taxi da aeroporto SG | D5: - | E5: 0
B6: Taxi da SG a aeroporto | D6: - | E6: 0
B7: Fee Carlos | C7: WS da 1h30 | D7: - | E7: -200 | F7: Bonifico
B8: Pranzi | D8: - | E8: 0
B9: Cene | D9: - | E9: 0
B10: Adidas | C10: Tshirt | D10: 1 | E10: -18 | F10: Rid Bancario
B11: TOTALE USCITE X ARTISTA | E11: =SUM(E3:E10) -> -718
A13: USCITE EXTRA | B13: Affitto spazio | C13: No (minimo €300) | D13: - | E13: 0
B14: Personale | C14: 3h30/4h | D14: - | E14: -100 | F14: Bonifico
B15: Video maker | D15: - | E15: -200 | F15: Affitto Yuri
B16: Volantini | E16: -10 | F16: Bonifico
B17: Video per sponsorizzate Meta | D17: - | E17: -30 | F17: Bonifico
B18: Fish singolo per vendita | D18: - | E18: -20 | F18: Contanti cassa Elisa
B19: Bonus team per vendita | D19: - | E19: -20 | F19: Contanti cassa Elisa
B20: Pranzo per team | D20: - | E20: 0
B21: Sponsorizzate | D21: - | E21: -200 | F21: Carta
B22: Resi | D22: - | E22: 0
B23: Commissioni Online | C23: Percentuale del 1,5% su una media di €36 | D23: 50 | E23: =D23*36*-1.5% -> -27 | F23: Commissioni
B24: TOTALE USCITE EXTRA | E24: =SUM(E13:E23) -> -607
B26: TOTALE USCITE | E26: =E11+E24 -> -1325
A28: STIMA CONTRIBUTI/INCASSI €37 fino al 09 Maggio compreso (con cod sconto €35) €42 il giorno stesso (con cod sconto €40) | B28: Stima del MINIMO incassabile | C28: 35 | D28: 50 | E28: =C28*D28 -> 1750 | F28: =E26+E28 -> 425
B29: Stima del MASSIMO incassabile | C29: 42 | D29: 50 | E29: =C29*D29 -> 2100 | F29: =E26+E29 -> 775
B30: Stima MEDIA incassabile | C30: 37 | D30: 50 | E30: =C30*D30 -> 1850 | F30: =E26+E30 -> 525
A32: ENTRATE
B44: RICAVO/PERDITA | E44: =E37+E26 -> -1325

Sheet FERGIEANDREA_10MAG26
A1: FERGIE & ANDREA
B2: Descrizione | C2: Dettagli | D2: Q.t | E2: Importo | F2: Metodo di pagamento
A3: USCITE ARTISTA | B3: Fee artists | C3: Openclass da 1,5h | D3: - | E3: =E36*-30% -> 0 | F3: Bonifico
B4: Spese di viaggio | D4: - | E4: 0
B5: Taxi da aeroporto a Hotel | D5: - | E5: 0
B6: Taxi da Hotel a aeroporto | D6: - | E6: 0
B7: Hotel | D7: - | E7: 0
B8: Pranzi | D8: - | E8: 0
B9: Cene | D9: - | E9: 0
B10: Adidas | C10: Tshirt JE9024 tg M Tshirt JC5943 Tg M | D10: - | E10: -36 | F10: Rid Bancario
B11: TOTALE USCITE X ARTISTA | E11: =SUM(E3:E10) -> -36
A13: USCITE EXTRA | B13: Affitto spazio | C13: No (minimo €300) | D13: - | E13: 0
B14: Personale | C14: 3 persone (€10/h) x 2h30 | D14: - | E14: -75 | F14: Bonifico
B15: Video maker | D15: - | E15: 0
B16: Volantini | E16: 0 | F16: Bonifico
B17: Video per sponsorizzate Meta | D17: - | E17: 0
B18: Fish singolo per vendita | D18: - | E18: -10 | F18: Contanti cassa Elisa
B19: Bonus team per vendita | D19: - | E19: -25 | F19: Contanti cassa Elisa
B20: Sponsorizzate | D20: - | E20: 0 | F20: Carta
B21: Resi | D21: - | E21: 0
B22: Commissioni Online | C22: Percentuale del 1,5% su una media di €23,5 | D22: 40 | E22: =D22*23.5*-1.5% -> -14.1 | F22: Commissioni
B23: TOTALE USCITE EXTRA | E23: =SUM(E13:E22) -> -124.1
B25: TOTALE USCITE | E25: =E11+E23 -> -160.1
A27: STIMA CONTRIBUTI/INCASSI €22 entro il 30 Aprile compreso (con cod sconto €20) €27 dall'1 Maggio al 10 Maggio compreso (con cod sconto €25) | B27: Stima del MINIMO incassabile | C27: 20 | D27: 40 | E27: =C27*D27 -> 800 | F27: =E25+E27 -> 639.9
B28: Stima del MASSIMO incassabile | C28: 27 | D28: 40 | E28: =C28*D28 -> 1080 | F28: =E25+E28 -> 919.9
B29: Stima MEDIA incassabile | C29: 23.5 | D29: 40 | E29: =C29*D29 -> 940 | F29: =E25+E29 -> 779.9
A31: ENTRATE
B43: RICAVO/PERDITA | E43: =E36+E25 -> -160.1

Sheet JASMINE_ANDRIANO_19APR26
A1: JASMINE ANDRIANO
B2: Descrizione | C2: Dettagli | D2: Q.t | E2: Importo | F2: Metodo di pagamento
A3: USCITE ARTISTA | B3: Fee artist | C3: WS da 1h 30 | D3: 1 | E3: -650 | F3: Bonifico
B4: Spese di viaggio | C4: Volo A/R Bari-Mi (al 50%) | D4: 2 | E4: -76.42 | F4: Carta
B5: Taxi da aeroporto a Hotel | D5: - | E5: 0
B6: Taxi da Hotel a aeroporto | D6: - | E6: 0
B7: Hotel | D7: 0 | E7: 0
B8: Pranzi | D8: 0 | E8: 0
B9: Cene | D9: 0 | E9: 0
B10: Adidas | C10: Tshirt JC5943 Tg M | D10: 1 | E10: -18 | F10: Rid Bancario
B11: TOTALE USCITE X ARTISTA | E11: =SUM(E3:E10) -> -744.42
A13: USCITE EXTRA | B13: Affitto spazio | C13: No (minimo €300) | D13: - | E13: 0
B14: Personale | C14: 2H30 Spese divise con Affitto Modulo (calcolo approssimativo) | D14: - | E14: -40 | F14: Bonifico
B15: Videomaker | D15: - | E15: 0 | F15: Affitto Yuri
B16: Volantini | E16: -10 | F16: Bonifico
B17: Video per sponsorizzate Meta | D17: - | E17: -30 | F17: Bonifico
B18: Fish singolo per vendita | D18: - | E18: 0 | F18: Contanti cassa Elisa
B19: Bonus team per vendita | D19: - | E19: -3 | F19: Contanti cassa Elisa
B20: Pranzo per team | D20: - | E20: 0
B21: Sponsorizzate | D21: - | E21: -244 | F21: Carta
B22: Resi | D22: - | E22: 0
B23: Commissioni Online | C23: Percentuale del 1,5% su una media di €36 | D23: 6 | E23: =D23*36*-1.5% -> -3.24 | F23: Commissioni
B24: TOTALE USCITE EXTRA | E24: =SUM(E13:E23) -> -330.24
B26: TOTALE USCITE | E26: =E11+E24 -> -1074.66
A28: STIMA CONTRIBUTI/INCASSI €32 entro il 18 marzo compreso (con cod sconto €30) €37 entro il 18 aprile compreso (con cod sconto €35) €42 il giorno stesso (con cod sconto €40) | B28: Stima del MINIMO incassabile | C28: 30 | D28: 50 | E28: =C28*D28 -> 1500 | F28: =E26+E28 -> 425.34
B29: Stima del MASSIMO incassabile | C29: 42 | D29: 50 | E29: =C29*D29 -> 2100 | F29: =E26+E29 -> 1025.34
B30: Stima MEDIA incassabile | C30: 36 | D30: 50 | E30: =C30*D30 -> 1800 | F30: =E26+E30 -> 725.34
A32: ENTRATE | B32: =IFERROR(__xludf.DUMMYFUNCTION("IMPORTRANGE(""https://docs.google.com/spreadsheets/d/1w_v-LytfJUSGD2382sduIgEApmqF1mMjksjNng1JfDs/edit?gid=134075723#gid=134075723"",""WS_JASMINE_ANDRIANO!D177:I181"")"),"TOTALI WS 1 e 2 ") -> TOTALI WS 1 e 2 | C32: =IFERROR(__xludf.DUMMYFUNCTION("""COMPUTED_VALUE""")," TOTALE PREZZI") -> TOTALE PREZZI | D32: =IFERROR(__xludf.DUMMYFUNCTION("""COMPUTED_VALUE"""),30.0) -> 30 | E32: =IFERROR(__xludf.DUMMYFUNCTION("""COMPUTED_VALUE"""),32.0) -> 32 | F32: =IFERROR(__xludf.DUMMYFUNCTION("""COMPUTED_VALUE"""),37.0) -> 37
C33: =IFERROR(__xludf.DUMMYFUNCTION("""COMPUTED_VALUE""")," TOTALE PERSONE SEDE") -> TOTALE PERSONE SEDE | D33: =IFERROR(__xludf.DUMMYFUNCTION("""COMPUTED_VALUE""")," 2 da €30") -> 2 da €30 | E33: =IFERROR(__xludf.DUMMYFUNCTION("""COMPUTED_VALUE""")," 0 da €32") -> 0 da €32 | F33: =IFERROR(__xludf.DUMMYFUNCTION("""COMPUTED_VALUE""")," 0 da €37") -> 0 da €37 | G33: =IFERROR(__xludf.DUMMYFUNCTION("""COMPUTED_VALUE""")," ")
C34: =IFERROR(__xludf.DUMMYFUNCTION("""COMPUTED_VALUE""")," subTOTALE SEDE") -> subTOTALE SEDE | D34: =IFERROR(__xludf.DUMMYFUNCTION("""COMPUTED_VALUE"""),60.0) -> 60 | E34: =IFERROR(__xludf.DUMMYFUNCTION("""COMPUTED_VALUE"""),0.0) -> 0 | F34: =IFERROR(__xludf.DUMMYFUNCTION("""COMPUTED_VALUE"""),0.0) -> 0 | G34: =IFERROR(__xludf.DUMMYFUNCTION("""COMPUTED_VALUE""")," ")
C35: =IFERROR(__xludf.DUMMYFUNCTION("""COMPUTED_VALUE""")," TOTALE PERSONE ONLINE") -> TOTALE PERSONE ONLINE | D35: =IFERROR(__xludf.DUMMYFUNCTION("""COMPUTED_VALUE""")," 1 da €30") -> 1 da €30 | E35: =IFERROR(__xludf.DUMMYFUNCTION("""COMPUTED_VALUE""")," 2 da €32") -> 2 da €32 | F35: =IFERROR(__xludf.DUMMYFUNCTION("""COMPUTED_VALUE""")," 3 da €37") -> 3 da €37 | G35: =IFERROR(__xludf.DUMMYFUNCTION("""COMPUTED_VALUE""")," ")
C36: =IFERROR(__xludf.DUMMYFUNCTION("""COMPUTED_VALUE""")," subTOTALE ONLINE") -> subTOTALE ONLINE | D36: =IFERROR(__xludf.DUMMYFUNCTION("""COMPUTED_VALUE"""),30.0) -> 30 | E36: =IFERROR(__xludf.DUMMYFUNCTION("""COMPUTED_VALUE"""),64.0) -> 64 | F36: =IFERROR(__xludf.DUMMYFUNCTION("""COMPUTED_VALUE"""),111.0) -> 111 | G36: =IFERROR(__xludf.DUMMYFUNCTION("""COMPUTED_VALUE""")," ")
B37: =IFERROR(__xludf.DUMMYFUNCTION("IMPORTRANGE(""https://docs.google.com/spreadsheets/d/1w_v-LytfJUSGD2382sduIgEApmqF1mMjksjNng1JfDs/edit?gid=134075723#gid=134075723"",""WS_JASMINE_ANDRIANO!P177:T181"")")," TOTALE SEDE") -> TOTALE SEDE | C37: =IFERROR(__xludf.DUMMYFUNCTION("""COMPUTED_VALUE"""),60.0) -> 60 | D37: =IFERROR(__xludf.DUMMYFUNCTION("""COMPUTED_VALUE""")," TOTALE GENERALE ENTRATE") -> TOTALE GENERALE ENTRATE | E37: =IFERROR(__xludf.DUMMYFUNCTION("""COMPUTED_VALUE"""),265.0) -> 265
B40: =IFERROR(__xludf.DUMMYFUNCTION("""COMPUTED_VALUE""")," TOTALE ONLINE") -> TOTALE ONLINE | C40: =IFERROR(__xludf.DUMMYFUNCTION("""COMPUTED_VALUE"""),205.0) -> 205
B44: RICAVO/PERDITA | E44: =E37+E26 -> -809.66

Sheet AMBERALDRIN_15MAR26
A1: AMBER e ALDRIN
B2: Descrizione | C2: Dettagli | D2: Q.t | E2: Importo | F2: Metodo di pagamento
A3: USCITE ARTISTA | B3: Fee artists | C3: Openclass da 2h 30% dell'incasso | D3: - | E3: =E36*-30% -> -157.8 | F3: Bonifico
B4: Spese di viaggio | D4: - | E4: 0 | F4: Carta
B5: Taxi da aeroporto a Hotel | D5: - | E5: 0
B6: Taxi da Hotel a aeroporto | D6: - | E6: 0
B7: Hotel | D7: 0 | E7: 0
B8: Pranzi | D8: 0 | E8: 0
B9: Cene | D9: 0 | E9: 0
B10: Adidas | C10: Tshirt JE9024 tg M Tshirt JC5943 Tg M | D10: 2 | E10: -36 | F10: Rid Bancario
B11: TOTALE USCITE X ARTISTA | E11: =SUM(E3:E10) -> -193.8
A13: USCITE EXTRA | B13: Affitto spazio | C13: No (minimo €300) | D13: - | E13: 0
B14: Personale | C14: 3h30/4h Spese divise con Affitto Modulo + WS Dìa en cuba (calcolo approssimativo) | D14: - | E14: -33 | F14: Bonifico
B15: Video maker | D15: - | E15: 0 | F15: Affitto Yuri
B16: Volantini | E16: -10 | F16: Bonifico
B17: Video per sponsorizzate Meta | D17: - | E17: 0
B18: Fish singolo per vendita | D18: - | E18: 0 | F18: Contanti cassa Elisa
B19: Bonus team per vendita | D19: - | E19: -9 | F19: Contanti cassa Elisa
B20: Sponsorizzate | D20: - | E20: -100 | F20: Carta
B21: Resi | D21: - | E21: 0
B22: Commissioni Online | C22: Percentuale del 1,5% su una media di €31 | D22: 11 | E22: =D22*31*-1.5% -> -5.115 | F22: Commissioni
B23: TOTALE USCITE EXTRA | E23: =SUM(E13:E22) -> -157.115
B25: TOTALE USCITE | E25: =E11+E23 -> -350.915
A27: STIMA CONTRIBUTI/INCASSI €32 entro il 14 Marzo compreso (con cod sconto €30) €37 il giorno stesso (con cod sconto €35) | B27: Stima del MINIMO incassabile | C27: 20 | D27: 25 | E27: =C27*D27 -> 500 | F27: =E25+E27 -> 149.085
B28: Stima del MASSIMO incassabile | C28: 37 | D28: 25 | E28: =C28*D28 -> 925 | F28: =E25+E28 -> 574.085
B29: Stima MEDIA incassabile | C29: 33.5 | D29: 25 | E29: =C29*D29 -> 837.5 | F29: =E25+E29 -> 486.585
A31: ENTRATE | B31: =IFERROR(__xludf.DUMMYFUNCTION("IMPORTRANGE(""https://docs.google.com/spreadsheets/d/1w_v-LytfJUSGD2382sduIgEApmqF1mMjksjNng1JfDs/edit?gid=134075723#gid=134075723"",""OC_AMBERALDRIN!D177:I181"")"),"TOTALI WS 1 e 2 ") -> TOTALI WS 1 e 2 | C31: =IFERROR(__xludf.DUMMYFUNCTION("""COMPUTED_VALUE""")," TOTALE PREZZI") -> TOTALE PREZZI | D31: =IFERROR(__xludf.DUMMYFUNCTION("""COMPUTED_VALUE"""),30.0) -> 30 | E31: =IFERROR(__xludf.DUMMYFUNCTION("""COMPUTED_VALUE"""),32.0) -> 32
C32: =IFERROR(__xludf.DUMMYFUNCTION("""COMPUTED_VALUE""")," TOTALE PERSONE SEDE") -> TOTALE PERSONE SEDE | D32: =IFERROR(__xludf.DUMMYFUNCTION("""COMPUTED_VALUE""")," 5 da €30") -> 5 da €30 | E32: =IFERROR(__xludf.DUMMYFUNCTION("""COMPUTED_VALUE""")," 1 da €32") -> 1 da €32 | F32: =IFERROR(__xludf.DUMMYFUNCTION("""COMPUTED_VALUE""")," ") | G32: =IFERROR(__xludf.DUMMYFUNCTION("""COMPUTED_VALUE""")," ")
C33: =IFERROR(__xludf.DUMMYFUNCTION("""COMPUTED_VALUE""")," subTOTALE SEDE") -> subTOTALE SEDE | D33: =IFERROR(__xludf.DUMMYFUNCTION("""COMPUTED_VALUE"""),150.0) -> 150 | E33: =IFERROR(__xludf.DUMMYFUNCTION("""COMPUTED_VALUE"""),32.0) -> 32 | F33: =IFERROR(__xludf.DUMMYFUNCTION("""COMPUTED_VALUE""")," ") | G33: =IFERROR(__xludf.DUMMYFUNCTION("""COMPUTED_VALUE""")," ")
C34: =IFERROR(__xludf.DUMMYFUNCTION("""COMPUTED_VALUE""")," TOTALE PERSONE ONLINE") -> TOTALE PERSONE ONLINE | D34: =IFERROR(__xludf.DUMMYFUNCTION("""COMPUTED_VALUE""")," 4 da €30") -> 4 da €30 | E34: =IFERROR(__xludf.DUMMYFUNCTION("""COMPUTED_VALUE""")," 7 da €32") -> 7 da €32 | F34: =IFERROR(__xludf.DUMMYFUNCTION("""COMPUTED_VALUE""")," ") | G34: =IFERROR(__xludf.DUMMYFUNCTION("""COMPUTED_VALUE""")," ")
C35: =IFERROR(__xludf.DUMMYFUNCTION("""COMPUTED_VALUE""")," subTOTALE ONLINE") -> subTOTALE ONLINE | D35: =IFERROR(__xludf.DUMMYFUNCTION("""COMPUTED_VALUE"""),120.0) -> 120 | E35: =IFERROR(__xludf.DUMMYFUNCTION("""COMPUTED_VALUE"""),224.0) -> 224 | F35: =IFERROR(__xludf.DUMMYFUNCTION("""COMPUTED_VALUE""")," ") | G35: =IFERROR(__xludf.DUMMYFUNCTION("""COMPUTED_VALUE""")," ")
B36: =IFERROR(__xludf.DUMMYFUNCTION("IMPORTRANGE(""https://docs.google.com/spreadsheets/d/1w_v-LytfJUSGD2382sduIgEApmqF1mMjksjNng1JfDs/edit?gid=134075723#gid=134075723"",""OC_AMBERALDRIN!P177:T181"")")," TOTALE SEDE") -> TOTALE SEDE | C36: =IFERROR(__xludf.DUMMYFUNCTION("""COMPUTED_VALUE"""),182.0) -> 182 | D36: =IFERROR(__xludf.DUMMYFUNCTION("""COMPUTED_VALUE""")," TOTALE GENERALE ENTRATE") -> TOTALE GENERALE ENTRATE | E36: =IFERROR(__xludf.DUMMYFUNCTION("""COMPUTED_VALUE"""),526.0) -> 526
B39: =IFERROR(__xludf.DUMMYFUNCTION("""COMPUTED_VALUE""")," TOTALE ONLINE") -> TOTALE ONLINE | C39: =IFERROR(__xludf.DUMMYFUNCTION("""COMPUTED_VALUE"""),344.0) -> 344
B43: RICAVO/PERDITA | E43: =E36+E25 -> 175.085

Sheet DIA_EN_CUBA_15MAR26
A1: DIA EN CUBA
B2: Descrizione | C2: Dettagli | D2: Q.t | E2: Importo | F2: Metodo di pagamento
A3: USCITE ARTISTA | B3: Fee artist | C3: 30% dell'incasso | D3: 2h | E3: =E36*-30% -> -510 | F3: Bonifico
B4: Spese di viaggio | D4: - | E4: 0 | F4: Carta
B5: Taxi da aeroporto a Hotel | D5: - | E5: 0
B6: Taxi da Hotel a aeroporto | D6: - | E6: 0
B7: Hotel | D7: - | E7: 0
B8: Pranzi | D8: - | E8: 0
B9: Cene | D9: - | E9: 0
B10: Adidas | C10: Tshirt JE9024 tg M Tshirt JC5943 Tg M | D10: 2 | E10: -36 | F10: Rid Bancario
B11: TOTALE USCITE X ARTISTA | E11: =SUM(E3:E10) -> -546
A13: USCITE EXTRA | B13: Affitto spazio | C13: No (minimo €300) | D13: - | E13: 0
B14: Personale | C14: 3h30/4h Spese divise con Affitto Modulo + Openclass Amber&Aldrin (calcolo approssimativo) | D14: - | E14: -33 | F14: Bonifico
B15: Video maker | C15: 180+IVA | D15: - | E15: -219.6 | F15: Bonifico
B16: Volantini | E16: -10 | F16: Bonifico
B17: Video per sponsorizzate Meta | D17: - | E17: 0
B18: Fish singolo per vendita | D18: - | E18: -3 | F18: Contanti cassa Elisa
B19: Bonus team per vendita | D19: - | E19: -26 | F19: Contanti cassa Elisa
B20: Sponsorizzate | D20: - | E20: 0 | F20: Carta
B21: Resi | D21: - | E21: 0
B22: Commissioni Online | C22: Percentuale del 1,5% su una media di €34,50 | D22: 40 | E22: =D22*34.5*-1.5% -> -20.7 | F22: Commissioni
B23: TOTALE USCITE EXTRA | E23: =SUM(E13:E22) -> -312.3
B25: TOTALE USCITE | E25: =E11+E23 -> -858.3
A27: STIMA CONTRIBUTI/INCASSI €32 entro il 14 febbraio compreso (con cod sconto €30) €37 entro il 15 marzo compreso (con cod sconto €35) COD SCONTO: €2 | B27: Stima del MINIMO incassabile | C27: 30 | D27: 80 | E27: =C27*D27 -> 2400 | F27: =E25+E27 -> 1541.7
B28: Stima del MASSIMO incassabile | C28: 37 | D28: 80 | E28: =C28*D28 -> 2960 | F28: =E25+E28 -> 2101.7
B29: Stima MEDIA incassabile | C29: 33.5 | D29: 80 | E29: =C29*D29 -> 2680 | F29: =E25+E29 -> 1821.7
A31: ENTRATE | B31: =IFERROR(__xludf.DUMMYFUNCTION("IMPORTRANGE(""https://docs.google.com/spreadsheets/d/1w_v-LytfJUSGD2382sduIgEApmqF1mMjksjNng1JfDs/edit?gid=134075723#gid=134075723"",""WS_DIA_EN_CUBA!D267:I271"")"),"TOTALI WS 1, 2, 3 ") -> TOTALI WS 1, 2, 3 | C31: =IFERROR(__xludf.DUMMYFUNCTION("""COMPUTED_VALUE""")," TOTALE PREZZI") -> TOTALE PREZZI | D31: =IFERROR(__xludf.DUMMYFUNCTION("""COMPUTED_VALUE"""),0.0) -> 0 | E31: =IFERROR(__xludf.DUMMYFUNCTION("""COMPUTED_VALUE"""),30.0) -> 30 | F31: =IFERROR(__xludf.DUMMYFUNCTION("""COMPUTED_VALUE"""),32.0) -> 32 | G31: =IFERROR(__xludf.DUMMYFUNCTION("""COMPUTED_VALUE"""),33.0) -> 33
C32: =IFERROR(__xludf.DUMMYFUNCTION("""COMPUTED_VALUE""")," TOTALE PERSONE SEDE") -> TOTALE PERSONE SEDE | D32: =IFERROR(__xludf.DUMMYFUNCTION("""COMPUTED_VALUE""")," 1 da €0") -> 1 da €0 | E32: =IFERROR(__xludf.DUMMYFUNCTION("""COMPUTED_VALUE""")," 4 da €30") -> 4 da €30 | F32: =IFERROR(__xludf.DUMMYFUNCTION("""COMPUTED_VALUE""")," 0 da €32") -> 0 da €32 | G32: =IFERROR(__xludf.DUMMYFUNCTION("""COMPUTED_VALUE""")," 0 da €33") -> 0 da €33
C33: =IFERROR(__xludf.DUMMYFUNCTION("""COMPUTED_VALUE""")," subTOTALE SEDE") -> subTOTALE SEDE | D33: =IFERROR(__xludf.DUMMYFUNCTION("""COMPUTED_VALUE"""),0.0) -> 0 | E33: =IFERROR(__xludf.DUMMYFUNCTION("""COMPUTED_VALUE"""),120.0) -> 120 | F33: =IFERROR(__xludf.DUMMYFUNCTION("""COMPUTED_VALUE"""),0.0) -> 0 | G33: =IFERROR(__xludf.DUMMYFUNCTION("""COMPUTED_VALUE"""),0.0) -> 0
C34: =IFERROR(__xludf.DUMMYFUNCTION("""COMPUTED_VALUE""")," TOTALE PERSONE ONLINE") -> TOTALE PERSONE ONLINE | D34: =IFERROR(__xludf.DUMMYFUNCTION("""COMPUTED_VALUE""")," 39 da €0") -> 39 da €0 | E34: =IFERROR(__xludf.DUMMYFUNCTION("""COMPUTED_VALUE""")," 5 da €30") -> 5 da €30 | F34: =IFERROR(__xludf.DUMMYFUNCTION("""COMPUTED_VALUE""")," 11 da €32") -> 11 da €32 | G34: =IFERROR(__xludf.DUMMYFUNCTION("""COMPUTED_VALUE""")," 1 da €33") -> 1 da €33
C35: =IFERROR(__xludf.DUMMYFUNCTION("""COMPUTED_VALUE""")," subTOTALE ONLINE") -> subTOTALE ONLINE | D35: =IFERROR(__xludf.DUMMYFUNCTION("""COMPUTED_VALUE"""),0.0) -> 0 | E35: =IFERROR(__xludf.DUMMYFUNCTION("""COMPUTED_VALUE"""),150.0) -> 150 | F35: =IFERROR(__xludf.DUMMYFUNCTION("""COMPUTED_VALUE"""),352.0) -> 352 | G35: =IFERROR(__xludf.DUMMYFUNCTION("""COMPUTED_VALUE"""),33.0) -> 33
B36: =IFERROR(__xludf.DUMMYFUNCTION("IMPORTRANGE(""https://docs.google.com/spreadsheets/d/1w_v-LytfJUSGD2382sduIgEApmqF1mMjksjNng1JfDs/edit?gid=134075723#gid=134075723"",""WS_DIA_EN_CUBA!P267:T271"")")," TOTALE SEDE") -> TOTALE SEDE | C36: =IFERROR(__xludf.DUMMYFUNCTION("""COMPUTED_VALUE"""),332.0) -> 332 | D36: =IFERROR(__xludf.DUMMYFUNCTION("""COMPUTED_VALUE""")," TOTALE GENERALE ENTRATE") -> TOTALE GENERALE ENTRATE | E36: =IFERROR(__xludf.DUMMYFUNCTION("""COMPUTED_VALUE"""),1700.0) -> 1700
B39: =IFERROR(__xludf.DUMMYFUNCTION("""COMPUTED_VALUE""")," TOTALE ONLINE") -> TOTALE ONLINE | C39: =IFERROR(__xludf.DUMMYFUNCTION("""COMPUTED_VALUE"""),1368.0) -> 1368
B43: RICAVO/PERDITA | E43: =E36+E25 -> 841.7

Sheet ANAHITA_01MAR26
A1: ANAHITA
B2: Descrizione | C2: Dettagli | D2: Q.t | E2: Importo | F2: Metodo di pagamento
A3: USCITE ARTISTA | B3: Fee artists | C3: Openclass da 1,5h | D3: - | E3: -158 | F3: Bonifico
B4: Spese di viaggio | D4: - | E4: 0
B5: Taxi da aeroporto a Hotel | D5: - | E5: 0
B6: Taxi da Hotel a aeroporto | D6: - | E6: 0
B7: Hotel | D7: - | E7: 0
B8: Pranzi | D8: - | E8: 0
B9: Cene | D9: - | E9: 0
B10: Adidas | C10: Tshirt JC5943 Tg M | D10: - | E10: -18 | F10: Rid Bancario
B11: TOTALE USCITE X ARTISTA | E11: =SUM(E3:E10) -> -176
A13: USCITE EXTRA | B13: Affitto spazio | C13: No (minimo €300) | D13: - | E13: 0
B14: Personale | C14: 3 persone (€10/h) x 2h30 | D14: - | E14: -75 | F14: Bonifico
B15: Video maker | D15: - | E15: 0
B16: Volantini | E16: 0 | F16: Bonifico
B17: Video per sponsorizzate Meta | D17: - | E17: 0
B18: Fish singolo per vendita | D18: - | E18: -1.5 | F18: Contanti cassa Elisa
B19: Bonus team per vendita | D19: - | E19: -24 | F19: Contanti cassa Elisa
B20: Sponsorizzate | D20: - | E20: 0 | F20: Carta
B21: Resi | D21: - | E21: 0
B22: Commissioni Online | C22: Percentuale del 1,5% su una media di €23,5 | D22: 38 | E22: =D22*23.5*-1.5% -> -13.395 | F22: Commissioni
B23: TOTALE USCITE EXTRA | E23: =SUM(E13:E22) -> -113.895
B25: TOTALE USCITE | E25: =E11+E23 -> -289.895
A27: STIMA CONTRIBUTI/INCASSI €22 entro il 15 Febbraio compreso (con cod sconto €20) €27 dal 15 Febbraio al 01 Marzo compreso (con cod sconto €25) | B27: Stima del MINIMO incassabile | C27: 20 | D27: 15 | E27: =C27*D27 -> 300 | F27: =E25+E27 -> 10.105
B28: Stima del MASSIMO incassabile | C28: 27 | D28: 15 | E28: =C28*D28 -> 405 | F28: =E25+E28 -> 115.105
B29: Stima MEDIA incassabile | C29: 23.5 | D29: 15 | E29: =C29*D29 -> 352.5 | F29: =E25+E29 -> 62.605
A31: ENTRATE | B31: =IFERROR(__xludf.DUMMYFUNCTION("IMPORTRANGE(""https://docs.google.com/spreadsheets/d/1w_v-LytfJUSGD2382sduIgEApmqF1mMjksjNng1JfDs/edit?gid=134075723#gid=134075723"",""OC_ANAHITA!D177:G181"")"),"TOTALI WS 1 e 2 ") -> TOTALI WS 1 e 2 | C31: =IFERROR(__xludf.DUMMYFUNCTION("""COMPUTED_VALUE""")," TOTALE PREZZI") -> TOTALE PREZZI | D31: =IFERROR(__xludf.DUMMYFUNCTION("""COMPUTED_VALUE"""),20.0) -> 20 | E31: =IFERROR(__xludf.DUMMYFUNCTION("""COMPUTED_VALUE"""),22.0) -> 22
C32: =IFERROR(__xludf.DUMMYFUNCTION("""COMPUTED_VALUE""")," TOTALE PERSONE SEDE") -> TOTALE PERSONE SEDE | D32: =IFERROR(__xludf.DUMMYFUNCTION("""COMPUTED_VALUE""")," 2 da €20") -> 2 da €20 | E32: =IFERROR(__xludf.DUMMYFUNCTION("""COMPUTED_VALUE""")," 0 da €22") -> 0 da €22
C33: =IFERROR(__xludf.DUMMYFUNCTION("""COMPUTED_VALUE""")," subTOTALE SEDE") -> subTOTALE SEDE | D33: =IFERROR(__xludf.DUMMYFUNCTION("""COMPUTED_VALUE"""),40.0) -> 40 | E33: =IFERROR(__xludf.DUMMYFUNCTION("""COMPUTED_VALUE"""),0.0) -> 0
C34: =IFERROR(__xludf.DUMMYFUNCTION("""COMPUTED_VALUE""")," TOTALE PERSONE ONLINE") -> TOTALE PERSONE ONLINE | D34: =IFERROR(__xludf.DUMMYFUNCTION("""COMPUTED_VALUE""")," 19 da €20") -> 19 da €20 | E34: =IFERROR(__xludf.DUMMYFUNCTION("""COMPUTED_VALUE""")," 12 da €22") -> 12 da €22
C35: =IFERROR(__xludf.DUMMYFUNCTION("""COMPUTED_VALUE""")," subTOTALE ONLINE") -> subTOTALE ONLINE | D35: =IFERROR(__xludf.DUMMYFUNCTION("""COMPUTED_VALUE"""),380.0) -> 380 | E35: =IFERROR(__xludf.DUMMYFUNCTION("""COMPUTED_VALUE"""),264.0) -> 264
B36: =IFERROR(__xludf.DUMMYFUNCTION("IMPORTRANGE(""https://docs.google.com/spreadsheets/d/1w_v-LytfJUSGD2382sduIgEApmqF1mMjksjNng1JfDs/edit?gid=134075723#gid=134075723"",""OC_ANAHITA!P177:T181"")")," TOTALE SEDE") -> TOTALE SEDE | C36: =IFERROR(__xludf.DUMMYFUNCTION("""COMPUTED_VALUE"""),67.0) -> 67 | D36: =IFERROR(__xludf.DUMMYFUNCTION("""COMPUTED_VALUE""")," TOTALE GENERALE ENTRATE") -> TOTALE GENERALE ENTRATE | E36: =IFERROR(__xludf.DUMMYFUNCTION("""COMPUTED_VALUE"""),896.0) -> 896
B39: =IFERROR(__xludf.DUMMYFUNCTION("""COMPUTED_VALUE""")," TOTALE ONLINE") -> TOTALE ONLINE | C39: =IFERROR(__xludf.DUMMYFUNCTION("""COMPUTED_VALUE"""),829.0) -> 829
B43: RICAVO/PERDITA | E43: =E36+E25 -> 606.105

Sheet EMANUEL_LO_22FEB26
A1: EMANUEL LO
B2: Descrizione | C2: Dettagli | D2: Q.t | E2: Importo | F2: Metodo di pagamento
A3: USCITE ARTISTA | B3: Fee artist | C3: WS da 1h 45 | D3: 2 | E3: -2300 | F3: Bonifico
B4: Spese di viaggio | C4: Roma-Milano Executive | D4: 2 | E4: -413 | F4: Carta
B5: Taxi da aeroporto a Hotel | D5: - | E5: 0
B6: Taxi da Hotel a aeroporto | D6: - | E6: 0
B7: Hotel | D7: - | E7: 0
B8: Pranzi | D8: - | E8: 0
B9: Cene | D9: - | E9: 0
B10: Adidas | C10: Tshirt JE9024 tg XL | D10: 1 | E10: -18 | F10: Rid Bancario
B11: TOTALE USCITE X ARTISTA | E11: =SUM(E3:E10) -> -2731
A13: USCITE EXTRA | B13: Affitto spazio | C13: No (minimo €300) | D13: - | E13: 0
B14: Personale | C14: 3h30/4h Spese divise con Affitto KV (calcolo approssimativo) | D14: - | E14: -50 | F14: Bonifico
B15: Video maker | D15: - | E15: -200 | F15: Affitto Yuri
B16: Volantini | E16: -10 | F16: Bonifico
B17: Video per sponsorizzate Meta | D17: - | E17: -33 | F17: Bonifico
B18: Fish singolo per vendita | D18: - | E18: 0 | F18: Contanti cassa Elisa
B19: Bonus team per vendita | D19: - | E19: -43 | F19: Contanti cassa Elisa
B20: Sponsorizzate | D20: - | E20: -200 | F20: Carta
B21: Resi | D21: - | E21: 0
B22: Commissioni Online | C22: Percentuale del 1,5% su una media di €44 | D22: 85 | E22: =D22*44*-1.5% -> -56.1 | F22: Commissioni
B23: TOTALE USCITE EXTRA | E23: =SUM(E13:E22) -> -592.1
B25: TOTALE USCITE | E25: =E11+E23 -> -3323.1
A27: STIMA CONTRIBUTI/INCASSI €45 COD SCONTO: €2 | B27: Stima del MINIMO incassabile | C27: 43 | D27: 60 | E27: =C27*D27 -> 2580 | F27: =E25+E27 -> -743.1
B28: Stima del MASSIMO incassabile | C28: 45 | D28: 60 | E28: =C28*D28 -> 2700 | F28: =E25+E28 -> -623.1
B29: Stima MEDIA incassabile | C29: 44 | D29: 60 | E29: =C29*D29 -> 2640 | F29: =E25+E29 -> -683.1
A31: ENTRATE | B31: =IFERROR(__xludf.DUMMYFUNCTION("IMPORTRANGE(""https://docs.google.com/spreadsheets/d/1w_v-LytfJUSGD2382sduIgEApmqF1mMjksjNng1JfDs/edit?gid=134075723#gid=134075723"",""WS_EMANUELLO!D177:G181"")"),"TOTALI WS 1 e 2 ") -> TOTALI WS 1 e 2 | C31: =IFERROR(__xludf.DUMMYFUNCTION("""COMPUTED_VALUE""")," TOTALE PREZZI") -> TOTALE PREZZI | D31: =IFERROR(__xludf.DUMMYFUNCTION("""COMPUTED_VALUE"""),43.0) -> 43 | E31: =IFERROR(__xludf.DUMMYFUNCTION("""COMPUTED_VALUE"""),45.0) -> 45
C32: =IFERROR(__xludf.DUMMYFUNCTION("""COMPUTED_VALUE""")," TOTALE PERSONE SEDE") -> TOTALE PERSONE SEDE | D32: =IFERROR(__xludf.DUMMYFUNCTION("""COMPUTED_VALUE""")," 6 da €43") -> 6 da €43 | E32: =IFERROR(__xludf.DUMMYFUNCTION("""COMPUTED_VALUE""")," 0 da €45") -> 0 da €45
C33: =IFERROR(__xludf.DUMMYFUNCTION("""COMPUTED_VALUE""")," subTOTALE SEDE") -> subTOTALE SEDE | D33: =IFERROR(__xludf.DUMMYFUNCTION("""COMPUTED_VALUE"""),258.0) -> 258 | E33: =IFERROR(__xludf.DUMMYFUNCTION("""COMPUTED_VALUE"""),0.0) -> 0
C34: =IFERROR(__xludf.DUMMYFUNCTION("""COMPUTED_VALUE""")," TOTALE PERSONE ONLINE") -> TOTALE PERSONE ONLINE | D34: =IFERROR(__xludf.DUMMYFUNCTION("""COMPUTED_VALUE""")," 37 da €43") -> 37 da €43 | E34: =IFERROR(__xludf.DUMMYFUNCTION("""COMPUTED_VALUE""")," 43 da €45") -> 43 da €45
C35: =IFERROR(__xludf.DUMMYFUNCTION("""COMPUTED_VALUE""")," subTOTALE ONLINE") -> subTOTALE ONLINE | D35: =IFERROR(__xludf.DUMMYFUNCTION("""COMPUTED_VALUE"""),1591.0) -> 1591 | E35: =IFERROR(__xludf.DUMMYFUNCTION("""COMPUTED_VALUE"""),1935.0) -> 1935
B36: =IFERROR(__xludf.DUMMYFUNCTION("IMPORTRANGE(""https://docs.google.com/spreadsheets/d/1w_v-LytfJUSGD2382sduIgEApmqF1mMjksjNng1JfDs/edit?gid=134075723#gid=134075723"",""WS_EMANUELLO!P177:T181"")")," TOTALE SEDE") -> TOTALE SEDE | C36: =IFERROR(__xludf.DUMMYFUNCTION("""COMPUTED_VALUE"""),258.0) -> 258 | D36: =IFERROR(__xludf.DUMMYFUNCTION("""COMPUTED_VALUE""")," TOTALE GENERALE ENTRATE") -> TOTALE GENERALE ENTRATE | E36: =IFERROR(__xludf.DUMMYFUNCTION("""COMPUTED_VALUE"""),3784.0) -> 3784
B39: =IFERROR(__xludf.DUMMYFUNCTION("""COMPUTED_VALUE""")," TOTALE ONLINE") -> TOTALE ONLINE | C39: =IFERROR(__xludf.DUMMYFUNCTION("""COMPUTED_VALUE"""),3526.0) -> 3526
B42: RICAVO/PERDITA | E42: =E36+E25 -> 460.9

Sheet ALESSIO_CAVALIERE_01FEB26
A1: ALESSIO CAVALIERE
B2: Descrizione | C2: Dettagli | D2: Q.t | E2: Importo | F2: Metodo di pagamento
A3: USCITE ARTISTA | B3: Fee artist | C3: WS da 1h 30 | D3: 1 | E3: -500 | F3: Bonifico
B4: Treno | C4: A/R Na-Mi Anticipati da Sara | D4: 2 | E4: -78 | F4: Contanti cassa Elisa
B5: Spese trasporto | C5: - | D5: - | E5: 0
B6: Hotel | C6: - | D6: - | E6: 0
B7: Pranzi | C7: - | D7: - | E7: 0
B8: Cene | C8: - | D8: - | E8: 0
B9: Adidas | C9: Tshirt JE9024 tg L | D9: 1 | E9: -18 | F9: Rid Bancario
B10: TOTALE USCITE ARTISTA | E10: =SUM(E3:E9) -> -596
A12: USCITE EXTRA | B12: Affitto spazio | C12: No (ma minimo €300 euro) | D12: - | E12: 0
B13: Personale | C13: 2h30 | D13: 3 | E13: -75 | F13: Bonifico
B14: Videomaker | D14: - | E14: -180 | F14: Bonifico
B15: Volantini | D15: - | E15: -10 | F15: Bonifico
B16: Video per sponsorizzate Meta | D16: - | E16: -30
B17: Fish singolo per vendita | D17: - | E17: 0 | F17: Contanti cassa Elisa
B18: Bonus team per vendita | D18: - | E18: -6 | F18: Contanti cassa Elisa
B19: Pranzo per team | D19: - | E19: 0
B20: Sponsorizzate | D20: - | E20: -200 | F20: Carta
B21: Commissioni Online | C21: Percentuale del 1,5% su una media di €36 | D21: 20 | E21: =D21*36*-1.5% -> -10.8 | F21: Commissioni
B22: TOTALE USCITE EXTRA | E22: =SUM(E12:E21) -> -511.8
B24: TOTALE USCITE | E24: =E10+E22 -> -1107.8
A26: STIMA CONTRIBUTI/INCASSI €37 entro il 31 Gennaio compreso (con cod sconto €35) €42 il giorno stesso (con cod sconto €40) | B26: Stima del MINIMO incassabile (60 PX che pagano con cod sconto €30) | C26: 36 | D26: 50 | E26: =C26*D26 -> 1800 | F26: =E24+E26 -> 692.2
B27: Stima del MASSIMO incassabile (60 PX che pagano prezzo pieno €42) | C27: 42 | D27: 50 | E27: =C27*D27 -> 2100 | F27: =E24+E27 -> 992.2
B28: Stima MEDIA incassabile | C28: 36 | D28: 50 | E28: =C28*D28 -> 1800 | F28: =E24+E28 -> 692.2
A30: ENTRATE | B30: =IFERROR(__xludf.DUMMYFUNCTION("IMPORTRANGE(""https://docs.google.com/spreadsheets/d/1w_v-LytfJUSGD2382sduIgEApmqF1mMjksjNng1JfDs/edit?gid=134075723#gid=134075723"",""WS_ALESSIOCAVALIERE!D177:H182"")"),"TOTALI WS 1 e 2 ") -> TOTALI WS 1 e 2 | C30: =IFERROR(__xludf.DUMMYFUNCTION("""COMPUTED_VALUE"""),"TOTALE PREZZI") -> TOTALE PREZZI | D30: =IFERROR(__xludf.DUMMYFUNCTION("""COMPUTED_VALUE"""),35.0) -> 35 | E30: =IFERROR(__xludf.DUMMYFUNCTION("""COMPUTED_VALUE"""),37.0) -> 37 | F30: =IFERROR(__xludf.DUMMYFUNCTION("""COMPUTED_VALUE"""),42.0) -> 42
C31: =IFERROR(__xludf.DUMMYFUNCTION("""COMPUTED_VALUE"""),"TOTALE PERSONE SEDE") -> TOTALE PERSONE SEDE | D31: =IFERROR(__xludf.DUMMYFUNCTION("""COMPUTED_VALUE"""),"3 da €35") -> 3 da €35 | E31: =IFERROR(__xludf.DUMMYFUNCTION("""COMPUTED_VALUE"""),"0 da €37") -> 0 da €37 | F31: =IFERROR(__xludf.DUMMYFUNCTION("""COMPUTED_VALUE"""),"0 da €42") -> 0 da €42
C32: =IFERROR(__xludf.DUMMYFUNCTION("""COMPUTED_VALUE"""),"subTOTALE SEDE") -> subTOTALE SEDE | D32: =IFERROR(__xludf.DUMMYFUNCTION("""COMPUTED_VALUE"""),105.0) -> 105 | E32: =IFERROR(__xludf.DUMMYFUNCTION("""COMPUTED_VALUE"""),0.0) -> 0 | F32: =IFERROR(__xludf.DUMMYFUNCTION("""COMPUTED_VALUE"""),0.0) -> 0
C33: =IFERROR(__xludf.DUMMYFUNCTION("""COMPUTED_VALUE"""),"TOTALE PERSONE ONLINE") -> TOTALE PERSONE ONLINE | D33: =IFERROR(__xludf.DUMMYFUNCTION("""COMPUTED_VALUE"""),"3 da €35") -> 3 da €35 | E33: =IFERROR(__xludf.DUMMYFUNCTION("""COMPUTED_VALUE"""),"15 da €37") -> 15 da €37 | F33: =IFERROR(__xludf.DUMMYFUNCTION("""COMPUTED_VALUE"""),"2 da €42") -> 2 da €42
C34: =IFERROR(__xludf.DUMMYFUNCTION("""COMPUTED_VALUE"""),"subTOTALE ONLINE") -> subTOTALE ONLINE | D34: =IFERROR(__xludf.DUMMYFUNCTION("""COMPUTED_VALUE"""),105.0) -> 105 | E34: =IFERROR(__xludf.DUMMYFUNCTION("""COMPUTED_VALUE"""),555.0) -> 555 | F34: =IFERROR(__xludf.DUMMYFUNCTION("""COMPUTED_VALUE"""),84.0) -> 84
B35: =IFERROR(__xludf.DUMMYFUNCTION("IMPORTRANGE(""https://docs.google.com/spreadsheets/d/1w_v-LytfJUSGD2382sduIgEApmqF1mMjksjNng1JfDs/edit?gid=134075723#gid=134075723"",""WS_ALESSIOCAVALIERE!P177:T181"")")," TOTALE SEDE") -> TOTALE SEDE | C35: =IFERROR(__xludf.DUMMYFUNCTION("""COMPUTED_VALUE"""),105.0) -> 105 | D35: =IFERROR(__xludf.DUMMYFUNCTION("""COMPUTED_VALUE""")," TOTALE GENERALE ENTRATE") -> TOTALE GENERALE ENTRATE | E35: =IFERROR(__xludf.DUMMYFUNCTION("""COMPUTED_VALUE"""),849.0) -> 849
B38: =IFERROR(__xludf.DUMMYFUNCTION("""COMPUTED_VALUE""")," TOTALE ONLINE") -> TOTALE ONLINE | C38: =IFERROR(__xludf.DUMMYFUNCTION("""COMPUTED_VALUE"""),744.0) -> 744
B41: RICAVO/PERDITA | E41: =E35+E24 -> -258.8

Sheet NEREA_14DIC25
A1: NEREA
B2: Descrizione | C2: Dettagli | D2: Q.t | E2: Importo | F2: Metodo di pagamento
A3: USCITE ARTISTA | B3: Fee artist | C3: WS da 1h 30 | D3: 1 | E3: -200 | F3: Bonifico
B4: Treno | C4: - | D4: - | E4: 0
B5: Spese trasporto | C5: - | D5: - | E5: 0
B6: Hotel (due notti) | C6: - | D6: - | E6: 0
B7: Pranzi | C7: - | D7: - | E7: 0
B8: Cene | C8: - | D8: - | E8: 0
B9: Adidas | C9: Tshirt JC5943 Tg S | D9: 1 | E9: -18 | F9: Rid Bancario
B10: TOTALE USCITE ARTISTA | E10: =SUM(E3:E9) -> -218
A12: USCITE EXTRA | B12: Affitto spazio | C12: No (ma minimo €300 euro) | D12: - | E12: 0
B13: Personale | C13: 1 persona | D13: - | E13: -25 | F13: Contanti cassa Elisa
B14: Video maker | D14: - | E14: 0 | F14: Affitto Yuri
B15: Volantini | D15: - | E15: -10 | F15: Bonifico
B16: Video per sponsorizzate Meta | D16: - | E16: 0
B17: Fish singolo per vendita | D17: - | E17: 0
B18: Bonus team per vendita | D18: - | E18: -8 | F18: Contanti cassa Elisa
B19: Pranzo per team | D19: - | E19: 0
B20: Sponsorizzate | D20: - | E20: -200 | F20: Carta
B21: Commissioni Online | C21: Percentuale del 1,5% su una media di €31 | D21: 10 | E21: =D21*31*-1.5% -> -4.65 | F21: Commissioni
B22: TOTALE USCITE EXTRA | E22: =SUM(E12:E21) -> -247.65
B24: TOTALE USCITE | E24: =E10+E22 -> -465.65
A26: STIMA CONTRIBUTI/INCASSI €27 entro il 15 ottobre compreso (con cod sconto €25) €32 entro iul 15 novembre compreso (con cod sconto €30) €37 il giorno stesso (con cod sconto €35) | B26: Stima del MINIMO incassabile (40 PX che pagano con cod sconto €25) | C26: 25 | D26: 40 | E26: =C26*D26 -> 1000 | F26: =E24+E26 -> 534.35
B27: Stima del MASSIMO incassabile (40 PX che pagano prezzo pieno €37) | C27: 37 | D27: 40 | E27: =C27*D27 -> 1480 | F27: =E24+E27 -> 1014.35
B28: Stima MEDIA incassabile | C28: 31 | D28: 40 | E28: =C28*D28 -> 1240 | F28: =E24+E28 -> 774.35
A30: ENTRATE | B30: =IFERROR(__xludf.DUMMYFUNCTION("IMPORTRANGE(""https://docs.google.com/spreadsheets/d/1w_v-LytfJUSGD2382sduIgEApmqF1mMjksjNng1JfDs/edit?gid=134075723#gid=134075723"",""WS_NEREA!I153:O156"")"),"TOTALE PERSONE SEDE") -> TOTALE PERSONE SEDE | C30: =IFERROR(__xludf.DUMMYFUNCTION("""COMPUTED_VALUE""")," 0 da €27") -> 0 da €27 | D30: =IFERROR(__xludf.DUMMYFUNCTION("""COMPUTED_VALUE""")," 2 da €25") -> 2 da €25 | E30: =IFERROR(__xludf.DUMMYFUNCTION("""COMPUTED_VALUE""")," 0 da €32") -> 0 da €32 | F30: =IFERROR(__xludf.DUMMYFUNCTION("""COMPUTED_VALUE""")," 2 da €30") -> 2 da €30 | G30: =IFERROR(__xludf.DUMMYFUNCTION("""COMPUTED_VALUE""")," 0 da €37") -> 0 da €37 | H30: =IFERROR(__xludf.DUMMYFUNCTION("""COMPUTED_VALUE""")," 0 da €35") -> 0 da €35
B31: =IFERROR(__xludf.DUMMYFUNCTION("""COMPUTED_VALUE"""),"subTOTALE SEDE") -> subTOTALE SEDE | C31: =IFERROR(__xludf.DUMMYFUNCTION("""COMPUTED_VALUE"""),0.0) -> 0 | D31: =IFERROR(__xludf.DUMMYFUNCTION("""COMPUTED_VALUE"""),50.0) -> 50 | E31: =IFERROR(__xludf.DUMMYFUNCTION("""COMPUTED_VALUE"""),0.0) -> 0 | F31: =IFERROR(__xludf.DUMMYFUNCTION("""COMPUTED_VALUE"""),60.0) -> 60 | G31: =IFERROR(__xludf.DUMMYFUNCTION("""COMPUTED_VALUE"""),0.0) -> 0 | H31: =IFERROR(__xludf.DUMMYFUNCTION("""COMPUTED_VALUE"""),0.0) -> 0
B32: =IFERROR(__xludf.DUMMYFUNCTION("""COMPUTED_VALUE"""),"TOTALE PERSONE ONLINE") -> TOTALE PERSONE ONLINE | C32: =IFERROR(__xludf.DUMMYFUNCTION("""COMPUTED_VALUE""")," 2 da €27") -> 2 da €27 | D32: =IFERROR(__xludf.DUMMYFUNCTION("""COMPUTED_VALUE""")," 1 da €25") -> 1 da €25 | E32: =IFERROR(__xludf.DUMMYFUNCTION("""COMPUTED_VALUE""")," 3 da €32") -> 3 da €32 | F32: =IFERROR(__xludf.DUMMYFUNCTION("""COMPUTED_VALUE""")," 3 da €30") -> 3 da €30 | G32: =IFERROR(__xludf.DUMMYFUNCTION("""COMPUTED_VALUE""")," 0 da €37") -> 0 da €37 | H32: =IFERROR(__xludf.DUMMYFUNCTION("""COMPUTED_VALUE""")," 0 da €35") -> 0 da €35
B33: =IFERROR(__xludf.DUMMYFUNCTION("""COMPUTED_VALUE"""),"subTOTALE ONLINE") -> subTOTALE ONLINE | C33: =IFERROR(__xludf.DUMMYFUNCTION("""COMPUTED_VALUE"""),54.0) -> 54 | D33: =IFERROR(__xludf.DUMMYFUNCTION("""COMPUTED_VALUE"""),25.0) -> 25 | E33: =IFERROR(__xludf.DUMMYFUNCTION("""COMPUTED_VALUE"""),96.0) -> 96 | F33: =IFERROR(__xludf.DUMMYFUNCTION("""COMPUTED_VALUE"""),90.0) -> 90 | G33: =IFERROR(__xludf.DUMMYFUNCTION("""COMPUTED_VALUE"""),0.0) -> 0 | H33: =IFERROR(__xludf.DUMMYFUNCTION("""COMPUTED_VALUE"""),0.0) -> 0
B34: =IFERROR(__xludf.DUMMYFUNCTION("IMPORTRANGE(""https://docs.google.com/spreadsheets/d/1w_v-LytfJUSGD2382sduIgEApmqF1mMjksjNng1JfDs/edit?gid=134075723#gid=134075723"",""WS_NEREA!P153:T156"")")," TOTALE SEDE") -> TOTALE SEDE | C34: =IFERROR(__xludf.DUMMYFUNCTION("""COMPUTED_VALUE"""),110.0) -> 110 | D34: =IFERROR(__xludf.DUMMYFUNCTION("""COMPUTED_VALUE""")," TOTALE GENERALE ENTRATE") -> TOTALE GENERALE ENTRATE | E34: =IFERROR(__xludf.DUMMYFUNCTION("""COMPUTED_VALUE"""),427.0) -> 427
B36: =IFERROR(__xludf.DUMMYFUNCTION("""COMPUTED_VALUE""")," TOTALE ONLINE") -> TOTALE ONLINE | C36: =IFERROR(__xludf.DUMMYFUNCTION("""COMPUTED_VALUE"""),265.0) -> 265
B39: RICAVO/PERDITA | E39: =E34+E24 -> -38.65

Sheet DEBORAH_ESPOSITO_16NOV25
A1: DEBORAH ESPOSITO
B2: Descrizione | C2: Dettagli | D2: Q.t | E2: Importo | F2: Metodo di pagamento
A3: USCITE ARTISTA | B3: Fee artist | C3: WS da 1h 30 | D3: 1 | E3: -350 | F3: Contanti cassa Elisa
B4: Treno | C4: A/R Na-Mi | D4: 2 | E4: -120 | F4: Bonifico
B5: Spese trasporto | C5: - | D5: 0 | E5: 0
B6: Hotel | C6: - | D6: 0 | E6: 0
B7: Pranzi | C7: - | D7: 0 | E7: 0
B8: Cene | C8: - | D8: 0 | E8: 0
B9: Adidas | C9: Tshirt JC5943 Tg L | D9: 1 | E9: -18 | F9: Rid Bancario
B10: TOTALE USCITE ARTISTA | E10: =SUM(E3:E9) -> -488
A12: USCITE EXTRA | B12: Affitto spazio | C12: No (ma minimo €300 euro) | D12: - | E12: 0
B13: Personale | C13: 3h30/4h Spese divise con WS Nicolò (calcolo approssimativo) | D13: 3 | E13: -50 | F13: Bonifico
B14: Video maker | C14: Spese divise con WS Nicolò | D14: - | E14: -175 | F14: Affitto Yuri
B15: Volantini | D15: - | E15: -10 | F15: Bonifico
B16: Manifesti | D16: - | E16: 0
B17: Fish singolo per vendita | D17: - | E17: -7.5 | F17: Contanti cassa Elisa
B18: Bonus team per vendita | D18: - | E18: -22 | F18: Contanti cassa Elisa
B19: Sponsorizzate | D19: - | E19: -350.56 | F19: Carta
B20: Commissioni Online | C20: Percentuale del 1,5% su una media di €36 | D20: 47 | E20: =D20*36*-1.5% -> -25.38 | F20: Commissioni
B21: TOTALE USCITE EXTRA | E21: =SUM(E12:E20) -> -640.44
B23: TOTALE USCITE | E23: =E10+E21 -> -1128.44
A25: STIMA CONTRIBUTI/INCASSI €32 entro il 15 ottobre compreso (con cod sconto €30) €37 entro il 15 novembre compreso (con cod sconto €35) €42 il giorno stesso (con cod sconto €40) | B25: Stima del MINIMO incassabile (40 PX che pagano con cod sconto €30) | C25: 30 | D25: 50 | E25: =C25*D25 -> 1500 | F25: =E23+E25 -> 371.56
B26: Stima del MASSIMO incassabile (40 PX che pagano prezzo pieno €32) | C26: 42 | D26: 50 | E26: =C26*D26 -> 2100 | F26: =E23+E26 -> 971.56
B27: Stima MEDIA incassabile | C27: 36 | D27: 50 | E27: =C27*D27 -> 1800 | F27: =E23+E27 -> 671.56
A29: ENTRATE | B29: =IFERROR(__xludf.DUMMYFUNCTION("IMPORTRANGE(""https://docs.google.com/spreadsheets/d/1w_v-LytfJUSGD2382sduIgEApmqF1mMjksjNng1JfDs/edit?gid=134075723#gid=134075723"",""WS_DEBORAHESPOSITO!I153:O156"")"),"TOTALE PERSONE SEDE") -> TOTALE PERSONE SEDE | C29: =IFERROR(__xludf.DUMMYFUNCTION("""COMPUTED_VALUE""")," 0 da €32") -> 0 da €32 | D29: =IFERROR(__xludf.DUMMYFUNCTION("""COMPUTED_VALUE""")," 1 da €30") -> 1 da €30 | E29: =IFERROR(__xludf.DUMMYFUNCTION("""COMPUTED_VALUE""")," 2 da €37") -> 2 da €37 | F29: =IFERROR(__xludf.DUMMYFUNCTION("""COMPUTED_VALUE""")," 3 da €35") -> 3 da €35 | G29: =IFERROR(__xludf.DUMMYFUNCTION("""COMPUTED_VALUE""")," 2 da €42") -> 2 da €42 | H29: =IFERROR(__xludf.DUMMYFUNCTION("""COMPUTED_VALUE""")," 2 da €40") -> 2 da €40
B30: =IFERROR(__xludf.DUMMYFUNCTION("""COMPUTED_VALUE"""),"subTOTALE SEDE") -> subTOTALE SEDE | C30: =IFERROR(__xludf.DUMMYFUNCTION("""COMPUTED_VALUE"""),0.0) -> 0 | D30: =IFERROR(__xludf.DUMMYFUNCTION("""COMPUTED_VALUE"""),30.0) -> 30 | E30: =IFERROR(__xludf.DUMMYFUNCTION("""COMPUTED_VALUE"""),74.0) -> 74 | F30: =IFERROR(__xludf.DUMMYFUNCTION("""COMPUTED_VALUE"""),105.0) -> 105 | G30: =IFERROR(__xludf.DUMMYFUNCTION("""COMPUTED_VALUE"""),84.0) -> 84 | H30: =IFERROR(__xludf.DUMMYFUNCTION("""COMPUTED_VALUE"""),80.0) -> 80
B31: =IFERROR(__xludf.DUMMYFUNCTION("""COMPUTED_VALUE"""),"TOTALE PERSONE ONLINE") -> TOTALE PERSONE ONLINE | C31: =IFERROR(__xludf.DUMMYFUNCTION("""COMPUTED_VALUE""")," 4 da €32") -> 4 da €32 | D31: =IFERROR(__xludf.DUMMYFUNCTION("""COMPUTED_VALUE""")," 2 da €30") -> 2 da €30 | E31: =IFERROR(__xludf.DUMMYFUNCTION("""COMPUTED_VALUE""")," 32 da €37") -> 32 da €37 | F31: =IFERROR(__xludf.DUMMYFUNCTION("""COMPUTED_VALUE""")," 9 da €35") -> 9 da €35 | G31: =IFERROR(__xludf.DUMMYFUNCTION("""COMPUTED_VALUE""")," 0 da €42") -> 0 da €42 | H31: =IFERROR(__xludf.DUMMYFUNCTION("""COMPUTED_VALUE""")," 0 da €40") -> 0 da €40
B32: =IFERROR(__xludf.DUMMYFUNCTION("""COMPUTED_VALUE"""),"subTOTALE ONLINE") -> subTOTALE ONLINE | C32: =IFERROR(__xludf.DUMMYFUNCTION("""COMPUTED_VALUE"""),128.0) -> 128 | D32: =IFERROR(__xludf.DUMMYFUNCTION("""COMPUTED_VALUE"""),60.0) -> 60 | E32: =IFERROR(__xludf.DUMMYFUNCTION("""COMPUTED_VALUE"""),1184.0) -> 1184 | F32: =IFERROR(__xludf.DUMMYFUNCTION("""COMPUTED_VALUE"""),315.0) -> 315 | G32: =IFERROR(__xludf.DUMMYFUNCTION("""COMPUTED_VALUE"""),0.0) -> 0 | H32: =IFERROR(__xludf.DUMMYFUNCTION("""COMPUTED_VALUE"""),0.0) -> 0
B33: =IFERROR(__xludf.DUMMYFUNCTION("IMPORTRANGE(""https://docs.google.com/spreadsheets/d/1w_v-LytfJUSGD2382sduIgEApmqF1mMjksjNng1JfDs/edit?gid=134075723#gid=134075723"",""WS_DEBORAHESPOSITO!P153:T156"")")," TOTALE SEDE") -> TOTALE SEDE | C33: =IFERROR(__xludf.DUMMYFUNCTION("""COMPUTED_VALUE"""),373.0) -> 373 | D33: =IFERROR(__xludf.DUMMYFUNCTION("""COMPUTED_VALUE""")," TOTALE GENERALE ENTRATE") -> TOTALE GENERALE ENTRATE | E33: =IFERROR(__xludf.DUMMYFUNCTION("""COMPUTED_VALUE"""),2089.6) -> 2089.6
B35: =IFERROR(__xludf.DUMMYFUNCTION("""COMPUTED_VALUE""")," TOTALE ONLINE") -> TOTALE ONLINE | C35: =IFERROR(__xludf.DUMMYFUNCTION("""COMPUTED_VALUE"""),1687.0) -> 1687
B38: RICAVO/PERDITA | E38: =E33+E23 -> 961.16

Sheet NICOLO_DE_ANGELIS_16NOV25
A1: NICOLO DE ANGELIS
B2: Descrizione | C2: Dettagli | D2: Q.t | E2: Importo | F2: Metodo di pagamento
A3: USCITE ARTISTA | B3: Fee artist | C3: WS da 1h 30 | D3: 1 | E3: -300 | F3: Contanti cassa Elisa
B4: Treno | C4: - | D4: - | E4: 0
B5: Spese trasporto | C5: - | D5: 0 | E5: 0
B6: Hotel (due notti) | C6: - | D6: 0 | E6: 0
B7: Pranzi | C7: - | D7: 0 | E7: 0
B8: Cene | C8: - | D8: 0 | E8: 0
B9: Adidas | C9: Tshirt JE9024 tg M | D9: 1 | E9: -18 | F9: Rid Bancario
B10: TOTALE USCITE ARTISTA | E10: =SUM(E3:E9) -> -318
A12: USCITE EXTRA | B12: Affitto spazio | C12: No (ma minimo €300 euro) | D12: - | E12: 0
B13: Personale | C13: 3h30/4h Spese divise con WS Deborah (calcolo approssimativo) | D13: 3 | E13: -50 | F13: Bonifico
B14: Video maker | C14: Spese divise con WS Deborah Esposito | D14: - | E14: -175 | F14: Affitto Yuri
B15: Volantini | D15: - | E15: -10 | F15: Bonifico
B16: Manifesti | D16: - | E16: 0
B17: Fish singolo per vendita | D17: - | E17: -6 | F17: Contanti cassa Elisa
B18: Bonus team per vendita | D18: - | E18: -10 | F18: Contanti cassa Elisa
B19: Sponsorizzate | D19: - | E19: -138.01 | F19: Carta
B20: Commissioni Online | C20: Percentuale del 1,5% su una media di €30 | D20: 31 | E20: =D20*30*-1.5% -> -13.95 | F20: Commissioni
B21: TOTALE USCITE EXTRA | E21: =SUM(E12:E20) -> -402.96
B23: TOTALE USCITE | E23: =E10+E21 -> -720.96
A25: STIMA CONTRIBUTI/INCASSI €27 entro il 15 ottobre compreso (con cod sconto €25) €32 entro iul 15 novembre compreso (con cod sconto €30) €37 il giorno stesso (con cod sconto €35) | B25: Stima del MINIMO incassabile (40 PX che pagano con cod sconto €25) | C25: 25 | D25: 40 | E25: =C25*D25 -> 1000 | F25: =E23+E25 -> 279.04
B26: Stima del MASSIMO incassabile (40 PX che pagano prezzo pieno €37) | C26: 37 | D26: 40 | E26: =C26*D26 -> 1480 | F26: =E23+E26 -> 759.04
B27: Stima MEDIA incassabile | C27: 31 | D27: 40 | E27: =C27*D27 -> 1240 | F27: =E23+E27 -> 519.04
A29: ENTRATE | B29: =IFERROR(__xludf.DUMMYFUNCTION("IMPORTRANGE(""https://docs.google.com/spreadsheets/d/1w_v-LytfJUSGD2382sduIgEApmqF1mMjksjNng1JfDs/edit?gid=134075723#gid=134075723"",""WS_DEANGELIS!I153:O156"")"),"subTOTALE ONLINE") -> subTOTALE ONLINE | C29: =IFERROR(__xludf.DUMMYFUNCTION("""COMPUTED_VALUE"""),0.0) -> 0 | D29: =IFERROR(__xludf.DUMMYFUNCTION("""COMPUTED_VALUE"""),0.0) -> 0 | E29: =IFERROR(__xludf.DUMMYFUNCTION("""COMPUTED_VALUE"""),0.0) -> 0 | F29: =IFERROR(__xludf.DUMMYFUNCTION("""COMPUTED_VALUE"""),0.0) -> 0 | G29: =IFERROR(__xludf.DUMMYFUNCTION("""COMPUTED_VALUE"""),0.0) -> 0 | H29: =IFERROR(__xludf.DUMMYFUNCTION("""COMPUTED_VALUE"""),0.0) -> 0
B30: =IFERROR(__xludf.DUMMYFUNCTION("""COMPUTED_VALUE"""),"TOTALE PERSONE SEDE") -> TOTALE PERSONE SEDE | C30: =IFERROR(__xludf.DUMMYFUNCTION("""COMPUTED_VALUE""")," 2 da €27") -> 2 da €27 | D30: =IFERROR(__xludf.DUMMYFUNCTION("""COMPUTED_VALUE""")," 2 da €25") -> 2 da €25 | E30: =IFERROR(__xludf.DUMMYFUNCTION("""COMPUTED_VALUE""")," 1 da €32") -> 1 da €32 | F30: =IFERROR(__xludf.DUMMYFUNCTION("""COMPUTED_VALUE""")," 0 da €30") -> 0 da €30 | G30: =IFERROR(__xludf.DUMMYFUNCTION("""COMPUTED_VALUE""")," 1 da €37") -> 1 da €37 | H30: =IFERROR(__xludf.DUMMYFUNCTION("""COMPUTED_VALUE""")," 0 da €35") -> 0 da €35
B31: =IFERROR(__xludf.DUMMYFUNCTION("""COMPUTED_VALUE"""),"subTOTALE SEDE") -> subTOTALE SEDE | C31: =IFERROR(__xludf.DUMMYFUNCTION("""COMPUTED_VALUE"""),54.0) -> 54 | D31: =IFERROR(__xludf.DUMMYFUNCTION("""COMPUTED_VALUE"""),50.0) -> 50 | E31: =IFERROR(__xludf.DUMMYFUNCTION("""COMPUTED_VALUE"""),32.0) -> 32 | F31: =IFERROR(__xludf.DUMMYFUNCTION("""COMPUTED_VALUE"""),0.0) -> 0 | G31: =IFERROR(__xludf.DUMMYFUNCTION("""COMPUTED_VALUE"""),37.0) -> 37 | H31: =IFERROR(__xludf.DUMMYFUNCTION("""COMPUTED_VALUE"""),0.0) -> 0
B32: =IFERROR(__xludf.DUMMYFUNCTION("""COMPUTED_VALUE"""),"TOTALE PERSONE ONLINE") -> TOTALE PERSONE ONLINE | C32: =IFERROR(__xludf.DUMMYFUNCTION("""COMPUTED_VALUE""")," 9 da €27") -> 9 da €27 | D32: =IFERROR(__xludf.DUMMYFUNCTION("""COMPUTED_VALUE""")," 0 da €25") -> 0 da €25 | E32: =IFERROR(__xludf.DUMMYFUNCTION("""COMPUTED_VALUE""")," 18 da €32") -> 18 da €32 | F32: =IFERROR(__xludf.DUMMYFUNCTION("""COMPUTED_VALUE""")," 4 da €30") -> 4 da €30 | G32: =IFERROR(__xludf.DUMMYFUNCTION("""COMPUTED_VALUE""")," 0 da €37") -> 0 da €37 | H32: =IFERROR(__xludf.DUMMYFUNCTION("""COMPUTED_VALUE""")," 0 da €35") -> 0 da €35
B33: =IFERROR(__xludf.DUMMYFUNCTION("IMPORTRANGE(""https://docs.google.com/spreadsheets/d/1w_v-LytfJUSGD2382sduIgEApmqF1mMjksjNng1JfDs/edit?gid=134075723#gid=134075723"",""WS_DEANGELIS!P154:T157"")")," TOTALE SEDE") -> TOTALE SEDE | C33: =IFERROR(__xludf.DUMMYFUNCTION("""COMPUTED_VALUE"""),173.0) -> 173 | D33: =IFERROR(__xludf.DUMMYFUNCTION("""COMPUTED_VALUE""")," TOTALE GENERALE ENTRATE") -> TOTALE GENERALE ENTRATE | E33: =IFERROR(__xludf.DUMMYFUNCTION("""COMPUTED_VALUE"""),1112.0) -> 1112
B35: =IFERROR(__xludf.DUMMYFUNCTION("""COMPUTED_VALUE""")," TOTALE ONLINE") -> TOTALE ONLINE | C35: =IFERROR(__xludf.DUMMYFUNCTION("""COMPUTED_VALUE"""),939.0) -> 939
B38: RICAVO/PERDITA | E38: =E33+E23 -> 391.04

Sheet KUMO_09NOV25
A1: KUMO
B2: Descrizione | C2: Dettagli | D2: Q.t | E2: Importo | F2: Metodo di pagamento
A3: USCITE ARTISTA | B3: Fee artist | C3: WS da 2h | D3: 1 | E3: -600 | F3: Bonifico
B4: Treno | C4: - | D4: - | E4: 0
B5: Spese trasporto | C5: - | D5: - | E5: 0
B6: Hotel | C6: - | D6: - | E6: 0
B7: Pranzi | C7: - | D7: - | E7: 0
B8: Cene | C8: - | D8: - | E8: 0
B9: Adidas | C9: Tshirt JE9024 tg L | D9: 1 | E9: -18 | F9: Rid Bancario
B10: TOTALE USCITE ARTISTA | E10: =SUM(E3:E9) -> -618
A12: USCITE EXTRA | B12: Affitto spazio | C12: No (ma minimo €300 euro) | D12: - | E12: 0
B13: Personale | C13: 3h30/4h Spese divise con WS Leli (calcolo approssimativo) | D13: 3 | E13: -50 | F13: Bonifico
B14: Video maker | D14: - | E14: -200 | F14: Affitto Yuri
B15: Volantini | D15: - | E15: -10 | F15: Bonifico
B16: Manifesti | D16: - | E16: 0
B17: Fish singolo per vendita | D17: - | E17: -3 | F17: Contanti cassa Elisa
B18: Bonus team per vendita | D18: - | E18: -11 | F18: Contanti cassa Elisa
B19: Sponsorizzate | D19: - | E19: -687.33 | F19: Carta
B20: Commissioni Online | C20: Percentuale del 1,5% su una media di €35 | D20: 61 | E20: =D20*35*-1.5% -> -32.025 | F20: Commissioni
B21: TOTALE USCITE EXTRA | E21: =SUM(E12:E20) -> -993.355
B23: TOTALE USCITE | E23: =E10+E21 -> -1611.355
A25: STIMA CONTRIBUTI/INCASSI €32 entro l'8 ottobre compreso (con cod sconto €30) €37 entro il l'8 novembre compreso (con cod sconto €35) €42 il giorno stesso (con cod sconto €40) | B25: Stima del MINIMO incassabile (60 PX che pagano con cod sconto €30) | C25: 30 | D25: 60 | E25: =C25*D25 -> 1800 | F25: =E23+E25 -> 188.645
B26: Stima del MASSIMO incassabile (60 PX che pagano prezzo pieno €42) | C26: 42 | D26: 60 | E26: =C26*D26 -> 2520 | F26: =E23+E26 -> 908.645
B27: Stima MEDIA incassabile | C27: 36 | D27: 60 | E27: =C27*D27 -> 2160 | F27: =E23+E27 -> 548.645
A29: ENTRATE | B29: =IFERROR(__xludf.DUMMYFUNCTION("IMPORTRANGE(""https://docs.google.com/spreadsheets/d/1w_v-LytfJUSGD2382sduIgEApmqF1mMjksjNng1JfDs/edit?gid=134075723#gid=134075723"",""WS_KUMO!I153:O156"")"),"TOTALE PERSONE SEDE") -> TOTALE PERSONE SEDE | C29: =IFERROR(__xludf.DUMMYFUNCTION("""COMPUTED_VALUE""")," 1 da €32") -> 1 da €32 | D29: =IFERROR(__xludf.DUMMYFUNCTION("""COMPUTED_VALUE""")," 0 da €30") -> 0 da €30 | E29: =IFERROR(__xludf.DUMMYFUNCTION("""COMPUTED_VALUE""")," 1 da €37") -> 1 da €37 | F29: =IFERROR(__xludf.DUMMYFUNCTION("""COMPUTED_VALUE""")," 0 da €35") -> 0 da €35 | G29: =IFERROR(__xludf.DUMMYFUNCTION("""COMPUTED_VALUE""")," 0 da €42") -> 0 da €42 | H29: =IFERROR(__xludf.DUMMYFUNCTION("""COMPUTED_VALUE""")," 0 da €40") -> 0 da €40
B30: =IFERROR(__xludf.DUMMYFUNCTION("""COMPUTED_VALUE"""),"subTOTALE SEDE") -> subTOTALE SEDE | C30: =IFERROR(__xludf.DUMMYFUNCTION("""COMPUTED_VALUE"""),32.0) -> 32 | D30: =IFERROR(__xludf.DUMMYFUNCTION("""COMPUTED_VALUE"""),0.0) -> 0 | E30: =IFERROR(__xludf.DUMMYFUNCTION("""COMPUTED_VALUE"""),37.0) -> 37 | F30: =IFERROR(__xludf.DUMMYFUNCTION("""COMPUTED_VALUE"""),0.0) -> 0 | G30: =IFERROR(__xludf.DUMMYFUNCTION("""COMPUTED_VALUE"""),0.0) -> 0 | H30: =IFERROR(__xludf.DUMMYFUNCTION("""COMPUTED_VALUE"""),0.0) -> 0
B31: =IFERROR(__xludf.DUMMYFUNCTION("""COMPUTED_VALUE"""),"TOTALE PERSONE ONLINE") -> TOTALE PERSONE ONLINE | C31: =IFERROR(__xludf.DUMMYFUNCTION("""COMPUTED_VALUE""")," 12 da €32") -> 12 da €32 | D31: =IFERROR(__xludf.DUMMYFUNCTION("""COMPUTED_VALUE""")," 5 da €30") -> 5 da €30 | E31: =IFERROR(__xludf.DUMMYFUNCTION("""COMPUTED_VALUE""")," 40 da €37") -> 40 da €37 | F31: =IFERROR(__xludf.DUMMYFUNCTION("""COMPUTED_VALUE""")," 4 da €35") -> 4 da €35 | G31: =IFERROR(__xludf.DUMMYFUNCTION("""COMPUTED_VALUE""")," 0 da €42") -> 0 da €42 | H31: =IFERROR(__xludf.DUMMYFUNCTION("""COMPUTED_VALUE""")," 0 da €40") -> 0 da €40
B32: =IFERROR(__xludf.DUMMYFUNCTION("""COMPUTED_VALUE"""),"subTOTALE ONLINE") -> subTOTALE ONLINE | C32: =IFERROR(__xludf.DUMMYFUNCTION("""COMPUTED_VALUE"""),384.0) -> 384 | D32: =IFERROR(__xludf.DUMMYFUNCTION("""COMPUTED_VALUE"""),150.0) -> 150 | E32: =IFERROR(__xludf.DUMMYFUNCTION("""COMPUTED_VALUE"""),1480.0) -> 1480 | F32: =IFERROR(__xludf.DUMMYFUNCTION("""COMPUTED_VALUE"""),140.0) -> 140 | G32: =IFERROR(__xludf.DUMMYFUNCTION("""COMPUTED_VALUE"""),0.0) -> 0 | H32: =IFERROR(__xludf.DUMMYFUNCTION("""COMPUTED_VALUE"""),0.0) -> 0
B33: =IFERROR(__xludf.DUMMYFUNCTION("IMPORTRANGE(""https://docs.google.com/spreadsheets/d/1w_v-LytfJUSGD2382sduIgEApmqF1mMjksjNng1JfDs/edit?gid=134075723#gid=134075723"",""WS_KUMO!P153:T156"")")," TOTALE SEDE") -> TOTALE SEDE | C33: =IFERROR(__xludf.DUMMYFUNCTION("""COMPUTED_VALUE"""),69.0) -> 69 | D33: =IFERROR(__xludf.DUMMYFUNCTION("""COMPUTED_VALUE""")," TOTALE GENERALE ENTRATE") -> TOTALE GENERALE ENTRATE | E33: =IFERROR(__xludf.DUMMYFUNCTION("""COMPUTED_VALUE"""),2223.0) -> 2223
B35: =IFERROR(__xludf.DUMMYFUNCTION("""COMPUTED_VALUE""")," TOTALE ONLINE") -> TOTALE ONLINE | C35: =IFERROR(__xludf.DUMMYFUNCTION("""COMPUTED_VALUE"""),2154.0) -> 2154
B38: RICAVO/PERDITA | E38: =E33+E23 -> 611.645

Sheet LELI_09NOV25
A1: LELI
B2: Descrizione | C2: Dettagli | D2: Q.t | E2: Importo | F2: Metodo di pagamento
A3: USCITE ARTISTA | B3: Fee artist | C3: WS da 1h 30 | D3: 1 | E3: -100 | F3: Contanti cassa Elisa
B4: Treno | C4: - | D4: - | E4: 0
B5: Spese trasporto | C5: - | D5: 0 | E5: 0
B6: Hotel (due notti) | C6: - | D6: 0 | E6: 0
B7: Pranzi | C7: - | D7: 0 | E7: 0
B8: Cene | C8: - | D8: 0 | E8: 0
B9: Adidas | C9: Top JX3896 tg M | D9: 1 | E9: -25.01 | F9: Rid Bancario
B10: TOTALE USCITE ARTISTA | E10: =SUM(E3:E9) -> -125.01
A12: USCITE EXTRA | B12: Affitto spazio | C12: No (ma minimo €300 euro) | D12: - | E12: 0
B13: Personale | C13: 3h30/4h Spese divise con WS Kumo (calcolo approssimativo) | D13: 3 | E13: -50 | F13: Bonifico
B14: Video maker | D14: - | E14: 0 | F14: Affitto Yuri
B15: Volantini | D15: - | E15: -10 | F15: Bonifico
B16: Manifesti | D16: - | E16: 0
B17: Fish singolo per vendita | D17: - | E17: -1.5 | F17: Contanti cassa Elisa
B18: Bonus team per vendita | D18: - | E18: -5 | F18: Contanti cassa Elisa
B19: Sponsorizzate | D19: - | E19: -43.73 | F19: Carta
B20: Commissioni Online | C20: Percentuale del 1,5% su una media di €27 | D20: 7 | E20: =D20*27*-1.5% -> -2.835 | F20: Commissioni
B21: TOTALE USCITE EXTRA | E21: =SUM(E12:E20) -> -113.065
B23: TOTALE USCITE | E23: =E10+E21 -> -238.075
A25: STIMA CONTRIBUTI/INCASSI €27 entro l' 8 ottobre compreso (con cod sconto €25) €32 entro l' 8 novembre compreso (con cod sconto €30) €37 il giorno stesso (con cod sconto €35) | B25: Stima del MINIMO incassabile (20 PX che pagano con cod sconto €25) | C25: 25 | D25: 20 | E25: =C25*D25 -> 500 | F25: =E23+E25 -> 261.925
B26: Stima del MASSIMO incassabile (20 PX che pagano prezzo pieno €37) | C26: 37 | D26: 20 | E26: =C26*D26 -> 740 | F26: =E23+E26 -> 501.925
B27: Stima MEDIA incassabile | C27: 31 | D27: 20 | E27: =C27*D27 -> 620 | F27: =E24+E27 -> 620
A29: ENTRATE | B29: =IFERROR(__xludf.DUMMYFUNCTION("IMPORTRANGE(""https://docs.google.com/spreadsheets/d/1w_v-LytfJUSGD2382sduIgEApmqF1mMjksjNng1JfDs/edit?gid=134075723#gid=134075723"",""WS_LELI!I153:O156"")"),"TOTALE PERSONE SEDE") -> TOTALE PERSONE SEDE | C29: =IFERROR(__xludf.DUMMYFUNCTION("""COMPUTED_VALUE""")," 1 da €27") -> 1 da €27 | D29: =IFERROR(__xludf.DUMMYFUNCTION("""COMPUTED_VALUE""")," 1 da €25") -> 1 da €25 | E29: =IFERROR(__xludf.DUMMYFUNCTION("""COMPUTED_VALUE""")," 0 da €32") -> 0 da €32 | F29: =IFERROR(__xludf.DUMMYFUNCTION("""COMPUTED_VALUE""")," 1 da €30") -> 1 da €30 | G29: =IFERROR(__xludf.DUMMYFUNCTION("""COMPUTED_VALUE""")," 0 da €37") -> 0 da €37 | H29: =IFERROR(__xludf.DUMMYFUNCTION("""COMPUTED_VALUE""")," 0 da €35") -> 0 da €35
B30: =IFERROR(__xludf.DUMMYFUNCTION("""COMPUTED_VALUE"""),"subTOTALE SEDE") -> subTOTALE SEDE | C30: =IFERROR(__xludf.DUMMYFUNCTION("""COMPUTED_VALUE"""),27.0) -> 27 | D30: =IFERROR(__xludf.DUMMYFUNCTION("""COMPUTED_VALUE"""),25.0) -> 25 | E30: =IFERROR(__xludf.DUMMYFUNCTION("""COMPUTED_VALUE"""),0.0) -> 0 | F30: =IFERROR(__xludf.DUMMYFUNCTION("""COMPUTED_VALUE"""),30.0) -> 30 | G30: =IFERROR(__xludf.DUMMYFUNCTION("""COMPUTED_VALUE"""),0.0) -> 0 | H30: =IFERROR(__xludf.DUMMYFUNCTION("""COMPUTED_VALUE"""),0.0) -> 0
B31: =IFERROR(__xludf.DUMMYFUNCTION("""COMPUTED_VALUE"""),"TOTALE PERSONE ONLINE") -> TOTALE PERSONE ONLINE | C31: =IFERROR(__xludf.DUMMYFUNCTION("""COMPUTED_VALUE""")," 4 da €27") -> 4 da €27 | D31: =IFERROR(__xludf.DUMMYFUNCTION("""COMPUTED_VALUE""")," 2 da €25") -> 2 da €25 | E31: =IFERROR(__xludf.DUMMYFUNCTION("""COMPUTED_VALUE""")," 1 da €32") -> 1 da €32 | F31: =IFERROR(__xludf.DUMMYFUNCTION("""COMPUTED_VALUE""")," 0 da €30") -> 0 da €30 | G31: =IFERROR(__xludf.DUMMYFUNCTION("""COMPUTED_VALUE""")," 0 da €37") -> 0 da €37 | H31: =IFERROR(__xludf.DUMMYFUNCTION("""COMPUTED_VALUE""")," 0 da €35") -> 0 da €35
B32: =IFERROR(__xludf.DUMMYFUNCTION("""COMPUTED_VALUE"""),"subTOTALE ONLINE") -> subTOTALE ONLINE | C32: =IFERROR(__xludf.DUMMYFUNCTION("""COMPUTED_VALUE"""),108.0) -> 108 | D32: =IFERROR(__xludf.DUMMYFUNCTION("""COMPUTED_VALUE"""),50.0) -> 50 | E32: =IFERROR(__xludf.DUMMYFUNCTION("""COMPUTED_VALUE"""),32.0) -> 32 | F32: =IFERROR(__xludf.DUMMYFUNCTION("""COMPUTED_VALUE"""),0.0) -> 0 | G32: =IFERROR(__xludf.DUMMYFUNCTION("""COMPUTED_VALUE"""),0.0) -> 0 | H32: =IFERROR(__xludf.DUMMYFUNCTION("""COMPUTED_VALUE"""),0.0) -> 0
B33: =IFERROR(__xludf.DUMMYFUNCTION("IMPORTRANGE(""https://docs.google.com/spreadsheets/d/1w_v-LytfJUSGD2382sduIgEApmqF1mMjksjNng1JfDs/edit?gid=134075723#gid=134075723"",""WS_LELI!P153:T156"")")," TOTALE SEDE") -> TOTALE SEDE | C33: =IFERROR(__xludf.DUMMYFUNCTION("""COMPUTED_VALUE"""),82.0) -> 82 | D33: =IFERROR(__xludf.DUMMYFUNCTION("""COMPUTED_VALUE""")," TOTALE GENERALE ENTRATE") -> TOTALE GENERALE ENTRATE | E33: =IFERROR(__xludf.DUMMYFUNCTION("""COMPUTED_VALUE"""),272.0) -> 272
B35: =IFERROR(__xludf.DUMMYFUNCTION("""COMPUTED_VALUE""")," TOTALE ONLINE") -> TOTALE ONLINE | C35: =IFERROR(__xludf.DUMMYFUNCTION("""COMPUTED_VALUE"""),190.0) -> 190
B38: RICAVO/PERDITA | E38: =E33+E23 -> 33.925

Sheet LULU_26OTT25
A1: LULU KULOVA
