Workbook

Sheet ResocontoWS
C1: ALEXANDRA | E1: ESTEFANY | G1: GIUDITTA | I1: NURA | K1: JOEL | M1: aa | O1: SANTO | P1: SARA | Q1: MASSI | R1: STAFF | S1: STAFF2 | T1: aa | U1: ANAHITA | V1: ANDREA | W1: CINZIA | X1: FERGIE | Y1: CARLOS | Z1: aa | AA1: aa | AB1: aa | AC1: aa
A2: DATA EVENTO | B2: DESCRIZIONE | C2: Sede | D2: Codice | E2: Sede | F2: Codice | G2: Sede | H2: Codice | I2: Sede | J2: Codice | K2: Sede | L2: Codice | M2: Sede | N2: Codice | O2: Codice | P2: Codice | Q2: Codice | R2: Codice | S2: Codice | T2: Codice | U2: Codice | V2: Codice | W2: Codice | X2: Codice | Y2: Codice | Z2: Codice | AA2: Codice | AB2: Codice | AC2: Codice | AD2: TOTALE Sede e Codice | AE2: Bonus Team Vendita
A3: 45949 | B3: WS_BANANA | C3: =COUNTIF(INDIRECT("'"&$B3&"'!$B:$B"),"*"&C$1&"*")- COUNTIFS(INDIRECT("'"&$B3&"'!$B:$B"),"*"&C$1&"*",INDIRECT("'"&$B3&"'!$L:$L"),"*") -> 1 | D3: =COUNTIF(INDIRECT("'"&$B3&"'!$L:$L"),"*"&C$1&"*") -> 4 | E3: =COUNTIF(INDIRECT("'"&$B3&"'!$B:$B"),"*"&E$1&"*")- COUNTIFS(INDIRECT("'"&$B3&"'!$B:$B"),"*"&E$1&"*",INDIRECT("'"&$B3&"'!$L:$L"),"*") -> 0 | F3: =COUNTIF(INDIRECT("'"&$B3&"'!$L:$L"),"*"&E$1&"*") -> 4 | G3: =COUNTIF(INDIRECT("'"&$B3&"'!$B:$B"),"*"&G$1&"*")- COUNTIFS(INDIRECT("'"&$B3&"'!$B:$B"),"*"&G$1&"*",INDIRECT("'"&$B3&"'!$L:$L"),"*") -> 0 | H3: =COUNTIF(INDIRECT("'"&$B3&"'!$L:$L"),"*"&G$1&"*") -> 0 | I3: =COUNTIF(INDIRECT("'"&$B3&"'!$B:$B"),"*"&I$1&"*")- COUNTIFS(INDIRECT("'"&$B3&"'!$B:$B"),"*"&I$1&"*",INDIRECT("'"&$B3&"'!$L:$L"),"*") -> 1 | J3: =COUNTIF(INDIRECT("'"&$B3&"'!$L:$L"),"*"&I$1&"*") -> 8 | K3: =COUNTIF(INDIRECT("'"&$B3&"'!$B:$B"),"*"&K$1&"*")- COUNTIFS(INDIRECT("'"&$B3&"'!$B:$B"),"*"&K$1&"*",INDIRECT("'"&$B3&"'!$L:$L"),"*") -> 0 | L3: =COUNTIF(INDIRECT("'"&$B3&"'!$L:$L"),"*"&K$1&"*") -> 0 | M3: =COUNTIF(INDIRECT("'"&$B3&"'!$B:$B"),"*"&M$1&"*")- COUNTIFS(INDIRECT("'"&$B3&"'!$B:$B"),"*"&M$1&"*",INDIRECT("'"&$B3&"'!$L:$L"),"*") -> 0 | N3: =COUNTIF(INDIRECT("'"&$B3&"'!$L:$L"),"*"&M$1&"*") -> 0 | O3: =COUNTIF(INDIRECT("'"&$B3&"'!$L:$L"),"*"&O$1&"*") -> 0 | P3: =COUNTIF(INDIRECT("'"&$B3&"'!$L:$L"),"*"&P$1&"*") -> 1 | Q3: =COUNTIF(INDIRECT("'"&$B3&"'!$L:$L"),"*"&Q$1&"*") -> 0 | R3: =COUNTIF(INDIRECT("'"&$B3&"'!$L:$L"),"*"&R$1&"*") -> 0 | S3: =COUNTIF(INDIRECT("'"&$B3&"'!$L:$L"),"*"&S$1&"*") -> 0 | T3: =COUNTIF(INDIRECT("'"&$B3&"'!$L:$L"),"*"&T$1&"*") -> 0 | U3: =COUNTIF(INDIRECT("'"&$B3&"'!$L:$L"),"*"&U$1&"*") -> 0 | V3: =COUNTIF(INDIRECT("'"&$B3&"'!$L:$L"),"*"&V$1&"*") -> 0 | ... AC3: =COUNTIF(INDIRECT("'"&$B3&"'!$L:$L"),"*"&AC$1&"*") -> 0 | AD3: =SUM(C3:AC3) -> 19 | AE3: =AD3*1 -> 19
A4: 45956 | B4: WS_TIMOR | C4: =COUNTIF(INDIRECT("'"&$B4&"'!$B:$B"),"*"&C$1&"*")- COUNTIFS(INDIRECT("'"&$B4&"'!$B:$B"),"*"&C$1&"*",INDIRECT("'"&$B4&"'!$L:$L"),"*") -> 3 | D4: =COUNTIF(INDIRECT("'"&$B4&"'!$L:$L"),"*"&C$1&"*") -> 2 | E4: =COUNTIF(INDIRECT("'"&$B4&"'!$B:$B"),"*"&E$1&"*")- COUNTIFS(INDIRECT("'"&$B4&"'!$B:$B"),"*"&E$1&"*",INDIRECT("'"&$B4&"'!$L:$L"),"*") -> 0 | F4: =COUNTIF(INDIRECT("'"&$B4&"'!$L:$L"),"*"&E$1&"*") -> 5 | G4: =COUNTIF(INDIRECT("'"&$B4&"'!$B:$B"),"*"&G$1&"*")- COUNTIFS(INDIRECT("'"&$B4&"'!$B:$B"),"*"&G$1&"*",INDIRECT("'"&$B4&"'!$L:$L"),"*") -> 0 | H4: =COUNTIF(INDIRECT("'"&$B4&"'!$L:$L"),"*"&G$1&"*") -> 2 | I4: =COUNTIF(INDIRECT("'"&$B4&"'!$B:$B"),"*"&I$1&"*")- COUNTIFS(INDIRECT("'"&$B4&"'!$B:$B"),"*"&I$1&"*",INDIRECT("'"&$B4&"'!$L:$L"),"*") -> 0 | J4: =COUNTIF(INDIRECT("'"&$B4&"'!$L:$L"),"*"&I$1&"*") -> 4 | K4: =COUNTIF(INDIRECT("'"&$B4&"'!$B:$B"),"*"&K$1&"*")- COUNTIFS(INDIRECT("'"&$B4&"'!$B:$B"),"*"&K$1&"*",INDIRECT("'"&$B4&"'!$L:$L"),"*") -> 0 | L4: =COUNTIF(INDIRECT("'"&$B4&"'!$L:$L"),"*"&K$1&"*") -> 0 | M4: =COUNTIF(INDIRECT("'"&$B4&"'!$B:$B"),"*"&M$1&"*")- COUNTIFS(INDIRECT("'"&$B4&"'!$B:$B"),"*"&M$1&"*",INDIRECT("'"&$B4&"'!$L:$L"),"*") -> 0 | N4: =COUNTIF(INDIRECT("'"&$B4&"'!$L:$L"),"*"&M$1&"*") -> 0 | O4: =COUNTIF(INDIRECT("'"&$B4&"'!$L:$L"),"*"&O$1&"*") -> 0 | P4: =COUNTIF(INDIRECT("'"&$B4&"'!$L:$L"),"*"&P$1&"*") -> 2 | Q4: =COUNTIF(INDIRECT("'"&$B4&"'!$L:$L"),"*"&Q$1&"*") -> 0 | R4: =COUNTIF(INDIRECT("'"&$B4&"'!$L:$L"),"*"&R$1&"*") -> 0 | S4: =COUNTIF(INDIRECT("'"&$B4&"'!$L:$L"),"*"&S$1&"*") -> 0 | T4: =COUNTIF(INDIRECT("'"&$B4&"'!$L:$L"),"*"&T$1&"*") -> 0 | U4: =COUNTIF(INDIRECT("'"&$B4&"'!$L:$L"),"*"&U$1&"*") -> 0 | V4: =COUNTIF(INDIRECT("'"&$B4&"'!$L:$L"),"*"&V$1&"*") -> 0 | ... AC4: =COUNTIF(INDIRECT("'"&$B4&"'!$L:$L"),"*"&AC$1&"*") -> 0 | AD4: =SUM(C4:AC4) -> 18 | AE4: =AD4*1 -> 18
A5: 45956 | B5: WS_LULU | C5: =COUNTIF(INDIRECT("'"&$B5&"'!$B:$B"),"*"&C$1&"*")- COUNTIFS(INDIRECT("'"&$B5&"'!$B:$B"),"*"&C$1&"*",INDIRECT("'"&$B5&"'!$L:$L"),"*") -> 0 | D5: =COUNTIF(INDIRECT("'"&$B5&"'!$L:$L"),"*"&C$1&"*") -> 1 | E5: =COUNTIF(INDIRECT("'"&$B5&"'!$B:$B"),"*"&E$1&"*")- COUNTIFS(INDIRECT("'"&$B5&"'!$B:$B"),"*"&E$1&"*",INDIRECT("'"&$B5&"'!$L:$L"),"*") -> 0 | F5: =COUNTIF(INDIRECT("'"&$B5&"'!$L:$L"),"*"&E$1&"*") -> 4 | G5: =COUNTIF(INDIRECT("'"&$B5&"'!$B:$B"),"*"&G$1&"*")- COUNTIFS(INDIRECT("'"&$B5&"'!$B:$B"),"*"&G$1&"*",INDIRECT("'"&$B5&"'!$L:$L"),"*") -> 0 | H5: =COUNTIF(INDIRECT("'"&$B5&"'!$L:$L"),"*"&G$1&"*") -> 0 | I5: =COUNTIF(INDIRECT("'"&$B5&"'!$B:$B"),"*"&I$1&"*")- COUNTIFS(INDIRECT("'"&$B5&"'!$B:$B"),"*"&I$1&"*",INDIRECT("'"&$B5&"'!$L:$L"),"*") -> 0 | J5: =COUNTIF(INDIRECT("'"&$B5&"'!$L:$L"),"*"&I$1&"*") -> 3 | K5: =COUNTIF(INDIRECT("'"&$B5&"'!$B:$B"),"*"&K$1&"*")- COUNTIFS(INDIRECT("'"&$B5&"'!$B:$B"),"*"&K$1&"*",INDIRECT("'"&$B5&"'!$L:$L"),"*") -> 0 | L5: =COUNTIF(INDIRECT("'"&$B5&"'!$L:$L"),"*"&K$1&"*") -> 4 | M5: =COUNTIF(INDIRECT("'"&$B5&"'!$B:$B"),"*"&M$1&"*")- COUNTIFS(INDIRECT("'"&$B5&"'!$B:$B"),"*"&M$1&"*",INDIRECT("'"&$B5&"'!$L:$L"),"*") -> 0 | N5: =COUNTIF(INDIRECT("'"&$B5&"'!$L:$L"),"*"&M$1&"*") -> 0 | O5: =COUNTIF(INDIRECT("'"&$B5&"'!$L:$L"),"*"&O$1&"*") -> 0 | P5: =COUNTIF(INDIRECT("'"&$B5&"'!$L:$L"),"*"&P$1&"*") -> 0 | Q5: =COUNTIF(INDIRECT("'"&$B5&"'!$L:$L"),"*"&Q$1&"*") -> 0 | R5: =COUNTIF(INDIRECT("'"&$B5&"'!$L:$L"),"*"&R$1&"*") -> 0 | S5: =COUNTIF(INDIRECT("'"&$B5&"'!$L:$L"),"*"&S$1&"*") -> 0 | T5: =COUNTIF(INDIRECT("'"&$B5&"'!$L:$L"),"*"&T$1&"*") -> 0 | U5: =COUNTIF(INDIRECT("'"&$B5&"'!$L:$L"),"*"&U$1&"*") -> 0 | V5: =COUNTIF(INDIRECT("'"&$B5&"'!$L:$L"),"*"&V$1&"*") -> 0 | ... AC5: =COUNTIF(INDIRECT("'"&$B5&"'!$L:$L"),"*"&AC$1&"*") -> 0 | AD5: =SUM(C5:AC5) -> 12 | AE5: =AD5*1 -> 12
A6: 45970 | B6: WS_KUMO | C6: =COUNTIF(INDIRECT("'"&$B6&"'!$B:$B"),"*"&C$1&"*")- COUNTIFS(INDIRECT("'"&$B6&"'!$B:$B"),"*"&C$1&"*",INDIRECT("'"&$B6&"'!$L:$L"),"*") -> 0 | D6: =COUNTIF(INDIRECT("'"&$B6&"'!$L:$L"),"*"&C$1&"*") -> 1 | E6: =COUNTIF(INDIRECT("'"&$B6&"'!$B:$B"),"*"&E$1&"*")- COUNTIFS(INDIRECT("'"&$B6&"'!$B:$B"),"*"&E$1&"*",INDIRECT("'"&$B6&"'!$L:$L"),"*") -> 0 | F6: =COUNTIF(INDIRECT("'"&$B6&"'!$L:$L"),"*"&E$1&"*") -> 2 | G6: =COUNTIF(INDIRECT("'"&$B6&"'!$B:$B"),"*"&G$1&"*")- COUNTIFS(INDIRECT("'"&$B6&"'!$B:$B"),"*"&G$1&"*",INDIRECT("'"&$B6&"'!$L:$L"),"*") -> 0 | H6: =COUNTIF(INDIRECT("'"&$B6&"'!$L:$L"),"*"&G$1&"*") -> 0 | I6: =COUNTIF(INDIRECT("'"&$B6&"'!$B:$B"),"*"&I$1&"*")- COUNTIFS(INDIRECT("'"&$B6&"'!$B:$B"),"*"&I$1&"*",INDIRECT("'"&$B6&"'!$L:$L"),"*") -> 2 | J6: =COUNTIF(INDIRECT("'"&$B6&"'!$L:$L"),"*"&I$1&"*") -> 4 | K6: =COUNTIF(INDIRECT("'"&$B6&"'!$B:$B"),"*"&K$1&"*")- COUNTIFS(INDIRECT("'"&$B6&"'!$B:$B"),"*"&K$1&"*",INDIRECT("'"&$B6&"'!$L:$L"),"*") -> 0 | L6: =COUNTIF(INDIRECT("'"&$B6&"'!$L:$L"),"*"&K$1&"*") -> 1 | M6: =COUNTIF(INDIRECT("'"&$B6&"'!$B:$B"),"*"&M$1&"*")- COUNTIFS(INDIRECT("'"&$B6&"'!$B:$B"),"*"&M$1&"*",INDIRECT("'"&$B6&"'!$L:$L"),"*") -> 0 | N6: =COUNTIF(INDIRECT("'"&$B6&"'!$L:$L"),"*"&M$1&"*") -> 0 | O6: =COUNTIF(INDIRECT("'"&$B6&"'!$L:$L"),"*"&O$1&"*") -> 0 | P6: =COUNTIF(INDIRECT("'"&$B6&"'!$L:$L"),"*"&P$1&"*") -> 1 | Q6: =COUNTIF(INDIRECT("'"&$B6&"'!$L:$L"),"*"&Q$1&"*") -> 0 | R6: =COUNTIF(INDIRECT("'"&$B6&"'!$L:$L"),"*"&R$1&"*") -> 0 | S6: =COUNTIF(INDIRECT("'"&$B6&"'!$L:$L"),"*"&S$1&"*") -> 0 | T6: =COUNTIF(INDIRECT("'"&$B6&"'!$L:$L"),"*"&T$1&"*") -> 0 | U6: =COUNTIF(INDIRECT("'"&$B6&"'!$L:$L"),"*"&U$1&"*") -> 0 | V6: =COUNTIF(INDIRECT("'"&$B6&"'!$L:$L"),"*"&V$1&"*") -> 0 | ... AC6: =COUNTIF(INDIRECT("'"&$B6&"'!$L:$L"),"*"&AC$1&"*") -> 0 | AD6: =SUM(C6:AC6) -> 11 | AE6: =AD6*1 -> 11
A7: 45970 | B7: WS_LELI | C7: =COUNTIF(INDIRECT("'"&$B7&"'!$B:$B"),"*"&C$1&"*")- COUNTIFS(INDIRECT("'"&$B7&"'!$B:$B"),"*"&C$1&"*",INDIRECT("'"&$B7&"'!$L:$L"),"*") -> 0 | D7: =COUNTIF(INDIRECT("'"&$B7&"'!$L:$L"),"*"&C$1&"*") -> 2 | E7: =COUNTIF(INDIRECT("'"&$B7&"'!$B:$B"),"*"&E$1&"*")- COUNTIFS(INDIRECT("'"&$B7&"'!$B:$B"),"*"&E$1&"*",INDIRECT("'"&$B7&"'!$L:$L"),"*") -> 0 | F7: =COUNTIF(INDIRECT("'"&$B7&"'!$L:$L"),"*"&E$1&"*") -> 1 | G7: =COUNTIF(INDIRECT("'"&$B7&"'!$B:$B"),"*"&G$1&"*")- COUNTIFS(INDIRECT("'"&$B7&"'!$B:$B"),"*"&G$1&"*",INDIRECT("'"&$B7&"'!$L:$L"),"*") -> 0 | H7: =COUNTIF(INDIRECT("'"&$B7&"'!$L:$L"),"*"&G$1&"*") -> 0 | I7: =COUNTIF(INDIRECT("'"&$B7&"'!$B:$B"),"*"&I$1&"*")- COUNTIFS(INDIRECT("'"&$B7&"'!$B:$B"),"*"&I$1&"*",INDIRECT("'"&$B7&"'!$L:$L"),"*") -> 1 | J7: =COUNTIF(INDIRECT("'"&$B7&"'!$L:$L"),"*"&I$1&"*") -> 0 | K7: =COUNTIF(INDIRECT("'"&$B7&"'!$B:$B"),"*"&K$1&"*")- COUNTIFS(INDIRECT("'"&$B7&"'!$B:$B"),"*"&K$1&"*",INDIRECT("'"&$B7&"'!$L:$L"),"*") -> 0 | L7: =COUNTIF(INDIRECT("'"&$B7&"'!$L:$L"),"*"&K$1&"*") -> 1 | M7: =COUNTIF(INDIRECT("'"&$B7&"'!$B:$B"),"*"&M$1&"*")- COUNTIFS(INDIRECT("'"&$B7&"'!$B:$B"),"*"&M$1&"*",INDIRECT("'"&$B7&"'!$L:$L"),"*") -> 0 | N7: =COUNTIF(INDIRECT("'"&$B7&"'!$L:$L"),"*"&M$1&"*") -> 0 | O7: =COUNTIF(INDIRECT("'"&$B7&"'!$L:$L"),"*"&O$1&"*") -> 0 | P7: =COUNTIF(INDIRECT("'"&$B7&"'!$L:$L"),"*"&P$1&"*") -> 0 | Q7: =COUNTIF(INDIRECT("'"&$B7&"'!$L:$L"),"*"&Q$1&"*") -> 0 | R7: =COUNTIF(INDIRECT("'"&$B7&"'!$L:$L"),"*"&R$1&"*") -> 0 | S7: =COUNTIF(INDIRECT("'"&$B7&"'!$L:$L"),"*"&S$1&"*") -> 0 | T7: =COUNTIF(INDIRECT("'"&$B7&"'!$L:$L"),"*"&T$1&"*") -> 0 | U7: =COUNTIF(INDIRECT("'"&$B7&"'!$L:$L"),"*"&U$1&"*") -> 0 | V7: =COUNTIF(INDIRECT("'"&$B7&"'!$L:$L"),"*"&V$1&"*") -> 0 | ... AC7: =COUNTIF(INDIRECT("'"&$B7&"'!$L:$L"),"*"&AC$1&"*") -> 0 | AD7: =SUM(C7:AC7) -> 5 | AE7: =AD7*1 -> 5
A8: 45977 | B8: WS_DEBORAHESPOSITO | C8: =COUNTIF(INDIRECT("'"&$B8&"'!$B:$B"),"*"&C$1&"*")- COUNTIFS(INDIRECT("'"&$B8&"'!$B:$B"),"*"&C$1&"*",INDIRECT("'"&$B8&"'!$L:$L"),"*") -> 0 | D8: =COUNTIF(INDIRECT("'"&$B8&"'!$L:$L"),"*"&C$1&"*") -> 6 | E8: =COUNTIF(INDIRECT("'"&$B8&"'!$B:$B"),"*"&E$1&"*")- COUNTIFS(INDIRECT("'"&$B8&"'!$B:$B"),"*"&E$1&"*",INDIRECT("'"&$B8&"'!$L:$L"),"*") -> 0 | F8: =COUNTIF(INDIRECT("'"&$B8&"'!$L:$L"),"*"&E$1&"*") -> 4 | G8: =COUNTIF(INDIRECT("'"&$B8&"'!$B:$B"),"*"&G$1&"*")- COUNTIFS(INDIRECT("'"&$B8&"'!$B:$B"),"*"&G$1&"*",INDIRECT("'"&$B8&"'!$L:$L"),"*") -> 0 | H8: =COUNTIF(INDIRECT("'"&$B8&"'!$L:$L"),"*"&G$1&"*") -> 0 | I8: =COUNTIF(INDIRECT("'"&$B8&"'!$B:$B"),"*"&I$1&"*")- COUNTIFS(INDIRECT("'"&$B8&"'!$B:$B"),"*"&I$1&"*",INDIRECT("'"&$B8&"'!$L:$L"),"*") -> 4 | J8: =COUNTIF(INDIRECT("'"&$B8&"'!$L:$L"),"*"&I$1&"*") -> 5 | K8: =COUNTIF(INDIRECT("'"&$B8&"'!$B:$B"),"*"&K$1&"*")- COUNTIFS(INDIRECT("'"&$B8&"'!$B:$B"),"*"&K$1&"*",INDIRECT("'"&$B8&"'!$L:$L"),"*") -> 0 | L8: =COUNTIF(INDIRECT("'"&$B8&"'!$L:$L"),"*"&K$1&"*") -> 1 | M8: =COUNTIF(INDIRECT("'"&$B8&"'!$B:$B"),"*"&M$1&"*")- COUNTIFS(INDIRECT("'"&$B8&"'!$B:$B"),"*"&M$1&"*",INDIRECT("'"&$B8&"'!$L:$L"),"*") -> 0 | N8: =COUNTIF(INDIRECT("'"&$B8&"'!$L:$L"),"*"&M$1&"*") -> 0 | O8: =COUNTIF(INDIRECT("'"&$B8&"'!$L:$L"),"*"&O$1&"*") -> 0 | P8: =COUNTIF(INDIRECT("'"&$B8&"'!$L:$L"),"*"&P$1&"*") -> 1 | Q8: =COUNTIF(INDIRECT("'"&$B8&"'!$L:$L"),"*"&Q$1&"*") -> 0 | R8: =COUNTIF(INDIRECT("'"&$B8&"'!$L:$L"),"*"&R$1&"*") -> 0 | S8: =COUNTIF(INDIRECT("'"&$B8&"'!$L:$L"),"*"&S$1&"*") -> 0 | T8: =COUNTIF(INDIRECT("'"&$B8&"'!$L:$L"),"*"&T$1&"*") -> 0 | U8: =COUNTIF(INDIRECT("'"&$B8&"'!$L:$L"),"*"&U$1&"*") -> 0 | V8: =COUNTIF(INDIRECT("'"&$B8&"'!$L:$L"),"*"&V$1&"*") -> 0 | ... AC8: =COUNTIF(INDIRECT("'"&$B8&"'!$L:$L"),"*"&AC$1&"*") -> 0 | AD8: =SUM(C8:AC8) -> 21 | AE8: =AD8*1 -> 21
A9: 45977 | B9: WS_DEANGELIS | C9: =COUNTIF(INDIRECT("'"&$B9&"'!$B:$B"),"*"&C$1&"*")- COUNTIFS(INDIRECT("'"&$B9&"'!$B:$B"),"*"&C$1&"*",INDIRECT("'"&$B9&"'!$L:$L"),"*") -> 0 | D9: =COUNTIF(INDIRECT("'"&$B9&"'!$L:$L"),"*"&C$1&"*") -> 0 | E9: =COUNTIF(INDIRECT("'"&$B9&"'!$B:$B"),"*"&E$1&"*")- COUNTIFS(INDIRECT("'"&$B9&"'!$B:$B"),"*"&E$1&"*",INDIRECT("'"&$B9&"'!$L:$L"),"*") -> 0 | F9: =COUNTIF(INDIRECT("'"&$B9&"'!$L:$L"),"*"&E$1&"*") -> 1 | G9: =COUNTIF(INDIRECT("'"&$B9&"'!$B:$B"),"*"&G$1&"*")- COUNTIFS(INDIRECT("'"&$B9&"'!$B:$B"),"*"&G$1&"*",INDIRECT("'"&$B9&"'!$L:$L"),"*") -> 0 | H9: =COUNTIF(INDIRECT("'"&$B9&"'!$L:$L"),"*"&G$1&"*") -> 1 | I9: =COUNTIF(INDIRECT("'"&$B9&"'!$B:$B"),"*"&I$1&"*")- COUNTIFS(INDIRECT("'"&$B9&"'!$B:$B"),"*"&I$1&"*",INDIRECT("'"&$B9&"'!$L:$L"),"*") -> 4 | J9: =COUNTIF(INDIRECT("'"&$B9&"'!$L:$L"),"*"&I$1&"*") -> 2 | K9: =COUNTIF(INDIRECT("'"&$B9&"'!$B:$B"),"*"&K$1&"*")- COUNTIFS(INDIRECT("'"&$B9&"'!$B:$B"),"*"&K$1&"*",INDIRECT("'"&$B9&"'!$L:$L"),"*") -> 0 | L9: =COUNTIF(INDIRECT("'"&$B9&"'!$L:$L"),"*"&K$1&"*") -> 1 | M9: =COUNTIF(INDIRECT("'"&$B9&"'!$B:$B"),"*"&M$1&"*")- COUNTIFS(INDIRECT("'"&$B9&"'!$B:$B"),"*"&M$1&"*",INDIRECT("'"&$B9&"'!$L:$L"),"*") -> 0 | N9: =COUNTIF(INDIRECT("'"&$B9&"'!$L:$L"),"*"&M$1&"*") -> 0 | O9: =COUNTIF(INDIRECT("'"&$B9&"'!$L:$L"),"*"&O$1&"*") -> 0 | P9: =COUNTIF(INDIRECT("'"&$B9&"'!$L:$L"),"*"&P$1&"*") -> 0 | Q9: =COUNTIF(INDIRECT("'"&$B9&"'!$L:$L"),"*"&Q$1&"*") -> 1 | R9: =COUNTIF(INDIRECT("'"&$B9&"'!$L:$L"),"*"&R$1&"*") -> 0 | S9: =COUNTIF(INDIRECT("'"&$B9&"'!$L:$L"),"*"&S$1&"*") -> 0 | T9: =COUNTIF(INDIRECT("'"&$B9&"'!$L:$L"),"*"&T$1&"*") -> 0 | U9: =COUNTIF(INDIRECT("'"&$B9&"'!$L:$L"),"*"&U$1&"*") -> 0 | V9: =COUNTIF(INDIRECT("'"&$B9&"'!$L:$L"),"*"&V$1&"*") -> 0 | ... AC9: =COUNTIF(INDIRECT("'"&$B9&"'!$L:$L"),"*"&AC$1&"*") -> 0 | AD9: =SUM(C9:AC9) -> 10 | AE9: =AD9*1 -> 10
A10: 46005 | B10: WS_NEREA | C10: =COUNTIF(INDIRECT("'"&$B10&"'!$B:$B"),"*"&C$1&"*")- COUNTIFS(INDIRECT("'"&$B10&"'!$B:$B"),"*"&C$1&"*",INDIRECT("'"&$B10&"'!$L:$L"),"*") -> 0 | D10: =COUNTIF(INDIRECT("'"&$B10&"'!$L:$L"),"*"&C$1&"*") -> 1 | E10: =COUNTIF(INDIRECT("'"&$B10&"'!$B:$B"),"*"&E$1&"*")- COUNTIFS(INDIRECT("'"&$B10&"'!$B:$B"),"*"&E$1&"*",INDIRECT("'"&$B10&"'!$L:$L"),"*") -> 0 | F10: =COUNTIF(INDIRECT("'"&$B10&"'!$L:$L"),"*"&E$1&"*") -> 1 | G10: =COUNTIF(INDIRECT("'"&$B10&"'!$B:$B"),"*"&G$1&"*")- COUNTIFS(INDIRECT("'"&$B10&"'!$B:$B"),"*"&G$1&"*",INDIRECT("'"&$B10&"'!$L:$L"),"*") -> 0 | H10: =COUNTIF(INDIRECT("'"&$B10&"'!$L:$L"),"*"&G$1&"*") -> 1 | I10: =COUNTIF(INDIRECT("'"&$B10&"'!$B:$B"),"*"&I$1&"*")- COUNTIFS(INDIRECT("'"&$B10&"'!$B:$B"),"*"&I$1&"*",INDIRECT("'"&$B10&"'!$L:$L"),"*") -> 0 | J10: =COUNTIF(INDIRECT("'"&$B10&"'!$L:$L"),"*"&I$1&"*") -> 4 | K10: =COUNTIF(INDIRECT("'"&$B10&"'!$B:$B"),"*"&K$1&"*")- COUNTIFS(INDIRECT("'"&$B10&"'!$B:$B"),"*"&K$1&"*",INDIRECT("'"&$B10&"'!$L:$L"),"*") -> 0 | L10: =COUNTIF(INDIRECT("'"&$B10&"'!$L:$L"),"*"&K$1&"*") -> 0 | M10: =COUNTIF(INDIRECT("'"&$B10&"'!$B:$B"),"*"&M$1&"*")- COUNTIFS(INDIRECT("'"&$B10&"'!$B:$B"),"*"&M$1&"*",INDIRECT("'"&$B10&"'!$L:$L"),"*") -> 0 | N10: =COUNTIF(INDIRECT("'"&$B10&"'!$L:$L"),"*"&M$1&"*") -> 0 | O10: =COUNTIF(INDIRECT("'"&$B10&"'!$L:$L"),"*"&O$1&"*") -> 0 | P10: =COUNTIF(INDIRECT("'"&$B10&"'!$L:$L"),"*"&P$1&"*") -> 0 | Q10: =COUNTIF(INDIRECT("'"&$B10&"'!$L:$L"),"*"&Q$1&"*") -> 1 | R10: =COUNTIF(INDIRECT("'"&$B10&"'!$L:$L"),"*"&R$1&"*") -> 0 | S10: =COUNTIF(INDIRECT("'"&$B10&"'!$L:$L"),"*"&S$1&"*") -> 0 | T10: =COUNTIF(INDIRECT("'"&$B10&"'!$L:$L"),"*"&T$1&"*") -> 0 | U10: =COUNTIF(INDIRECT("'"&$B10&"'!$L:$L"),"*"&U$1&"*") -> 0 | V10: =COUNTIF(INDIRECT("'"&$B10&"'!$L:$L"),"*"&V$1&"*") -> 0 | ... AC10: =COUNTIF(INDIRECT("'"&$B10&"'!$L:$L"),"*"&AC$1&"*") -> 0 | AD10: =SUM(C10:AC10) -> 8 | AE10: =AD10*1 -> 8
A11: 46005 | B11: WS_FESTA NATALE | C11: =COUNTIF(INDIRECT("'"&$B11&"'!$B:$B"),"*"&C$1&"*")- COUNTIFS(INDIRECT("'"&$B11&"'!$B:$B"),"*"&C$1&"*",INDIRECT("'"&$B11&"'!$L:$L"),"*") -> 0 | D11: =COUNTIF(INDIRECT("'"&$B11&"'!$L:$L"),"*"&C$1&"*") -> 10 | E11: =COUNTIF(INDIRECT("'"&$B11&"'!$B:$B"),"*"&E$1&"*")- COUNTIFS(INDIRECT("'"&$B11&"'!$B:$B"),"*"&E$1&"*",INDIRECT("'"&$B11&"'!$L:$L"),"*") -> 2 | F11: =COUNTIF(INDIRECT("'"&$B11&"'!$L:$L"),"*"&E$1&"*") -> 6 | G11: =COUNTIF(INDIRECT("'"&$B11&"'!$B:$B"),"*"&G$1&"*")- COUNTIFS(INDIRECT("'"&$B11&"'!$B:$B"),"*"&G$1&"*",INDIRECT("'"&$B11&"'!$L:$L"),"*") -> 0 | H11: =COUNTIF(INDIRECT("'"&$B11&"'!$L:$L"),"*"&G$1&"*") -> 8 | I11: =COUNTIF(INDIRECT("'"&$B11&"'!$B:$B"),"*"&I$1&"*")- COUNTIFS(INDIRECT("'"&$B11&"'!$B:$B"),"*"&I$1&"*",INDIRECT("'"&$B11&"'!$L:$L"),"*") -> 0 | J11: =COUNTIF(INDIRECT("'"&$B11&"'!$L:$L"),"*"&I$1&"*") -> 23 | K11: =COUNTIF(INDIRECT("'"&$B11&"'!$B:$B"),"*"&K$1&"*")- COUNTIFS(INDIRECT("'"&$B11&"'!$B:$B"),"*"&K$1&"*",INDIRECT("'"&$B11&"'!$L:$L"),"*") -> 0 | L11: =COUNTIF(INDIRECT("'"&$B11&"'!$L:$L"),"*"&K$1&"*") -> 7 | M11: =COUNTIF(INDIRECT("'"&$B11&"'!$B:$B"),"*"&M$1&"*")- COUNTIFS(INDIRECT("'"&$B11&"'!$B:$B"),"*"&M$1&"*",INDIRECT("'"&$B11&"'!$L:$L"),"*") -> 0 | N11: =COUNTIF(INDIRECT("'"&$B11&"'!$L:$L"),"*"&M$1&"*") -> 0 | O11: =COUNTIF(INDIRECT("'"&$B11&"'!$L:$L"),"*"&O$1&"*") -> 49 | P11: =COUNTIF(INDIRECT("'"&$B11&"'!$L:$L"),"*"&P$1&"*") -> 0 | Q11: =COUNTIF(INDIRECT("'"&$B11&"'!$L:$L"),"*"&Q$1&"*") -> 0 | R11: =COUNTIF(INDIRECT("'"&$B11&"'!$L:$L"),"*"&R$1&"*") -> 0 | S11: =COUNTIF(INDIRECT("'"&$B11&"'!$L:$L"),"*"&S$1&"*") -> 0 | T11: =COUNTIF(INDIRECT("'"&$B11&"'!$L:$L"),"*"&T$1&"*") -> 0 | U11: =COUNTIF(INDIRECT("'"&$B11&"'!$L:$L"),"*"&U$1&"*") -> 0 | V11: =COUNTIF(INDIRECT("'"&$B11&"'!$L:$L"),"*"&V$1&"*") -> 0 | ... AC11: =COUNTIF(INDIRECT("'"&$B11&"'!$L:$L"),"*"&AC$1&"*") -> 0 | AD11: =SUM(C11:AC11) -> 105 | AE11: =AD11*1 -> 105
A12: 46005 | B12: SOLO SERATA_FESTA NATALE | C12: =COUNTIF(INDIRECT("'"&$B12&"'!$B:$B"),"*"&C$1&"*")- COUNTIFS(INDIRECT("'"&$B12&"'!$B:$B"),"*"&C$1&"*",INDIRECT("'"&$B12&"'!$L:$L"),"*") -> 1 | D12: =COUNTIF(INDIRECT("'"&$B12&"'!$L:$L"),"*"&C$1&"*") -> 31 | E12: =COUNTIF(INDIRECT("'"&$B12&"'!$B:$B"),"*"&E$1&"*")- COUNTIFS(INDIRECT("'"&$B12&"'!$B:$B"),"*"&E$1&"*",INDIRECT("'"&$B12&"'!$L:$L"),"*") -> 3 | F12: =COUNTIF(INDIRECT("'"&$B12&"'!$L:$L"),"*"&E$1&"*") -> 14 | G12: =COUNTIF(INDIRECT("'"&$B12&"'!$B:$B"),"*"&G$1&"*")- COUNTIFS(INDIRECT("'"&$B12&"'!$B:$B"),"*"&G$1&"*",INDIRECT("'"&$B12&"'!$L:$L"),"*") -> 0 | H12: =COUNTIF(INDIRECT("'"&$B12&"'!$L:$L"),"*"&G$1&"*") -> 18 | I12: =COUNTIF(INDIRECT("'"&$B12&"'!$B:$B"),"*"&I$1&"*")- COUNTIFS(INDIRECT("'"&$B12&"'!$B:$B"),"*"&I$1&"*",INDIRECT("'"&$B12&"'!$L:$L"),"*") -> 0 | J12: =COUNTIF(INDIRECT("'"&$B12&"'!$L:$L"),"*"&I$1&"*") -> 22 | K12: =COUNTIF(INDIRECT("'"&$B12&"'!$B:$B"),"*"&K$1&"*")- COUNTIFS(INDIRECT("'"&$B12&"'!$B:$B"),"*"&K$1&"*",INDIRECT("'"&$B12&"'!$L:$L"),"*") -> 1 | L12: =COUNTIF(INDIRECT("'"&$B12&"'!$L:$L"),"*"&K$1&"*") -> 11 | M12: =COUNTIF(INDIRECT("'"&$B12&"'!$B:$B"),"*"&M$1&"*")- COUNTIFS(INDIRECT("'"&$B12&"'!$B:$B"),"*"&M$1&"*",INDIRECT("'"&$B12&"'!$L:$L"),"*") -> 0 | N12: =COUNTIF(INDIRECT("'"&$B12&"'!$L:$L"),"*"&M$1&"*") -> 0 | O12: =COUNTIF(INDIRECT("'"&$B12&"'!$L:$L"),"*"&O$1&"*") -> 51 | P12: =COUNTIF(INDIRECT("'"&$B12&"'!$L:$L"),"*"&P$1&"*") -> 0 | Q12: =COUNTIF(INDIRECT("'"&$B12&"'!$L:$L"),"*"&Q$1&"*") -> 2 | R12: =COUNTIF(INDIRECT("'"&$B12&"'!$L:$L"),"*"&R$1&"*") -> 0 | S12: =COUNTIF(INDIRECT("'"&$B12&"'!$L:$L"),"*"&S$1&"*") -> 0 | T12: =COUNTIF(INDIRECT("'"&$B12&"'!$L:$L"),"*"&T$1&"*") -> 0 | U12: =COUNTIF(INDIRECT("'"&$B12&"'!$L:$L"),"*"&U$1&"*") -> 0 | V12: =COUNTIF(INDIRECT("'"&$B12&"'!$L:$L"),"*"&V$1&"*") -> 0 | ... AC12: =COUNTIF(INDIRECT("'"&$B12&"'!$L:$L"),"*"&AC$1&"*") -> 0 | AD12: =SUM(C12:AC12) -> 154 | AE12: =AD12*1 -> 154
A13: 46054 | B13: WS_ALESSIOCAVALIERE | C13: =COUNTIF(INDIRECT("'"&$B13&"'!$B:$B"),"*"&C$1&"*")- COUNTIFS(INDIRECT("'"&$B13&"'!$B:$B"),"*"&C$1&"*",INDIRECT("'"&$B13&"'!$L:$L"),"*") -> 0 | D13: =COUNTIF(INDIRECT("'"&$B13&"'!$L:$L"),"*"&C$1&"*") -> 2 | E13: =COUNTIF(INDIRECT("'"&$B13&"'!$B:$B"),"*"&E$1&"*")- COUNTIFS(INDIRECT("'"&$B13&"'!$B:$B"),"*"&E$1&"*",INDIRECT("'"&$B13&"'!$L:$L"),"*") -> 0 | F13: =COUNTIF(INDIRECT("'"&$B13&"'!$L:$L"),"*"&E$1&"*") -> 1 | G13: =COUNTIF(INDIRECT("'"&$B13&"'!$B:$B"),"*"&G$1&"*")- COUNTIFS(INDIRECT("'"&$B13&"'!$B:$B"),"*"&G$1&"*",INDIRECT("'"&$B13&"'!$L:$L"),"*") -> 0 | H13: =COUNTIF(INDIRECT("'"&$B13&"'!$L:$L"),"*"&G$1&"*") -> 0 | I13: =COUNTIF(INDIRECT("'"&$B13&"'!$B:$B"),"*"&I$1&"*")- COUNTIFS(INDIRECT("'"&$B13&"'!$B:$B"),"*"&I$1&"*",INDIRECT("'"&$B13&"'!$L:$L"),"*") -> 0 | J13: =COUNTIF(INDIRECT("'"&$B13&"'!$L:$L"),"*"&I$1&"*") -> 2 | K13: =COUNTIF(INDIRECT("'"&$B13&"'!$B:$B"),"*"&K$1&"*")- COUNTIFS(INDIRECT("'"&$B13&"'!$B:$B"),"*"&K$1&"*",INDIRECT("'"&$B13&"'!$L:$L"),"*") -> 0 | L13: =COUNTIF(INDIRECT("'"&$B13&"'!$L:$L"),"*"&K$1&"*") -> 0 | M13: =COUNTIF(INDIRECT("'"&$B13&"'!$B:$B"),"*"&M$1&"*")- COUNTIFS(INDIRECT("'"&$B13&"'!$B:$B"),"*"&M$1&"*",INDIRECT("'"&$B13&"'!$L:$L"),"*") -> 0 | N13: =COUNTIF(INDIRECT("'"&$B13&"'!$L:$L"),"*"&M$1&"*") -> 0 | O13: =COUNTIF(INDIRECT("'"&$B13&"'!$L:$L"),"*"&O$1&"*") -> 0 | P13: =COUNTIF(INDIRECT("'"&$B13&"'!$L:$L"),"*"&P$1&"*") -> 1 | Q13: =COUNTIF(INDIRECT("'"&$B13&"'!$L:$L"),"*"&Q$1&"*") -> 0 | R13: =COUNTIF(INDIRECT("'"&$B13&"'!$L:$L"),"*"&R$1&"*") -> 0 | S13: =COUNTIF(INDIRECT("'"&$B13&"'!$L:$L"),"*"&S$1&"*") -> 0 | T13: =COUNTIF(INDIRECT("'"&$B13&"'!$L:$L"),"*"&T$1&"*") -> 0 | U13: =COUNTIF(INDIRECT("'"&$B13&"'!$L:$L"),"*"&U$1&"*") -> 0 | V13: =COUNTIF(INDIRECT("'"&$B13&"'!$L:$L"),"*"&V$1&"*") -> 0 | ... AC13: =COUNTIF(INDIRECT("'"&$B13&"'!$L:$L"),"*"&AC$1&"*") -> 0 | AD13: =SUM(C13:AC13) -> 6 | AE13: =AD13*1 -> 6
A14: 46075 | B14: WS_EMANUELLO | C14: =COUNTIF(INDIRECT("'"&$B14&"'!$B:$B"),"*"&C$1&"*")- COUNTIFS(INDIRECT("'"&$B14&"'!$B:$B"),"*"&C$1&"*",INDIRECT("'"&$B14&"'!$L:$L"),"*") -> 0 | D14: =COUNTIF(INDIRECT("'"&$B14&"'!$L:$L"),"*"&C$1&"*") -> 10 | E14: =COUNTIF(INDIRECT("'"&$B14&"'!$B:$B"),"*"&E$1&"*")- COUNTIFS(INDIRECT("'"&$B14&"'!$B:$B"),"*"&E$1&"*",INDIRECT("'"&$B14&"'!$L:$L"),"*") -> 0 | F14: =COUNTIF(INDIRECT("'"&$B14&"'!$L:$L"),"*"&E$1&"*") -> 3 | G14: =COUNTIF(INDIRECT("'"&$B14&"'!$B:$B"),"*"&G$1&"*")- COUNTIFS(INDIRECT("'"&$B14&"'!$B:$B"),"*"&G$1&"*",INDIRECT("'"&$B14&"'!$L:$L"),"*") -> 0 | H14: =COUNTIF(INDIRECT("'"&$B14&"'!$L:$L"),"*"&G$1&"*") -> 1 | I14: =COUNTIF(INDIRECT("'"&$B14&"'!$B:$B"),"*"&I$1&"*")- COUNTIFS(INDIRECT("'"&$B14&"'!$B:$B"),"*"&I$1&"*",INDIRECT("'"&$B14&"'!$L:$L"),"*") -> 0 | J14: =COUNTIF(INDIRECT("'"&$B14&"'!$L:$L"),"*"&I$1&"*") -> 24 | K14: =COUNTIF(INDIRECT("'"&$B14&"'!$B:$B"),"*"&K$1&"*")- COUNTIFS(INDIRECT("'"&$B14&"'!$B:$B"),"*"&K$1&"*",INDIRECT("'"&$B14&"'!$L:$L"),"*") -> 0 | L14: =COUNTIF(INDIRECT("'"&$B14&"'!$L:$L"),"*"&K$1&"*") -> 4 | M14: =COUNTIF(INDIRECT("'"&$B14&"'!$B:$B"),"*"&M$1&"*")- COUNTIFS(INDIRECT("'"&$B14&"'!$B:$B"),"*"&M$1&"*",INDIRECT("'"&$B14&"'!$L:$L"),"*") -> 0 | N14: =COUNTIF(INDIRECT("'"&$B14&"'!$L:$L"),"*"&M$1&"*") -> 0 | O14: =COUNTIF(INDIRECT("'"&$B14&"'!$L:$L"),"*"&O$1&"*") -> 0 | P14: =COUNTIF(INDIRECT("'"&$B14&"'!$L:$L"),"*"&P$1&"*") -> 1 | Q14: =COUNTIF(INDIRECT("'"&$B14&"'!$L:$L"),"*"&Q$1&"*") -> 0 | R14: =COUNTIF(INDIRECT("'"&$B14&"'!$L:$L"),"*"&R$1&"*") -> 0 | S14: =COUNTIF(INDIRECT("'"&$B14&"'!$L:$L"),"*"&S$1&"*") -> 0 | T14: =COUNTIF(INDIRECT("'"&$B14&"'!$L:$L"),"*"&T$1&"*") -> 0 | U14: =COUNTIF(INDIRECT("'"&$B14&"'!$L:$L"),"*"&U$1&"*") -> 0 | V14: =COUNTIF(INDIRECT("'"&$B14&"'!$L:$L"),"*"&V$1&"*") -> 0 | ... AC14: =COUNTIF(INDIRECT("'"&$B14&"'!$L:$L"),"*"&AC$1&"*") -> 0 | AD14: =SUM(C14:AC14) -> 43 | AE14: =AD14*1 -> 43
... A18: 46131 | B18: WS_JASMINE_ANDRIANO | C18: =COUNTIF(INDIRECT("'"&$B18&"'!$B:$B"),"*"&C$1&"*")- COUNTIFS(INDIRECT("'"&$B18&"'!$B:$B"),"*"&C$1&"*",INDIRECT("'"&$B18&"'!$L:$L"),"*") -> 0 | D18: =COUNTIF(INDIRECT("'"&$B18&"'!$L:$L"),"*"&C$1&"*") -> 1 | E18: =COUNTIF(INDIRECT("'"&$B18&"'!$B:$B"),"*"&E$1&"*")- COUNTIFS(INDIRECT("'"&$B18&"'!$B:$B"),"*"&E$1&"*",INDIRECT("'"&$B18&"'!$L:$L"),"*") -> 0 | F18: =COUNTIF(INDIRECT("'"&$B18&"'!$L:$L"),"*"&E$1&"*") -> 1 | G18: =COUNTIF(INDIRECT("'"&$B18&"'!$B:$B"),"*"&G$1&"*")- COUNTIFS(INDIRECT("'"&$B18&"'!$B:$B"),"*"&G$1&"*",INDIRECT("'"&$B18&"'!$L:$L"),"*") -> 0 | H18: =COUNTIF(INDIRECT("'"&$B18&"'!$L:$L"),"*"&G$1&"*") -> 0 | I18: =COUNTIF(INDIRECT("'"&$B18&"'!$B:$B"),"*"&I$1&"*")- COUNTIFS(INDIRECT("'"&$B18&"'!$B:$B"),"*"&I$1&"*",INDIRECT("'"&$B18&"'!$L:$L"),"*") -> 0 | J18: =COUNTIF(INDIRECT("'"&$B18&"'!$L:$L"),"*"&I$1&"*") -> 1 | K18: =COUNTIF(INDIRECT("'"&$B18&"'!$B:$B"),"*"&K$1&"*")- COUNTIFS(INDIRECT("'"&$B18&"'!$B:$B"),"*"&K$1&"*",INDIRECT("'"&$B18&"'!$L:$L"),"*") -> 0 | L18: =COUNTIF(INDIRECT("'"&$B18&"'!$L:$L"),"*"&K$1&"*") -> 0 | M18: =COUNTIF(INDIRECT("'"&$B18&"'!$B:$B"),"*"&M$1&"*")- COUNTIFS(INDIRECT("'"&$B18&"'!$B:$B"),"*"&M$1&"*",INDIRECT("'"&$B18&"'!$L:$L"),"*") -> 0 | N18: =COUNTIF(INDIRECT("'"&$B18&"'!$L:$L"),"*"&M$1&"*") -> 0 | O18: =COUNTIF(INDIRECT("'"&$B18&"'!$L:$L"),"*"&O$1&"*") -> 0 | P18: =COUNTIF(INDIRECT("'"&$B18&"'!$L:$L"),"*"&P$1&"*") -> 0 | Q18: =COUNTIF(INDIRECT("'"&$B18&"'!$L:$L"),"*"&Q$1&"*") -> 0 | R18: =COUNTIF(INDIRECT("'"&$B18&"'!$L:$L"),"*"&R$1&"*") -> 0 | S18: =COUNTIF(INDIRECT("'"&$B18&"'!$L:$L"),"*"&S$1&"*") -> 0 | T18: =COUNTIF(INDIRECT("'"&$B18&"'!$L:$L"),"*"&T$1&"*") -> 0 | U18: =COUNTIF(INDIRECT("'"&$B18&"'!$L:$L"),"*"&U$1&"*") -> 0 | V18: =COUNTIF(INDIRECT("'"&$B18&"'!$L:$L"),"*"&V$1&"*") -> 0 | ... AC18: =COUNTIF(INDIRECT("'"&$B18&"'!$L:$L"),"*"&AC$1&"*") -> 0 | AD18: =SUM(C18:AC18) -> 3 | AE18: =AD18*1 -> 3
C19: =COUNTIF(INDIRECT("'"&$B19&"'!$B:$B"),"*"&C$1&"*")- COUNTIFS(INDIRECT("'"&$B19&"'!$B:$B"),"*"&C$1&"*",INDIRECT("'"&$B19&"'!$L:$L"),"*") -> 0 | D19: =COUNTIF(INDIRECT("'"&$B19&"'!$L:$L"),"*"&C$1&"*") -> 0 | E19: =COUNTIF(INDIRECT("'"&$B19&"'!$B:$B"),"*"&E$1&"*")- COUNTIFS(INDIRECT("'"&$B19&"'!$B:$B"),"*"&E$1&"*",INDIRECT("'"&$B19&"'!$L:$L"),"*") -> 0 | F19: =COUNTIF(INDIRECT("'"&$B19&"'!$L:$L"),"*"&E$1&"*") -> 0 | G19: =COUNTIF(INDIRECT("'"&$B19&"'!$B:$B"),"*"&G$1&"*")- COUNTIFS(INDIRECT("'"&$B19&"'!$B:$B"),"*"&G$1&"*",INDIRECT("'"&$B19&"'!$L:$L"),"*") -> 0 | H19: =COUNTIF(INDIRECT("'"&$B19&"'!$L:$L"),"*"&G$1&"*") -> 0 | I19: =COUNTIF(INDIRECT("'"&$B19&"'!$B:$B"),"*"&I$1&"*")- COUNTIFS(INDIRECT("'"&$B19&"'!$B:$B"),"*"&I$1&"*",INDIRECT("'"&$B19&"'!$L:$L"),"*") -> 0 | J19: =COUNTIF(INDIRECT("'"&$B19&"'!$L:$L"),"*"&I$1&"*") -> 0 | K19: =COUNTIF(INDIRECT("'"&$B19&"'!$B:$B"),"*"&K$1&"*")- COUNTIFS(INDIRECT("'"&$B19&"'!$B:$B"),"*"&K$1&"*",INDIRECT("'"&$B19&"'!$L:$L"),"*") -> 0 | L19: =COUNTIF(INDIRECT("'"&$B19&"'!$L:$L"),"*"&K$1&"*") -> 0 | M19: =COUNTIF(INDIRECT("'"&$B19&"'!$B:$B"),"*"&M$1&"*")- COUNTIFS(INDIRECT("'"&$B19&"'!$B:$B"),"*"&M$1&"*",INDIRECT("'"&$B19&"'!$L:$L"),"*") -> 0 | N19: =COUNTIF(INDIRECT("'"&$B19&"'!$L:$L"),"*"&M$1&"*") -> 0 | O19: =COUNTIF(INDIRECT("'"&$B19&"'!$L:$L"),"*"&O$1&"*") -> 0 | P19: =COUNTIF(INDIRECT("'"&$B19&"'!$L:$L"),"*"&P$1&"*") -> 0 | Q19: =COUNTIF(INDIRECT("'"&$B19&"'!$L:$L"),"*"&Q$1&"*") -> 0 | R19: =COUNTIF(INDIRECT("'"&$B19&"'!$L:$L"),"*"&R$1&"*") -> 0 | S19: =COUNTIF(INDIRECT("'"&$B19&"'!$L:$L"),"*"&S$1&"*") -> 0 | T19: =COUNTIF(INDIRECT("'"&$B19&"'!$L:$L"),"*"&T$1&"*") -> 0 | U19: =COUNTIF(INDIRECT("'"&$B19&"'!$L:$L"),"*"&U$1&"*") -> 0 | V19: =COUNTIF(INDIRECT("'"&$B19&"'!$L:$L"),"*"&V$1&"*") -> 0 | ... AC19: =COUNTIF(INDIRECT("'"&$B19&"'!$L:$L"),"*"&AC$1&"*") -> 0 | AD19: =SUM(C19:AC19) -> 0 | AE19: =AD19*1 -> 0
C20: =COUNTIF(INDIRECT("'"&$B20&"'!$B:$B"),"*"&C$1&"*")- COUNTIFS(INDIRECT("'"&$B20&"'!$B:$B"),"*"&C$1&"*",INDIRECT("'"&$B20&"'!$L:$L"),"*") -> 0 | D20: =COUNTIF(INDIRECT("'"&$B20&"'!$L:$L"),"*"&C$1&"*") -> 0 | E20: =COUNTIF(INDIRECT("'"&$B20&"'!$B:$B"),"*"&E$1&"*")- COUNTIFS(INDIRECT("'"&$B20&"'!$B:$B"),"*"&E$1&"*",INDIRECT("'"&$B20&"'!$L:$L"),"*") -> 0 | F20: =COUNTIF(INDIRECT("'"&$B20&"'!$L:$L"),"*"&E$1&"*") -> 0 | G20: =COUNTIF(INDIRECT("'"&$B20&"'!$B:$B"),"*"&G$1&"*")- COUNTIFS(INDIRECT("'"&$B20&"'!$B:$B"),"*"&G$1&"*",INDIRECT("'"&$B20&"'!$L:$L"),"*") -> 0 | H20: =COUNTIF(INDIRECT("'"&$B20&"'!$L:$L"),"*"&G$1&"*") -> 0 | I20: =COUNTIF(INDIRECT("'"&$B20&"'!$B:$B"),"*"&I$1&"*")- COUNTIFS(INDIRECT("'"&$B20&"'!$B:$B"),"*"&I$1&"*",INDIRECT("'"&$B20&"'!$L:$L"),"*") -> 0 | J20: =COUNTIF(INDIRECT("'"&$B20&"'!$L:$L"),"*"&I$1&"*") -> 0 | K20: =COUNTIF(INDIRECT("'"&$B20&"'!$B:$B"),"*"&K$1&"*")- COUNTIFS(INDIRECT("'"&$B20&"'!$B:$B"),"*"&K$1&"*",INDIRECT("'"&$B20&"'!$L:$L"),"*") -> 0 | L20: =COUNTIF(INDIRECT("'"&$B20&"'!$L:$L"),"*"&K$1&"*") -> 0 | M20: =COUNTIF(INDIRECT("'"&$B20&"'!$B:$B"),"*"&M$1&"*")- COUNTIFS(INDIRECT("'"&$B20&"'!$B:$B"),"*"&M$1&"*",INDIRECT("'"&$B20&"'!$L:$L"),"*") -> 0 | N20: =COUNTIF(INDIRECT("'"&$B20&"'!$L:$L"),"*"&M$1&"*") -> 0 | O20: =COUNTIF(INDIRECT("'"&$B20&"'!$L:$L"),"*"&O$1&"*") -> 0 | P20: =COUNTIF(INDIRECT("'"&$B20&"'!$L:$L"),"*"&P$1&"*") -> 0 | Q20: =COUNTIF(INDIRECT("'"&$B20&"'!$L:$L"),"*"&Q$1&"*") -> 0 | R20: =COUNTIF(INDIRECT("'"&$B20&"'!$L:$L"),"*"&R$1&"*") -> 0 | S20: =COUNTIF(INDIRECT("'"&$B20&"'!$L:$L"),"*"&S$1&"*") -> 0 | T20: =COUNTIF(INDIRECT("'"&$B20&"'!$L:$L"),"*"&T$1&"*") -> 0 | U20: =COUNTIF(INDIRECT("'"&$B20&"'!$L:$L"),"*"&U$1&"*") -> 0 | V20: =COUNTIF(INDIRECT("'"&$B20&"'!$L:$L"),"*"&V$1&"*") -> 0 | ... AC20: =COUNTIF(INDIRECT("'"&$B20&"'!$L:$L"),"*"&AC$1&"*") -> 0 | AD20: =SUM(C20:AC20) -> 0 | AE20: =AD20*1 -> 0
C21: =COUNTIF(INDIRECT("'"&$B21&"'!$B:$B"),"*"&C$1&"*")- COUNTIFS(INDIRECT("'"&$B21&"'!$B:$B"),"*"&C$1&"*",INDIRECT("'"&$B21&"'!$L:$L"),"*") -> 0 | D21: =COUNTIF(INDIRECT("'"&$B21&"'!$L:$L"),"*"&C$1&"*") -> 0 | E21: =COUNTIF(INDIRECT("'"&$B21&"'!$B:$B"),"*"&E$1&"*")- COUNTIFS(INDIRECT("'"&$B21&"'!$B:$B"),"*"&E$1&"*",INDIRECT("'"&$B21&"'!$L:$L"),"*") -> 0 | F21: =COUNTIF(INDIRECT("'"&$B21&"'!$L:$L"),"*"&E$1&"*") -> 0 | G21: =COUNTIF(INDIRECT("'"&$B21&"'!$B:$B"),"*"&G$1&"*")- COUNTIFS(INDIRECT("'"&$B21&"'!$B:$B"),"*"&G$1&"*",INDIRECT("'"&$B21&"'!$L:$L"),"*") -> 0 | H21: =COUNTIF(INDIRECT("'"&$B21&"'!$L:$L"),"*"&G$1&"*") -> 0 | I21: =COUNTIF(INDIRECT("'"&$B21&"'!$B:$B"),"*"&I$1&"*")- COUNTIFS(INDIRECT("'"&$B21&"'!$B:$B"),"*"&I$1&"*",INDIRECT("'"&$B21&"'!$L:$L"),"*") -> 0 | J21: =COUNTIF(INDIRECT("'"&$B21&"'!$L:$L"),"*"&I$1&"*") -> 0 | K21: =COUNTIF(INDIRECT("'"&$B21&"'!$B:$B"),"*"&K$1&"*")- COUNTIFS(INDIRECT("'"&$B21&"'!$B:$B"),"*"&K$1&"*",INDIRECT("'"&$B21&"'!$L:$L"),"*") -> 0 | L21: =COUNTIF(INDIRECT("'"&$B21&"'!$L:$L"),"*"&K$1&"*") -> 0 | M21: =COUNTIF(INDIRECT("'"&$B21&"'!$B:$B"),"*"&M$1&"*")- COUNTIFS(INDIRECT("'"&$B21&"'!$B:$B"),"*"&M$1&"*",INDIRECT("'"&$B21&"'!$L:$L"),"*") -> 0 | N21: =COUNTIF(INDIRECT("'"&$B21&"'!$L:$L"),"*"&M$1&"*") -> 0 | O21: =COUNTIF(INDIRECT("'"&$B21&"'!$L:$L"),"*"&O$1&"*") -> 0 | P21: =COUNTIF(INDIRECT("'"&$B21&"'!$L:$L"),"*"&P$1&"*") -> 0 | Q21: =COUNTIF(INDIRECT("'"&$B21&"'!$L:$L"),"*"&Q$1&"*") -> 0 | R21: =COUNTIF(INDIRECT("'"&$B21&"'!$L:$L"),"*"&R$1&"*") -> 0 | S21: =COUNTIF(INDIRECT("'"&$B21&"'!$L:$L"),"*"&S$1&"*") -> 0 | T21: =COUNTIF(INDIRECT("'"&$B21&"'!$L:$L"),"*"&T$1&"*") -> 0 | U21: =COUNTIF(INDIRECT("'"&$B21&"'!$L:$L"),"*"&U$1&"*") -> 0 | V21: =COUNTIF(INDIRECT("'"&$B21&"'!$L:$L"),"*"&V$1&"*") -> 0 | ... AC21: =COUNTIF(INDIRECT("'"&$B21&"'!$L:$L"),"*"&AC$1&"*") -> 0 | AD21: =SUM(C21:AC21) -> 0 | AE21: =AD21*1 -> 0
C22: =COUNTIF(INDIRECT("'"&$B22&"'!$B:$B"),"*"&C$1&"*")- COUNTIFS(INDIRECT("'"&$B22&"'!$B:$B"),"*"&C$1&"*",INDIRECT("'"&$B22&"'!$L:$L"),"*") -> 0 | D22: =COUNTIF(INDIRECT("'"&$B22&"'!$L:$L"),"*"&C$1&"*") -> 0 | E22: =COUNTIF(INDIRECT("'"&$B22&"'!$B:$B"),"*"&E$1&"*")- COUNTIFS(INDIRECT("'"&$B22&"'!$B:$B"),"*"&E$1&"*",INDIRECT("'"&$B22&"'!$L:$L"),"*") -> 0 | F22: =COUNTIF(INDIRECT("'"&$B22&"'!$L:$L"),"*"&E$1&"*") -> 0 | G22: =COUNTIF(INDIRECT("'"&$B22&"'!$B:$B"),"*"&G$1&"*")- COUNTIFS(INDIRECT("'"&$B22&"'!$B:$B"),"*"&G$1&"*",INDIRECT("'"&$B22&"'!$L:$L"),"*") -> 0 | H22: =COUNTIF(INDIRECT("'"&$B22&"'!$L:$L"),"*"&G$1&"*") -> 0 | I22: =COUNTIF(INDIRECT("'"&$B22&"'!$B:$B"),"*"&I$1&"*")- COUNTIFS(INDIRECT("'"&$B22&"'!$B:$B"),"*"&I$1&"*",INDIRECT("'"&$B22&"'!$L:$L"),"*") -> 0 | J22: =COUNTIF(INDIRECT("'"&$B22&"'!$L:$L"),"*"&I$1&"*") -> 0 | K22: =COUNTIF(INDIRECT("'"&$B22&"'!$B:$B"),"*"&K$1&"*")- COUNTIFS(INDIRECT("'"&$B22&"'!$B:$B"),"*"&K$1&"*",INDIRECT("'"&$B22&"'!$L:$L"),"*") -> 0 | L22: =COUNTIF(INDIRECT("'"&$B22&"'!$L:$L"),"*"&K$1&"*") -> 0 | M22: =COUNTIF(INDIRECT("'"&$B22&"'!$B:$B"),"*"&M$1&"*")- COUNTIFS(INDIRECT("'"&$B22&"'!$B:$B"),"*"&M$1&"*",INDIRECT("'"&$B22&"'!$L:$L"),"*") -> 0 | N22: =COUNTIF(INDIRECT("'"&$B22&"'!$L:$L"),"*"&M$1&"*") -> 0 | O22: =COUNTIF(INDIRECT("'"&$B22&"'!$L:$L"),"*"&O$1&"*") -> 0 | P22: =COUNTIF(INDIRECT("'"&$B22&"'!$L:$L"),"*"&P$1&"*") -> 0 | Q22: =COUNTIF(INDIRECT("'"&$B22&"'!$L:$L"),"*"&Q$1&"*") -> 0 | R22: =COUNTIF(INDIRECT("'"&$B22&"'!$L:$L"),"*"&R$1&"*") -> 0 | S22: =COUNTIF(INDIRECT("'"&$B22&"'!$L:$L"),"*"&S$1&"*") -> 0 | T22: =COUNTIF(INDIRECT("'"&$B22&"'!$L:$L"),"*"&T$1&"*") -> 0 | U22: =COUNTIF(INDIRECT("'"&$B22&"'!$L:$L"),"*"&U$1&"*") -> 0 | V22: =COUNTIF(INDIRECT("'"&$B22&"'!$L:$L"),"*"&V$1&"*") -> 0 | ... AC22: =COUNTIF(INDIRECT("'"&$B22&"'!$L:$L"),"*"&AC$1&"*") -> 0 | AD22: =SUM(C22:AC22) -> 0 | AE22: =AD22*1 -> 0
C23: =COUNTIF(INDIRECT("'"&$B23&"'!$B:$B"),"*"&C$1&"*")- COUNTIFS(INDIRECT("'"&$B23&"'!$B:$B"),"*"&C$1&"*",INDIRECT("'"&$B23&"'!$L:$L"),"*") -> 0 | D23: =COUNTIF(INDIRECT("'"&$B23&"'!$L:$L"),"*"&C$1&"*") -> 0 | E23: =COUNTIF(INDIRECT("'"&$B23&"'!$B:$B"),"*"&E$1&"*")- COUNTIFS(INDIRECT("'"&$B23&"'!$B:$B"),"*"&E$1&"*",INDIRECT("'"&$B23&"'!$L:$L"),"*") -> 0 | F23: =COUNTIF(INDIRECT("'"&$B23&"'!$L:$L"),"*"&E$1&"*") -> 0 | G23: =COUNTIF(INDIRECT("'"&$B23&"'!$B:$B"),"*"&G$1&"*")- COUNTIFS(INDIRECT("'"&$B23&"'!$B:$B"),"*"&G$1&"*",INDIRECT("'"&$B23&"'!$L:$L"),"*") -> 0 | H23: =COUNTIF(INDIRECT("'"&$B23&"'!$L:$L"),"*"&G$1&"*") -> 0 | I23: =COUNTIF(INDIRECT("'"&$B23&"'!$B:$B"),"*"&I$1&"*")- COUNTIFS(INDIRECT("'"&$B23&"'!$B:$B"),"*"&I$1&"*",INDIRECT("'"&$B23&"'!$L:$L"),"*") -> 0 | J23: =COUNTIF(INDIRECT("'"&$B23&"'!$L:$L"),"*"&I$1&"*") -> 0 | K23: =COUNTIF(INDIRECT("'"&$B23&"'!$B:$B"),"*"&K$1&"*")- COUNTIFS(INDIRECT("'"&$B23&"'!$B:$B"),"*"&K$1&"*",INDIRECT("'"&$B23&"'!$L:$L"),"*") -> 0 | L23: =COUNTIF(INDIRECT("'"&$B23&"'!$L:$L"),"*"&K$1&"*") -> 0 | M23: =COUNTIF(INDIRECT("'"&$B23&"'!$B:$B"),"*"&M$1&"*")- COUNTIFS(INDIRECT("'"&$B23&"'!$B:$B"),"*"&M$1&"*",INDIRECT("'"&$B23&"'!$L:$L"),"*") -> 0 | N23: =COUNTIF(INDIRECT("'"&$B23&"'!$L:$L"),"*"&M$1&"*") -> 0 | O23: =COUNTIF(INDIRECT("'"&$B23&"'!$L:$L"),"*"&O$1&"*") -> 0 | P23: =COUNTIF(INDIRECT("'"&$B23&"'!$L:$L"),"*"&P$1&"*") -> 0 | Q23: =COUNTIF(INDIRECT("'"&$B23&"'!$L:$L"),"*"&Q$1&"*") -> 0 | R23: =COUNTIF(INDIRECT("'"&$B23&"'!$L:$L"),"*"&R$1&"*") -> 0 | S23: =COUNTIF(INDIRECT("'"&$B23&"'!$L:$L"),"*"&S$1&"*") -> 0 | T23: =COUNTIF(INDIRECT("'"&$B23&"'!$L:$L"),"*"&T$1&"*") -> 0 | U23: =COUNTIF(INDIRECT("'"&$B23&"'!$L:$L"),"*"&U$1&"*") -> 0 | V23: =COUNTIF(INDIRECT("'"&$B23&"'!$L:$L"),"*"&V$1&"*") -> 0 | ... AC23: =COUNTIF(INDIRECT("'"&$B23&"'!$L:$L"),"*"&AC$1&"*") -> 0 | AD23: =SUM(C23:AC23) -> 0 | AE23: =AD23*1 -> 0
C24: =COUNTIF(INDIRECT("'"&$B24&"'!$B:$B"),"*"&C$1&"*")- COUNTIFS(INDIRECT("'"&$B24&"'!$B:$B"),"*"&C$1&"*",INDIRECT("'"&$B24&"'!$L:$L"),"*") -> 0 | D24: =COUNTIF(INDIRECT("'"&$B24&"'!$L:$L"),"*"&C$1&"*") -> 0 | E24: =COUNTIF(INDIRECT("'"&$B24&"'!$B:$B"),"*"&E$1&"*")- COUNTIFS(INDIRECT("'"&$B24&"'!$B:$B"),"*"&E$1&"*",INDIRECT("'"&$B24&"'!$L:$L"),"*") -> 0 | F24: =COUNTIF(INDIRECT("'"&$B24&"'!$L:$L"),"*"&E$1&"*") -> 0 | G24: =COUNTIF(INDIRECT("'"&$B24&"'!$B:$B"),"*"&G$1&"*")- COUNTIFS(INDIRECT("'"&$B24&"'!$B:$B"),"*"&G$1&"*",INDIRECT("'"&$B24&"'!$L:$L"),"*") -> 0 | H24: =COUNTIF(INDIRECT("'"&$B24&"'!$L:$L"),"*"&G$1&"*") -> 0 | I24: =COUNTIF(INDIRECT("'"&$B24&"'!$B:$B"),"*"&I$1&"*")- COUNTIFS(INDIRECT("'"&$B24&"'!$B:$B"),"*"&I$1&"*",INDIRECT("'"&$B24&"'!$L:$L"),"*") -> 0 | J24: =COUNTIF(INDIRECT("'"&$B24&"'!$L:$L"),"*"&I$1&"*") -> 0 | K24: =COUNTIF(INDIRECT("'"&$B24&"'!$B:$B"),"*"&K$1&"*")- COUNTIFS(INDIRECT("'"&$B24&"'!$B:$B"),"*"&K$1&"*",INDIRECT("'"&$B24&"'!$L:$L"),"*") -> 0 | L24: =COUNTIF(INDIRECT("'"&$B24&"'!$L:$L"),"*"&K$1&"*") -> 0 | M24: =COUNTIF(INDIRECT("'"&$B24&"'!$B:$B"),"*"&M$1&"*")- COUNTIFS(INDIRECT("'"&$B24&"'!$B:$B"),"*"&M$1&"*",INDIRECT("'"&$B24&"'!$L:$L"),"*") -> 0 | N24: =COUNTIF(INDIRECT("'"&$B24&"'!$L:$L"),"*"&M$1&"*") -> 0 | O24: =COUNTIF(INDIRECT("'"&$B24&"'!$L:$L"),"*"&O$1&"*") -> 0 | P24: =COUNTIF(INDIRECT("'"&$B24&"'!$L:$L"),"*"&P$1&"*") -> 0 | Q24: =COUNTIF(INDIRECT("'"&$B24&"'!$L:$L"),"*"&Q$1&"*") -> 0 | R24: =COUNTIF(INDIRECT("'"&$B24&"'!$L:$L"),"*"&R$1&"*") -> 0 | S24: =COUNTIF(INDIRECT("'"&$B24&"'!$L:$L"),"*"&S$1&"*") -> 0 | T24: =COUNTIF(INDIRECT("'"&$B24&"'!$L:$L"),"*"&T$1&"*") -> 0 | U24: =COUNTIF(INDIRECT("'"&$B24&"'!$L:$L"),"*"&U$1&"*") -> 0 | V24: =COUNTIF(INDIRECT("'"&$B24&"'!$L:$L"),"*"&V$1&"*") -> 0 | ... AC24: =COUNTIF(INDIRECT("'"&$B24&"'!$L:$L"),"*"&AC$1&"*") -> 0 | AD24: =SUM(C24:AC24) -> 0 | AE24: =AD24*1 -> 0
C25: =COUNTIF(INDIRECT("'"&$B25&"'!$B:$B"),"*"&C$1&"*")- COUNTIFS(INDIRECT("'"&$B25&"'!$B:$B"),"*"&C$1&"*",INDIRECT("'"&$B25&"'!$L:$L"),"*") -> 0 | D25: =COUNTIF(INDIRECT("'"&$B25&"'!$L:$L"),"*"&C$1&"*") -> 0 | E25: =COUNTIF(INDIRECT("'"&$B25&"'!$B:$B"),"*"&E$1&"*")- COUNTIFS(INDIRECT("'"&$B25&"'!$B:$B"),"*"&E$1&"*",INDIRECT("'"&$B25&"'!$L:$L"),"*") -> 0 | F25: =COUNTIF(INDIRECT("'"&$B25&"'!$L:$L"),"*"&E$1&"*") -> 0 | G25: =COUNTIF(INDIRECT("'"&$B25&"'!$B:$B"),"*"&G$1&"*")- COUNTIFS(INDIRECT("'"&$B25&"'!$B:$B"),"*"&G$1&"*",INDIRECT("'"&$B25&"'!$L:$L"),"*") -> 0 | H25: =COUNTIF(INDIRECT("'"&$B25&"'!$L:$L"),"*"&G$1&"*") -> 0 | I25: =COUNTIF(INDIRECT("'"&$B25&"'!$B:$B"),"*"&I$1&"*")- COUNTIFS(INDIRECT("'"&$B25&"'!$B:$B"),"*"&I$1&"*",INDIRECT("'"&$B25&"'!$L:$L"),"*") -> 0 | J25: =COUNTIF(INDIRECT("'"&$B25&"'!$L:$L"),"*"&I$1&"*") -> 0 | K25: =COUNTIF(INDIRECT("'"&$B25&"'!$B:$B"),"*"&K$1&"*")- COUNTIFS(INDIRECT("'"&$B25&"'!$B:$B"),"*"&K$1&"*",INDIRECT("'"&$B25&"'!$L:$L"),"*") -> 0 | L25: =COUNTIF(INDIRECT("'"&$B25&"'!$L:$L"),"*"&K$1&"*") -> 0 | M25: =COUNTIF(INDIRECT("'"&$B25&"'!$B:$B"),"*"&M$1&"*")- COUNTIFS(INDIRECT("'"&$B25&"'!$B:$B"),"*"&M$1&"*",INDIRECT("'"&$B25&"'!$L:$L"),"*") -> 0 | N25: =COUNTIF(INDIRECT("'"&$B25&"'!$L:$L"),"*"&M$1&"*") -> 0 | O25: =COUNTIF(INDIRECT("'"&$B25&"'!$L:$L"),"*"&O$1&"*") -> 0 | P25: =COUNTIF(INDIRECT("'"&$B25&"'!$L:$L"),"*"&P$1&"*") -> 0 | Q25: =COUNTIF(INDIRECT("'"&$B25&"'!$L:$L"),"*"&Q$1&"*") -> 0 | R25: =COUNTIF(INDIRECT("'"&$B25&"'!$L:$L"),"*"&R$1&"*") -> 0 | S25: =COUNTIF(INDIRECT("'"&$B25&"'!$L:$L"),"*"&S$1&"*") -> 0 | T25: =COUNTIF(INDIRECT("'"&$B25&"'!$L:$L"),"*"&T$1&"*") -> 0 | U25: =COUNTIF(INDIRECT("'"&$B25&"'!$L:$L"),"*"&U$1&"*") -> 0 | V25: =COUNTIF(INDIRECT("'"&$B25&"'!$L:$L"),"*"&V$1&"*") -> 0 | ... AC25: =COUNTIF(INDIRECT("'"&$B25&"'!$L:$L"),"*"&AC$1&"*") -> 0 | AD25: =SUM(C25:AC25) -> 0 | AE25: =AD25*1 -> 0
B32: punti TOTALE | C32: =SUM(C3:C31) -> 6 | D32: =SUM(D3:D31) -> 82 | E32: =SUM(E3:E31) -> 5 | F32: =SUM(F3:F31) -> 63 | G32: =SUM(G3:G31) -> 0 | H32: =SUM(H3:H31) -> 36 | I32: =SUM(I3:I31) -> 14 | J32: =SUM(J3:J31) -> 124 | ... AE32: =SUM(AE3:AE31) -> 475
B33: subTOTALE | C33: =C32*1.5 -> 9 | D33: =D32*1 -> 82 | E33: =E32*1.5 -> 7.5 | F33: =F32*1 -> 63 | G33: =G32*1.5 -> 0 | H33: =H32*1 -> 36 | I33: =I32*1.5 -> 21 | J33: =J32*1 -> 124 | K33: =K32*1.5 -> 3 | L33: =L32*1 -> 32 | M33: =M32*1.5 -> 0 | N33: =N32*1 -> 0 | O33: =O32*1 -> 100 | P33: =P32*1 -> 7 | Q33: =Q32*1 -> 4 | R33: =R32*1 -> 0 | S33: =S32*1 -> 0 | T33: =T32*3 -> 0 | U33: =U32*3 -> 0 | V33: =V32*3 -> 0 | W33: =W32*3 -> 0 | X33: =X32*3 -> 0 | Y33: =Y32*3 -> 0
B34: TOTALE | C34: =C33+D33 -> 91 | E34: =E33+F33 -> 70.5 | G34: =G33+H33 -> 36 | I34: =I33+J33 -> 145 | K34: =K33+L33 -> 35 | M34: =M33+N33 -> 0 | O34: =O33 -> 100 | P34: =P33 -> 7 | Q34: =Q33 -> 4 | R34: =R33 -> 0 | S34: =S33 -> 0 | T34: =T33 -> 0 | U34: =U33 -> 0 | V34: =V33 -> 0 | ... Y34: =Y33 -> 0 | AE34: =SUM(C34:AC34) -> 488.5
A35: Legenda: | B35: 1 sede = € 1,50 | C35: 1 codice = € 1,00 | E35: 1 bonus Team = €1,00 | G35: 1 bonus Staff (nome) = €3,00 | I35: Il saldo verrà liquidato a metà luglio 2025 in contanti
B36: SEDE: | C36: la colonna SEDE conta solo se un nome si trova nella colonna che si chiama VENDITA e PAGAMENTO di qualsiasi file collegato a questo Resoconto
B37: CODICE: | C37: la colonna CODICE conta solo se un nome si trova nella colonna che si chiama CODICE SCONTO di qualsiasi file collegato a questo Resoconto

Sheet WS_JASMINE_ANDRIANO
C1: WS_JASMINE ANDRIANO_19APR2026
A2: CHI SCRIVE | B2: VENDITA | C2: DATA INSERIMENTO /RICHIESTA | D2: ID ANAGRAFICA | E2: COGNOME | F2: NOME | G2: TELEFONO | H2: CODICE FISCALE | I2: EMAIL | J2: DATA PAGAMENTO /RICEVUTA | K2: QUOTA | L2: CODICE SCONTO | M2: IMPORTO FINALE | N2: DIGIT/CASH - TESS/NON TESS | O2: PRESENZA | P2: NOTE | Q2: INSERITO SU ATHENA | R2: RICEVUTA FATTA | S2: FATTURA FATTA | T2: VERIFICA PAGAMENTO
C3: 14:30-16:00_COMMERCIAL (€32 entro il 18 Marzo compreso → €37 dal 19 Marzo al 18 Aprile compreso → €42 il giorno stesso)
A4: Estefany | B4: ONLINE | C4: 46065 | E4: CARRIERA | F4: MARTA | G4: 3770848139 | H4: CRRMRT00P67G388G | I4: mcarriera27@gmail.com | J4: 46065 | K4: 32 | L4: ALEXANDRA02WS | M4: =IFERROR(__xludf.DUMMYFUNCTION("IF( K4="""", """", ROUND( IF( L4="""", K4, IF( ISERROR(FIND(""-"",L4)), K4 - VALUE(REGEXEXTRACT(L4,""(\d+)"")), K4 * (1 - VALUE(REGEXEXTRACT(L4,""(\d+)""))/100) ) ), 2 ) ) "),30.0) -> 30 | N4: DIGIT - NON TESSERATO | O4: FALSE | Q4: INSERITO | R4: FALSE | S4: TRUE | T4: TRUE
A5: Estefany | B5: ONLINE | C5: 46094 | E5: KOSTANECKA | F5: ALEKSANDRA | G5: 3478569980 | H5: KSTLSN05A68Z127Q | I5: ola.kostanecka2005@gmail.com | J5: 46094 | K5: 32 | M5: =IFERROR(__xludf.DUMMYFUNCTION("IF( K5="""", """", ROUND( IF( L5="""", K5, IF( ISERROR(FIND(""-"",L5)), K5 - VALUE(REGEXEXTRACT(L5,""(\d+)"")), K5 * (1 - VALUE(REGEXEXTRACT(L5,""(\d+)""))/100) ) ), 2 ) ) "),32.0) -> 32 | N5: DIGIT - NON TESSERATO | O5: FALSE | Q5: INSERITO | R5: FALSE | S5: TRUE | T5: TRUE
A6: Estefany | B6: ONLINE | C6: 46078 | E6: LUNGHI | F6: REBECCA | G6: 3463062200 | H6: LNGRCC05R48B300Y | I6: rebeccalunghi@gmail.com | J6: 46078 | K6: 37 | M6: =IFERROR(__xludf.DUMMYFUNCTION("IF( K6="""", """", ROUND( IF( L6="""", K6, IF( ISERROR(FIND(""-"",L6)), K6 - VALUE(REGEXEXTRACT(L6,""(\d+)"")), K6 * (1 - VALUE(REGEXEXTRACT(L6,""(\d+)""))/100) ) ), 2 ) ) "),37.0) -> 37 | N6: DIGIT - NON TESSERATO | O6: FALSE | Q6: INSERITO | R6: FALSE | S6: TRUE | T6: TRUE
A7: Estefany | B7: ONLINE | C7: 46078 | E7: ESPINOZA | F7: CAMILLA | G7: 3711436102 | H7: SPNSLY03B44Z605H | I7: ce200304@gmail.com | J7: 46078 | K7: 37 | M7: =IFERROR(__xludf.DUMMYFUNCTION("IF( K7="""", """", ROUND( IF( L7="""", K7, IF( ISERROR(FIND(""-"",L7)), K7 - VALUE(REGEXEXTRACT(L7,""(\d+)"")), K7 * (1 - VALUE(REGEXEXTRACT(L7,""(\d+)""))/100) ) ), 2 ) ) "),37.0) -> 37 | N7: DIGIT - NON TESSERATO | O7: FALSE | Q7: INSERITO | R7: FALSE | S7: TRUE | T7: TRUE
A8: Estefany | B8: SEDE Estefany | C8: 46097 | E8: CAMPAGNA | F8: ALESSIO | G8: 3517240804 | H8: CMPLSS98A21H501J | I8: alessiotcgtrade@gmail.com | J8: 46097 | K8: 32 | L8: ESTEFANY02WS | M8: =IFERROR(__xludf.DUMMYFUNCTION("IF( K8="""", """", ROUND( IF( L8="""", K8, IF( ISERROR(FIND(""-"",L8)), K8 - VALUE(REGEXEXTRACT(L8,""(\d+)"")), K8 * (1 - VALUE(REGEXEXTRACT(L8,""(\d+)""))/100) ) ), 2 ) ) "),30.0) -> 30 | N8: DIGIT - TESSERATO | O8: FALSE | Q8: INSERITO | R8: TRUE | S8: TRUE | T8: TRUE
A9: Nura | B9: SEDE Nura | C9: 46098 | E9: MAMMANO | F9: SARA | G9: 3497813495 | H9: MMMSRA06R61F205O | I9: carlotta.contina01@gmail.com | J9: 46098 | K9: 32 | L9: NURA02WS | M9: =IFERROR(__xludf.DUMMYFUNCTION("IF( K9="""", """", ROUND( IF( L9="""", K9, IF( ISERROR(FIND(""-"",L9)), K9 - VALUE(REGEXEXTRACT(L9,""(\d+)"")), K9 * (1 - VALUE(REGEXEXTRACT(L9,""(\d+)""))/100) ) ), 2 ) ) "),30.0) -> 30 | N9: DIGIT - TESSERATO | O9: FALSE | Q9: INSERITO | R9: FALSE | S9: TRUE | T9: TRUE
A10: Estefany | B10: ONLINE | C10: 46099 | E10: SITNIKOVA | F10: SOFIIA | G10: 3511913556 | H10: STNSFO06R59Z138C | I10: sitnikovasofiia42@gmail.com | J10: 46099 | K10: 32 | M10: =IFERROR(__xludf.DUMMYFUNCTION("IF( K10="""", """", ROUND( IF( L10="""", K10, IF( ISERROR(FIND(""-"",L10)), K10 - VALUE(REGEXEXTRACT(L10,""(\d+)"")), K10 * (1 - VALUE(REGEXEXTRACT(L10,""(\d+)""))/100) ) ), 2 ) ) "),32.0) -> 32 | N10: DIGIT - NON TESSERATO | O10: FALSE | Q10: INSERITO | R10: FALSE | S10: TRUE | T10: TRUE
A11: Estefany | B11: ONLINE | C11: 46102 | E11: ALVARADO | F11: ANTONELL | G11: 3444243088 | H11: LVRNNL03D61Z511D | I11: antonella.alvarado13@gmail.com | J11: 46102 | K11: 37 | M11: =IFERROR(__xludf.DUMMYFUNCTION("IF( K11="""", """", ROUND( IF( L11="""", K11, IF( ISERROR(FIND(""-"",L11)), K11 - VALUE(REGEXEXTRACT(L11,""(\d+)"")), K11 * (1 - VALUE(REGEXEXTRACT(L11,""(\d+)""))/100) ) ), 2 ) ) "),37.0) -> 37 | N11: DIGIT - TESSERATO | O11: FALSE | Q11: INSERITO | R11: TRUE | S11: FALSE | T11: TRUE
M12: =IFERROR(__xludf.DUMMYFUNCTION("IF( K12="""", """", ROUND( IF( L12="""", K12, IF( ISERROR(FIND(""-"",L12)), K12 - VALUE(REGEXEXTRACT(L12,""(\d+)"")), K12 * (1 - VALUE(REGEXEXTRACT(L12,""(\d+)""))/100) ) ), 2 ) ) ")," ") | O12: FALSE | R12: FALSE | S12: FALSE | T12: FALSE
M13: =IFERROR(__xludf.DUMMYFUNCTION("IF( K13="""", """", ROUND( IF( L13="""", K13, IF( ISERROR(FIND(""-"",L13)), K13 - VALUE(REGEXEXTRACT(L13,""(\d+)"")), K13 * (1 - VALUE(REGEXEXTRACT(L13,""(\d+)""))/100) ) ), 2 ) ) ")," ") | O13: FALSE | R13: FALSE | S13: FALSE | T13: FALSE
M14: =IFERROR(__xludf.DUMMYFUNCTION("IF( K14="""", """", ROUND( IF( L14="""", K14, IF( ISERROR(FIND(""-"",L14)), K14 - VALUE(REGEXEXTRACT(L14,""(\d+)"")), K14 * (1 - VALUE(REGEXEXTRACT(L14,""(\d+)""))/100) ) ), 2 ) ) ")," ") | O14: FALSE | R14: FALSE | S14: FALSE | T14: FALSE
M15: =IFERROR(__xludf.DUMMYFUNCTION("IF( K15="""", """", ROUND( IF( L15="""", K15, IF( ISERROR(FIND(""-"",L15)), K15 - VALUE(REGEXEXTRACT(L15,""(\d+)"")), K15 * (1 - VALUE(REGEXEXTRACT(L15,""(\d+)""))/100) ) ), 2 ) ) ")," ") | O15: FALSE | R15: FALSE | S15: FALSE | T15: FALSE
G16: SMS E MAIL INVIATE | M16: =IFERROR(__xludf.DUMMYFUNCTION("IF( K16="""", """", ROUND( IF( L16="""", K16, IF( ISERROR(FIND(""-"",L16)), K16 - VALUE(REGEXEXTRACT(L16,""(\d+)"")), K16 * (1 - VALUE(REGEXEXTRACT(L16,""(\d+)""))/100) ) ), 2 ) ) ")," ") | O16: FALSE | R16: FALSE | S16: FALSE | T16: FALSE
M17: =IFERROR(__xludf.DUMMYFUNCTION("IF( K17="""", """", ROUND( IF( L17="""", K17, IF( ISERROR(FIND(""-"",L17)), K17 - VALUE(REGEXEXTRACT(L17,""(\d+)"")), K17 * (1 - VALUE(REGEXEXTRACT(L17,""(\d+)""))/100) ) ), 2 ) ) ")," ") | O17: FALSE | R17: FALSE | S17: FALSE | T17: FALSE
M18: =IFERROR(__xludf.DUMMYFUNCTION("IF( K18="""", """", ROUND( IF( L18="""", K18, IF( ISERROR(FIND(""-"",L18)), K18 - VALUE(REGEXEXTRACT(L18,""(\d+)"")), K18 * (1 - VALUE(REGEXEXTRACT(L18,""(\d+)""))/100) ) ), 2 ) ) ")," ") | O18: FALSE | R18: FALSE | S18: FALSE | T18: FALSE
M19: =IFERROR(__xludf.DUMMYFUNCTION("IF( K19="""", """", ROUND( IF( L19="""", K19, IF( ISERROR(FIND(""-"",L19)), K19 - VALUE(REGEXEXTRACT(L19,""(\d+)"")), K19 * (1 - VALUE(REGEXEXTRACT(L19,""(\d+)""))/100) ) ), 2 ) ) ")," ") | O19: FALSE | R19: FALSE | S19: FALSE | T19: FALSE
M20: =IFERROR(__xludf.DUMMYFUNCTION("IF( K20="""", """", ROUND( IF( L20="""", K20, IF( ISERROR(FIND(""-"",L20)), K20 - VALUE(REGEXEXTRACT(L20,""(\d+)"")), K20 * (1 - VALUE(REGEXEXTRACT(L20,""(\d+)""))/100) ) ), 2 ) ) ")," ") | O20: FALSE | R20: FALSE | S20: FALSE | T20: FALSE
M21: =IFERROR(__xludf.DUMMYFUNCTION("IF( K21="""", """", ROUND( IF( L21="""", K21, IF( ISERROR(FIND(""-"",L21)), K21 - VALUE(REGEXEXTRACT(L21,""(\d+)"")), K21 * (1 - VALUE(REGEXEXTRACT(L21,""(\d+)""))/100) ) ), 2 ) ) ")," ") | O21: FALSE | R21: FALSE | S21: FALSE | T21: FALSE
M22: =IFERROR(__xludf.DUMMYFUNCTION("IF( K22="""", """", ROUND( IF( L22="""", K22, IF( ISERROR(FIND(""-"",L22)), K22 - VALUE(REGEXEXTRACT(L22,""(\d+)"")), K22 * (1 - VALUE(REGEXEXTRACT(L22,""(\d+)""))/100) ) ), 2 ) ) ")," ") | O22: FALSE | R22: FALSE | S22: FALSE | T22: FALSE
M23: =IFERROR(__xludf.DUMMYFUNCTION("IF( K23="""", """", ROUND( IF( L23="""", K23, IF( ISERROR(FIND(""-"",L23)), K23 - VALUE(REGEXEXTRACT(L23,""(\d+)"")), K23 * (1 - VALUE(REGEXEXTRACT(L23,""(\d+)""))/100) ) ), 2 ) ) ")," ") | O23: FALSE | R23: FALSE | S23: FALSE | T23: FALSE
M24: =IFERROR(__xludf.DUMMYFUNCTION("IF( K24="""", """", ROUND( IF( L24="""", K24, IF( ISERROR(FIND(""-"",L24)), K24 - VALUE(REGEXEXTRACT(L24,""(\d+)"")), K24 * (1 - VALUE(REGEXEXTRACT(L24,""(\d+)""))/100) ) ), 2 ) ) ")," ") | O24: FALSE | R24: FALSE | S24: FALSE | T24: FALSE
M25: =IFERROR(__xludf.DUMMYFUNCTION("IF( K25="""", """", ROUND( IF( L25="""", K25, IF( ISERROR(FIND(""-"",L25)), K25 - VALUE(REGEXEXTRACT(L25,""(\d+)"")), K25 * (1 - VALUE(REGEXEXTRACT(L25,""(\d+)""))/100) ) ), 2 ) ) ")," ") | O25: FALSE | R25: FALSE | S25: FALSE | T25: FALSE
M26: =IFERROR(__xludf.DUMMYFUNCTION("IF( K26="""", """", ROUND( IF( L26="""", K26, IF( ISERROR(FIND(""-"",L26)), K26 - VALUE(REGEXEXTRACT(L26,""(\d+)"")), K26 * (1 - VALUE(REGEXEXTRACT(L26,""(\d+)""))/100) ) ), 2 ) ) ")," ") | O26: FALSE | R26: FALSE | S26: FALSE | T26: FALSE
M27: =IFERROR(__xludf.DUMMYFUNCTION("IF( K27="""", """", ROUND( IF( L27="""", K27, IF( ISERROR(FIND(""-"",L27)), K27 - VALUE(REGEXEXTRACT(L27,""(\d+)"")), K27 * (1 - VALUE(REGEXEXTRACT(L27,""(\d+)""))/100) ) ), 2 ) ) ")," ") | O27: FALSE | R27: FALSE | S27: FALSE | T27: FALSE
M28: =IFERROR(__xludf.DUMMYFUNCTION("IF( K28="""", """", ROUND( IF( L28="""", K28, IF( ISERROR(FIND(""-"",L28)), K28 - VALUE(REGEXEXTRACT(L28,""(\d+)"")), K28 * (1 - VALUE(REGEXEXTRACT(L28,""(\d+)""))/100) ) ), 2 ) ) ")," ") | O28: FALSE | R28: FALSE | S28: FALSE | T28: FALSE
M29: =IFERROR(__xludf.DUMMYFUNCTION("IF( K29="""", """", ROUND( IF( L29="""", K29, IF( ISERROR(FIND(""-"",L29)), K29 - VALUE(REGEXEXTRACT(L29,""(\d+)"")), K29 * (1 - VALUE(REGEXEXTRACT(L29,""(\d+)""))/100) ) ), 2 ) ) ")," ") | O29: FALSE | R29: FALSE | S29: FALSE | T29: FALSE
M30: =IFERROR(__xludf.DUMMYFUNCTION("IF( K30="""", """", ROUND( IF( L30="""", K30, IF( ISERROR(FIND(""-"",L30)), K30 - VALUE(REGEXEXTRACT(L30,""(\d+)"")), K30 * (1 - VALUE(REGEXEXTRACT(L30,""(\d+)""))/100) ) ), 2 ) ) ")," ") | O30: FALSE | R30: FALSE | S30: FALSE | T30: FALSE
M31: =IFERROR(__xludf.DUMMYFUNCTION("IF( K31="""", """", ROUND( IF( L31="""", K31, IF( ISERROR(FIND(""-"",L31)), K31 - VALUE(REGEXEXTRACT(L31,""(\d+)"")), K31 * (1 - VALUE(REGEXEXTRACT(L31,""(\d+)""))/100) ) ), 2 ) ) ")," ") | O31: FALSE | R31: FALSE | S31: FALSE | T31: FALSE
M32: =IFERROR(__xludf.DUMMYFUNCTION("IF( K32="""", """", ROUND( IF( L32="""", K32, IF( ISERROR(FIND(""-"",L32)), K32 - VALUE(REGEXEXTRACT(L32,""(\d+)"")), K32 * (1 - VALUE(REGEXEXTRACT(L32,""(\d+)""))/100) ) ), 2 ) ) ")," ") | O32: FALSE | R32: FALSE | S32: FALSE | T32: FALSE
M33: =IFERROR(__xludf.DUMMYFUNCTION("IF( K33="""", """", ROUND( IF( L33="""", K33, IF( ISERROR(FIND(""-"",L33)), K33 - VALUE(REGEXEXTRACT(L33,""(\d+)"")), K33 * (1 - VALUE(REGEXEXTRACT(L33,""(\d+)""))/100) ) ), 2 ) ) ")," ") | O33: FALSE | R33: FALSE | S33: FALSE | T33: FALSE
M34: =IFERROR(__xludf.DUMMYFUNCTION("IF( K34="""", """", ROUND( IF( L34="""", K34, IF( ISERROR(FIND(""-"",L34)), K34 - VALUE(REGEXEXTRACT(L34,""(\d+)"")), K34 * (1 - VALUE(REGEXEXTRACT(L34,""(\d+)""))/100) ) ), 2 ) ) ")," ") | O34: FALSE | R34: FALSE | S34: FALSE | T34: FALSE
M35: =IFERROR(__xludf.DUMMYFUNCTION("IF( K35="""", """", ROUND( IF( L35="""", K35, IF( ISERROR(FIND(""-"",L35)), K35 - VALUE(REGEXEXTRACT(L35,""(\d+)"")), K35 * (1 - VALUE(REGEXEXTRACT(L35,""(\d+)""))/100) ) ), 2 ) ) ")," ") | O35: FALSE | R35: FALSE | S35: FALSE | T35: FALSE
M36: =IFERROR(__xludf.DUMMYFUNCTION("IF( K36="""", """", ROUND( IF( L36="""", K36, IF( ISERROR(FIND(""-"",L36)), K36 - VALUE(REGEXEXTRACT(L36,""(\d+)"")), K36 * (1 - VALUE(REGEXEXTRACT(L36,""(\d+)""))/100) ) ), 2 ) ) ")," ") | O36: FALSE | R36: FALSE | S36: FALSE | T36: FALSE
M37: =IFERROR(__xludf.DUMMYFUNCTION("IF( K37="""", """", ROUND( IF( L37="""", K37, IF( ISERROR(FIND(""-"",L37)), K37 - VALUE(REGEXEXTRACT(L37,""(\d+)"")), K37 * (1 - VALUE(REGEXEXTRACT(L37,""(\d+)""))/100) ) ), 2 ) ) ")," ") | O37: FALSE | R37: FALSE | S37: FALSE | T37: FALSE
M38: =IFERROR(__xludf.DUMMYFUNCTION("IF( K38="""", """", ROUND( IF( L38="""", K38, IF( ISERROR(FIND(""-"",L38)), K38 - VALUE(REGEXEXTRACT(L38,""(\d+)"")), K38 * (1 - VALUE(REGEXEXTRACT(L38,""(\d+)""))/100) ) ), 2 ) ) ")," ") | O38: FALSE | R38: FALSE | S38: FALSE | T38: FALSE
M39: =IFERROR(__xludf.DUMMYFUNCTION("IF( K39="""", """", ROUND( IF( L39="""", K39, IF( ISERROR(FIND(""-"",L39)), K39 - VALUE(REGEXEXTRACT(L39,""(\d+)"")), K39 * (1 - VALUE(REGEXEXTRACT(L39,""(\d+)""))/100) ) ), 2 ) ) ")," ") | O39: FALSE | R39: FALSE | S39: FALSE | T39: FALSE
M40: =IFERROR(__xludf.DUMMYFUNCTION("IF( K40="""", """", ROUND( IF( L40="""", K40, IF( ISERROR(FIND(""-"",L40)), K40 - VALUE(REGEXEXTRACT(L40,""(\d+)"")), K40 * (1 - VALUE(REGEXEXTRACT(L40,""(\d+)""))/100) ) ), 2 ) ) ")," ") | O40: FALSE | R40: FALSE | S40: FALSE | T40: FALSE
...

Sheet OC_AMBERALDRIN
C1: OC_AMBERALDRIN_15MAR2026
A2: CHI SCRIVE | B2: VENDITA | C2: DATA INSERIMENTO /RICHIESTA | D2: ID ANAGRAFICA | E2: COGNOME | F2: NOME | G2: TELEFONO | H2: CODICE FISCALE | I2: EMAIL | J2: DATA PAGAMENTO /RICEVUTA | K2: QUOTA | L2: CODICE SCONTO | M2: IMPORTO FINALE | N2: DIGIT/CASH - TESS/NON TESS | O2: PRESENZA | P2: NOTE | Q2: INSERITO SU ATHENA | R2: RICEVUTA FATTA | S2: FATTURA FATTA | T2: VERIFICA PAGAMENTO
C3: 14:30-16:30_URBAN COREOGRAFICO (€32 entro il 14/03 compreso → €37 il giorno stesso)
A4: Estefany | B4: ONLINE | C4: 46070 | D4: ID-000398 | E4: BRUZZESE | F4: ALISEA | G4: 3490659648 | H4: BRZLSA96L57F205J | I4: alisea.bruzzese@gmail.com | J4: 46070 | K4: 32 | L4: NURA02WS | M4: =IFERROR(__xludf.DUMMYFUNCTION("IF( K4="""", """", ROUND( IF( L4="""", K4, IF( ISERROR(FIND(""-"",L4)), K4 - VALUE(REGEXEXTRACT(L4,""(\d+)"")), K4 * (1 - VALUE(REGEXEXTRACT(L4,""(\d+)""))/100) ) ), 2 ) ) "),30.0) -> 30 | N4: DIGIT - TESSERATO | O4: TRUE | Q4: INSERITO | R4: TRUE | S4: FALSE | T4: TRUE
A5: Estefany | B5: ONLINE | C5: 46072 | D5: ID-000137 | E5: RAMBALDI | F5: ROBERTA | G5: 3313419879 | H5: RMBRRT96T64F205N | I5: rambaldi.roberta6@gmail.com | J5: 46072 | K5: 32 | L5: NURA02WS | M5: =IFERROR(__xludf.DUMMYFUNCTION("IF( K5="""", """", ROUND( IF( L5="""", K5, IF( ISERROR(FIND(""-"",L5)), K5 - VALUE(REGEXEXTRACT(L5,""(\d+)"")), K5 * (1 - VALUE(REGEXEXTRACT(L5,""(\d+)""))/100) ) ), 2 ) ) "),30.0) -> 30 | N5: DIGIT - TESSERATO | O5: TRUE | Q5: INSERITO | R5: TRUE | S5: FALSE | T5: TRUE
A6: Estefany | B6: ONLINE | C6: 46076 | D6: ID-000760 | E6: BINARELLI | F6: BEATRICE | G6: 3343934888 | H6: BNRBRC09B57H501G | I6: chiarabiselli@hotmail.com | J6: 46076 | K6: 32 | M6: =IFERROR(__xludf.DUMMYFUNCTION("IF( K6="""", """", ROUND( IF( L6="""", K6, IF( ISERROR(FIND(""-"",L6)), K6 - VALUE(REGEXEXTRACT(L6,""(\d+)"")), K6 * (1 - VALUE(REGEXEXTRACT(L6,""(\d+)""))/100) ) ), 2 ) ) "),32.0) -> 32 | N6: DIGIT - TESSERATO | O6: TRUE | Q6: INSERITO | R6: TRUE | S6: FALSE | T6: TRUE
A7: Estefany | B7: ONLINE | C7: 46077 | E7: REYES RODRIGUEZ | F7: CHRISTIAN MICHEL | G7: 3481955108 | H7: RYSCRS90C08Z514J | I7: Michel.9017@libero.it | J7: 46077 | K7: 32 | M7: =IFERROR(__xludf.DUMMYFUNCTION("IF( K7="""", """", ROUND( IF( L7="""", K7, IF( ISERROR(FIND(""-"",L7)), K7 - VALUE(REGEXEXTRACT(L7,""(\d+)"")), K7 * (1 - VALUE(REGEXEXTRACT(L7,""(\d+)""))/100) ) ), 2 ) ) "),32.0) -> 32 | N7: DIGIT - NON TESSERATO | O7: TRUE | Q7: INSERITO | R7: FALSE | S7: TRUE | T7: TRUE
A8: Estefany | B8: SEDE Estefany | C8: 46081 | D8: ID-000109 | E8: GALARDO | F8: CAMILLA | G8: 3389088473 | H8: GLRCLL09M57B354T | I8: perillimarta@gmail.com | J8: 46081 | K8: 32 | L8: ESTEFANY02WS | M8: =IFERROR(__xludf.DUMMYFUNCTION("IF( K8="""", """", ROUND( IF( L8="""", K8, IF( ISERROR(FIND(""-"",L8)), K8 - VALUE(REGEXEXTRACT(L8,""(\d+)"")), K8 * (1 - VALUE(REGEXEXTRACT(L8,""(\d+)""))/100) ) ), 2 ) ) "),30.0) -> 30 | N8: CASH - TESSERATO | O8: TRUE | Q8: INSERITO | R8: TRUE | S8: FALSE | T8: TRUE
A9: Estefany | B9: ONLINE | C9: 46082 | D9: ID-000440 | E9: CRIPPA | F9: GIULIA | G9: 3342145266 | H9: CRPGLI95E70A944Q | I9: giuliacrippa0@icloud.com | J9: 46082 | K9: 32 | M9: =IFERROR(__xludf.DUMMYFUNCTION("IF( K9="""", """", ROUND( IF( L9="""", K9, IF( ISERROR(FIND(""-"",L9)), K9 - VALUE(REGEXEXTRACT(L9,""(\d+)"")), K9 * (1 - VALUE(REGEXEXTRACT(L9,""(\d+)""))/100) ) ), 2 ) ) "),32.0) -> 32 | N9: DIGIT - TESSERATO | O9: TRUE | Q9: INSERITO | R9: TRUE | S9: FALSE | T9: TRUE
A10: Nura | B10: SEDE Nura | C10: 46087 | E10: TAGLIAVENTO | F10: GIULIA | G10: 3342627444 | H10: TGLGLI98L51H211P | I10: giuliatagliavento98@gmail.com | J10: 46087 | K10: 32 | M10: =IFERROR(__xludf.DUMMYFUNCTION("IF( K10="""", """", ROUND( IF( L10="""", K10, IF( ISERROR(FIND(""-"",L10)), K10 - VALUE(REGEXEXTRACT(L10,""(\d+)"")), K10 * (1 - VALUE(REGEXEXTRACT(L10,""(\d+)""))/100) ) ), 2 ) ) "),32.0) -> 32 | N10: DIGIT - TESSERATO | O10: TRUE | Q10: INSERITO | R10: TRUE | S10: FALSE | T10: TRUE
A11: Nura | B11: SEDE Nura | C11: 46087 | E11: PAOLO | F11: ROCCO | G11: 3487100315 | H11: RCCPLA70E23H264S | I11: castore@live.it | J11: 46087 | K11: 32 | L11: NURA02WS | M11: =IFERROR(__xludf.DUMMYFUNCTION("IF( K11="""", """", ROUND( IF( L11="""", K11, IF( ISERROR(FIND(""-"",L11)), K11 - VALUE(REGEXEXTRACT(L11,""(\d+)"")), K11 * (1 - VALUE(REGEXEXTRACT(L11,""(\d+)""))/100) ) ), 2 ) ) "),30.0) -> 30 | N11: DIGIT - TESSERATO | O11: TRUE | Q11: INSERITO | R11: TRUE | S11: FALSE | T11: TRUE
A12: Estefany | B12: ONLINE | C12: 46089 | E12: BRUZZESE | F12: ASIA | G12: 3337205209 | H12: BRZSAI03A41F205V | I12: asiabruzzese@gmail.com | J12: 46089 | K12: 32 | L12: NURA02WS | M12: =IFERROR(__xludf.DUMMYFUNCTION("IF( K12="""", """", ROUND( IF( L12="""", K12, IF( ISERROR(FIND(""-"",L12)), K12 - VALUE(REGEXEXTRACT(L12,""(\d+)"")), K12 * (1 - VALUE(REGEXEXTRACT(L12,""(\d+)""))/100) ) ), 2 ) ) "),30.0) -> 30 | N12: DIGIT - NON TESSERATO | O12: TRUE | Q12: INSERITO | R12: FALSE | S12: TRUE | T12: TRUE
A13: Estefany | B13: ONLINE | C13: 46090 | D13: ID-000803 | E13: PARATI | F13: SOFIA | G13: 3495601535 | H13: PRTSFO10L62I577J | I13: sara.garlati@gmail.com | J13: 46090 | K13: 32 | L13: ALEXANDRA02WS | M13: =IFERROR(__xludf.DUMMYFUNCTION("IF( K13="""", """", ROUND( IF( L13="""", K13, IF( ISERROR(FIND(""-"",L13)), K13 - VALUE(REGEXEXTRACT(L13,""(\d+)"")), K13 * (1 - VALUE(REGEXEXTRACT(L13,""(\d+)""))/100) ) ), 2 ) ) "),30.0) -> 30 | N13: DIGIT - TESSERATO | O13: TRUE | Q13: INSERITO | R13: TRUE | S13: FALSE | T13: TRUE
A14: Estefany | B14: ONLINE | C14: 46093 | D14: ID-000479 | E14: VENTURA | F14: GINEVRA | G14: 3400552152 | H14: VNTGVR10T50F205J | I14: chiaravenvi@gmail.com | J14: 46093 | K14: 32 | M14: =IFERROR(__xludf.DUMMYFUNCTION("IF( K14="""", """", ROUND( IF( L14="""", K14, IF( ISERROR(FIND(""-"",L14)), K14 - VALUE(REGEXEXTRACT(L14,""(\d+)"")), K14 * (1 - VALUE(REGEXEXTRACT(L14,""(\d+)""))/100) ) ), 2 ) ) "),32.0) -> 32 | N14: DIGIT - TESSERATO | O14: TRUE | Q14: INSERITO | R14: TRUE | S14: FALSE | T14: TRUE
A15: Estefany | B15: ONLINE | C15: 46092 | E15: CUELA | F15: ANTONIA | G15: 3513213519 | H15: CLUNNC02P55Z129J | I15: antoniaculea3@gmail.com | J15: 46092 | K15: 32 | M15: =IFERROR(__xludf.DUMMYFUNCTION("IF( K15="""", """", ROUND( IF( L15="""", K15, IF( ISERROR(FIND(""-"",L15)), K15 - VALUE(REGEXEXTRACT(L15,""(\d+)"")), K15 * (1 - VALUE(REGEXEXTRACT(L15,""(\d+)""))/100) ) ), 2 ) ) "),32.0) -> 32 | N15: DIGIT - NON TESSERATO | O15: TRUE | Q15: INSERITO | R15: FALSE | S15: TRUE | T15: TRUE
A16: Estefany | B16: ONLINE | C16: 46094 | D16: ID-002534 | E16: DE PANDIS | F16: BEATRICE | G16: 3382295075 | H16: DPNBRC06S46B157K | I16: beadepa@virgilio.it | J16: 46094 | K16: 32 | M16: =IFERROR(__xludf.DUMMYFUNCTION("IF( K16="""", """", ROUND( IF( L16="""", K16, IF( ISERROR(FIND(""-"",L16)), K16 - VALUE(REGEXEXTRACT(L16,""(\d+)"")), K16 * (1 - VALUE(REGEXEXTRACT(L16,""(\d+)""))/100) ) ), 2 ) ) "),32.0) -> 32 | N16: DIGIT - TESSERATO | O16: TRUE | Q16: INSERITO | R16: TRUE | S16: FALSE | T16: TRUE
